W0116 14:07:21.548828       1 options.go:272] Neither --kubeconfig nor --master was specified. Using default API client. This might not work.
I0116 14:07:21.550319       1 server.go:128] Version: v0.0.0-master+$Format:%h$
W0116 14:07:21.550340       1 defaults.go:207] TaintNodesByCondition is enabled, PodToleratesNodeTaints predicate is mandatory
I0116 14:07:21.550576       1 factory.go:1530] [tanle] LogComplTimeFeature %!s(bool=true)
I0116 14:07:21.550593       1 generic_scheduler.go:1830] version 1.11: 2018.10.29 4:00 EUROSYS1.3
I0116 14:07:21.550597       1 generic_scheduler.go:1832] ENABLE_PROFILING true
I0116 14:07:21.550600       1 generic_scheduler.go:1834] ============= IRA =============
I0116 14:07:21.550604       1 generic_scheduler.go:1835] IS_TEST: false
I0116 14:07:21.550610       1 generic_scheduler.go:1836] QUEUED_UP_JOBS: 40
I0116 14:07:21.550614       1 generic_scheduler.go:1837] NUM_USERS: 4
I0116 14:07:21.550617       1 generic_scheduler.go:1838] SCHEDULER AlloX
I0116 14:07:21.550623       1 generic_scheduler.go:1839] NUM_RESERVE_CPU_NODE %!s(int=1)
I0116 14:07:21.550627       1 generic_scheduler.go:1840] ENABLE_MOCKUP_GPU %!s(bool=false)
I0116 14:07:21.550635       1 util.go:369] [tanle] WORK around capacity &{176000 68719476736 0 0 map[ucare.cs.uchicago.edu/e-gpu:4]}
W0116 14:07:21.551517       1 authorization.go:47] Authorization is disabled
W0116 14:07:21.551735       1 authentication.go:55] Authentication is disabled
I0116 14:07:21.551758       1 deprecated_insecure_serving.go:48] Serving healthz insecurely on [::]:10251
I0116 14:07:22.452455       1 controller_utils.go:1027] Waiting for caches to sync for scheduler controller
I0116 14:07:22.552540       1 controller_utils.go:1034] Caches are synced for scheduler controller
I0116 14:07:57.976825       1 scheduling_queue.go:193] [meng] set schedule time to 2024-01-16 14:07:57.976816012 +0000 UTC m=+36.465717832
I0116 14:07:57.976850       1 util.go:1534] [meng] calling OnlineAlloX
I0116 14:07:57.976921       1 util.go:1550] [meng] numAvailMachines == 15,  allpods length: 40
I0116 14:07:57.977452       1 util.go:1631] input  D: [[0 0 0 0 0 0 0 0 0 0 0 0 0 0 0 0 0 0 0 0 0 0 0 0 0 0 0 0 0 0 0 0 0 0 0 0 0 0 0 0] [0 0 0 0 0 0 0 0 0 0 0 0 0 0 0 0 0 0 0 0 0 0 0 0 0 0 0 0 0 0 0 0 0 0 0 0 0 0 0 0] [0 0 0 0 0 0 0 0 0 0 0 0 0 0 0 0 0 0 0 0 0 0 0 0 0 0 0 0 0 0 0 0 0 0 0 0 0 0 0 0] [0 0 0 0 0 0 0 0 0 0 0 0 0 0 0 0 0 0 0 0 0 0 0 0 0 0 0 0 0 0 0 0 0 0 0 0 0 0 0 0] [0 0 0 0 0 0 0 0 0 0 0 0 0 0 0 0 0 0 0 0 0 0 0 0 0 0 0 0 0 0 0 0 0 0 0 0 0 0 0 0] [0 0 0 0 0 0 0 0 0 0 0 0 0 0 0 0 0 0 0 0 0 0 0 0 0 0 0 0 0 0 0 0 0 0 0 0 0 0 0 0] [0 0 0 0 0 0 0 0 0 0 0 0 0 0 0 0 0 0 0 0 0 0 0 0 0 0 0 0 0 0 0 0 0 0 0 0 0 0 0 0] [0 0 0 0 0 0 0 0 0 0 0 0 0 0 0 0 0 0 0 0 0 0 0 0 0 0 0 0 0 0 0 0 0 0 0 0 0 0 0 0] [0 0 0 0 0 0 0 0 0 0 0 0 0 0 0 0 0 0 0 0 0 0 0 0 0 0 0 0 0 0 0 0 0 0 0 0 0 0 0 0] [0 0 0 0 0 0 0 0 0 0 0 0 0 0 0 0 0 0 0 0 0 0 0 0 0 0 0 0 0 0 0 0 0 0 0 0 0 0 0 0] [0 0 0 0 0 0 0 0 0 0 0 0 0 0 0 0 0 0 0 0 0 0 0 0 0 0 0 0 0 0 0 0 0 0 0 0 0 0 0 0] [0 0 0 0 0 0 0 0 0 0 0 0 0 0 0 0 0 0 0 0 0 0 0 0 0 0 0 0 0 0 0 0 0 0 0 0 0 0 0 0] [0 0 0 0 0 0 0 0 0 0 0 0 0 0 0 0 0 0 0 0 0 0 0 0 0 0 0 0 0 0 0 0 0 0 0 0 0 0 0 0] [0 0 0 0 0 0 0 0 0 0 0 0 0 0 0 0 0 0 0 0 0 0 0 0 0 0 0 0 0 0 0 0 0 0 0 0 0 0 0 0] [0 0 0 0 0 0 0 0 0 0 0 0 0 0 0 0 0 0 0 0 0 0 0 0 0 0 0 0 0 0 0 0 0 0 0 0 0 0 0 0]]
I0116 14:07:57.977543       1 util.go:1632] input  P: [[8 13 9 21 10 7 21 13 7 13 21 8 10 21 7 13 14 28 8 13 14 14 9 8 9 13 10 21 21 21 13 21 10 28 13 28 9 28 7 14] [8 13 9 21 10 7 21 13 7 13 21 8 10 21 7 13 14 28 8 13 14 14 9 8 9 13 10 21 21 21 13 21 10 28 13 28 9 28 7 14] [8 13 9 21 10 7 21 13 7 13 21 8 10 21 7 13 14 28 8 13 14 14 9 8 9 13 10 21 21 21 13 21 10 28 13 28 9 28 7 14] [8 13 9 21 10 7 21 13 7 13 21 8 10 21 7 13 14 28 8 13 14 14 9 8 9 13 10 21 21 21 13 21 10 28 13 28 9 28 7 14] [51 103 49 27 57 9 27 103 9 62 27 51 57 27 9 103 18 36 51 103 18 18 49 51 49 62 57 27 27 27 62 27 57 36 62 36 49 36 9 18] [51 103 49 27 57 9 27 103 9 62 27 51 57 27 9 103 18 36 51 103 18 18 49 51 49 62 57 27 27 27 62 27 57 36 62 36 49 36 9 18] [51 103 49 27 57 9 27 103 9 62 27 51 57 27 9 103 18 36 51 103 18 18 49 51 49 62 57 27 27 27 62 27 57 36 62 36 49 36 9 18] [51 103 49 27 57 9 27 103 9 62 27 51 57 27 9 103 18 36 51 103 18 18 49 51 49 62 57 27 27 27 62 27 57 36 62 36 49 36 9 18] [51 103 49 27 57 9 27 103 9 62 27 51 57 27 9 103 18 36 51 103 18 18 49 51 49 62 57 27 27 27 62 27 57 36 62 36 49 36 9 18] [51 103 49 27 57 9 27 103 9 62 27 51 57 27 9 103 18 36 51 103 18 18 49 51 49 62 57 27 27 27 62 27 57 36 62 36 49 36 9 18] [51 103 49 27 57 9 27 103 9 62 27 51 57 27 9 103 18 36 51 103 18 18 49 51 49 62 57 27 27 27 62 27 57 36 62 36 49 36 9 18] [51 103 49 27 57 9 27 103 9 62 27 51 57 27 9 103 18 36 51 103 18 18 49 51 49 62 57 27 27 27 62 27 57 36 62 36 49 36 9 18] [51 103 49 27 57 9 27 103 9 62 27 51 57 27 9 103 18 36 51 103 18 18 49 51 49 62 57 27 27 27 62 27 57 36 62 36 49 36 9 18] [51 103 49 27 57 9 27 103 9 62 27 51 57 27 9 103 18 36 51 103 18 18 49 51 49 62 57 27 27 27 62 27 57 36 62 36 49 36 9 18] [51 103 49 27 57 9 27 103 9 62 27 51 57 27 9 103 18 36 51 103 18 18 49 51 49 62 57 27 27 27 62 27 57 36 62 36 49 36 9 18]]
I0116 14:07:58.054847       1 util.go:1636] input  sols: [19 25 30 34 28 29 17 33 35 37 3 6 10 13 27 1 7 9 15 -1 -1 31 16 20 21 39 5 8 14 38 4 12 26 32 -1 -1 -1 -1 -1 -1 -1 -1 -1 -1 -1 2 22 24 36 -1 -1 -1 -1 -1 -1 -1 -1 -1 -1 -1 0 11 18 23 -1 -1 -1 -1 -1 -1 -1 -1 -1 -1 -1 -1 -1 -1 -1 -1 -1 -1 -1 -1 -1 -1 -1 -1 -1 -1 -1 -1 -1 -1 -1 -1 -1 -1 -1 -1 -1 -1 -1 -1 -1 -1 -1 -1 -1 -1 -1 -1 -1 -1 -1 -1 -1 -1 -1 -1 -1 -1 -1 -1 -1 -1 -1 -1 -1 -1 -1 -1 -1 -1 -1 -1 -1 -1 -1 -1 -1 -1 -1 -1 -1 -1 -1 -1 -1 -1 -1 -1 -1 -1 -1 -1 -1 -1 -1 -1 -1 -1 -1 -1 -1 -1 -1 -1 -1 -1 -1 -1 -1 -1 -1 -1 -1 -1 -1 -1 -1 -1 -1 -1 -1 -1 -1 -1 -1 -1 -1 -1 -1 -1 -1 -1 -1 -1 -1 -1 -1 -1 -1 -1 -1 -1 -1 -1 -1 -1 -1 -1 -1 -1 -1 -1 -1 -1 -1 -1 -1 -1 -1 -1 -1 -1 -1 -1 -1 -1 -1 -1 -1 -1 -1 -1 -1 -1 -1 -1 -1 -1 -1 -1 -1 -1 -1 -1 -1 -1 -1 -1 -1 -1 -1 -1 -1 -1 -1 -1 -1 -1 -1 -1 -1 -1 -1 -1 -1 -1 -1 -1 -1 -1 -1 -1 -1 -1 -1 -1 -1 -1 -1 -1 -1 -1 -1 -1 -1 -1 -1 -1 -1 -1 -1 -1 -1 -1 -1 -1 -1 -1 -1 -1 -1 -1 -1 -1 -1 -1 -1 -1 -1 -1 -1 -1 -1 -1 -1 -1 -1 -1 -1 -1 -1 -1 -1 -1 -1 -1 -1 -1 -1 -1 -1 -1 -1 -1 -1 -1 -1 -1 -1 -1 -1 -1 -1 -1 -1 -1 -1 -1 -1 -1 -1 -1 -1 -1 -1 -1 -1 -1 -1 -1 -1 -1 -1 -1 -1 -1 -1 -1 -1 -1 -1 -1 -1 -1 -1 -1 -1 -1 -1 -1 -1 -1 -1 -1 -1 -1 -1 -1 -1 -1 -1 -1 -1 -1 -1 -1 -1 -1 -1 -1 -1 -1 -1 -1 -1 -1 -1 -1 -1 -1 -1 -1 -1 -1 -1 -1 -1 -1 -1 -1 -1 -1 -1 -1 -1 -1 -1 -1 -1 -1 -1 -1 -1 -1 -1 -1 -1 -1 -1 -1 -1 -1 -1 -1 -1 -1 -1 -1 -1 -1 -1 -1 -1 -1 -1 -1 -1 -1 -1 -1 -1 -1 -1 -1 -1 -1 -1 -1 -1 -1 -1 -1 -1 -1 -1 -1 -1 -1 -1 -1 -1 -1 -1 -1 -1 -1 -1 -1 -1 -1 -1 -1 -1 -1 -1 -1 -1 -1 -1 -1 -1 -1 -1 -1 -1 -1 -1 -1 -1 -1 -1 -1 -1 -1 -1 -1 -1 -1 -1 -1 -1 -1 -1 -1 -1 -1 -1 -1 -1 -1 -1 -1 -1 -1 -1 -1 -1 -1 -1 -1 -1 -1 -1 -1 -1 -1 -1 -1 -1 -1 -1 -1 -1 -1 -1 -1 -1 -1 -1 -1 -1 -1 -1 -1 -1 -1 -1 -1 -1 -1 -1 -1 -1 -1 -1 -1 -1 -1 -1 -1 -1 -1 -1 -1 -1 -1 -1 -1 -1 -1 -1 -1 -1 -1 -1 -1]
I0116 14:07:58.054997       1 util.go:908]     Done creating pod user2/user2-pytorch-lenet on another device. New cpuDemand: 90000, gpuDemand: 0, memory: 20
I0116 14:07:58.065780       1 util.go:196] [tanle] FairScoreMap:  map[user1:0 user2:0.19444444444444445 user3:0 user4:0]
I0116 14:07:58.067809       1 scheduler.go:406] [tanle] binding user2/user2-pytorch-lenet on GPU false-->meng-allox-cpu-6
I0116 14:07:58.165957       1 util.go:1534] [meng] calling OnlineAlloX
I0116 14:07:58.165992       1 util.go:1550] [meng] numAvailMachines == 14,  allpods length: 39
I0116 14:07:58.234530       1 util.go:908]     Done creating pod user1/user1-pytorch-lenet on another device. New cpuDemand: 90000, gpuDemand: 0, memory: 20
I0116 14:07:58.241228       1 util.go:196] [tanle] FairScoreMap:  map[user3:0 user4:0 user1:0.19444444444444445 user2:0.19444444444444445]
I0116 14:07:58.243132       1 scheduler.go:406] [tanle] binding user1/user1-pytorch-lenet on GPU false-->meng-allox-cpu-8
I0116 14:07:58.341397       1 util.go:1534] [meng] calling OnlineAlloX
I0116 14:07:58.341437       1 util.go:1550] [meng] numAvailMachines == 13,  allpods length: 38
I0116 14:07:58.404324       1 util.go:908]     Done creating pod user4/user4-pytorch-lenet-2 on another device. New cpuDemand: 90000, gpuDemand: 0, memory: 20
I0116 14:07:58.411096       1 util.go:196] [tanle] FairScoreMap:  map[user4:0.19444444444444445 user1:0.19444444444444445 user2:0.19444444444444445 user3:0]
I0116 14:07:58.412861       1 scheduler.go:406] [tanle] binding user4/user4-pytorch-lenet-2 on GPU false-->meng-allox-cpu-2
I0116 14:07:58.511262       1 util.go:1534] [meng] calling OnlineAlloX
I0116 14:07:58.511315       1 util.go:1550] [meng] numAvailMachines == 12,  allpods length: 37
I0116 14:07:58.583935       1 util.go:908]     Done creating pod user1/user1-pytorch-lenet-2 on another device. New cpuDemand: 90000, gpuDemand: 0, memory: 20
I0116 14:07:58.590507       1 util.go:196] [tanle] FairScoreMap:  map[user4:0.19444444444444445 user1:0.3888888888888889 user2:0.19444444444444445 user3:0]
I0116 14:07:58.592537       1 scheduler.go:406] [tanle] binding user1/user1-pytorch-lenet-2 on GPU false-->meng-allox-cpu-4
I0116 14:07:58.690681       1 util.go:1534] [meng] calling OnlineAlloX
I0116 14:07:58.690709       1 util.go:1550] [meng] numAvailMachines == 11,  allpods length: 36
I0116 14:07:58.748925       1 util.go:908]     Done creating pod user3/user3-pytorch-lenet-3 on another device. New cpuDemand: 90000, gpuDemand: 0, memory: 20
I0116 14:07:58.755510       1 util.go:196] [tanle] FairScoreMap:  map[user1:0.3888888888888889 user2:0.19444444444444445 user3:0.19444444444444445 user4:0.19444444444444445]
I0116 14:07:58.757261       1 scheduler.go:406] [tanle] binding user3/user3-pytorch-lenet-3 on GPU false-->meng-allox-cpu-5
I0116 14:07:58.855678       1 util.go:1534] [meng] calling OnlineAlloX
I0116 14:07:58.855715       1 util.go:1550] [meng] numAvailMachines == 10,  allpods length: 35
I0116 14:07:58.908002       1 util.go:908]     Done creating pod user4/user4-pytorch-lenet-3 on another device. New cpuDemand: 90000, gpuDemand: 0, memory: 20
I0116 14:07:58.916377       1 util.go:196] [tanle] FairScoreMap:  map[user1:0.3888888888888889 user2:0.19444444444444445 user3:0.19444444444444445 user4:0.3888888888888889]
I0116 14:07:58.918784       1 scheduler.go:406] [tanle] binding user4/user4-pytorch-lenet-3 on GPU false-->meng-allox-cpu-7
I0116 14:07:59.016570       1 util.go:1534] [meng] calling OnlineAlloX
I0116 14:07:59.016617       1 util.go:1550] [meng] numAvailMachines == 9,  allpods length: 34
I0116 14:07:59.071681       1 util.go:908]     Done creating pod user1/user1-pytorch-lenet-5 on another device. New cpuDemand: 90000, gpuDemand: 0, memory: 20
I0116 14:07:59.078389       1 util.go:196] [tanle] FairScoreMap:  map[user1:0.5833333333333334 user2:0.19444444444444445 user3:0.19444444444444445 user4:0.3888888888888889]
I0116 14:07:59.080550       1 scheduler.go:406] [tanle] binding user1/user1-pytorch-lenet-5 on GPU false-->meng-allox-cpu-1
I0116 14:07:59.178560       1 util.go:1534] [meng] calling OnlineAlloX
I0116 14:07:59.178597       1 util.go:1550] [meng] numAvailMachines == 8,  allpods length: 33
I0116 14:07:59.227780       1 util.go:908]     Done creating pod user2/user2-pytorch-lenet-5 on another device. New cpuDemand: 90000, gpuDemand: 0, memory: 20
I0116 14:07:59.234589       1 util.go:196] [tanle] FairScoreMap:  map[user3:0.19444444444444445 user4:0.3888888888888889 user1:0.5833333333333334 user2:0.3888888888888889]
I0116 14:07:59.236419       1 scheduler.go:406] [tanle] binding user2/user2-pytorch-lenet-5 on GPU false-->meng-allox-cpu-3
I0116 14:07:59.334754       1 util.go:1534] [meng] calling OnlineAlloX
I0116 14:07:59.334797       1 util.go:1550] [meng] numAvailMachines == 7,  allpods length: 32
I0116 14:07:59.379506       1 util.go:908]     Done creating pod user3/user3-pytorch-lenet-4 on another device. New cpuDemand: 90000, gpuDemand: 0, memory: 20
I0116 14:07:59.386852       1 scheduler.go:459] [meng] sched.schedule(pod) has error: user3/user3-pytorch-lenet-4, 0/13 nodes are available: 1 node(s) had taints that the pod didn't tolerate, 12 Insufficient cpu.
I0116 14:07:59.488447       1 util.go:1534] [meng] calling OnlineAlloX
I0116 14:07:59.488479       1 util.go:1550] [meng] numAvailMachines == 7,  allpods length: 32
I0116 14:07:59.535444       1 scheduler.go:459] [meng] sched.schedule(pod) has error: user3/user3-pytorch-lenet-4, 0/13 nodes are available: 1 node(s) had taints that the pod didn't tolerate, 12 Insufficient cpu.
I0116 14:07:59.637040       1 util.go:1534] [meng] calling OnlineAlloX
I0116 14:07:59.637079       1 util.go:1550] [meng] numAvailMachines == 7,  allpods length: 32
I0116 14:07:59.681710       1 scheduler.go:459] [meng] sched.schedule(pod) has error: user3/user3-pytorch-lenet-4, 0/13 nodes are available: 1 node(s) had taints that the pod didn't tolerate, 12 Insufficient cpu.
I0116 14:07:59.783776       1 util.go:1534] [meng] calling OnlineAlloX
I0116 14:07:59.783809       1 util.go:1550] [meng] numAvailMachines == 7,  allpods length: 32
I0116 14:07:59.828763       1 scheduler.go:459] [meng] sched.schedule(pod) has error: user3/user3-pytorch-lenet-4, 0/13 nodes are available: 1 node(s) had taints that the pod didn't tolerate, 12 Insufficient cpu.
I0116 14:07:59.930980       1 util.go:1534] [meng] calling OnlineAlloX
I0116 14:07:59.931010       1 util.go:1550] [meng] numAvailMachines == 7,  allpods length: 32
I0116 14:07:59.975661       1 scheduler.go:459] [meng] sched.schedule(pod) has error: user3/user3-pytorch-lenet-4, 0/13 nodes are available: 1 node(s) had taints that the pod didn't tolerate, 12 Insufficient cpu.
I0116 14:08:00.077927       1 util.go:1534] [meng] calling OnlineAlloX
I0116 14:08:00.077958       1 util.go:1550] [meng] numAvailMachines == 7,  allpods length: 32
I0116 14:08:00.122333       1 util.go:908]     Done creating pod user4/user4-pytorch-lenet-4 on another device. New cpuDemand: 90000, gpuDemand: 0, memory: 20
I0116 14:08:00.129691       1 scheduler.go:459] [meng] sched.schedule(pod) has error: user4/user4-pytorch-lenet-4, 0/13 nodes are available: 1 node(s) had taints that the pod didn't tolerate, 12 Insufficient cpu.
I0116 14:08:00.231840       1 util.go:1534] [meng] calling OnlineAlloX
I0116 14:08:00.231879       1 util.go:1550] [meng] numAvailMachines == 7,  allpods length: 32
I0116 14:08:00.276504       1 scheduler.go:459] [meng] sched.schedule(pod) has error: user3/user3-pytorch-lenet-4, 0/13 nodes are available: 1 node(s) had taints that the pod didn't tolerate, 12 Insufficient cpu.
I0116 14:08:00.378421       1 util.go:1534] [meng] calling OnlineAlloX
I0116 14:08:00.378459       1 util.go:1550] [meng] numAvailMachines == 7,  allpods length: 32
I0116 14:08:00.422872       1 scheduler.go:459] [meng] sched.schedule(pod) has error: user3/user3-pytorch-lenet-4, 0/13 nodes are available: 1 node(s) had taints that the pod didn't tolerate, 12 Insufficient cpu.
I0116 14:08:00.525286       1 util.go:1534] [meng] calling OnlineAlloX
I0116 14:08:00.525332       1 util.go:1550] [meng] numAvailMachines == 7,  allpods length: 32
I0116 14:08:00.569717       1 scheduler.go:459] [meng] sched.schedule(pod) has error: user3/user3-pytorch-lenet-4, 0/13 nodes are available: 1 node(s) had taints that the pod didn't tolerate, 12 Insufficient cpu.
I0116 14:08:00.672199       1 util.go:1534] [meng] calling OnlineAlloX
I0116 14:08:00.672227       1 util.go:1550] [meng] numAvailMachines == 7,  allpods length: 32
I0116 14:08:00.717274       1 scheduler.go:459] [meng] sched.schedule(pod) has error: user3/user3-pytorch-lenet-4, 0/13 nodes are available: 1 node(s) had taints that the pod didn't tolerate, 12 Insufficient cpu.
I0116 14:08:00.819363       1 util.go:1534] [meng] calling OnlineAlloX
I0116 14:08:00.819392       1 util.go:1550] [meng] numAvailMachines == 7,  allpods length: 32
I0116 14:08:00.864679       1 scheduler.go:459] [meng] sched.schedule(pod) has error: user3/user3-pytorch-lenet-4, 0/13 nodes are available: 1 node(s) had taints that the pod didn't tolerate, 12 Insufficient cpu.
I0116 14:08:00.966996       1 util.go:1534] [meng] calling OnlineAlloX
I0116 14:08:00.967029       1 util.go:1550] [meng] numAvailMachines == 7,  allpods length: 32
I0116 14:08:01.012405       1 scheduler.go:459] [meng] sched.schedule(pod) has error: user3/user3-pytorch-lenet-4, 0/13 nodes are available: 1 node(s) had taints that the pod didn't tolerate, 12 Insufficient cpu.
I0116 14:08:01.115279       1 util.go:1534] [meng] calling OnlineAlloX
I0116 14:08:01.115308       1 util.go:1550] [meng] numAvailMachines == 7,  allpods length: 32
I0116 14:08:01.159432       1 scheduler.go:459] [meng] sched.schedule(pod) has error: user3/user3-pytorch-lenet-4, 0/13 nodes are available: 1 node(s) had taints that the pod didn't tolerate, 12 Insufficient cpu.
I0116 14:08:01.261596       1 util.go:1534] [meng] calling OnlineAlloX
I0116 14:08:01.261637       1 util.go:1550] [meng] numAvailMachines == 7,  allpods length: 32
I0116 14:08:01.306551       1 scheduler.go:459] [meng] sched.schedule(pod) has error: user3/user3-pytorch-lenet-4, 0/13 nodes are available: 1 node(s) had taints that the pod didn't tolerate, 12 Insufficient cpu.
I0116 14:08:01.408569       1 util.go:1534] [meng] calling OnlineAlloX
I0116 14:08:01.408597       1 util.go:1550] [meng] numAvailMachines == 7,  allpods length: 32
I0116 14:08:01.452875       1 scheduler.go:459] [meng] sched.schedule(pod) has error: user3/user3-pytorch-lenet-4, 0/13 nodes are available: 1 node(s) had taints that the pod didn't tolerate, 12 Insufficient cpu.
I0116 14:08:01.555154       1 util.go:1534] [meng] calling OnlineAlloX
I0116 14:08:01.555186       1 util.go:1550] [meng] numAvailMachines == 7,  allpods length: 32
I0116 14:08:01.600293       1 scheduler.go:459] [meng] sched.schedule(pod) has error: user3/user3-pytorch-lenet-4, 0/13 nodes are available: 1 node(s) had taints that the pod didn't tolerate, 12 Insufficient cpu.
I0116 14:08:01.702537       1 util.go:1534] [meng] calling OnlineAlloX
I0116 14:08:01.702578       1 util.go:1550] [meng] numAvailMachines == 7,  allpods length: 32
I0116 14:08:01.747413       1 scheduler.go:459] [meng] sched.schedule(pod) has error: user3/user3-pytorch-lenet-4, 0/13 nodes are available: 1 node(s) had taints that the pod didn't tolerate, 12 Insufficient cpu.
I0116 14:08:01.849290       1 util.go:1534] [meng] calling OnlineAlloX
I0116 14:08:01.849319       1 util.go:1550] [meng] numAvailMachines == 7,  allpods length: 32
I0116 14:08:01.894490       1 scheduler.go:459] [meng] sched.schedule(pod) has error: user3/user3-pytorch-lenet-4, 0/13 nodes are available: 1 node(s) had taints that the pod didn't tolerate, 12 Insufficient cpu.
I0116 14:08:01.996633       1 util.go:1534] [meng] calling OnlineAlloX
I0116 14:08:01.996662       1 util.go:1550] [meng] numAvailMachines == 7,  allpods length: 32
I0116 14:08:02.041997       1 scheduler.go:459] [meng] sched.schedule(pod) has error: user3/user3-pytorch-lenet-4, 0/13 nodes are available: 1 node(s) had taints that the pod didn't tolerate, 12 Insufficient cpu.
I0116 14:08:02.144397       1 util.go:1534] [meng] calling OnlineAlloX
I0116 14:08:02.144426       1 util.go:1550] [meng] numAvailMachines == 7,  allpods length: 32
I0116 14:08:02.189932       1 scheduler.go:459] [meng] sched.schedule(pod) has error: user3/user3-pytorch-lenet-4, 0/13 nodes are available: 1 node(s) had taints that the pod didn't tolerate, 12 Insufficient cpu.
I0116 14:08:02.292019       1 util.go:1534] [meng] calling OnlineAlloX
I0116 14:08:02.292057       1 util.go:1550] [meng] numAvailMachines == 7,  allpods length: 32
I0116 14:08:02.340576       1 scheduler.go:459] [meng] sched.schedule(pod) has error: user4/user4-pytorch-lenet-4, 0/13 nodes are available: 1 node(s) had taints that the pod didn't tolerate, 12 Insufficient cpu.
I0116 14:08:02.442221       1 util.go:1534] [meng] calling OnlineAlloX
I0116 14:08:02.442261       1 util.go:1550] [meng] numAvailMachines == 7,  allpods length: 32
I0116 14:08:02.486686       1 scheduler.go:459] [meng] sched.schedule(pod) has error: user3/user3-pytorch-lenet-4, 0/13 nodes are available: 1 node(s) had taints that the pod didn't tolerate, 12 Insufficient cpu.
I0116 14:08:02.588848       1 util.go:1534] [meng] calling OnlineAlloX
I0116 14:08:02.588888       1 util.go:1550] [meng] numAvailMachines == 7,  allpods length: 32
I0116 14:08:02.633565       1 scheduler.go:459] [meng] sched.schedule(pod) has error: user4/user4-pytorch-lenet-4, 0/13 nodes are available: 1 node(s) had taints that the pod didn't tolerate, 12 Insufficient cpu.
I0116 14:08:02.735601       1 util.go:1534] [meng] calling OnlineAlloX
I0116 14:08:02.735633       1 util.go:1550] [meng] numAvailMachines == 7,  allpods length: 32
I0116 14:08:02.779726       1 scheduler.go:459] [meng] sched.schedule(pod) has error: user3/user3-pytorch-lenet-4, 0/13 nodes are available: 1 node(s) had taints that the pod didn't tolerate, 12 Insufficient cpu.
I0116 14:08:02.882139       1 util.go:1534] [meng] calling OnlineAlloX
I0116 14:08:02.882178       1 util.go:1550] [meng] numAvailMachines == 7,  allpods length: 32
I0116 14:08:02.926492       1 scheduler.go:459] [meng] sched.schedule(pod) has error: user3/user3-pytorch-lenet-4, 0/13 nodes are available: 1 node(s) had taints that the pod didn't tolerate, 12 Insufficient cpu.
I0116 14:08:03.029022       1 util.go:1534] [meng] calling OnlineAlloX
I0116 14:08:03.029050       1 util.go:1550] [meng] numAvailMachines == 7,  allpods length: 32
I0116 14:08:03.073545       1 scheduler.go:459] [meng] sched.schedule(pod) has error: user3/user3-pytorch-lenet-4, 0/13 nodes are available: 1 node(s) had taints that the pod didn't tolerate, 12 Insufficient cpu.
I0116 14:08:03.175563       1 util.go:1534] [meng] calling OnlineAlloX
I0116 14:08:03.175592       1 util.go:1550] [meng] numAvailMachines == 7,  allpods length: 32
I0116 14:08:03.220456       1 scheduler.go:459] [meng] sched.schedule(pod) has error: user3/user3-pytorch-lenet-4, 0/13 nodes are available: 1 node(s) had taints that the pod didn't tolerate, 12 Insufficient cpu.
I0116 14:08:03.322634       1 util.go:1534] [meng] calling OnlineAlloX
I0116 14:08:03.322662       1 util.go:1550] [meng] numAvailMachines == 7,  allpods length: 32
I0116 14:08:03.366596       1 scheduler.go:459] [meng] sched.schedule(pod) has error: user3/user3-pytorch-lenet-4, 0/13 nodes are available: 1 node(s) had taints that the pod didn't tolerate, 12 Insufficient cpu.
I0116 14:08:03.468799       1 util.go:1534] [meng] calling OnlineAlloX
I0116 14:08:03.468839       1 util.go:1550] [meng] numAvailMachines == 7,  allpods length: 32
I0116 14:08:03.513964       1 scheduler.go:459] [meng] sched.schedule(pod) has error: user3/user3-pytorch-lenet-4, 0/13 nodes are available: 1 node(s) had taints that the pod didn't tolerate, 12 Insufficient cpu.
I0116 14:08:03.616370       1 util.go:1534] [meng] calling OnlineAlloX
I0116 14:08:03.616398       1 util.go:1550] [meng] numAvailMachines == 7,  allpods length: 32
I0116 14:08:03.660851       1 scheduler.go:459] [meng] sched.schedule(pod) has error: user3/user3-pytorch-lenet-4, 0/13 nodes are available: 1 node(s) had taints that the pod didn't tolerate, 12 Insufficient cpu.
I0116 14:08:03.762898       1 util.go:1534] [meng] calling OnlineAlloX
I0116 14:08:03.762937       1 util.go:1550] [meng] numAvailMachines == 7,  allpods length: 32
I0116 14:08:03.806505       1 scheduler.go:459] [meng] sched.schedule(pod) has error: user3/user3-pytorch-lenet-4, 0/13 nodes are available: 1 node(s) had taints that the pod didn't tolerate, 12 Insufficient cpu.
I0116 14:08:03.908838       1 util.go:1534] [meng] calling OnlineAlloX
I0116 14:08:03.908877       1 util.go:1550] [meng] numAvailMachines == 7,  allpods length: 32
I0116 14:08:03.953869       1 util.go:908]     Done creating pod user2/user2-pytorch-lenet-4 on another device. New cpuDemand: 90000, gpuDemand: 0, memory: 20
I0116 14:08:03.961381       1 scheduler.go:459] [meng] sched.schedule(pod) has error: user2/user2-pytorch-lenet-4, 0/13 nodes are available: 1 node(s) had taints that the pod didn't tolerate, 12 Insufficient cpu.
I0116 14:08:04.062787       1 util.go:1534] [meng] calling OnlineAlloX
I0116 14:08:04.062816       1 util.go:1550] [meng] numAvailMachines == 7,  allpods length: 32
I0116 14:08:04.107790       1 scheduler.go:459] [meng] sched.schedule(pod) has error: user4/user4-pytorch-lenet-4, 0/13 nodes are available: 1 node(s) had taints that the pod didn't tolerate, 12 Insufficient cpu.
I0116 14:08:04.209911       1 util.go:1534] [meng] calling OnlineAlloX
I0116 14:08:04.209939       1 util.go:1550] [meng] numAvailMachines == 7,  allpods length: 32
I0116 14:08:04.253735       1 scheduler.go:459] [meng] sched.schedule(pod) has error: user3/user3-pytorch-lenet-4, 0/13 nodes are available: 1 node(s) had taints that the pod didn't tolerate, 12 Insufficient cpu.
I0116 14:08:04.355886       1 util.go:1534] [meng] calling OnlineAlloX
I0116 14:08:04.355914       1 util.go:1550] [meng] numAvailMachines == 7,  allpods length: 32
I0116 14:08:04.400390       1 scheduler.go:459] [meng] sched.schedule(pod) has error: user3/user3-pytorch-lenet-4, 0/13 nodes are available: 1 node(s) had taints that the pod didn't tolerate, 12 Insufficient cpu.
I0116 14:08:04.502506       1 util.go:1534] [meng] calling OnlineAlloX
I0116 14:08:04.502546       1 util.go:1550] [meng] numAvailMachines == 7,  allpods length: 32
I0116 14:08:04.546564       1 scheduler.go:459] [meng] sched.schedule(pod) has error: user3/user3-pytorch-lenet-4, 0/13 nodes are available: 1 node(s) had taints that the pod didn't tolerate, 12 Insufficient cpu.
I0116 14:08:04.648644       1 util.go:1534] [meng] calling OnlineAlloX
I0116 14:08:04.648682       1 util.go:1550] [meng] numAvailMachines == 7,  allpods length: 32
I0116 14:08:04.693485       1 scheduler.go:459] [meng] sched.schedule(pod) has error: user3/user3-pytorch-lenet-4, 0/13 nodes are available: 1 node(s) had taints that the pod didn't tolerate, 12 Insufficient cpu.
I0116 14:08:04.795827       1 util.go:1534] [meng] calling OnlineAlloX
I0116 14:08:04.795857       1 util.go:1550] [meng] numAvailMachines == 7,  allpods length: 32
I0116 14:08:04.839852       1 scheduler.go:459] [meng] sched.schedule(pod) has error: user3/user3-pytorch-lenet-4, 0/13 nodes are available: 1 node(s) had taints that the pod didn't tolerate, 12 Insufficient cpu.
I0116 14:08:04.941986       1 util.go:1534] [meng] calling OnlineAlloX
I0116 14:08:04.942026       1 util.go:1550] [meng] numAvailMachines == 7,  allpods length: 32
I0116 14:08:04.995113       1 scheduler.go:459] [meng] sched.schedule(pod) has error: user3/user3-pytorch-lenet-4, 0/13 nodes are available: 1 node(s) had taints that the pod didn't tolerate, 12 Insufficient cpu.
I0116 14:08:05.097459       1 util.go:1534] [meng] calling OnlineAlloX
I0116 14:08:05.097497       1 util.go:1550] [meng] numAvailMachines == 7,  allpods length: 32
I0116 14:08:05.143755       1 scheduler.go:459] [meng] sched.schedule(pod) has error: user3/user3-pytorch-lenet-4, 0/13 nodes are available: 1 node(s) had taints that the pod didn't tolerate, 12 Insufficient cpu.
I0116 14:08:05.245946       1 util.go:1534] [meng] calling OnlineAlloX
I0116 14:08:05.245991       1 util.go:1550] [meng] numAvailMachines == 7,  allpods length: 32
I0116 14:08:05.290138       1 scheduler.go:459] [meng] sched.schedule(pod) has error: user3/user3-pytorch-lenet-4, 0/13 nodes are available: 1 node(s) had taints that the pod didn't tolerate, 12 Insufficient cpu.
I0116 14:08:05.392453       1 util.go:1534] [meng] calling OnlineAlloX
I0116 14:08:05.392487       1 util.go:1550] [meng] numAvailMachines == 7,  allpods length: 32
I0116 14:08:05.437519       1 scheduler.go:459] [meng] sched.schedule(pod) has error: user3/user3-pytorch-lenet-4, 0/13 nodes are available: 1 node(s) had taints that the pod didn't tolerate, 12 Insufficient cpu.
I0116 14:08:05.539607       1 util.go:1534] [meng] calling OnlineAlloX
I0116 14:08:05.539637       1 util.go:1550] [meng] numAvailMachines == 7,  allpods length: 32
I0116 14:08:05.583539       1 scheduler.go:459] [meng] sched.schedule(pod) has error: user3/user3-pytorch-lenet-4, 0/13 nodes are available: 1 node(s) had taints that the pod didn't tolerate, 12 Insufficient cpu.
I0116 14:08:05.685619       1 util.go:1534] [meng] calling OnlineAlloX
I0116 14:08:05.685656       1 util.go:1550] [meng] numAvailMachines == 7,  allpods length: 32
I0116 14:08:05.730271       1 scheduler.go:459] [meng] sched.schedule(pod) has error: user3/user3-pytorch-lenet-4, 0/13 nodes are available: 1 node(s) had taints that the pod didn't tolerate, 12 Insufficient cpu.
I0116 14:08:05.832216       1 util.go:1534] [meng] calling OnlineAlloX
I0116 14:08:05.832253       1 util.go:1550] [meng] numAvailMachines == 7,  allpods length: 32
I0116 14:08:05.876174       1 scheduler.go:459] [meng] sched.schedule(pod) has error: user3/user3-pytorch-lenet-4, 0/13 nodes are available: 1 node(s) had taints that the pod didn't tolerate, 12 Insufficient cpu.
I0116 14:08:05.978201       1 util.go:1534] [meng] calling OnlineAlloX
I0116 14:08:05.978229       1 util.go:1550] [meng] numAvailMachines == 7,  allpods length: 32
I0116 14:08:06.023098       1 scheduler.go:459] [meng] sched.schedule(pod) has error: user3/user3-pytorch-lenet-4, 0/13 nodes are available: 1 node(s) had taints that the pod didn't tolerate, 12 Insufficient cpu.
I0116 14:08:06.125124       1 util.go:1534] [meng] calling OnlineAlloX
I0116 14:08:06.125169       1 util.go:1550] [meng] numAvailMachines == 7,  allpods length: 32
I0116 14:08:06.169074       1 scheduler.go:459] [meng] sched.schedule(pod) has error: user3/user3-pytorch-lenet-4, 0/13 nodes are available: 1 node(s) had taints that the pod didn't tolerate, 12 Insufficient cpu.
I0116 14:08:06.271414       1 util.go:1534] [meng] calling OnlineAlloX
I0116 14:08:06.271443       1 util.go:1550] [meng] numAvailMachines == 7,  allpods length: 32
I0116 14:08:06.316099       1 scheduler.go:459] [meng] sched.schedule(pod) has error: user3/user3-pytorch-lenet-4, 0/13 nodes are available: 1 node(s) had taints that the pod didn't tolerate, 12 Insufficient cpu.
I0116 14:08:06.418117       1 util.go:1534] [meng] calling OnlineAlloX
I0116 14:08:06.418146       1 util.go:1550] [meng] numAvailMachines == 7,  allpods length: 32
I0116 14:08:06.462012       1 scheduler.go:459] [meng] sched.schedule(pod) has error: user3/user3-pytorch-lenet-4, 0/13 nodes are available: 1 node(s) had taints that the pod didn't tolerate, 12 Insufficient cpu.
I0116 14:08:06.564265       1 util.go:1534] [meng] calling OnlineAlloX
I0116 14:08:06.564298       1 util.go:1550] [meng] numAvailMachines == 7,  allpods length: 32
I0116 14:08:06.609255       1 scheduler.go:459] [meng] sched.schedule(pod) has error: user3/user3-pytorch-lenet-4, 0/13 nodes are available: 1 node(s) had taints that the pod didn't tolerate, 12 Insufficient cpu.
I0116 14:08:06.711469       1 util.go:1534] [meng] calling OnlineAlloX
I0116 14:08:06.711500       1 util.go:1550] [meng] numAvailMachines == 7,  allpods length: 32
I0116 14:08:06.756451       1 scheduler.go:459] [meng] sched.schedule(pod) has error: user3/user3-pytorch-lenet-4, 0/13 nodes are available: 1 node(s) had taints that the pod didn't tolerate, 12 Insufficient cpu.
I0116 14:08:06.858710       1 util.go:1534] [meng] calling OnlineAlloX
I0116 14:08:06.858743       1 util.go:1550] [meng] numAvailMachines == 7,  allpods length: 32
I0116 14:08:06.903694       1 scheduler.go:459] [meng] sched.schedule(pod) has error: user3/user3-pytorch-lenet-4, 0/13 nodes are available: 1 node(s) had taints that the pod didn't tolerate, 12 Insufficient cpu.
I0116 14:08:07.005888       1 util.go:1534] [meng] calling OnlineAlloX
I0116 14:08:07.005935       1 util.go:1550] [meng] numAvailMachines == 7,  allpods length: 32
I0116 14:08:07.050751       1 scheduler.go:459] [meng] sched.schedule(pod) has error: user3/user3-pytorch-lenet-4, 0/13 nodes are available: 1 node(s) had taints that the pod didn't tolerate, 12 Insufficient cpu.
I0116 14:08:07.152744       1 util.go:1534] [meng] calling OnlineAlloX
I0116 14:08:07.152771       1 util.go:1550] [meng] numAvailMachines == 7,  allpods length: 32
I0116 14:08:07.196802       1 scheduler.go:459] [meng] sched.schedule(pod) has error: user4/user4-pytorch-lenet-4, 0/13 nodes are available: 1 node(s) had taints that the pod didn't tolerate, 12 Insufficient cpu.
I0116 14:08:07.299286       1 util.go:1534] [meng] calling OnlineAlloX
I0116 14:08:07.299324       1 util.go:1550] [meng] numAvailMachines == 7,  allpods length: 32
I0116 14:08:07.343718       1 scheduler.go:459] [meng] sched.schedule(pod) has error: user3/user3-pytorch-lenet-4, 0/13 nodes are available: 1 node(s) had taints that the pod didn't tolerate, 12 Insufficient cpu.
I0116 14:08:07.445936       1 util.go:1534] [meng] calling OnlineAlloX
I0116 14:08:07.445997       1 util.go:1550] [meng] numAvailMachines == 7,  allpods length: 32
I0116 14:08:07.490982       1 scheduler.go:459] [meng] sched.schedule(pod) has error: user3/user3-pytorch-lenet-4, 0/13 nodes are available: 1 node(s) had taints that the pod didn't tolerate, 12 Insufficient cpu.
I0116 14:08:07.593232       1 util.go:1534] [meng] calling OnlineAlloX
I0116 14:08:07.593272       1 util.go:1550] [meng] numAvailMachines == 7,  allpods length: 32
I0116 14:08:07.637751       1 scheduler.go:459] [meng] sched.schedule(pod) has error: user3/user3-pytorch-lenet-4, 0/13 nodes are available: 1 node(s) had taints that the pod didn't tolerate, 12 Insufficient cpu.
I0116 14:08:07.740101       1 util.go:1534] [meng] calling OnlineAlloX
I0116 14:08:07.740130       1 util.go:1550] [meng] numAvailMachines == 7,  allpods length: 32
I0116 14:08:07.785103       1 scheduler.go:459] [meng] sched.schedule(pod) has error: user3/user3-pytorch-lenet-4, 0/13 nodes are available: 1 node(s) had taints that the pod didn't tolerate, 12 Insufficient cpu.
I0116 14:08:07.887252       1 util.go:1534] [meng] calling OnlineAlloX
I0116 14:08:07.887282       1 util.go:1550] [meng] numAvailMachines == 7,  allpods length: 32
I0116 14:08:07.932231       1 scheduler.go:459] [meng] sched.schedule(pod) has error: user4/user4-pytorch-lenet-4, 0/13 nodes are available: 1 node(s) had taints that the pod didn't tolerate, 12 Insufficient cpu.
I0116 14:08:08.034467       1 util.go:1534] [meng] calling OnlineAlloX
I0116 14:08:08.034506       1 util.go:1550] [meng] numAvailMachines == 7,  allpods length: 32
I0116 14:08:08.079618       1 scheduler.go:459] [meng] sched.schedule(pod) has error: user3/user3-pytorch-lenet-4, 0/13 nodes are available: 1 node(s) had taints that the pod didn't tolerate, 12 Insufficient cpu.
I0116 14:08:08.185292       1 util.go:1534] [meng] calling OnlineAlloX
I0116 14:08:08.185333       1 util.go:1550] [meng] numAvailMachines == 7,  allpods length: 32
I0116 14:08:08.230533       1 scheduler.go:459] [meng] sched.schedule(pod) has error: user3/user3-pytorch-lenet-4, 0/13 nodes are available: 1 node(s) had taints that the pod didn't tolerate, 12 Insufficient cpu.
I0116 14:08:08.333042       1 util.go:1534] [meng] calling OnlineAlloX
I0116 14:08:08.333072       1 util.go:1550] [meng] numAvailMachines == 7,  allpods length: 32
I0116 14:08:08.378278       1 scheduler.go:459] [meng] sched.schedule(pod) has error: user3/user3-pytorch-lenet-4, 0/13 nodes are available: 1 node(s) had taints that the pod didn't tolerate, 12 Insufficient cpu.
I0116 14:08:08.480507       1 util.go:1534] [meng] calling OnlineAlloX
I0116 14:08:08.480541       1 util.go:1550] [meng] numAvailMachines == 7,  allpods length: 32
I0116 14:08:08.524976       1 scheduler.go:459] [meng] sched.schedule(pod) has error: user3/user3-pytorch-lenet-4, 0/13 nodes are available: 1 node(s) had taints that the pod didn't tolerate, 12 Insufficient cpu.
I0116 14:08:08.627087       1 util.go:1534] [meng] calling OnlineAlloX
I0116 14:08:08.627126       1 util.go:1550] [meng] numAvailMachines == 7,  allpods length: 32
I0116 14:08:08.671191       1 scheduler.go:459] [meng] sched.schedule(pod) has error: user3/user3-pytorch-lenet-4, 0/13 nodes are available: 1 node(s) had taints that the pod didn't tolerate, 12 Insufficient cpu.
I0116 14:08:08.773435       1 util.go:1534] [meng] calling OnlineAlloX
I0116 14:08:08.773466       1 util.go:1550] [meng] numAvailMachines == 7,  allpods length: 32
I0116 14:08:08.816257       1 factory.go:1129] [meng] deletePodFromCache
I0116 14:08:08.816290       1 factory.go:1136] [meng] JCT: 10.839469751s, total jct: 10.839469751s, count: 1, average JCT: 10.839469751s
I0116 14:08:08.818002       1 scheduler.go:459] [meng] sched.schedule(pod) has error: user3/user3-pytorch-lenet-4, 0/13 nodes are available: 1 node(s) had taints that the pod didn't tolerate, 12 Insufficient cpu.
I0116 14:08:08.826126       1 factory.go:798] [meng] computeComplTimeForAllPods completed
I0116 14:08:08.826144       1 factory.go:806] [tanle] Event pod completed user2/user2-pytorch-lenet%!(EXTRA v1.PodPhase=Succeeded)
I0116 14:08:08.826166       1 factory.go:1149] [meng] check delete pod user2/user2-pytorch-lenet, Running
I0116 14:08:08.826171       1 util.go:143] [meng] UpdateFairScore user2/user2-pytorch-lenet, false
I0116 14:08:08.826178       1 util.go:192] [meng] delete PodMachineMap in UpdateFairScore user2/user2-pytorch-lenet, false
I0116 14:08:08.826184       1 util.go:196] [tanle] FairScoreMap:  map[user1:0.5833333333333334 user2:0.19444444444444445 user3:0.19444444444444445 user4:0.3888888888888889]
I0116 14:08:08.919817       1 util.go:1534] [meng] calling OnlineAlloX
I0116 14:08:08.919866       1 util.go:1550] [meng] numAvailMachines == 8,  allpods length: 32
I0116 14:08:08.966141       1 util.go:908]     Done creating pod user4/user4-pytorch-lenet on another device. New cpuDemand: 90000, gpuDemand: 0, memory: 20
I0116 14:08:08.972920       1 util.go:196] [tanle] FairScoreMap:  map[user2:0.19444444444444445 user3:0.19444444444444445 user4:0.5833333333333334 user1:0.5833333333333334]
I0116 14:08:08.974894       1 scheduler.go:406] [tanle] binding user4/user4-pytorch-lenet on GPU false-->meng-allox-cpu-6
I0116 14:08:09.073098       1 util.go:1534] [meng] calling OnlineAlloX
I0116 14:08:09.073178       1 util.go:1550] [meng] numAvailMachines == 7,  allpods length: 31
I0116 14:08:09.122427       1 scheduler.go:459] [meng] sched.schedule(pod) has error: user2/user2-pytorch-lenet-4, 0/13 nodes are available: 1 node(s) had taints that the pod didn't tolerate, 12 Insufficient cpu.
I0116 14:08:09.224026       1 util.go:1534] [meng] calling OnlineAlloX
I0116 14:08:09.224056       1 util.go:1550] [meng] numAvailMachines == 7,  allpods length: 31
I0116 14:08:09.267651       1 scheduler.go:459] [meng] sched.schedule(pod) has error: user2/user2-pytorch-lenet-4, 0/13 nodes are available: 1 node(s) had taints that the pod didn't tolerate, 12 Insufficient cpu.
I0116 14:08:09.273086       1 factory.go:1129] [meng] deletePodFromCache
I0116 14:08:09.273099       1 factory.go:1136] [meng] JCT: 11.296279371s, total jct: 22.135749122s, count: 2, average JCT: 11.067874561s
I0116 14:08:09.282552       1 factory.go:798] [meng] computeComplTimeForAllPods completed
I0116 14:08:09.282568       1 factory.go:806] [tanle] Event pod completed user1/user1-pytorch-lenet%!(EXTRA v1.PodPhase=Succeeded)
I0116 14:08:09.282589       1 factory.go:1149] [meng] check delete pod user1/user1-pytorch-lenet, Running
I0116 14:08:09.282597       1 util.go:143] [meng] UpdateFairScore user1/user1-pytorch-lenet, false
I0116 14:08:09.282605       1 util.go:192] [meng] delete PodMachineMap in UpdateFairScore user1/user1-pytorch-lenet, false
I0116 14:08:09.282609       1 util.go:196] [tanle] FairScoreMap:  map[user2:0.19444444444444445 user3:0.19444444444444445 user4:0.5833333333333334 user1:0.38888888888888895]
I0116 14:08:09.369840       1 util.go:1534] [meng] calling OnlineAlloX
I0116 14:08:09.369883       1 util.go:1550] [meng] numAvailMachines == 8,  allpods length: 31
I0116 14:08:09.412687       1 util.go:908]     Done creating pod user2/user2-pytorch-lenet-2 on another device. New cpuDemand: 90000, gpuDemand: 0, memory: 20
I0116 14:08:09.418987       1 util.go:196] [tanle] FairScoreMap:  map[user1:0.38888888888888895 user2:0.3888888888888889 user3:0.19444444444444445 user4:0.5833333333333334]
I0116 14:08:09.420742       1 scheduler.go:406] [tanle] binding user2/user2-pytorch-lenet-2 on GPU false-->meng-allox-cpu-8
I0116 14:08:09.519153       1 util.go:1534] [meng] calling OnlineAlloX
I0116 14:08:09.519182       1 util.go:1550] [meng] numAvailMachines == 7,  allpods length: 30
I0116 14:08:09.557797       1 scheduler.go:459] [meng] sched.schedule(pod) has error: user4/user4-pytorch-lenet-4, 0/13 nodes are available: 1 node(s) had taints that the pod didn't tolerate, 12 Insufficient cpu.
I0116 14:08:09.659718       1 util.go:1534] [meng] calling OnlineAlloX
I0116 14:08:09.659747       1 util.go:1550] [meng] numAvailMachines == 7,  allpods length: 30
I0116 14:08:09.699456       1 scheduler.go:459] [meng] sched.schedule(pod) has error: user3/user3-pytorch-lenet-4, 0/13 nodes are available: 1 node(s) had taints that the pod didn't tolerate, 12 Insufficient cpu.
I0116 14:08:09.801789       1 util.go:1534] [meng] calling OnlineAlloX
I0116 14:08:09.801818       1 util.go:1550] [meng] numAvailMachines == 7,  allpods length: 30
I0116 14:08:09.840641       1 scheduler.go:459] [meng] sched.schedule(pod) has error: user3/user3-pytorch-lenet-4, 0/13 nodes are available: 1 node(s) had taints that the pod didn't tolerate, 12 Insufficient cpu.
I0116 14:08:09.942881       1 util.go:1534] [meng] calling OnlineAlloX
I0116 14:08:09.942959       1 util.go:1550] [meng] numAvailMachines == 7,  allpods length: 30
I0116 14:08:09.986189       1 scheduler.go:459] [meng] sched.schedule(pod) has error: user4/user4-pytorch-lenet-4, 0/13 nodes are available: 1 node(s) had taints that the pod didn't tolerate, 12 Insufficient cpu.
I0116 14:08:10.088445       1 util.go:1534] [meng] calling OnlineAlloX
I0116 14:08:10.088493       1 util.go:1550] [meng] numAvailMachines == 7,  allpods length: 30
I0116 14:08:10.129570       1 scheduler.go:459] [meng] sched.schedule(pod) has error: user4/user4-pytorch-lenet-4, 0/13 nodes are available: 1 node(s) had taints that the pod didn't tolerate, 12 Insufficient cpu.
I0116 14:08:10.231811       1 util.go:1534] [meng] calling OnlineAlloX
I0116 14:08:10.231854       1 util.go:1550] [meng] numAvailMachines == 7,  allpods length: 30
I0116 14:08:10.271921       1 scheduler.go:459] [meng] sched.schedule(pod) has error: user3/user3-pytorch-lenet-4, 0/13 nodes are available: 1 node(s) had taints that the pod didn't tolerate, 12 Insufficient cpu.
I0116 14:08:10.374159       1 util.go:1534] [meng] calling OnlineAlloX
I0116 14:08:10.374197       1 util.go:1550] [meng] numAvailMachines == 7,  allpods length: 30
I0116 14:08:10.414081       1 scheduler.go:459] [meng] sched.schedule(pod) has error: user3/user3-pytorch-lenet-4, 0/13 nodes are available: 1 node(s) had taints that the pod didn't tolerate, 12 Insufficient cpu.
I0116 14:08:10.516383       1 util.go:1534] [meng] calling OnlineAlloX
I0116 14:08:10.516413       1 util.go:1550] [meng] numAvailMachines == 7,  allpods length: 30
I0116 14:08:10.554891       1 scheduler.go:459] [meng] sched.schedule(pod) has error: user3/user3-pytorch-lenet-4, 0/13 nodes are available: 1 node(s) had taints that the pod didn't tolerate, 12 Insufficient cpu.
I0116 14:08:10.657133       1 util.go:1534] [meng] calling OnlineAlloX
I0116 14:08:10.657323       1 util.go:1550] [meng] numAvailMachines == 7,  allpods length: 30
I0116 14:08:10.696317       1 scheduler.go:459] [meng] sched.schedule(pod) has error: user3/user3-pytorch-lenet-4, 0/13 nodes are available: 1 node(s) had taints that the pod didn't tolerate, 12 Insufficient cpu.
I0116 14:08:10.798556       1 util.go:1534] [meng] calling OnlineAlloX
I0116 14:08:10.798585       1 util.go:1550] [meng] numAvailMachines == 7,  allpods length: 30
I0116 14:08:10.836237       1 scheduler.go:459] [meng] sched.schedule(pod) has error: user4/user4-pytorch-lenet-4, 0/13 nodes are available: 1 node(s) had taints that the pod didn't tolerate, 12 Insufficient cpu.
I0116 14:08:10.938476       1 util.go:1534] [meng] calling OnlineAlloX
I0116 14:08:10.938516       1 util.go:1550] [meng] numAvailMachines == 7,  allpods length: 30
I0116 14:08:10.977689       1 scheduler.go:459] [meng] sched.schedule(pod) has error: user3/user3-pytorch-lenet-4, 0/13 nodes are available: 1 node(s) had taints that the pod didn't tolerate, 12 Insufficient cpu.
I0116 14:08:11.079872       1 util.go:1534] [meng] calling OnlineAlloX
I0116 14:08:11.079914       1 util.go:1550] [meng] numAvailMachines == 7,  allpods length: 30
I0116 14:08:11.118745       1 scheduler.go:459] [meng] sched.schedule(pod) has error: user4/user4-pytorch-lenet-4, 0/13 nodes are available: 1 node(s) had taints that the pod didn't tolerate, 12 Insufficient cpu.
I0116 14:08:11.220840       1 util.go:1534] [meng] calling OnlineAlloX
I0116 14:08:11.220868       1 util.go:1550] [meng] numAvailMachines == 7,  allpods length: 30
I0116 14:08:11.259437       1 scheduler.go:459] [meng] sched.schedule(pod) has error: user3/user3-pytorch-lenet-4, 0/13 nodes are available: 1 node(s) had taints that the pod didn't tolerate, 12 Insufficient cpu.
I0116 14:08:11.361614       1 util.go:1534] [meng] calling OnlineAlloX
I0116 14:08:11.361655       1 util.go:1550] [meng] numAvailMachines == 7,  allpods length: 30
I0116 14:08:11.402040       1 scheduler.go:459] [meng] sched.schedule(pod) has error: user3/user3-pytorch-lenet-4, 0/13 nodes are available: 1 node(s) had taints that the pod didn't tolerate, 12 Insufficient cpu.
I0116 14:08:11.504103       1 util.go:1534] [meng] calling OnlineAlloX
I0116 14:08:11.504143       1 util.go:1550] [meng] numAvailMachines == 7,  allpods length: 30
I0116 14:08:11.543158       1 scheduler.go:459] [meng] sched.schedule(pod) has error: user3/user3-pytorch-lenet-4, 0/13 nodes are available: 1 node(s) had taints that the pod didn't tolerate, 12 Insufficient cpu.
I0116 14:08:11.645642       1 util.go:1534] [meng] calling OnlineAlloX
I0116 14:08:11.645675       1 util.go:1550] [meng] numAvailMachines == 7,  allpods length: 30
I0116 14:08:11.683458       1 scheduler.go:459] [meng] sched.schedule(pod) has error: user3/user3-pytorch-lenet-4, 0/13 nodes are available: 1 node(s) had taints that the pod didn't tolerate, 12 Insufficient cpu.
I0116 14:08:11.785464       1 util.go:1534] [meng] calling OnlineAlloX
I0116 14:08:11.785504       1 util.go:1550] [meng] numAvailMachines == 7,  allpods length: 30
I0116 14:08:11.824996       1 scheduler.go:459] [meng] sched.schedule(pod) has error: user4/user4-pytorch-lenet-4, 0/13 nodes are available: 1 node(s) had taints that the pod didn't tolerate, 12 Insufficient cpu.
I0116 14:08:11.927297       1 util.go:1534] [meng] calling OnlineAlloX
I0116 14:08:11.927326       1 util.go:1550] [meng] numAvailMachines == 7,  allpods length: 30
I0116 14:08:11.965656       1 scheduler.go:459] [meng] sched.schedule(pod) has error: user4/user4-pytorch-lenet-4, 0/13 nodes are available: 1 node(s) had taints that the pod didn't tolerate, 12 Insufficient cpu.
I0116 14:08:12.067818       1 util.go:1534] [meng] calling OnlineAlloX
I0116 14:08:12.067847       1 util.go:1550] [meng] numAvailMachines == 7,  allpods length: 30
I0116 14:08:12.106637       1 scheduler.go:459] [meng] sched.schedule(pod) has error: user2/user2-pytorch-lenet-4, 0/13 nodes are available: 1 node(s) had taints that the pod didn't tolerate, 12 Insufficient cpu.
I0116 14:08:12.208991       1 util.go:1534] [meng] calling OnlineAlloX
I0116 14:08:12.209019       1 util.go:1550] [meng] numAvailMachines == 7,  allpods length: 30
I0116 14:08:12.247652       1 scheduler.go:459] [meng] sched.schedule(pod) has error: user2/user2-pytorch-lenet-4, 0/13 nodes are available: 1 node(s) had taints that the pod didn't tolerate, 12 Insufficient cpu.
I0116 14:08:12.349940       1 util.go:1534] [meng] calling OnlineAlloX
I0116 14:08:12.349982       1 util.go:1550] [meng] numAvailMachines == 7,  allpods length: 30
I0116 14:08:12.388025       1 scheduler.go:459] [meng] sched.schedule(pod) has error: user4/user4-pytorch-lenet-4, 0/13 nodes are available: 1 node(s) had taints that the pod didn't tolerate, 12 Insufficient cpu.
I0116 14:08:12.490150       1 util.go:1534] [meng] calling OnlineAlloX
I0116 14:08:12.490178       1 util.go:1550] [meng] numAvailMachines == 7,  allpods length: 30
I0116 14:08:12.528338       1 scheduler.go:459] [meng] sched.schedule(pod) has error: user3/user3-pytorch-lenet-4, 0/13 nodes are available: 1 node(s) had taints that the pod didn't tolerate, 12 Insufficient cpu.
I0116 14:08:12.630446       1 util.go:1534] [meng] calling OnlineAlloX
I0116 14:08:12.630475       1 util.go:1550] [meng] numAvailMachines == 7,  allpods length: 30
I0116 14:08:12.669237       1 scheduler.go:459] [meng] sched.schedule(pod) has error: user3/user3-pytorch-lenet-4, 0/13 nodes are available: 1 node(s) had taints that the pod didn't tolerate, 12 Insufficient cpu.
I0116 14:08:12.771496       1 util.go:1534] [meng] calling OnlineAlloX
I0116 14:08:12.771526       1 util.go:1550] [meng] numAvailMachines == 7,  allpods length: 30
I0116 14:08:12.810089       1 scheduler.go:459] [meng] sched.schedule(pod) has error: user3/user3-pytorch-lenet-4, 0/13 nodes are available: 1 node(s) had taints that the pod didn't tolerate, 12 Insufficient cpu.
I0116 14:08:12.912078       1 util.go:1534] [meng] calling OnlineAlloX
I0116 14:08:12.912117       1 util.go:1550] [meng] numAvailMachines == 7,  allpods length: 30
I0116 14:08:12.950098       1 scheduler.go:459] [meng] sched.schedule(pod) has error: user3/user3-pytorch-lenet-4, 0/13 nodes are available: 1 node(s) had taints that the pod didn't tolerate, 12 Insufficient cpu.
I0116 14:08:13.052308       1 util.go:1534] [meng] calling OnlineAlloX
I0116 14:08:13.052337       1 util.go:1550] [meng] numAvailMachines == 7,  allpods length: 30
I0116 14:08:13.091026       1 scheduler.go:459] [meng] sched.schedule(pod) has error: user4/user4-pytorch-lenet-4, 0/13 nodes are available: 1 node(s) had taints that the pod didn't tolerate, 12 Insufficient cpu.
I0116 14:08:13.192732       1 util.go:1534] [meng] calling OnlineAlloX
I0116 14:08:13.192761       1 util.go:1550] [meng] numAvailMachines == 7,  allpods length: 30
I0116 14:08:13.231084       1 scheduler.go:459] [meng] sched.schedule(pod) has error: user3/user3-pytorch-lenet-4, 0/13 nodes are available: 1 node(s) had taints that the pod didn't tolerate, 12 Insufficient cpu.
I0116 14:08:13.332936       1 util.go:1534] [meng] calling OnlineAlloX
I0116 14:08:13.332974       1 util.go:1550] [meng] numAvailMachines == 7,  allpods length: 30
I0116 14:08:13.371202       1 scheduler.go:459] [meng] sched.schedule(pod) has error: user4/user4-pytorch-lenet-4, 0/13 nodes are available: 1 node(s) had taints that the pod didn't tolerate, 12 Insufficient cpu.
I0116 14:08:13.473515       1 util.go:1534] [meng] calling OnlineAlloX
I0116 14:08:13.473553       1 util.go:1550] [meng] numAvailMachines == 7,  allpods length: 30
I0116 14:08:13.512414       1 scheduler.go:459] [meng] sched.schedule(pod) has error: user3/user3-pytorch-lenet-4, 0/13 nodes are available: 1 node(s) had taints that the pod didn't tolerate, 12 Insufficient cpu.
I0116 14:08:13.614690       1 util.go:1534] [meng] calling OnlineAlloX
I0116 14:08:13.614721       1 util.go:1550] [meng] numAvailMachines == 7,  allpods length: 30
I0116 14:08:13.653748       1 scheduler.go:459] [meng] sched.schedule(pod) has error: user3/user3-pytorch-lenet-4, 0/13 nodes are available: 1 node(s) had taints that the pod didn't tolerate, 12 Insufficient cpu.
I0116 14:08:13.755898       1 util.go:1534] [meng] calling OnlineAlloX
I0116 14:08:13.755927       1 util.go:1550] [meng] numAvailMachines == 7,  allpods length: 30
I0116 14:08:13.795104       1 scheduler.go:459] [meng] sched.schedule(pod) has error: user4/user4-pytorch-lenet-4, 0/13 nodes are available: 1 node(s) had taints that the pod didn't tolerate, 12 Insufficient cpu.
I0116 14:08:13.897285       1 util.go:1534] [meng] calling OnlineAlloX
I0116 14:08:13.897315       1 util.go:1550] [meng] numAvailMachines == 7,  allpods length: 30
I0116 14:08:13.935386       1 scheduler.go:459] [meng] sched.schedule(pod) has error: user3/user3-pytorch-lenet-4, 0/13 nodes are available: 1 node(s) had taints that the pod didn't tolerate, 12 Insufficient cpu.
I0116 14:08:14.037601       1 util.go:1534] [meng] calling OnlineAlloX
I0116 14:08:14.037630       1 util.go:1550] [meng] numAvailMachines == 7,  allpods length: 30
I0116 14:08:14.076499       1 scheduler.go:459] [meng] sched.schedule(pod) has error: user4/user4-pytorch-lenet-4, 0/13 nodes are available: 1 node(s) had taints that the pod didn't tolerate, 12 Insufficient cpu.
I0116 14:08:14.178888       1 util.go:1534] [meng] calling OnlineAlloX
I0116 14:08:14.178928       1 util.go:1550] [meng] numAvailMachines == 7,  allpods length: 30
I0116 14:08:14.218032       1 scheduler.go:459] [meng] sched.schedule(pod) has error: user4/user4-pytorch-lenet-4, 0/13 nodes are available: 1 node(s) had taints that the pod didn't tolerate, 12 Insufficient cpu.
I0116 14:08:14.320142       1 util.go:1534] [meng] calling OnlineAlloX
I0116 14:08:14.320168       1 util.go:1550] [meng] numAvailMachines == 7,  allpods length: 30
I0116 14:08:14.358344       1 scheduler.go:459] [meng] sched.schedule(pod) has error: user3/user3-pytorch-lenet-4, 0/13 nodes are available: 1 node(s) had taints that the pod didn't tolerate, 12 Insufficient cpu.
I0116 14:08:14.460469       1 util.go:1534] [meng] calling OnlineAlloX
I0116 14:08:14.460498       1 util.go:1550] [meng] numAvailMachines == 7,  allpods length: 30
I0116 14:08:14.498613       1 scheduler.go:459] [meng] sched.schedule(pod) has error: user3/user3-pytorch-lenet-4, 0/13 nodes are available: 1 node(s) had taints that the pod didn't tolerate, 12 Insufficient cpu.
I0116 14:08:14.600945       1 util.go:1534] [meng] calling OnlineAlloX
I0116 14:08:14.600983       1 util.go:1550] [meng] numAvailMachines == 7,  allpods length: 30
I0116 14:08:14.639096       1 scheduler.go:459] [meng] sched.schedule(pod) has error: user4/user4-pytorch-lenet-4, 0/13 nodes are available: 1 node(s) had taints that the pod didn't tolerate, 12 Insufficient cpu.
I0116 14:08:14.741103       1 util.go:1534] [meng] calling OnlineAlloX
I0116 14:08:14.741141       1 util.go:1550] [meng] numAvailMachines == 7,  allpods length: 30
I0116 14:08:14.780173       1 scheduler.go:459] [meng] sched.schedule(pod) has error: user2/user2-pytorch-lenet-4, 0/13 nodes are available: 1 node(s) had taints that the pod didn't tolerate, 12 Insufficient cpu.
I0116 14:08:14.882090       1 util.go:1534] [meng] calling OnlineAlloX
I0116 14:08:14.882124       1 util.go:1550] [meng] numAvailMachines == 7,  allpods length: 30
I0116 14:08:14.921220       1 scheduler.go:459] [meng] sched.schedule(pod) has error: user3/user3-pytorch-lenet-4, 0/13 nodes are available: 1 node(s) had taints that the pod didn't tolerate, 12 Insufficient cpu.
I0116 14:08:15.023248       1 util.go:1534] [meng] calling OnlineAlloX
I0116 14:08:15.023289       1 util.go:1550] [meng] numAvailMachines == 7,  allpods length: 30
I0116 14:08:15.061417       1 scheduler.go:459] [meng] sched.schedule(pod) has error: user2/user2-pytorch-lenet-4, 0/13 nodes are available: 1 node(s) had taints that the pod didn't tolerate, 12 Insufficient cpu.
I0116 14:08:15.163889       1 util.go:1534] [meng] calling OnlineAlloX
I0116 14:08:15.163929       1 util.go:1550] [meng] numAvailMachines == 7,  allpods length: 30
I0116 14:08:15.201565       1 scheduler.go:459] [meng] sched.schedule(pod) has error: user4/user4-pytorch-lenet-4, 0/13 nodes are available: 1 node(s) had taints that the pod didn't tolerate, 12 Insufficient cpu.
I0116 14:08:15.303608       1 util.go:1534] [meng] calling OnlineAlloX
I0116 14:08:15.303637       1 util.go:1550] [meng] numAvailMachines == 7,  allpods length: 30
I0116 14:08:15.341336       1 scheduler.go:459] [meng] sched.schedule(pod) has error: user3/user3-pytorch-lenet-4, 0/13 nodes are available: 1 node(s) had taints that the pod didn't tolerate, 12 Insufficient cpu.
I0116 14:08:15.443713       1 util.go:1534] [meng] calling OnlineAlloX
I0116 14:08:15.443742       1 util.go:1550] [meng] numAvailMachines == 7,  allpods length: 30
I0116 14:08:15.482731       1 scheduler.go:459] [meng] sched.schedule(pod) has error: user3/user3-pytorch-lenet-4, 0/13 nodes are available: 1 node(s) had taints that the pod didn't tolerate, 12 Insufficient cpu.
I0116 14:08:15.584994       1 util.go:1534] [meng] calling OnlineAlloX
I0116 14:08:15.585022       1 util.go:1550] [meng] numAvailMachines == 7,  allpods length: 30
I0116 14:08:15.623483       1 scheduler.go:459] [meng] sched.schedule(pod) has error: user3/user3-pytorch-lenet-4, 0/13 nodes are available: 1 node(s) had taints that the pod didn't tolerate, 12 Insufficient cpu.
I0116 14:08:15.725558       1 util.go:1534] [meng] calling OnlineAlloX
I0116 14:08:15.725606       1 util.go:1550] [meng] numAvailMachines == 7,  allpods length: 30
I0116 14:08:15.763464       1 scheduler.go:459] [meng] sched.schedule(pod) has error: user4/user4-pytorch-lenet-4, 0/13 nodes are available: 1 node(s) had taints that the pod didn't tolerate, 12 Insufficient cpu.
I0116 14:08:15.865578       1 util.go:1534] [meng] calling OnlineAlloX
I0116 14:08:15.865617       1 util.go:1550] [meng] numAvailMachines == 7,  allpods length: 30
I0116 14:08:15.903783       1 scheduler.go:459] [meng] sched.schedule(pod) has error: user3/user3-pytorch-lenet-4, 0/13 nodes are available: 1 node(s) had taints that the pod didn't tolerate, 12 Insufficient cpu.
I0116 14:08:16.006109       1 util.go:1534] [meng] calling OnlineAlloX
I0116 14:08:16.006137       1 util.go:1550] [meng] numAvailMachines == 7,  allpods length: 30
I0116 14:08:16.045596       1 scheduler.go:459] [meng] sched.schedule(pod) has error: user3/user3-pytorch-lenet-4, 0/13 nodes are available: 1 node(s) had taints that the pod didn't tolerate, 12 Insufficient cpu.
I0116 14:08:16.147840       1 util.go:1534] [meng] calling OnlineAlloX
I0116 14:08:16.147880       1 util.go:1550] [meng] numAvailMachines == 7,  allpods length: 30
I0116 14:08:16.186522       1 scheduler.go:459] [meng] sched.schedule(pod) has error: user3/user3-pytorch-lenet-4, 0/13 nodes are available: 1 node(s) had taints that the pod didn't tolerate, 12 Insufficient cpu.
I0116 14:08:16.288626       1 util.go:1534] [meng] calling OnlineAlloX
I0116 14:08:16.288654       1 util.go:1550] [meng] numAvailMachines == 7,  allpods length: 30
I0116 14:08:16.326900       1 scheduler.go:459] [meng] sched.schedule(pod) has error: user4/user4-pytorch-lenet-4, 0/13 nodes are available: 1 node(s) had taints that the pod didn't tolerate, 12 Insufficient cpu.
I0116 14:08:16.429161       1 util.go:1534] [meng] calling OnlineAlloX
I0116 14:08:16.429199       1 util.go:1550] [meng] numAvailMachines == 7,  allpods length: 30
I0116 14:08:16.467300       1 scheduler.go:459] [meng] sched.schedule(pod) has error: user4/user4-pytorch-lenet-4, 0/13 nodes are available: 1 node(s) had taints that the pod didn't tolerate, 12 Insufficient cpu.
I0116 14:08:16.569587       1 util.go:1534] [meng] calling OnlineAlloX
I0116 14:08:16.569630       1 util.go:1550] [meng] numAvailMachines == 7,  allpods length: 30
I0116 14:08:16.607822       1 scheduler.go:459] [meng] sched.schedule(pod) has error: user4/user4-pytorch-lenet-4, 0/13 nodes are available: 1 node(s) had taints that the pod didn't tolerate, 12 Insufficient cpu.
I0116 14:08:16.710039       1 util.go:1534] [meng] calling OnlineAlloX
I0116 14:08:16.710070       1 util.go:1550] [meng] numAvailMachines == 7,  allpods length: 30
I0116 14:08:16.749186       1 scheduler.go:459] [meng] sched.schedule(pod) has error: user3/user3-pytorch-lenet-4, 0/13 nodes are available: 1 node(s) had taints that the pod didn't tolerate, 12 Insufficient cpu.
I0116 14:08:16.851057       1 util.go:1534] [meng] calling OnlineAlloX
I0116 14:08:16.851122       1 util.go:1550] [meng] numAvailMachines == 7,  allpods length: 30
I0116 14:08:16.894470       1 scheduler.go:459] [meng] sched.schedule(pod) has error: user4/user4-pytorch-lenet-4, 0/13 nodes are available: 1 node(s) had taints that the pod didn't tolerate, 12 Insufficient cpu.
I0116 14:08:16.996623       1 util.go:1534] [meng] calling OnlineAlloX
I0116 14:08:16.996652       1 util.go:1550] [meng] numAvailMachines == 7,  allpods length: 30
I0116 14:08:17.036530       1 scheduler.go:459] [meng] sched.schedule(pod) has error: user2/user2-pytorch-lenet-4, 0/13 nodes are available: 1 node(s) had taints that the pod didn't tolerate, 12 Insufficient cpu.
I0116 14:08:17.138639       1 util.go:1534] [meng] calling OnlineAlloX
I0116 14:08:17.138669       1 util.go:1550] [meng] numAvailMachines == 7,  allpods length: 30
I0116 14:08:17.176837       1 scheduler.go:459] [meng] sched.schedule(pod) has error: user3/user3-pytorch-lenet-4, 0/13 nodes are available: 1 node(s) had taints that the pod didn't tolerate, 12 Insufficient cpu.
I0116 14:08:17.279024       1 util.go:1534] [meng] calling OnlineAlloX
I0116 14:08:17.279085       1 util.go:1550] [meng] numAvailMachines == 7,  allpods length: 30
I0116 14:08:17.318310       1 scheduler.go:459] [meng] sched.schedule(pod) has error: user3/user3-pytorch-lenet-4, 0/13 nodes are available: 1 node(s) had taints that the pod didn't tolerate, 12 Insufficient cpu.
I0116 14:08:17.420598       1 util.go:1534] [meng] calling OnlineAlloX
I0116 14:08:17.420626       1 util.go:1550] [meng] numAvailMachines == 7,  allpods length: 30
I0116 14:08:17.459266       1 scheduler.go:459] [meng] sched.schedule(pod) has error: user2/user2-pytorch-lenet-4, 0/13 nodes are available: 1 node(s) had taints that the pod didn't tolerate, 12 Insufficient cpu.
I0116 14:08:17.561218       1 util.go:1534] [meng] calling OnlineAlloX
I0116 14:08:17.561249       1 util.go:1550] [meng] numAvailMachines == 7,  allpods length: 30
I0116 14:08:17.600439       1 scheduler.go:459] [meng] sched.schedule(pod) has error: user3/user3-pytorch-lenet-4, 0/13 nodes are available: 1 node(s) had taints that the pod didn't tolerate, 12 Insufficient cpu.
I0116 14:08:17.702555       1 util.go:1534] [meng] calling OnlineAlloX
I0116 14:08:17.702586       1 util.go:1550] [meng] numAvailMachines == 7,  allpods length: 30
I0116 14:08:17.741015       1 scheduler.go:459] [meng] sched.schedule(pod) has error: user2/user2-pytorch-lenet-4, 0/13 nodes are available: 1 node(s) had taints that the pod didn't tolerate, 12 Insufficient cpu.
I0116 14:08:17.843359       1 util.go:1534] [meng] calling OnlineAlloX
I0116 14:08:17.843399       1 util.go:1550] [meng] numAvailMachines == 7,  allpods length: 30
I0116 14:08:17.882522       1 scheduler.go:459] [meng] sched.schedule(pod) has error: user4/user4-pytorch-lenet-4, 0/13 nodes are available: 1 node(s) had taints that the pod didn't tolerate, 12 Insufficient cpu.
I0116 14:08:17.984829       1 util.go:1534] [meng] calling OnlineAlloX
I0116 14:08:17.984862       1 util.go:1550] [meng] numAvailMachines == 7,  allpods length: 30
I0116 14:08:18.023902       1 scheduler.go:459] [meng] sched.schedule(pod) has error: user3/user3-pytorch-lenet-4, 0/13 nodes are available: 1 node(s) had taints that the pod didn't tolerate, 12 Insufficient cpu.
I0116 14:08:18.125722       1 util.go:1534] [meng] calling OnlineAlloX
I0116 14:08:18.125752       1 util.go:1550] [meng] numAvailMachines == 7,  allpods length: 30
I0116 14:08:18.163687       1 scheduler.go:459] [meng] sched.schedule(pod) has error: user3/user3-pytorch-lenet-4, 0/13 nodes are available: 1 node(s) had taints that the pod didn't tolerate, 12 Insufficient cpu.
I0116 14:08:18.269694       1 util.go:1534] [meng] calling OnlineAlloX
I0116 14:08:18.269734       1 util.go:1550] [meng] numAvailMachines == 7,  allpods length: 30
I0116 14:08:18.308479       1 scheduler.go:459] [meng] sched.schedule(pod) has error: user4/user4-pytorch-lenet-4, 0/13 nodes are available: 1 node(s) had taints that the pod didn't tolerate, 12 Insufficient cpu.
I0116 14:08:18.410849       1 util.go:1534] [meng] calling OnlineAlloX
I0116 14:08:18.410879       1 util.go:1550] [meng] numAvailMachines == 7,  allpods length: 30
I0116 14:08:18.449192       1 scheduler.go:459] [meng] sched.schedule(pod) has error: user4/user4-pytorch-lenet-4, 0/13 nodes are available: 1 node(s) had taints that the pod didn't tolerate, 12 Insufficient cpu.
I0116 14:08:18.551218       1 util.go:1534] [meng] calling OnlineAlloX
I0116 14:08:18.551248       1 util.go:1550] [meng] numAvailMachines == 7,  allpods length: 30
I0116 14:08:18.591195       1 scheduler.go:459] [meng] sched.schedule(pod) has error: user4/user4-pytorch-lenet-4, 0/13 nodes are available: 1 node(s) had taints that the pod didn't tolerate, 12 Insufficient cpu.
I0116 14:08:18.610881       1 factory.go:1129] [meng] deletePodFromCache
I0116 14:08:18.610891       1 factory.go:1136] [meng] JCT: 20.634071607s, total jct: 42.769820729s, count: 3, average JCT: 14.256606909s
I0116 14:08:18.620165       1 factory.go:798] [meng] computeComplTimeForAllPods completed
I0116 14:08:18.620181       1 factory.go:806] [tanle] Event pod completed user1/user1-pytorch-lenet-2%!(EXTRA v1.PodPhase=Succeeded)
I0116 14:08:18.620202       1 factory.go:1149] [meng] check delete pod user1/user1-pytorch-lenet-2, Running
I0116 14:08:18.620209       1 util.go:143] [meng] UpdateFairScore user1/user1-pytorch-lenet-2, false
I0116 14:08:18.620216       1 util.go:192] [meng] delete PodMachineMap in UpdateFairScore user1/user1-pytorch-lenet-2, false
I0116 14:08:18.620219       1 util.go:196] [tanle] FairScoreMap:  map[user3:0.19444444444444445 user4:0.5833333333333334 user1:0.1944444444444445 user2:0.3888888888888889]
I0116 14:08:18.693334       1 util.go:1534] [meng] calling OnlineAlloX
I0116 14:08:18.693364       1 util.go:1550] [meng] numAvailMachines == 8,  allpods length: 30
I0116 14:08:18.731697       1 util.go:908]     Done creating pod user2/user2-pytorch-lenet-3 on another device. New cpuDemand: 90000, gpuDemand: 0, memory: 20
I0116 14:08:18.737662       1 util.go:196] [tanle] FairScoreMap:  map[user4:0.5833333333333334 user1:0.1944444444444445 user2:0.5833333333333334 user3:0.19444444444444445]
I0116 14:08:18.739378       1 scheduler.go:406] [tanle] binding user2/user2-pytorch-lenet-3 on GPU false-->meng-allox-cpu-4
I0116 14:08:18.780042       1 factory.go:1129] [meng] deletePodFromCache
I0116 14:08:18.780052       1 factory.go:1136] [meng] JCT: 20.803233397s, total jct: 1m3.573054126s, count: 4, average JCT: 15.893263531s
I0116 14:08:18.790300       1 factory.go:798] [meng] computeComplTimeForAllPods completed
I0116 14:08:18.790324       1 factory.go:806] [tanle] Event pod completed user4/user4-pytorch-lenet-2%!(EXTRA v1.PodPhase=Succeeded)
I0116 14:08:18.790343       1 factory.go:1149] [meng] check delete pod user4/user4-pytorch-lenet-2, Running
I0116 14:08:18.790349       1 util.go:143] [meng] UpdateFairScore user4/user4-pytorch-lenet-2, false
I0116 14:08:18.790355       1 util.go:192] [meng] delete PodMachineMap in UpdateFairScore user4/user4-pytorch-lenet-2, false
I0116 14:08:18.790359       1 util.go:196] [tanle] FairScoreMap:  map[user1:0.1944444444444445 user2:0.5833333333333334 user3:0.19444444444444445 user4:0.38888888888888895]
I0116 14:08:18.837823       1 util.go:1534] [meng] calling OnlineAlloX
I0116 14:08:18.837856       1 util.go:1550] [meng] numAvailMachines == 8,  allpods length: 29
I0116 14:08:18.873337       1 util.go:908]     Done creating pod user3/user3-pytorch-lenet-5 on another device. New cpuDemand: 90000, gpuDemand: 0, memory: 20
I0116 14:08:18.880546       1 util.go:196] [tanle] FairScoreMap:  map[user1:0.1944444444444445 user2:0.5833333333333334 user3:0.3888888888888889 user4:0.38888888888888895]
I0116 14:08:18.882477       1 scheduler.go:406] [tanle] binding user3/user3-pytorch-lenet-5 on GPU false-->meng-allox-cpu-2
I0116 14:08:18.980701       1 util.go:1534] [meng] calling OnlineAlloX
I0116 14:08:18.980728       1 util.go:1550] [meng] numAvailMachines == 7,  allpods length: 28
I0116 14:08:19.007703       1 scheduler.go:459] [meng] sched.schedule(pod) has error: user4/user4-pytorch-lenet-4, 0/13 nodes are available: 1 node(s) had taints that the pod didn't tolerate, 12 Insufficient cpu.
I0116 14:08:19.109862       1 util.go:1534] [meng] calling OnlineAlloX
I0116 14:08:19.109892       1 util.go:1550] [meng] numAvailMachines == 7,  allpods length: 28
I0116 14:08:19.136068       1 scheduler.go:459] [meng] sched.schedule(pod) has error: user4/user4-pytorch-lenet-4, 0/13 nodes are available: 1 node(s) had taints that the pod didn't tolerate, 12 Insufficient cpu.
I0116 14:08:19.238030       1 util.go:1534] [meng] calling OnlineAlloX
I0116 14:08:19.238059       1 util.go:1550] [meng] numAvailMachines == 7,  allpods length: 28
I0116 14:08:19.264877       1 scheduler.go:459] [meng] sched.schedule(pod) has error: user4/user4-pytorch-lenet-4, 0/13 nodes are available: 1 node(s) had taints that the pod didn't tolerate, 12 Insufficient cpu.
I0116 14:08:19.366923       1 util.go:1534] [meng] calling OnlineAlloX
I0116 14:08:19.366952       1 util.go:1550] [meng] numAvailMachines == 7,  allpods length: 28
I0116 14:08:19.393673       1 scheduler.go:459] [meng] sched.schedule(pod) has error: user3/user3-pytorch-lenet-4, 0/13 nodes are available: 1 node(s) had taints that the pod didn't tolerate, 12 Insufficient cpu.
I0116 14:08:19.495679       1 util.go:1534] [meng] calling OnlineAlloX
I0116 14:08:19.495715       1 util.go:1550] [meng] numAvailMachines == 7,  allpods length: 28
I0116 14:08:19.522092       1 scheduler.go:459] [meng] sched.schedule(pod) has error: user3/user3-pytorch-lenet-4, 0/13 nodes are available: 1 node(s) had taints that the pod didn't tolerate, 12 Insufficient cpu.
I0116 14:08:19.624005       1 util.go:1534] [meng] calling OnlineAlloX
I0116 14:08:19.624036       1 util.go:1550] [meng] numAvailMachines == 7,  allpods length: 28
I0116 14:08:19.649937       1 scheduler.go:459] [meng] sched.schedule(pod) has error: user4/user4-pytorch-lenet-4, 0/13 nodes are available: 1 node(s) had taints that the pod didn't tolerate, 12 Insufficient cpu.
I0116 14:08:19.752094       1 util.go:1534] [meng] calling OnlineAlloX
I0116 14:08:19.752127       1 util.go:1550] [meng] numAvailMachines == 7,  allpods length: 28
I0116 14:08:19.778970       1 scheduler.go:459] [meng] sched.schedule(pod) has error: user3/user3-pytorch-lenet-4, 0/13 nodes are available: 1 node(s) had taints that the pod didn't tolerate, 12 Insufficient cpu.
I0116 14:08:19.881162       1 util.go:1534] [meng] calling OnlineAlloX
I0116 14:08:19.881190       1 util.go:1550] [meng] numAvailMachines == 7,  allpods length: 28
I0116 14:08:19.907484       1 scheduler.go:459] [meng] sched.schedule(pod) has error: user2/user2-pytorch-lenet-4, 0/13 nodes are available: 1 node(s) had taints that the pod didn't tolerate, 12 Insufficient cpu.
I0116 14:08:19.940611       1 factory.go:1129] [meng] deletePodFromCache
I0116 14:08:19.940622       1 factory.go:1136] [meng] JCT: 21.963802659s, total jct: 1m25.536856785s, count: 5, average JCT: 17.107371357s
I0116 14:08:19.949509       1 factory.go:798] [meng] computeComplTimeForAllPods completed
I0116 14:08:19.949527       1 factory.go:806] [tanle] Event pod completed user4/user4-pytorch-lenet%!(EXTRA v1.PodPhase=Succeeded)
I0116 14:08:19.949546       1 factory.go:1149] [meng] check delete pod user4/user4-pytorch-lenet, Running
I0116 14:08:19.949552       1 util.go:143] [meng] UpdateFairScore user4/user4-pytorch-lenet, false
I0116 14:08:19.949559       1 util.go:192] [meng] delete PodMachineMap in UpdateFairScore user4/user4-pytorch-lenet, false
I0116 14:08:19.949565       1 util.go:196] [tanle] FairScoreMap:  map[user1:0.1944444444444445 user2:0.5833333333333334 user3:0.3888888888888889 user4:0.1944444444444445]
I0116 14:08:20.009762       1 util.go:1534] [meng] calling OnlineAlloX
I0116 14:08:20.009814       1 util.go:1550] [meng] numAvailMachines == 8,  allpods length: 28
I0116 14:08:20.038425       1 util.go:908]     Done creating pod user3/user3-pytorch-lenet on another device. New cpuDemand: 90000, gpuDemand: 0, memory: 20
I0116 14:08:20.045132       1 util.go:196] [tanle] FairScoreMap:  map[user1:0.1944444444444445 user2:0.5833333333333334 user3:0.5833333333333334 user4:0.1944444444444445]
I0116 14:08:20.046932       1 scheduler.go:406] [tanle] binding user3/user3-pytorch-lenet on GPU false-->meng-allox-cpu-6
I0116 14:08:20.145299       1 util.go:1534] [meng] calling OnlineAlloX
I0116 14:08:20.145342       1 util.go:1550] [meng] numAvailMachines == 7,  allpods length: 27
I0116 14:08:20.170888       1 scheduler.go:459] [meng] sched.schedule(pod) has error: user3/user3-pytorch-lenet-4, 0/13 nodes are available: 1 node(s) had taints that the pod didn't tolerate, 12 Insufficient cpu.
I0116 14:08:20.273527       1 util.go:1534] [meng] calling OnlineAlloX
I0116 14:08:20.273598       1 util.go:1550] [meng] numAvailMachines == 7,  allpods length: 27
I0116 14:08:20.298368       1 scheduler.go:459] [meng] sched.schedule(pod) has error: user4/user4-pytorch-lenet-4, 0/13 nodes are available: 1 node(s) had taints that the pod didn't tolerate, 12 Insufficient cpu.
I0116 14:08:20.400466       1 util.go:1534] [meng] calling OnlineAlloX
I0116 14:08:20.400495       1 util.go:1550] [meng] numAvailMachines == 7,  allpods length: 27
I0116 14:08:20.424947       1 scheduler.go:459] [meng] sched.schedule(pod) has error: user2/user2-pytorch-lenet-4, 0/13 nodes are available: 1 node(s) had taints that the pod didn't tolerate, 12 Insufficient cpu.
I0116 14:08:20.526890       1 util.go:1534] [meng] calling OnlineAlloX
I0116 14:08:20.526920       1 util.go:1550] [meng] numAvailMachines == 7,  allpods length: 27
I0116 14:08:20.550885       1 scheduler.go:459] [meng] sched.schedule(pod) has error: user4/user4-pytorch-lenet-4, 0/13 nodes are available: 1 node(s) had taints that the pod didn't tolerate, 12 Insufficient cpu.
I0116 14:08:20.652989       1 util.go:1534] [meng] calling OnlineAlloX
I0116 14:08:20.653025       1 util.go:1550] [meng] numAvailMachines == 7,  allpods length: 27
I0116 14:08:20.676675       1 scheduler.go:459] [meng] sched.schedule(pod) has error: user3/user3-pytorch-lenet-4, 0/13 nodes are available: 1 node(s) had taints that the pod didn't tolerate, 12 Insufficient cpu.
I0116 14:08:20.779865       1 util.go:1534] [meng] calling OnlineAlloX
I0116 14:08:20.779910       1 util.go:1550] [meng] numAvailMachines == 7,  allpods length: 27
I0116 14:08:20.804333       1 scheduler.go:459] [meng] sched.schedule(pod) has error: user3/user3-pytorch-lenet-4, 0/13 nodes are available: 1 node(s) had taints that the pod didn't tolerate, 12 Insufficient cpu.
I0116 14:08:20.906453       1 util.go:1534] [meng] calling OnlineAlloX
I0116 14:08:20.906522       1 util.go:1550] [meng] numAvailMachines == 7,  allpods length: 27
I0116 14:08:20.933333       1 scheduler.go:459] [meng] sched.schedule(pod) has error: user4/user4-pytorch-lenet-4, 0/13 nodes are available: 1 node(s) had taints that the pod didn't tolerate, 12 Insufficient cpu.
I0116 14:08:21.035991       1 util.go:1534] [meng] calling OnlineAlloX
I0116 14:08:21.036029       1 util.go:1550] [meng] numAvailMachines == 7,  allpods length: 27
I0116 14:08:21.061411       1 scheduler.go:459] [meng] sched.schedule(pod) has error: user3/user3-pytorch-lenet-4, 0/13 nodes are available: 1 node(s) had taints that the pod didn't tolerate, 12 Insufficient cpu.
I0116 14:08:21.163498       1 util.go:1534] [meng] calling OnlineAlloX
I0116 14:08:21.163543       1 util.go:1550] [meng] numAvailMachines == 7,  allpods length: 27
I0116 14:08:21.188956       1 scheduler.go:459] [meng] sched.schedule(pod) has error: user3/user3-pytorch-lenet-4, 0/13 nodes are available: 1 node(s) had taints that the pod didn't tolerate, 12 Insufficient cpu.
I0116 14:08:21.291486       1 util.go:1534] [meng] calling OnlineAlloX
I0116 14:08:21.291530       1 util.go:1550] [meng] numAvailMachines == 7,  allpods length: 27
I0116 14:08:21.317541       1 scheduler.go:459] [meng] sched.schedule(pod) has error: user3/user3-pytorch-lenet-4, 0/13 nodes are available: 1 node(s) had taints that the pod didn't tolerate, 12 Insufficient cpu.
I0116 14:08:21.419813       1 util.go:1534] [meng] calling OnlineAlloX
I0116 14:08:21.419861       1 util.go:1550] [meng] numAvailMachines == 7,  allpods length: 27
I0116 14:08:21.445314       1 scheduler.go:459] [meng] sched.schedule(pod) has error: user3/user3-pytorch-lenet-4, 0/13 nodes are available: 1 node(s) had taints that the pod didn't tolerate, 12 Insufficient cpu.
I0116 14:08:21.547478       1 util.go:1534] [meng] calling OnlineAlloX
I0116 14:08:21.547520       1 util.go:1550] [meng] numAvailMachines == 7,  allpods length: 27
I0116 14:08:21.573781       1 scheduler.go:459] [meng] sched.schedule(pod) has error: user3/user3-pytorch-lenet-4, 0/13 nodes are available: 1 node(s) had taints that the pod didn't tolerate, 12 Insufficient cpu.
I0116 14:08:21.676244       1 util.go:1534] [meng] calling OnlineAlloX
I0116 14:08:21.676282       1 util.go:1550] [meng] numAvailMachines == 7,  allpods length: 27
I0116 14:08:21.700913       1 scheduler.go:459] [meng] sched.schedule(pod) has error: user4/user4-pytorch-lenet-4, 0/13 nodes are available: 1 node(s) had taints that the pod didn't tolerate, 12 Insufficient cpu.
I0116 14:08:21.802929       1 util.go:1534] [meng] calling OnlineAlloX
I0116 14:08:21.802958       1 util.go:1550] [meng] numAvailMachines == 7,  allpods length: 27
I0116 14:08:21.827182       1 scheduler.go:459] [meng] sched.schedule(pod) has error: user4/user4-pytorch-lenet-4, 0/13 nodes are available: 1 node(s) had taints that the pod didn't tolerate, 12 Insufficient cpu.
I0116 14:08:21.929268       1 util.go:1534] [meng] calling OnlineAlloX
I0116 14:08:21.929300       1 util.go:1550] [meng] numAvailMachines == 7,  allpods length: 27
I0116 14:08:21.953614       1 scheduler.go:459] [meng] sched.schedule(pod) has error: user3/user3-pytorch-lenet-4, 0/13 nodes are available: 1 node(s) had taints that the pod didn't tolerate, 12 Insufficient cpu.
I0116 14:08:22.055585       1 util.go:1534] [meng] calling OnlineAlloX
I0116 14:08:22.055614       1 util.go:1550] [meng] numAvailMachines == 7,  allpods length: 27
I0116 14:08:22.079370       1 scheduler.go:459] [meng] sched.schedule(pod) has error: user3/user3-pytorch-lenet-4, 0/13 nodes are available: 1 node(s) had taints that the pod didn't tolerate, 12 Insufficient cpu.
I0116 14:08:22.181189       1 util.go:1534] [meng] calling OnlineAlloX
I0116 14:08:22.181224       1 util.go:1550] [meng] numAvailMachines == 7,  allpods length: 27
I0116 14:08:22.205786       1 scheduler.go:459] [meng] sched.schedule(pod) has error: user3/user3-pytorch-lenet-4, 0/13 nodes are available: 1 node(s) had taints that the pod didn't tolerate, 12 Insufficient cpu.
I0116 14:08:22.308047       1 util.go:1534] [meng] calling OnlineAlloX
I0116 14:08:22.308075       1 util.go:1550] [meng] numAvailMachines == 7,  allpods length: 27
I0116 14:08:22.332098       1 scheduler.go:459] [meng] sched.schedule(pod) has error: user3/user3-pytorch-lenet-4, 0/13 nodes are available: 1 node(s) had taints that the pod didn't tolerate, 12 Insufficient cpu.
I0116 14:08:22.434342       1 util.go:1534] [meng] calling OnlineAlloX
I0116 14:08:22.434372       1 util.go:1550] [meng] numAvailMachines == 7,  allpods length: 27
I0116 14:08:22.458045       1 scheduler.go:459] [meng] sched.schedule(pod) has error: user3/user3-pytorch-lenet-4, 0/13 nodes are available: 1 node(s) had taints that the pod didn't tolerate, 12 Insufficient cpu.
I0116 14:08:22.560291       1 util.go:1534] [meng] calling OnlineAlloX
I0116 14:08:22.560332       1 util.go:1550] [meng] numAvailMachines == 7,  allpods length: 27
I0116 14:08:22.583732       1 scheduler.go:459] [meng] sched.schedule(pod) has error: user3/user3-pytorch-lenet-4, 0/13 nodes are available: 1 node(s) had taints that the pod didn't tolerate, 12 Insufficient cpu.
I0116 14:08:22.685807       1 util.go:1534] [meng] calling OnlineAlloX
I0116 14:08:22.685836       1 util.go:1550] [meng] numAvailMachines == 7,  allpods length: 27
I0116 14:08:22.709468       1 scheduler.go:459] [meng] sched.schedule(pod) has error: user3/user3-pytorch-lenet-4, 0/13 nodes are available: 1 node(s) had taints that the pod didn't tolerate, 12 Insufficient cpu.
I0116 14:08:22.811745       1 util.go:1534] [meng] calling OnlineAlloX
I0116 14:08:22.811775       1 util.go:1550] [meng] numAvailMachines == 7,  allpods length: 27
I0116 14:08:22.835833       1 scheduler.go:459] [meng] sched.schedule(pod) has error: user4/user4-pytorch-lenet-4, 0/13 nodes are available: 1 node(s) had taints that the pod didn't tolerate, 12 Insufficient cpu.
I0116 14:08:22.937971       1 util.go:1534] [meng] calling OnlineAlloX
I0116 14:08:22.937999       1 util.go:1550] [meng] numAvailMachines == 7,  allpods length: 27
I0116 14:08:22.961253       1 scheduler.go:459] [meng] sched.schedule(pod) has error: user3/user3-pytorch-lenet-4, 0/13 nodes are available: 1 node(s) had taints that the pod didn't tolerate, 12 Insufficient cpu.
I0116 14:08:23.063514       1 util.go:1534] [meng] calling OnlineAlloX
I0116 14:08:23.063545       1 util.go:1550] [meng] numAvailMachines == 7,  allpods length: 27
I0116 14:08:23.086988       1 scheduler.go:459] [meng] sched.schedule(pod) has error: user2/user2-pytorch-lenet-4, 0/13 nodes are available: 1 node(s) had taints that the pod didn't tolerate, 12 Insufficient cpu.
I0116 14:08:23.189088       1 util.go:1534] [meng] calling OnlineAlloX
I0116 14:08:23.189120       1 util.go:1550] [meng] numAvailMachines == 7,  allpods length: 27
I0116 14:08:23.216738       1 scheduler.go:459] [meng] sched.schedule(pod) has error: user3/user3-pytorch-lenet-4, 0/13 nodes are available: 1 node(s) had taints that the pod didn't tolerate, 12 Insufficient cpu.
I0116 14:08:23.318990       1 util.go:1534] [meng] calling OnlineAlloX
I0116 14:08:23.319033       1 util.go:1550] [meng] numAvailMachines == 7,  allpods length: 27
I0116 14:08:23.342795       1 scheduler.go:459] [meng] sched.schedule(pod) has error: user3/user3-pytorch-lenet-4, 0/13 nodes are available: 1 node(s) had taints that the pod didn't tolerate, 12 Insufficient cpu.
I0116 14:08:23.444738       1 util.go:1534] [meng] calling OnlineAlloX
I0116 14:08:23.444767       1 util.go:1550] [meng] numAvailMachines == 7,  allpods length: 27
I0116 14:08:23.468614       1 scheduler.go:459] [meng] sched.schedule(pod) has error: user2/user2-pytorch-lenet-4, 0/13 nodes are available: 1 node(s) had taints that the pod didn't tolerate, 12 Insufficient cpu.
I0116 14:08:23.570770       1 util.go:1534] [meng] calling OnlineAlloX
I0116 14:08:23.570802       1 util.go:1550] [meng] numAvailMachines == 7,  allpods length: 27
I0116 14:08:23.595166       1 scheduler.go:459] [meng] sched.schedule(pod) has error: user3/user3-pytorch-lenet-4, 0/13 nodes are available: 1 node(s) had taints that the pod didn't tolerate, 12 Insufficient cpu.
I0116 14:08:23.697304       1 util.go:1534] [meng] calling OnlineAlloX
I0116 14:08:23.697343       1 util.go:1550] [meng] numAvailMachines == 7,  allpods length: 27
I0116 14:08:23.721002       1 scheduler.go:459] [meng] sched.schedule(pod) has error: user2/user2-pytorch-lenet-4, 0/13 nodes are available: 1 node(s) had taints that the pod didn't tolerate, 12 Insufficient cpu.
I0116 14:08:23.823331       1 util.go:1534] [meng] calling OnlineAlloX
I0116 14:08:23.823374       1 util.go:1550] [meng] numAvailMachines == 7,  allpods length: 27
I0116 14:08:23.846552       1 scheduler.go:459] [meng] sched.schedule(pod) has error: user2/user2-pytorch-lenet-4, 0/13 nodes are available: 1 node(s) had taints that the pod didn't tolerate, 12 Insufficient cpu.
I0116 14:08:23.948777       1 util.go:1534] [meng] calling OnlineAlloX
I0116 14:08:23.948805       1 util.go:1550] [meng] numAvailMachines == 7,  allpods length: 27
I0116 14:08:23.972104       1 scheduler.go:459] [meng] sched.schedule(pod) has error: user3/user3-pytorch-lenet-4, 0/13 nodes are available: 1 node(s) had taints that the pod didn't tolerate, 12 Insufficient cpu.
I0116 14:08:24.074228       1 util.go:1534] [meng] calling OnlineAlloX
I0116 14:08:24.074256       1 util.go:1550] [meng] numAvailMachines == 7,  allpods length: 27
I0116 14:08:24.097617       1 scheduler.go:459] [meng] sched.schedule(pod) has error: user3/user3-pytorch-lenet-4, 0/13 nodes are available: 1 node(s) had taints that the pod didn't tolerate, 12 Insufficient cpu.
I0116 14:08:24.199429       1 util.go:1534] [meng] calling OnlineAlloX
I0116 14:08:24.199458       1 util.go:1550] [meng] numAvailMachines == 7,  allpods length: 27
I0116 14:08:24.223574       1 scheduler.go:459] [meng] sched.schedule(pod) has error: user2/user2-pytorch-lenet-4, 0/13 nodes are available: 1 node(s) had taints that the pod didn't tolerate, 12 Insufficient cpu.
I0116 14:08:24.325490       1 util.go:1534] [meng] calling OnlineAlloX
I0116 14:08:24.325521       1 util.go:1550] [meng] numAvailMachines == 7,  allpods length: 27
I0116 14:08:24.349095       1 scheduler.go:459] [meng] sched.schedule(pod) has error: user3/user3-pytorch-lenet-4, 0/13 nodes are available: 1 node(s) had taints that the pod didn't tolerate, 12 Insufficient cpu.
I0116 14:08:24.451497       1 util.go:1534] [meng] calling OnlineAlloX
I0116 14:08:24.451527       1 util.go:1550] [meng] numAvailMachines == 7,  allpods length: 27
I0116 14:08:24.474927       1 scheduler.go:459] [meng] sched.schedule(pod) has error: user3/user3-pytorch-lenet-4, 0/13 nodes are available: 1 node(s) had taints that the pod didn't tolerate, 12 Insufficient cpu.
I0116 14:08:24.577181       1 util.go:1534] [meng] calling OnlineAlloX
I0116 14:08:24.577211       1 util.go:1550] [meng] numAvailMachines == 7,  allpods length: 27
I0116 14:08:24.600344       1 scheduler.go:459] [meng] sched.schedule(pod) has error: user3/user3-pytorch-lenet-4, 0/13 nodes are available: 1 node(s) had taints that the pod didn't tolerate, 12 Insufficient cpu.
I0116 14:08:24.702510       1 util.go:1534] [meng] calling OnlineAlloX
I0116 14:08:24.702538       1 util.go:1550] [meng] numAvailMachines == 7,  allpods length: 27
I0116 14:08:24.726513       1 scheduler.go:459] [meng] sched.schedule(pod) has error: user3/user3-pytorch-lenet-4, 0/13 nodes are available: 1 node(s) had taints that the pod didn't tolerate, 12 Insufficient cpu.
I0116 14:08:24.828866       1 util.go:1534] [meng] calling OnlineAlloX
I0116 14:08:24.828896       1 util.go:1550] [meng] numAvailMachines == 7,  allpods length: 27
I0116 14:08:24.853006       1 scheduler.go:459] [meng] sched.schedule(pod) has error: user4/user4-pytorch-lenet-4, 0/13 nodes are available: 1 node(s) had taints that the pod didn't tolerate, 12 Insufficient cpu.
I0116 14:08:24.955156       1 util.go:1534] [meng] calling OnlineAlloX
I0116 14:08:24.955186       1 util.go:1550] [meng] numAvailMachines == 7,  allpods length: 27
I0116 14:08:24.979706       1 scheduler.go:459] [meng] sched.schedule(pod) has error: user3/user3-pytorch-lenet-4, 0/13 nodes are available: 1 node(s) had taints that the pod didn't tolerate, 12 Insufficient cpu.
I0116 14:08:25.082076       1 util.go:1534] [meng] calling OnlineAlloX
I0116 14:08:25.082115       1 util.go:1550] [meng] numAvailMachines == 7,  allpods length: 27
I0116 14:08:25.106927       1 scheduler.go:459] [meng] sched.schedule(pod) has error: user4/user4-pytorch-lenet-4, 0/13 nodes are available: 1 node(s) had taints that the pod didn't tolerate, 12 Insufficient cpu.
I0116 14:08:25.209036       1 util.go:1534] [meng] calling OnlineAlloX
I0116 14:08:25.209064       1 util.go:1550] [meng] numAvailMachines == 7,  allpods length: 27
I0116 14:08:25.232704       1 scheduler.go:459] [meng] sched.schedule(pod) has error: user3/user3-pytorch-lenet-4, 0/13 nodes are available: 1 node(s) had taints that the pod didn't tolerate, 12 Insufficient cpu.
I0116 14:08:25.334989       1 util.go:1534] [meng] calling OnlineAlloX
I0116 14:08:25.335018       1 util.go:1550] [meng] numAvailMachines == 7,  allpods length: 27
I0116 14:08:25.359148       1 scheduler.go:459] [meng] sched.schedule(pod) has error: user3/user3-pytorch-lenet-4, 0/13 nodes are available: 1 node(s) had taints that the pod didn't tolerate, 12 Insufficient cpu.
I0116 14:08:25.461256       1 util.go:1534] [meng] calling OnlineAlloX
I0116 14:08:25.461290       1 util.go:1550] [meng] numAvailMachines == 7,  allpods length: 27
I0116 14:08:25.485145       1 scheduler.go:459] [meng] sched.schedule(pod) has error: user4/user4-pytorch-lenet-4, 0/13 nodes are available: 1 node(s) had taints that the pod didn't tolerate, 12 Insufficient cpu.
I0116 14:08:25.587441       1 util.go:1534] [meng] calling OnlineAlloX
I0116 14:08:25.587469       1 util.go:1550] [meng] numAvailMachines == 7,  allpods length: 27
I0116 14:08:25.611142       1 scheduler.go:459] [meng] sched.schedule(pod) has error: user3/user3-pytorch-lenet-4, 0/13 nodes are available: 1 node(s) had taints that the pod didn't tolerate, 12 Insufficient cpu.
I0116 14:08:25.713196       1 util.go:1534] [meng] calling OnlineAlloX
I0116 14:08:25.713224       1 util.go:1550] [meng] numAvailMachines == 7,  allpods length: 27
I0116 14:08:25.738005       1 scheduler.go:459] [meng] sched.schedule(pod) has error: user3/user3-pytorch-lenet-4, 0/13 nodes are available: 1 node(s) had taints that the pod didn't tolerate, 12 Insufficient cpu.
I0116 14:08:25.840203       1 util.go:1534] [meng] calling OnlineAlloX
I0116 14:08:25.840243       1 util.go:1550] [meng] numAvailMachines == 7,  allpods length: 27
I0116 14:08:25.863716       1 scheduler.go:459] [meng] sched.schedule(pod) has error: user4/user4-pytorch-lenet-4, 0/13 nodes are available: 1 node(s) had taints that the pod didn't tolerate, 12 Insufficient cpu.
I0116 14:08:25.965871       1 util.go:1534] [meng] calling OnlineAlloX
I0116 14:08:25.965900       1 util.go:1550] [meng] numAvailMachines == 7,  allpods length: 27
I0116 14:08:25.995031       1 scheduler.go:459] [meng] sched.schedule(pod) has error: user3/user3-pytorch-lenet-4, 0/13 nodes are available: 1 node(s) had taints that the pod didn't tolerate, 12 Insufficient cpu.
I0116 14:08:26.097207       1 util.go:1534] [meng] calling OnlineAlloX
I0116 14:08:26.097260       1 util.go:1550] [meng] numAvailMachines == 7,  allpods length: 27
I0116 14:08:26.128621       1 scheduler.go:459] [meng] sched.schedule(pod) has error: user2/user2-pytorch-lenet-4, 0/13 nodes are available: 1 node(s) had taints that the pod didn't tolerate, 12 Insufficient cpu.
I0116 14:08:26.230904       1 util.go:1534] [meng] calling OnlineAlloX
I0116 14:08:26.230933       1 util.go:1550] [meng] numAvailMachines == 7,  allpods length: 27
I0116 14:08:26.254751       1 scheduler.go:459] [meng] sched.schedule(pod) has error: user4/user4-pytorch-lenet-4, 0/13 nodes are available: 1 node(s) had taints that the pod didn't tolerate, 12 Insufficient cpu.
I0116 14:08:26.356764       1 util.go:1534] [meng] calling OnlineAlloX
I0116 14:08:26.356799       1 util.go:1550] [meng] numAvailMachines == 7,  allpods length: 27
I0116 14:08:26.379877       1 scheduler.go:459] [meng] sched.schedule(pod) has error: user3/user3-pytorch-lenet-4, 0/13 nodes are available: 1 node(s) had taints that the pod didn't tolerate, 12 Insufficient cpu.
I0116 14:08:26.481925       1 util.go:1534] [meng] calling OnlineAlloX
I0116 14:08:26.481953       1 util.go:1550] [meng] numAvailMachines == 7,  allpods length: 27
I0116 14:08:26.505772       1 scheduler.go:459] [meng] sched.schedule(pod) has error: user3/user3-pytorch-lenet-4, 0/13 nodes are available: 1 node(s) had taints that the pod didn't tolerate, 12 Insufficient cpu.
I0116 14:08:26.607991       1 util.go:1534] [meng] calling OnlineAlloX
I0116 14:08:26.608019       1 util.go:1550] [meng] numAvailMachines == 7,  allpods length: 27
I0116 14:08:26.631531       1 scheduler.go:459] [meng] sched.schedule(pod) has error: user3/user3-pytorch-lenet-4, 0/13 nodes are available: 1 node(s) had taints that the pod didn't tolerate, 12 Insufficient cpu.
I0116 14:08:26.733919       1 util.go:1534] [meng] calling OnlineAlloX
I0116 14:08:26.733947       1 util.go:1550] [meng] numAvailMachines == 7,  allpods length: 27
I0116 14:08:26.757473       1 scheduler.go:459] [meng] sched.schedule(pod) has error: user4/user4-pytorch-lenet-4, 0/13 nodes are available: 1 node(s) had taints that the pod didn't tolerate, 12 Insufficient cpu.
I0116 14:08:26.859606       1 util.go:1534] [meng] calling OnlineAlloX
I0116 14:08:26.859664       1 util.go:1550] [meng] numAvailMachines == 7,  allpods length: 27
I0116 14:08:26.885166       1 scheduler.go:459] [meng] sched.schedule(pod) has error: user4/user4-pytorch-lenet-4, 0/13 nodes are available: 1 node(s) had taints that the pod didn't tolerate, 12 Insufficient cpu.
I0116 14:08:26.987464       1 util.go:1534] [meng] calling OnlineAlloX
I0116 14:08:26.987495       1 util.go:1550] [meng] numAvailMachines == 7,  allpods length: 27
I0116 14:08:27.012727       1 scheduler.go:459] [meng] sched.schedule(pod) has error: user3/user3-pytorch-lenet-4, 0/13 nodes are available: 1 node(s) had taints that the pod didn't tolerate, 12 Insufficient cpu.
I0116 14:08:27.114813       1 util.go:1534] [meng] calling OnlineAlloX
I0116 14:08:27.114842       1 util.go:1550] [meng] numAvailMachines == 7,  allpods length: 27
I0116 14:08:27.138722       1 scheduler.go:459] [meng] sched.schedule(pod) has error: user4/user4-pytorch-lenet-4, 0/13 nodes are available: 1 node(s) had taints that the pod didn't tolerate, 12 Insufficient cpu.
I0116 14:08:27.240635       1 util.go:1534] [meng] calling OnlineAlloX
I0116 14:08:27.240663       1 util.go:1550] [meng] numAvailMachines == 7,  allpods length: 27
I0116 14:08:27.264442       1 scheduler.go:459] [meng] sched.schedule(pod) has error: user3/user3-pytorch-lenet-4, 0/13 nodes are available: 1 node(s) had taints that the pod didn't tolerate, 12 Insufficient cpu.
I0116 14:08:27.299632       1 factory.go:1129] [meng] deletePodFromCache
I0116 14:08:27.299641       1 factory.go:1136] [meng] JCT: 29.322822648s, total jct: 1m54.859679433s, count: 6, average JCT: 19.143279905s
I0116 14:08:27.308775       1 factory.go:798] [meng] computeComplTimeForAllPods completed
I0116 14:08:27.308795       1 factory.go:806] [tanle] Event pod completed user4/user4-pytorch-lenet-3%!(EXTRA v1.PodPhase=Succeeded)
I0116 14:08:27.308814       1 factory.go:1149] [meng] check delete pod user4/user4-pytorch-lenet-3, Running
I0116 14:08:27.308819       1 util.go:143] [meng] UpdateFairScore user4/user4-pytorch-lenet-3, false
I0116 14:08:27.308827       1 util.go:192] [meng] delete PodMachineMap in UpdateFairScore user4/user4-pytorch-lenet-3, false
I0116 14:08:27.308831       1 util.go:196] [tanle] FairScoreMap:  map[user1:0.1944444444444445 user2:0.5833333333333334 user3:0.5833333333333334 user4:5.551115123125783e-17]
I0116 14:08:27.366778       1 util.go:1534] [meng] calling OnlineAlloX
I0116 14:08:27.366824       1 util.go:1550] [meng] numAvailMachines == 8,  allpods length: 27
I0116 14:08:27.389362       1 util.go:908]     Done creating pod user1/user1-pytorch-lenet-4 on another device. New cpuDemand: 90000, gpuDemand: 0, memory: 20
I0116 14:08:27.398467       1 util.go:196] [tanle] FairScoreMap:  map[user1:0.38888888888888895 user2:0.5833333333333334 user3:0.5833333333333334 user4:5.551115123125783e-17]
I0116 14:08:27.400159       1 scheduler.go:406] [tanle] binding user1/user1-pytorch-lenet-4 on GPU false-->meng-allox-cpu-7
I0116 14:08:27.498653       1 util.go:1534] [meng] calling OnlineAlloX
I0116 14:08:27.498701       1 util.go:1550] [meng] numAvailMachines == 7,  allpods length: 26
I0116 14:08:27.520219       1 scheduler.go:459] [meng] sched.schedule(pod) has error: user3/user3-pytorch-lenet-4, 0/13 nodes are available: 1 node(s) had taints that the pod didn't tolerate, 12 Insufficient cpu.
I0116 14:08:27.622224       1 util.go:1534] [meng] calling OnlineAlloX
I0116 14:08:27.622264       1 util.go:1550] [meng] numAvailMachines == 7,  allpods length: 26
I0116 14:08:27.644061       1 scheduler.go:459] [meng] sched.schedule(pod) has error: user3/user3-pytorch-lenet-4, 0/13 nodes are available: 1 node(s) had taints that the pod didn't tolerate, 12 Insufficient cpu.
I0116 14:08:27.657551       1 factory.go:1129] [meng] deletePodFromCache
I0116 14:08:27.657561       1 factory.go:1136] [meng] JCT: 29.680742197s, total jct: 2m24.54042163s, count: 7, average JCT: 20.648631661s
I0116 14:08:27.667447       1 factory.go:798] [meng] computeComplTimeForAllPods completed
I0116 14:08:27.667474       1 factory.go:806] [tanle] Event pod completed user3/user3-pytorch-lenet-3%!(EXTRA v1.PodPhase=Succeeded)
I0116 14:08:27.667496       1 factory.go:1149] [meng] check delete pod user3/user3-pytorch-lenet-3, Running
I0116 14:08:27.667503       1 util.go:143] [meng] UpdateFairScore user3/user3-pytorch-lenet-3, false
I0116 14:08:27.667511       1 util.go:192] [meng] delete PodMachineMap in UpdateFairScore user3/user3-pytorch-lenet-3, false
I0116 14:08:27.667515       1 util.go:196] [tanle] FairScoreMap:  map[user2:0.5833333333333334 user3:0.38888888888888895 user4:5.551115123125783e-17 user1:0.38888888888888895]
I0116 14:08:27.676597       1 factory.go:1129] [meng] deletePodFromCache
I0116 14:08:27.676612       1 factory.go:1136] [meng] JCT: 29.699792252s, total jct: 2m54.240213882s, count: 8, average JCT: 21.780026735s
I0116 14:08:27.685597       1 factory.go:798] [meng] computeComplTimeForAllPods completed
I0116 14:08:27.685616       1 factory.go:806] [tanle] Event pod completed user1/user1-pytorch-lenet-5%!(EXTRA v1.PodPhase=Succeeded)
I0116 14:08:27.685637       1 factory.go:1149] [meng] check delete pod user1/user1-pytorch-lenet-5, Running
I0116 14:08:27.685643       1 util.go:143] [meng] UpdateFairScore user1/user1-pytorch-lenet-5, false
I0116 14:08:27.685649       1 util.go:192] [meng] delete PodMachineMap in UpdateFairScore user1/user1-pytorch-lenet-5, false
I0116 14:08:27.685653       1 util.go:196] [tanle] FairScoreMap:  map[user3:0.38888888888888895 user4:5.551115123125783e-17 user1:0.1944444444444445 user2:0.5833333333333334]
I0116 14:08:27.746024       1 util.go:1534] [meng] calling OnlineAlloX
I0116 14:08:27.746064       1 util.go:1550] [meng] numAvailMachines == 9,  allpods length: 26
I0116 14:08:27.768234       1 util.go:908]     Done creating pod user4/user4-pytorch-lenet-5 on another device. New cpuDemand: 90000, gpuDemand: 0, memory: 20
I0116 14:08:27.777767       1 util.go:196] [tanle] FairScoreMap:  map[user1:0.1944444444444445 user2:0.5833333333333334 user3:0.38888888888888895 user4:0.1944444444444445]
I0116 14:08:27.779600       1 scheduler.go:406] [tanle] binding user4/user4-pytorch-lenet-5 on GPU false-->meng-allox-cpu-5
I0116 14:08:27.877921       1 util.go:1534] [meng] calling OnlineAlloX
I0116 14:08:27.877952       1 util.go:1550] [meng] numAvailMachines == 8,  allpods length: 25
I0116 14:08:27.897494       1 util.go:196] [tanle] FairScoreMap:  map[user1:0.1944444444444445 user2:0.5833333333333334 user3:0.38888888888888895 user4:0.38888888888888895]
I0116 14:08:27.899805       1 scheduler.go:406] [tanle] binding user4/user4-pytorch-lenet-4 on GPU false-->meng-allox-cpu-1
I0116 14:08:27.997650       1 util.go:1534] [meng] calling OnlineAlloX
I0116 14:08:27.997677       1 util.go:1550] [meng] numAvailMachines == 7,  allpods length: 24
I0116 14:08:28.015332       1 scheduler.go:459] [meng] sched.schedule(pod) has error: user3/user3-pytorch-lenet-4, 0/13 nodes are available: 1 node(s) had taints that the pod didn't tolerate, 12 Insufficient cpu.
I0116 14:08:28.117311       1 util.go:1534] [meng] calling OnlineAlloX
I0116 14:08:28.117340       1 util.go:1550] [meng] numAvailMachines == 7,  allpods length: 24
I0116 14:08:28.134257       1 scheduler.go:459] [meng] sched.schedule(pod) has error: user2/user2-pytorch-lenet-4, 0/13 nodes are available: 1 node(s) had taints that the pod didn't tolerate, 12 Insufficient cpu.
I0116 14:08:28.159765       1 factory.go:1129] [meng] deletePodFromCache
I0116 14:08:28.159775       1 factory.go:1136] [meng] JCT: 30.182956321s, total jct: 3m24.423170203s, count: 9, average JCT: 22.713685578s
I0116 14:08:28.169547       1 factory.go:798] [meng] computeComplTimeForAllPods completed
I0116 14:08:28.169572       1 factory.go:806] [tanle] Event pod completed user2/user2-pytorch-lenet-5%!(EXTRA v1.PodPhase=Succeeded)
I0116 14:08:28.169598       1 factory.go:1149] [meng] check delete pod user2/user2-pytorch-lenet-5, Running
I0116 14:08:28.169604       1 util.go:143] [meng] UpdateFairScore user2/user2-pytorch-lenet-5, false
I0116 14:08:28.169611       1 util.go:192] [meng] delete PodMachineMap in UpdateFairScore user2/user2-pytorch-lenet-5, false
I0116 14:08:28.169615       1 util.go:196] [tanle] FairScoreMap:  map[user1:0.1944444444444445 user2:0.38888888888888895 user3:0.38888888888888895 user4:0.38888888888888895]
I0116 14:08:28.236659       1 util.go:1534] [meng] calling OnlineAlloX
I0116 14:08:28.236706       1 util.go:1550] [meng] numAvailMachines == 8,  allpods length: 24
I0116 14:08:28.254020       1 util.go:196] [tanle] FairScoreMap:  map[user1:0.1944444444444445 user2:0.5833333333333334 user3:0.38888888888888895 user4:0.38888888888888895]
I0116 14:08:28.259313       1 scheduler.go:406] [tanle] binding user2/user2-pytorch-lenet-4 on GPU false-->meng-allox-cpu-3
I0116 14:08:28.354175       1 util.go:1534] [meng] calling OnlineAlloX
I0116 14:08:28.354220       1 util.go:1550] [meng] numAvailMachines == 7,  allpods length: 23
I0116 14:08:28.369874       1 scheduler.go:459] [meng] sched.schedule(pod) has error: user3/user3-pytorch-lenet-4, 0/13 nodes are available: 1 node(s) had taints that the pod didn't tolerate, 12 Insufficient cpu.
I0116 14:08:28.472235       1 util.go:1534] [meng] calling OnlineAlloX
I0116 14:08:28.472264       1 util.go:1550] [meng] numAvailMachines == 7,  allpods length: 23
I0116 14:08:28.489260       1 scheduler.go:459] [meng] sched.schedule(pod) has error: user3/user3-pytorch-lenet-4, 0/13 nodes are available: 1 node(s) had taints that the pod didn't tolerate, 12 Insufficient cpu.
I0116 14:08:28.591095       1 util.go:1534] [meng] calling OnlineAlloX
I0116 14:08:28.591135       1 util.go:1550] [meng] numAvailMachines == 7,  allpods length: 23
I0116 14:08:28.607223       1 scheduler.go:459] [meng] sched.schedule(pod) has error: user3/user3-pytorch-lenet-4, 0/13 nodes are available: 1 node(s) had taints that the pod didn't tolerate, 12 Insufficient cpu.
I0116 14:08:28.709198       1 util.go:1534] [meng] calling OnlineAlloX
I0116 14:08:28.709226       1 util.go:1550] [meng] numAvailMachines == 7,  allpods length: 23
I0116 14:08:28.724440       1 scheduler.go:459] [meng] sched.schedule(pod) has error: user3/user3-pytorch-lenet-4, 0/13 nodes are available: 1 node(s) had taints that the pod didn't tolerate, 12 Insufficient cpu.
I0116 14:08:28.826430       1 util.go:1534] [meng] calling OnlineAlloX
I0116 14:08:28.826457       1 util.go:1550] [meng] numAvailMachines == 7,  allpods length: 23
I0116 14:08:28.842474       1 scheduler.go:459] [meng] sched.schedule(pod) has error: user3/user3-pytorch-lenet-4, 0/13 nodes are available: 1 node(s) had taints that the pod didn't tolerate, 12 Insufficient cpu.
I0116 14:08:28.944443       1 util.go:1534] [meng] calling OnlineAlloX
I0116 14:08:28.944471       1 util.go:1550] [meng] numAvailMachines == 7,  allpods length: 23
I0116 14:08:28.960216       1 scheduler.go:459] [meng] sched.schedule(pod) has error: user3/user3-pytorch-lenet-4, 0/13 nodes are available: 1 node(s) had taints that the pod didn't tolerate, 12 Insufficient cpu.
I0116 14:08:29.062450       1 util.go:1534] [meng] calling OnlineAlloX
I0116 14:08:29.062479       1 util.go:1550] [meng] numAvailMachines == 7,  allpods length: 23
I0116 14:08:29.077930       1 scheduler.go:459] [meng] sched.schedule(pod) has error: user3/user3-pytorch-lenet-4, 0/13 nodes are available: 1 node(s) had taints that the pod didn't tolerate, 12 Insufficient cpu.
I0116 14:08:29.179831       1 util.go:1534] [meng] calling OnlineAlloX
I0116 14:08:29.179859       1 util.go:1550] [meng] numAvailMachines == 7,  allpods length: 23
I0116 14:08:29.195792       1 scheduler.go:459] [meng] sched.schedule(pod) has error: user3/user3-pytorch-lenet-4, 0/13 nodes are available: 1 node(s) had taints that the pod didn't tolerate, 12 Insufficient cpu.
I0116 14:08:29.298034       1 util.go:1534] [meng] calling OnlineAlloX
I0116 14:08:29.298070       1 util.go:1550] [meng] numAvailMachines == 7,  allpods length: 23
I0116 14:08:29.313727       1 scheduler.go:459] [meng] sched.schedule(pod) has error: user3/user3-pytorch-lenet-4, 0/13 nodes are available: 1 node(s) had taints that the pod didn't tolerate, 12 Insufficient cpu.
I0116 14:08:29.405957       1 factory.go:1129] [meng] deletePodFromCache
I0116 14:08:29.405969       1 factory.go:1136] [meng] JCT: 31.429148227s, total jct: 3m55.85231843s, count: 10, average JCT: 23.585231843s
I0116 14:08:29.415171       1 factory.go:798] [meng] computeComplTimeForAllPods completed
I0116 14:08:29.415189       1 factory.go:806] [tanle] Event pod completed user2/user2-pytorch-lenet-2%!(EXTRA v1.PodPhase=Succeeded)
I0116 14:08:29.415215       1 factory.go:1149] [meng] check delete pod user2/user2-pytorch-lenet-2, Running
I0116 14:08:29.415222       1 util.go:143] [meng] UpdateFairScore user2/user2-pytorch-lenet-2, false
I0116 14:08:29.415229       1 util.go:192] [meng] delete PodMachineMap in UpdateFairScore user2/user2-pytorch-lenet-2, false
I0116 14:08:29.415233       1 util.go:196] [tanle] FairScoreMap:  map[user1:0.1944444444444445 user2:0.38888888888888895 user3:0.38888888888888895 user4:0.38888888888888895]
I0116 14:08:29.415626       1 util.go:1534] [meng] calling OnlineAlloX
I0116 14:08:29.415657       1 util.go:1550] [meng] numAvailMachines == 8,  allpods length: 23
I0116 14:08:29.431321       1 util.go:908]     Done creating pod user1/user1-pytorch-lenet-3 on another device. New cpuDemand: 90000, gpuDemand: 0, memory: 20
I0116 14:08:29.437454       1 util.go:196] [tanle] FairScoreMap:  map[user4:0.38888888888888895 user1:0.38888888888888895 user2:0.38888888888888895 user3:0.38888888888888895]
I0116 14:08:29.439188       1 scheduler.go:406] [tanle] binding user1/user1-pytorch-lenet-3 on GPU false-->meng-allox-cpu-8
I0116 14:08:29.537610       1 util.go:1534] [meng] calling OnlineAlloX
I0116 14:08:29.537645       1 util.go:1550] [meng] numAvailMachines == 7,  allpods length: 22
I0116 14:08:29.552260       1 scheduler.go:459] [meng] sched.schedule(pod) has error: user3/user3-pytorch-lenet-4, 0/13 nodes are available: 1 node(s) had taints that the pod didn't tolerate, 12 Insufficient cpu.
I0116 14:08:29.654375       1 util.go:1534] [meng] calling OnlineAlloX
I0116 14:08:29.654405       1 util.go:1550] [meng] numAvailMachines == 7,  allpods length: 22
I0116 14:08:29.668887       1 scheduler.go:459] [meng] sched.schedule(pod) has error: user3/user3-pytorch-lenet-4, 0/13 nodes are available: 1 node(s) had taints that the pod didn't tolerate, 12 Insufficient cpu.
I0116 14:08:29.771080       1 util.go:1534] [meng] calling OnlineAlloX
I0116 14:08:29.771118       1 util.go:1550] [meng] numAvailMachines == 7,  allpods length: 22
I0116 14:08:29.784642       1 scheduler.go:459] [meng] sched.schedule(pod) has error: user3/user3-pytorch-lenet-4, 0/13 nodes are available: 1 node(s) had taints that the pod didn't tolerate, 12 Insufficient cpu.
I0116 14:08:29.886532       1 util.go:1534] [meng] calling OnlineAlloX
I0116 14:08:29.886579       1 util.go:1550] [meng] numAvailMachines == 7,  allpods length: 22
I0116 14:08:29.900400       1 scheduler.go:459] [meng] sched.schedule(pod) has error: user3/user3-pytorch-lenet-4, 0/13 nodes are available: 1 node(s) had taints that the pod didn't tolerate, 12 Insufficient cpu.
I0116 14:08:30.002674       1 util.go:1534] [meng] calling OnlineAlloX
I0116 14:08:30.002702       1 util.go:1550] [meng] numAvailMachines == 7,  allpods length: 22
I0116 14:08:30.017575       1 scheduler.go:459] [meng] sched.schedule(pod) has error: user3/user3-pytorch-lenet-4, 0/13 nodes are available: 1 node(s) had taints that the pod didn't tolerate, 12 Insufficient cpu.
I0116 14:08:30.119278       1 util.go:1534] [meng] calling OnlineAlloX
I0116 14:08:30.119310       1 util.go:1550] [meng] numAvailMachines == 7,  allpods length: 22
I0116 14:08:30.133671       1 scheduler.go:459] [meng] sched.schedule(pod) has error: user3/user3-pytorch-lenet-4, 0/13 nodes are available: 1 node(s) had taints that the pod didn't tolerate, 12 Insufficient cpu.
I0116 14:08:30.235770       1 util.go:1534] [meng] calling OnlineAlloX
I0116 14:08:30.235809       1 util.go:1550] [meng] numAvailMachines == 7,  allpods length: 22
I0116 14:08:30.249683       1 scheduler.go:459] [meng] sched.schedule(pod) has error: user3/user3-pytorch-lenet-4, 0/13 nodes are available: 1 node(s) had taints that the pod didn't tolerate, 12 Insufficient cpu.
I0116 14:08:30.351978       1 util.go:1534] [meng] calling OnlineAlloX
I0116 14:08:30.352008       1 util.go:1550] [meng] numAvailMachines == 7,  allpods length: 22
I0116 14:08:30.366299       1 scheduler.go:459] [meng] sched.schedule(pod) has error: user3/user3-pytorch-lenet-4, 0/13 nodes are available: 1 node(s) had taints that the pod didn't tolerate, 12 Insufficient cpu.
I0116 14:08:30.468507       1 util.go:1534] [meng] calling OnlineAlloX
I0116 14:08:30.468535       1 util.go:1550] [meng] numAvailMachines == 7,  allpods length: 22
I0116 14:08:30.481861       1 scheduler.go:459] [meng] sched.schedule(pod) has error: user3/user3-pytorch-lenet-4, 0/13 nodes are available: 1 node(s) had taints that the pod didn't tolerate, 12 Insufficient cpu.
I0116 14:08:30.584130       1 util.go:1534] [meng] calling OnlineAlloX
I0116 14:08:30.584171       1 util.go:1550] [meng] numAvailMachines == 7,  allpods length: 22
I0116 14:08:30.598315       1 scheduler.go:459] [meng] sched.schedule(pod) has error: user3/user3-pytorch-lenet-4, 0/13 nodes are available: 1 node(s) had taints that the pod didn't tolerate, 12 Insufficient cpu.
I0116 14:08:30.700512       1 util.go:1534] [meng] calling OnlineAlloX
I0116 14:08:30.700543       1 util.go:1550] [meng] numAvailMachines == 7,  allpods length: 22
I0116 14:08:30.714095       1 scheduler.go:459] [meng] sched.schedule(pod) has error: user3/user3-pytorch-lenet-4, 0/13 nodes are available: 1 node(s) had taints that the pod didn't tolerate, 12 Insufficient cpu.
I0116 14:08:30.816774       1 util.go:1534] [meng] calling OnlineAlloX
I0116 14:08:30.816817       1 util.go:1550] [meng] numAvailMachines == 7,  allpods length: 22
I0116 14:08:30.830359       1 scheduler.go:459] [meng] sched.schedule(pod) has error: user3/user3-pytorch-lenet-4, 0/13 nodes are available: 1 node(s) had taints that the pod didn't tolerate, 12 Insufficient cpu.
I0116 14:08:30.932364       1 util.go:1534] [meng] calling OnlineAlloX
I0116 14:08:30.932395       1 util.go:1550] [meng] numAvailMachines == 7,  allpods length: 22
I0116 14:08:30.946415       1 scheduler.go:459] [meng] sched.schedule(pod) has error: user3/user3-pytorch-lenet-4, 0/13 nodes are available: 1 node(s) had taints that the pod didn't tolerate, 12 Insufficient cpu.
I0116 14:08:31.048860       1 util.go:1534] [meng] calling OnlineAlloX
I0116 14:08:31.048898       1 util.go:1550] [meng] numAvailMachines == 7,  allpods length: 22
I0116 14:08:31.062611       1 scheduler.go:459] [meng] sched.schedule(pod) has error: user3/user3-pytorch-lenet-4, 0/13 nodes are available: 1 node(s) had taints that the pod didn't tolerate, 12 Insufficient cpu.
I0116 14:08:31.113203       1 factory.go:1129] [meng] deletePodFromCache
I0116 14:08:31.113215       1 factory.go:1136] [meng] JCT: 33.136395673s, total jct: 4m28.988714103s, count: 11, average JCT: 24.453519463s
I0116 14:08:31.122313       1 factory.go:798] [meng] computeComplTimeForAllPods completed
I0116 14:08:31.122332       1 factory.go:806] [tanle] Event pod completed user3/user3-pytorch-lenet%!(EXTRA v1.PodPhase=Succeeded)
I0116 14:08:31.122352       1 factory.go:1149] [meng] check delete pod user3/user3-pytorch-lenet, Running
I0116 14:08:31.122359       1 util.go:143] [meng] UpdateFairScore user3/user3-pytorch-lenet, false
I0116 14:08:31.122366       1 util.go:192] [meng] delete PodMachineMap in UpdateFairScore user3/user3-pytorch-lenet, false
I0116 14:08:31.122370       1 util.go:196] [tanle] FairScoreMap:  map[user1:0.38888888888888895 user2:0.38888888888888895 user3:0.1944444444444445 user4:0.38888888888888895]
I0116 14:08:31.164500       1 util.go:1534] [meng] calling OnlineAlloX
I0116 14:08:31.164547       1 util.go:1550] [meng] numAvailMachines == 8,  allpods length: 22
I0116 14:08:31.180265       1 util.go:908]     Done creating pod user3/user3-pytorch-lenet-2 on another device. New cpuDemand: 90000, gpuDemand: 0, memory: 20
I0116 14:08:31.189398       1 util.go:196] [tanle] FairScoreMap:  map[user3:0.38888888888888895 user4:0.38888888888888895 user1:0.38888888888888895 user2:0.38888888888888895]
I0116 14:08:31.191082       1 scheduler.go:406] [tanle] binding user3/user3-pytorch-lenet-2 on GPU false-->meng-allox-cpu-6
I0116 14:08:31.289560       1 util.go:1534] [meng] calling OnlineAlloX
I0116 14:08:31.289598       1 util.go:1550] [meng] numAvailMachines == 7,  allpods length: 21
I0116 14:08:31.302877       1 scheduler.go:459] [meng] sched.schedule(pod) has error: user3/user3-pytorch-lenet-4, 0/13 nodes are available: 1 node(s) had taints that the pod didn't tolerate, 12 Insufficient cpu.
I0116 14:08:31.405314       1 util.go:1534] [meng] calling OnlineAlloX
I0116 14:08:31.405388       1 util.go:1550] [meng] numAvailMachines == 7,  allpods length: 21
I0116 14:08:31.419673       1 scheduler.go:459] [meng] sched.schedule(pod) has error: user3/user3-pytorch-lenet-4, 0/13 nodes are available: 1 node(s) had taints that the pod didn't tolerate, 12 Insufficient cpu.
I0116 14:08:31.522124       1 util.go:1534] [meng] calling OnlineAlloX
I0116 14:08:31.522161       1 util.go:1550] [meng] numAvailMachines == 7,  allpods length: 21
I0116 14:08:31.536138       1 scheduler.go:459] [meng] sched.schedule(pod) has error: user3/user3-pytorch-lenet-4, 0/13 nodes are available: 1 node(s) had taints that the pod didn't tolerate, 12 Insufficient cpu.
I0116 14:08:31.638439       1 util.go:1534] [meng] calling OnlineAlloX
I0116 14:08:31.638473       1 util.go:1550] [meng] numAvailMachines == 7,  allpods length: 21
I0116 14:08:31.652098       1 scheduler.go:459] [meng] sched.schedule(pod) has error: user3/user3-pytorch-lenet-4, 0/13 nodes are available: 1 node(s) had taints that the pod didn't tolerate, 12 Insufficient cpu.
I0116 14:08:31.754133       1 util.go:1534] [meng] calling OnlineAlloX
I0116 14:08:31.754172       1 util.go:1550] [meng] numAvailMachines == 7,  allpods length: 21
I0116 14:08:31.767407       1 scheduler.go:459] [meng] sched.schedule(pod) has error: user3/user3-pytorch-lenet-4, 0/13 nodes are available: 1 node(s) had taints that the pod didn't tolerate, 12 Insufficient cpu.
I0116 14:08:31.869828       1 util.go:1534] [meng] calling OnlineAlloX
I0116 14:08:31.869857       1 util.go:1550] [meng] numAvailMachines == 7,  allpods length: 21
I0116 14:08:31.882453       1 scheduler.go:459] [meng] sched.schedule(pod) has error: user3/user3-pytorch-lenet-4, 0/13 nodes are available: 1 node(s) had taints that the pod didn't tolerate, 12 Insufficient cpu.
I0116 14:08:31.984682       1 util.go:1534] [meng] calling OnlineAlloX
I0116 14:08:31.984759       1 util.go:1550] [meng] numAvailMachines == 7,  allpods length: 21
I0116 14:08:31.999702       1 scheduler.go:459] [meng] sched.schedule(pod) has error: user3/user3-pytorch-lenet-4, 0/13 nodes are available: 1 node(s) had taints that the pod didn't tolerate, 12 Insufficient cpu.
I0116 14:08:32.101945       1 util.go:1534] [meng] calling OnlineAlloX
I0116 14:08:32.101980       1 util.go:1550] [meng] numAvailMachines == 7,  allpods length: 21
I0116 14:08:32.116193       1 scheduler.go:459] [meng] sched.schedule(pod) has error: user3/user3-pytorch-lenet-4, 0/13 nodes are available: 1 node(s) had taints that the pod didn't tolerate, 12 Insufficient cpu.
I0116 14:08:32.218382       1 util.go:1534] [meng] calling OnlineAlloX
I0116 14:08:32.218426       1 util.go:1550] [meng] numAvailMachines == 7,  allpods length: 21
I0116 14:08:32.231830       1 scheduler.go:459] [meng] sched.schedule(pod) has error: user3/user3-pytorch-lenet-4, 0/13 nodes are available: 1 node(s) had taints that the pod didn't tolerate, 12 Insufficient cpu.
I0116 14:08:32.333952       1 util.go:1534] [meng] calling OnlineAlloX
I0116 14:08:32.334009       1 util.go:1550] [meng] numAvailMachines == 7,  allpods length: 21
I0116 14:08:32.348555       1 scheduler.go:459] [meng] sched.schedule(pod) has error: user3/user3-pytorch-lenet-4, 0/13 nodes are available: 1 node(s) had taints that the pod didn't tolerate, 12 Insufficient cpu.
I0116 14:08:32.450788       1 util.go:1534] [meng] calling OnlineAlloX
I0116 14:08:32.450826       1 util.go:1550] [meng] numAvailMachines == 7,  allpods length: 21
I0116 14:08:32.464660       1 scheduler.go:459] [meng] sched.schedule(pod) has error: user3/user3-pytorch-lenet-4, 0/13 nodes are available: 1 node(s) had taints that the pod didn't tolerate, 12 Insufficient cpu.
I0116 14:08:32.566844       1 util.go:1534] [meng] calling OnlineAlloX
I0116 14:08:32.566887       1 util.go:1550] [meng] numAvailMachines == 7,  allpods length: 21
I0116 14:08:32.580782       1 scheduler.go:459] [meng] sched.schedule(pod) has error: user3/user3-pytorch-lenet-4, 0/13 nodes are available: 1 node(s) had taints that the pod didn't tolerate, 12 Insufficient cpu.
I0116 14:08:32.683075       1 util.go:1534] [meng] calling OnlineAlloX
I0116 14:08:32.683105       1 util.go:1550] [meng] numAvailMachines == 7,  allpods length: 21
I0116 14:08:32.695780       1 scheduler.go:459] [meng] sched.schedule(pod) has error: user3/user3-pytorch-lenet-4, 0/13 nodes are available: 1 node(s) had taints that the pod didn't tolerate, 12 Insufficient cpu.
I0116 14:08:32.797941       1 util.go:1534] [meng] calling OnlineAlloX
I0116 14:08:32.797981       1 util.go:1550] [meng] numAvailMachines == 7,  allpods length: 21
I0116 14:08:32.810157       1 scheduler.go:459] [meng] sched.schedule(pod) has error: user3/user3-pytorch-lenet-4, 0/13 nodes are available: 1 node(s) had taints that the pod didn't tolerate, 12 Insufficient cpu.
I0116 14:08:32.912370       1 util.go:1534] [meng] calling OnlineAlloX
I0116 14:08:32.912412       1 util.go:1550] [meng] numAvailMachines == 7,  allpods length: 21
I0116 14:08:32.924523       1 scheduler.go:459] [meng] sched.schedule(pod) has error: user3/user3-pytorch-lenet-4, 0/13 nodes are available: 1 node(s) had taints that the pod didn't tolerate, 12 Insufficient cpu.
I0116 14:08:33.027233       1 util.go:1534] [meng] calling OnlineAlloX
I0116 14:08:33.027274       1 util.go:1550] [meng] numAvailMachines == 7,  allpods length: 21
I0116 14:08:33.039990       1 scheduler.go:459] [meng] sched.schedule(pod) has error: user3/user3-pytorch-lenet-4, 0/13 nodes are available: 1 node(s) had taints that the pod didn't tolerate, 12 Insufficient cpu.
I0116 14:08:33.142184       1 util.go:1534] [meng] calling OnlineAlloX
I0116 14:08:33.142227       1 util.go:1550] [meng] numAvailMachines == 7,  allpods length: 21
I0116 14:08:33.154949       1 scheduler.go:459] [meng] sched.schedule(pod) has error: user3/user3-pytorch-lenet-4, 0/13 nodes are available: 1 node(s) had taints that the pod didn't tolerate, 12 Insufficient cpu.
I0116 14:08:33.256725       1 util.go:1534] [meng] calling OnlineAlloX
I0116 14:08:33.256763       1 util.go:1550] [meng] numAvailMachines == 7,  allpods length: 21
I0116 14:08:33.269242       1 scheduler.go:459] [meng] sched.schedule(pod) has error: user3/user3-pytorch-lenet-4, 0/13 nodes are available: 1 node(s) had taints that the pod didn't tolerate, 12 Insufficient cpu.
I0116 14:08:33.371264       1 util.go:1534] [meng] calling OnlineAlloX
I0116 14:08:33.371298       1 util.go:1550] [meng] numAvailMachines == 7,  allpods length: 21
I0116 14:08:33.384361       1 scheduler.go:459] [meng] sched.schedule(pod) has error: user3/user3-pytorch-lenet-4, 0/13 nodes are available: 1 node(s) had taints that the pod didn't tolerate, 12 Insufficient cpu.
I0116 14:08:33.486404       1 util.go:1534] [meng] calling OnlineAlloX
I0116 14:08:33.486444       1 util.go:1550] [meng] numAvailMachines == 7,  allpods length: 21
I0116 14:08:33.498928       1 scheduler.go:459] [meng] sched.schedule(pod) has error: user3/user3-pytorch-lenet-4, 0/13 nodes are available: 1 node(s) had taints that the pod didn't tolerate, 12 Insufficient cpu.
I0116 14:08:33.601089       1 util.go:1534] [meng] calling OnlineAlloX
I0116 14:08:33.601128       1 util.go:1550] [meng] numAvailMachines == 7,  allpods length: 21
I0116 14:08:33.613035       1 scheduler.go:459] [meng] sched.schedule(pod) has error: user3/user3-pytorch-lenet-4, 0/13 nodes are available: 1 node(s) had taints that the pod didn't tolerate, 12 Insufficient cpu.
I0116 14:08:33.715250       1 util.go:1534] [meng] calling OnlineAlloX
I0116 14:08:33.715291       1 util.go:1550] [meng] numAvailMachines == 7,  allpods length: 21
I0116 14:08:33.728759       1 scheduler.go:459] [meng] sched.schedule(pod) has error: user3/user3-pytorch-lenet-4, 0/13 nodes are available: 1 node(s) had taints that the pod didn't tolerate, 12 Insufficient cpu.
I0116 14:08:33.830791       1 util.go:1534] [meng] calling OnlineAlloX
I0116 14:08:33.830820       1 util.go:1550] [meng] numAvailMachines == 7,  allpods length: 21
I0116 14:08:33.843870       1 scheduler.go:459] [meng] sched.schedule(pod) has error: user3/user3-pytorch-lenet-4, 0/13 nodes are available: 1 node(s) had taints that the pod didn't tolerate, 12 Insufficient cpu.
I0116 14:08:33.946156       1 util.go:1534] [meng] calling OnlineAlloX
I0116 14:08:33.946186       1 util.go:1550] [meng] numAvailMachines == 7,  allpods length: 21
I0116 14:08:33.958663       1 scheduler.go:459] [meng] sched.schedule(pod) has error: user3/user3-pytorch-lenet-4, 0/13 nodes are available: 1 node(s) had taints that the pod didn't tolerate, 12 Insufficient cpu.
I0116 14:08:34.060989       1 util.go:1534] [meng] calling OnlineAlloX
I0116 14:08:34.061019       1 util.go:1550] [meng] numAvailMachines == 7,  allpods length: 21
I0116 14:08:34.073707       1 scheduler.go:459] [meng] sched.schedule(pod) has error: user3/user3-pytorch-lenet-4, 0/13 nodes are available: 1 node(s) had taints that the pod didn't tolerate, 12 Insufficient cpu.
I0116 14:08:34.175738       1 util.go:1534] [meng] calling OnlineAlloX
I0116 14:08:34.175766       1 util.go:1550] [meng] numAvailMachines == 7,  allpods length: 21
I0116 14:08:34.188019       1 scheduler.go:459] [meng] sched.schedule(pod) has error: user3/user3-pytorch-lenet-4, 0/13 nodes are available: 1 node(s) had taints that the pod didn't tolerate, 12 Insufficient cpu.
I0116 14:08:34.290215       1 util.go:1534] [meng] calling OnlineAlloX
I0116 14:08:34.290256       1 util.go:1550] [meng] numAvailMachines == 7,  allpods length: 21
I0116 14:08:34.302291       1 scheduler.go:459] [meng] sched.schedule(pod) has error: user3/user3-pytorch-lenet-4, 0/13 nodes are available: 1 node(s) had taints that the pod didn't tolerate, 12 Insufficient cpu.
I0116 14:08:34.404464       1 util.go:1534] [meng] calling OnlineAlloX
I0116 14:08:34.404492       1 util.go:1550] [meng] numAvailMachines == 7,  allpods length: 21
I0116 14:08:34.417139       1 scheduler.go:459] [meng] sched.schedule(pod) has error: user3/user3-pytorch-lenet-4, 0/13 nodes are available: 1 node(s) had taints that the pod didn't tolerate, 12 Insufficient cpu.
I0116 14:08:34.519172       1 util.go:1534] [meng] calling OnlineAlloX
I0116 14:08:34.519204       1 util.go:1550] [meng] numAvailMachines == 7,  allpods length: 21
I0116 14:08:34.534124       1 scheduler.go:459] [meng] sched.schedule(pod) has error: user3/user3-pytorch-lenet-4, 0/13 nodes are available: 1 node(s) had taints that the pod didn't tolerate, 12 Insufficient cpu.
I0116 14:08:34.636091       1 util.go:1534] [meng] calling OnlineAlloX
I0116 14:08:34.636129       1 util.go:1550] [meng] numAvailMachines == 7,  allpods length: 21
I0116 14:08:34.650929       1 scheduler.go:459] [meng] sched.schedule(pod) has error: user3/user3-pytorch-lenet-4, 0/13 nodes are available: 1 node(s) had taints that the pod didn't tolerate, 12 Insufficient cpu.
I0116 14:08:34.753719       1 util.go:1534] [meng] calling OnlineAlloX
I0116 14:08:34.753748       1 util.go:1550] [meng] numAvailMachines == 7,  allpods length: 21
I0116 14:08:34.766945       1 scheduler.go:459] [meng] sched.schedule(pod) has error: user3/user3-pytorch-lenet-4, 0/13 nodes are available: 1 node(s) had taints that the pod didn't tolerate, 12 Insufficient cpu.
I0116 14:08:34.869260       1 util.go:1534] [meng] calling OnlineAlloX
I0116 14:08:34.869289       1 util.go:1550] [meng] numAvailMachines == 7,  allpods length: 21
I0116 14:08:34.882073       1 scheduler.go:459] [meng] sched.schedule(pod) has error: user3/user3-pytorch-lenet-4, 0/13 nodes are available: 1 node(s) had taints that the pod didn't tolerate, 12 Insufficient cpu.
I0116 14:08:34.984353       1 util.go:1534] [meng] calling OnlineAlloX
I0116 14:08:34.984383       1 util.go:1550] [meng] numAvailMachines == 7,  allpods length: 21
I0116 14:08:34.997659       1 scheduler.go:459] [meng] sched.schedule(pod) has error: user3/user3-pytorch-lenet-4, 0/13 nodes are available: 1 node(s) had taints that the pod didn't tolerate, 12 Insufficient cpu.
I0116 14:08:35.099564       1 util.go:1534] [meng] calling OnlineAlloX
I0116 14:08:35.099607       1 util.go:1550] [meng] numAvailMachines == 7,  allpods length: 21
I0116 14:08:35.112140       1 scheduler.go:459] [meng] sched.schedule(pod) has error: user3/user3-pytorch-lenet-4, 0/13 nodes are available: 1 node(s) had taints that the pod didn't tolerate, 12 Insufficient cpu.
I0116 14:08:35.214112       1 util.go:1534] [meng] calling OnlineAlloX
I0116 14:08:35.214142       1 util.go:1550] [meng] numAvailMachines == 7,  allpods length: 21
I0116 14:08:35.227404       1 scheduler.go:459] [meng] sched.schedule(pod) has error: user3/user3-pytorch-lenet-4, 0/13 nodes are available: 1 node(s) had taints that the pod didn't tolerate, 12 Insufficient cpu.
I0116 14:08:35.329362       1 util.go:1534] [meng] calling OnlineAlloX
I0116 14:08:35.329392       1 util.go:1550] [meng] numAvailMachines == 7,  allpods length: 21
I0116 14:08:35.341834       1 scheduler.go:459] [meng] sched.schedule(pod) has error: user3/user3-pytorch-lenet-4, 0/13 nodes are available: 1 node(s) had taints that the pod didn't tolerate, 12 Insufficient cpu.
I0116 14:08:35.444185       1 util.go:1534] [meng] calling OnlineAlloX
I0116 14:08:35.444215       1 util.go:1550] [meng] numAvailMachines == 7,  allpods length: 21
I0116 14:08:35.456457       1 scheduler.go:459] [meng] sched.schedule(pod) has error: user3/user3-pytorch-lenet-4, 0/13 nodes are available: 1 node(s) had taints that the pod didn't tolerate, 12 Insufficient cpu.
I0116 14:08:35.558694       1 util.go:1534] [meng] calling OnlineAlloX
I0116 14:08:35.558727       1 util.go:1550] [meng] numAvailMachines == 7,  allpods length: 21
I0116 14:08:35.571856       1 scheduler.go:459] [meng] sched.schedule(pod) has error: user3/user3-pytorch-lenet-4, 0/13 nodes are available: 1 node(s) had taints that the pod didn't tolerate, 12 Insufficient cpu.
I0116 14:08:35.673874       1 util.go:1534] [meng] calling OnlineAlloX
I0116 14:08:35.673903       1 util.go:1550] [meng] numAvailMachines == 7,  allpods length: 21
I0116 14:08:35.686253       1 scheduler.go:459] [meng] sched.schedule(pod) has error: user3/user3-pytorch-lenet-4, 0/13 nodes are available: 1 node(s) had taints that the pod didn't tolerate, 12 Insufficient cpu.
I0116 14:08:35.788610       1 util.go:1534] [meng] calling OnlineAlloX
I0116 14:08:35.788642       1 util.go:1550] [meng] numAvailMachines == 7,  allpods length: 21
I0116 14:08:35.800718       1 scheduler.go:459] [meng] sched.schedule(pod) has error: user3/user3-pytorch-lenet-4, 0/13 nodes are available: 1 node(s) had taints that the pod didn't tolerate, 12 Insufficient cpu.
I0116 14:08:35.902742       1 util.go:1534] [meng] calling OnlineAlloX
I0116 14:08:35.902771       1 util.go:1550] [meng] numAvailMachines == 7,  allpods length: 21
I0116 14:08:35.915926       1 scheduler.go:459] [meng] sched.schedule(pod) has error: user3/user3-pytorch-lenet-4, 0/13 nodes are available: 1 node(s) had taints that the pod didn't tolerate, 12 Insufficient cpu.
I0116 14:08:36.017989       1 util.go:1534] [meng] calling OnlineAlloX
I0116 14:08:36.018018       1 util.go:1550] [meng] numAvailMachines == 7,  allpods length: 21
I0116 14:08:36.030218       1 scheduler.go:459] [meng] sched.schedule(pod) has error: user3/user3-pytorch-lenet-4, 0/13 nodes are available: 1 node(s) had taints that the pod didn't tolerate, 12 Insufficient cpu.
I0116 14:08:36.131901       1 util.go:1534] [meng] calling OnlineAlloX
I0116 14:08:36.131930       1 util.go:1550] [meng] numAvailMachines == 7,  allpods length: 21
I0116 14:08:36.144431       1 scheduler.go:459] [meng] sched.schedule(pod) has error: user3/user3-pytorch-lenet-4, 0/13 nodes are available: 1 node(s) had taints that the pod didn't tolerate, 12 Insufficient cpu.
I0116 14:08:36.246391       1 util.go:1534] [meng] calling OnlineAlloX
I0116 14:08:36.246424       1 util.go:1550] [meng] numAvailMachines == 7,  allpods length: 21
I0116 14:08:36.258682       1 scheduler.go:459] [meng] sched.schedule(pod) has error: user3/user3-pytorch-lenet-4, 0/13 nodes are available: 1 node(s) had taints that the pod didn't tolerate, 12 Insufficient cpu.
I0116 14:08:36.361373       1 util.go:1534] [meng] calling OnlineAlloX
I0116 14:08:36.361415       1 util.go:1550] [meng] numAvailMachines == 7,  allpods length: 21
I0116 14:08:36.374296       1 scheduler.go:459] [meng] sched.schedule(pod) has error: user3/user3-pytorch-lenet-4, 0/13 nodes are available: 1 node(s) had taints that the pod didn't tolerate, 12 Insufficient cpu.
I0116 14:08:36.476172       1 util.go:1534] [meng] calling OnlineAlloX
I0116 14:08:36.476206       1 util.go:1550] [meng] numAvailMachines == 7,  allpods length: 21
I0116 14:08:36.488340       1 scheduler.go:459] [meng] sched.schedule(pod) has error: user3/user3-pytorch-lenet-4, 0/13 nodes are available: 1 node(s) had taints that the pod didn't tolerate, 12 Insufficient cpu.
I0116 14:08:36.590472       1 util.go:1534] [meng] calling OnlineAlloX
I0116 14:08:36.590503       1 util.go:1550] [meng] numAvailMachines == 7,  allpods length: 21
I0116 14:08:36.602520       1 scheduler.go:459] [meng] sched.schedule(pod) has error: user3/user3-pytorch-lenet-4, 0/13 nodes are available: 1 node(s) had taints that the pod didn't tolerate, 12 Insufficient cpu.
I0116 14:08:36.704692       1 util.go:1534] [meng] calling OnlineAlloX
I0116 14:08:36.704720       1 util.go:1550] [meng] numAvailMachines == 7,  allpods length: 21
I0116 14:08:36.720040       1 scheduler.go:459] [meng] sched.schedule(pod) has error: user3/user3-pytorch-lenet-4, 0/13 nodes are available: 1 node(s) had taints that the pod didn't tolerate, 12 Insufficient cpu.
I0116 14:08:36.822363       1 util.go:1534] [meng] calling OnlineAlloX
I0116 14:08:36.822408       1 util.go:1550] [meng] numAvailMachines == 7,  allpods length: 21
I0116 14:08:36.835857       1 scheduler.go:459] [meng] sched.schedule(pod) has error: user3/user3-pytorch-lenet-4, 0/13 nodes are available: 1 node(s) had taints that the pod didn't tolerate, 12 Insufficient cpu.
I0116 14:08:36.938180       1 util.go:1534] [meng] calling OnlineAlloX
I0116 14:08:36.938221       1 util.go:1550] [meng] numAvailMachines == 7,  allpods length: 21
I0116 14:08:36.950928       1 scheduler.go:459] [meng] sched.schedule(pod) has error: user3/user3-pytorch-lenet-4, 0/13 nodes are available: 1 node(s) had taints that the pod didn't tolerate, 12 Insufficient cpu.
I0116 14:08:37.053226       1 util.go:1534] [meng] calling OnlineAlloX
I0116 14:08:37.053275       1 util.go:1550] [meng] numAvailMachines == 7,  allpods length: 21
I0116 14:08:37.066367       1 scheduler.go:459] [meng] sched.schedule(pod) has error: user3/user3-pytorch-lenet-4, 0/13 nodes are available: 1 node(s) had taints that the pod didn't tolerate, 12 Insufficient cpu.
I0116 14:08:37.168816       1 util.go:1534] [meng] calling OnlineAlloX
I0116 14:08:37.168853       1 util.go:1550] [meng] numAvailMachines == 7,  allpods length: 21
I0116 14:08:37.184506       1 scheduler.go:459] [meng] sched.schedule(pod) has error: user3/user3-pytorch-lenet-4, 0/13 nodes are available: 1 node(s) had taints that the pod didn't tolerate, 12 Insufficient cpu.
I0116 14:08:37.286795       1 util.go:1534] [meng] calling OnlineAlloX
I0116 14:08:37.286827       1 util.go:1550] [meng] numAvailMachines == 7,  allpods length: 21
I0116 14:08:37.301168       1 scheduler.go:459] [meng] sched.schedule(pod) has error: user3/user3-pytorch-lenet-4, 0/13 nodes are available: 1 node(s) had taints that the pod didn't tolerate, 12 Insufficient cpu.
I0116 14:08:37.403180       1 util.go:1534] [meng] calling OnlineAlloX
I0116 14:08:37.403209       1 util.go:1550] [meng] numAvailMachines == 7,  allpods length: 21
I0116 14:08:37.415775       1 scheduler.go:459] [meng] sched.schedule(pod) has error: user3/user3-pytorch-lenet-4, 0/13 nodes are available: 1 node(s) had taints that the pod didn't tolerate, 12 Insufficient cpu.
I0116 14:08:37.517961       1 util.go:1534] [meng] calling OnlineAlloX
I0116 14:08:37.517993       1 util.go:1550] [meng] numAvailMachines == 7,  allpods length: 21
I0116 14:08:37.530452       1 scheduler.go:459] [meng] sched.schedule(pod) has error: user3/user3-pytorch-lenet-4, 0/13 nodes are available: 1 node(s) had taints that the pod didn't tolerate, 12 Insufficient cpu.
I0116 14:08:37.632656       1 util.go:1534] [meng] calling OnlineAlloX
I0116 14:08:37.632685       1 util.go:1550] [meng] numAvailMachines == 7,  allpods length: 21
I0116 14:08:37.645702       1 scheduler.go:459] [meng] sched.schedule(pod) has error: user3/user3-pytorch-lenet-4, 0/13 nodes are available: 1 node(s) had taints that the pod didn't tolerate, 12 Insufficient cpu.
I0116 14:08:37.747795       1 util.go:1534] [meng] calling OnlineAlloX
I0116 14:08:37.747837       1 util.go:1550] [meng] numAvailMachines == 7,  allpods length: 21
I0116 14:08:37.760470       1 scheduler.go:459] [meng] sched.schedule(pod) has error: user3/user3-pytorch-lenet-4, 0/13 nodes are available: 1 node(s) had taints that the pod didn't tolerate, 12 Insufficient cpu.
I0116 14:08:37.862798       1 util.go:1534] [meng] calling OnlineAlloX
I0116 14:08:37.862828       1 util.go:1550] [meng] numAvailMachines == 7,  allpods length: 21
I0116 14:08:37.875000       1 scheduler.go:459] [meng] sched.schedule(pod) has error: user3/user3-pytorch-lenet-4, 0/13 nodes are available: 1 node(s) had taints that the pod didn't tolerate, 12 Insufficient cpu.
I0116 14:08:37.977234       1 util.go:1534] [meng] calling OnlineAlloX
I0116 14:08:37.977265       1 util.go:1550] [meng] numAvailMachines == 7,  allpods length: 21
I0116 14:08:37.989603       1 scheduler.go:459] [meng] sched.schedule(pod) has error: user3/user3-pytorch-lenet-4, 0/13 nodes are available: 1 node(s) had taints that the pod didn't tolerate, 12 Insufficient cpu.
I0116 14:08:38.091842       1 util.go:1534] [meng] calling OnlineAlloX
I0116 14:08:38.091882       1 util.go:1550] [meng] numAvailMachines == 7,  allpods length: 21
I0116 14:08:38.104502       1 scheduler.go:459] [meng] sched.schedule(pod) has error: user3/user3-pytorch-lenet-4, 0/13 nodes are available: 1 node(s) had taints that the pod didn't tolerate, 12 Insufficient cpu.
I0116 14:08:38.207090       1 util.go:1534] [meng] calling OnlineAlloX
I0116 14:08:38.207120       1 util.go:1550] [meng] numAvailMachines == 7,  allpods length: 21
I0116 14:08:38.219408       1 scheduler.go:459] [meng] sched.schedule(pod) has error: user3/user3-pytorch-lenet-4, 0/13 nodes are available: 1 node(s) had taints that the pod didn't tolerate, 12 Insufficient cpu.
I0116 14:08:38.321359       1 util.go:1534] [meng] calling OnlineAlloX
I0116 14:08:38.321388       1 util.go:1550] [meng] numAvailMachines == 7,  allpods length: 21
I0116 14:08:38.333509       1 scheduler.go:459] [meng] sched.schedule(pod) has error: user3/user3-pytorch-lenet-4, 0/13 nodes are available: 1 node(s) had taints that the pod didn't tolerate, 12 Insufficient cpu.
I0116 14:08:38.439547       1 util.go:1534] [meng] calling OnlineAlloX
I0116 14:08:38.439577       1 util.go:1550] [meng] numAvailMachines == 7,  allpods length: 21
I0116 14:08:38.451517       1 scheduler.go:459] [meng] sched.schedule(pod) has error: user3/user3-pytorch-lenet-4, 0/13 nodes are available: 1 node(s) had taints that the pod didn't tolerate, 12 Insufficient cpu.
I0116 14:08:38.553509       1 util.go:1534] [meng] calling OnlineAlloX
I0116 14:08:38.553537       1 util.go:1550] [meng] numAvailMachines == 7,  allpods length: 21
I0116 14:08:38.566216       1 scheduler.go:459] [meng] sched.schedule(pod) has error: user3/user3-pytorch-lenet-4, 0/13 nodes are available: 1 node(s) had taints that the pod didn't tolerate, 12 Insufficient cpu.
I0116 14:08:38.668405       1 util.go:1534] [meng] calling OnlineAlloX
I0116 14:08:38.668434       1 util.go:1550] [meng] numAvailMachines == 7,  allpods length: 21
I0116 14:08:38.680788       1 scheduler.go:459] [meng] sched.schedule(pod) has error: user3/user3-pytorch-lenet-4, 0/13 nodes are available: 1 node(s) had taints that the pod didn't tolerate, 12 Insufficient cpu.
I0116 14:08:38.783168       1 util.go:1534] [meng] calling OnlineAlloX
I0116 14:08:38.783201       1 util.go:1550] [meng] numAvailMachines == 7,  allpods length: 21
I0116 14:08:38.796027       1 scheduler.go:459] [meng] sched.schedule(pod) has error: user3/user3-pytorch-lenet-4, 0/13 nodes are available: 1 node(s) had taints that the pod didn't tolerate, 12 Insufficient cpu.
I0116 14:08:38.898108       1 util.go:1534] [meng] calling OnlineAlloX
I0116 14:08:38.898137       1 util.go:1550] [meng] numAvailMachines == 7,  allpods length: 21
I0116 14:08:38.910608       1 scheduler.go:459] [meng] sched.schedule(pod) has error: user3/user3-pytorch-lenet-4, 0/13 nodes are available: 1 node(s) had taints that the pod didn't tolerate, 12 Insufficient cpu.
I0116 14:08:39.012526       1 util.go:1534] [meng] calling OnlineAlloX
I0116 14:08:39.012554       1 util.go:1550] [meng] numAvailMachines == 7,  allpods length: 21
I0116 14:08:39.024697       1 scheduler.go:459] [meng] sched.schedule(pod) has error: user3/user3-pytorch-lenet-4, 0/13 nodes are available: 1 node(s) had taints that the pod didn't tolerate, 12 Insufficient cpu.
I0116 14:08:39.126903       1 util.go:1534] [meng] calling OnlineAlloX
I0116 14:08:39.126943       1 util.go:1550] [meng] numAvailMachines == 7,  allpods length: 21
I0116 14:08:39.140068       1 scheduler.go:459] [meng] sched.schedule(pod) has error: user3/user3-pytorch-lenet-4, 0/13 nodes are available: 1 node(s) had taints that the pod didn't tolerate, 12 Insufficient cpu.
I0116 14:08:39.241669       1 util.go:1534] [meng] calling OnlineAlloX
I0116 14:08:39.241707       1 util.go:1550] [meng] numAvailMachines == 7,  allpods length: 21
I0116 14:08:39.254303       1 scheduler.go:459] [meng] sched.schedule(pod) has error: user3/user3-pytorch-lenet-4, 0/13 nodes are available: 1 node(s) had taints that the pod didn't tolerate, 12 Insufficient cpu.
I0116 14:08:39.356353       1 util.go:1534] [meng] calling OnlineAlloX
I0116 14:08:39.356383       1 util.go:1550] [meng] numAvailMachines == 7,  allpods length: 21
I0116 14:08:39.369427       1 scheduler.go:459] [meng] sched.schedule(pod) has error: user3/user3-pytorch-lenet-4, 0/13 nodes are available: 1 node(s) had taints that the pod didn't tolerate, 12 Insufficient cpu.
I0116 14:08:39.471381       1 util.go:1534] [meng] calling OnlineAlloX
I0116 14:08:39.471409       1 util.go:1550] [meng] numAvailMachines == 7,  allpods length: 21
I0116 14:08:39.484201       1 scheduler.go:459] [meng] sched.schedule(pod) has error: user3/user3-pytorch-lenet-4, 0/13 nodes are available: 1 node(s) had taints that the pod didn't tolerate, 12 Insufficient cpu.
I0116 14:08:39.586222       1 util.go:1534] [meng] calling OnlineAlloX
I0116 14:08:39.586251       1 util.go:1550] [meng] numAvailMachines == 7,  allpods length: 21
I0116 14:08:39.598435       1 scheduler.go:459] [meng] sched.schedule(pod) has error: user3/user3-pytorch-lenet-4, 0/13 nodes are available: 1 node(s) had taints that the pod didn't tolerate, 12 Insufficient cpu.
I0116 14:08:39.700418       1 util.go:1534] [meng] calling OnlineAlloX
I0116 14:08:39.700460       1 util.go:1550] [meng] numAvailMachines == 7,  allpods length: 21
I0116 14:08:39.715204       1 scheduler.go:459] [meng] sched.schedule(pod) has error: user3/user3-pytorch-lenet-4, 0/13 nodes are available: 1 node(s) had taints that the pod didn't tolerate, 12 Insufficient cpu.
I0116 14:08:39.817196       1 util.go:1534] [meng] calling OnlineAlloX
I0116 14:08:39.817224       1 util.go:1550] [meng] numAvailMachines == 7,  allpods length: 21
I0116 14:08:39.830072       1 scheduler.go:459] [meng] sched.schedule(pod) has error: user3/user3-pytorch-lenet-4, 0/13 nodes are available: 1 node(s) had taints that the pod didn't tolerate, 12 Insufficient cpu.
I0116 14:08:39.932184       1 util.go:1534] [meng] calling OnlineAlloX
I0116 14:08:39.932225       1 util.go:1550] [meng] numAvailMachines == 7,  allpods length: 21
I0116 14:08:39.944616       1 scheduler.go:459] [meng] sched.schedule(pod) has error: user3/user3-pytorch-lenet-4, 0/13 nodes are available: 1 node(s) had taints that the pod didn't tolerate, 12 Insufficient cpu.
I0116 14:08:40.046728       1 util.go:1534] [meng] calling OnlineAlloX
I0116 14:08:40.046766       1 util.go:1550] [meng] numAvailMachines == 7,  allpods length: 21
I0116 14:08:40.058828       1 scheduler.go:459] [meng] sched.schedule(pod) has error: user3/user3-pytorch-lenet-4, 0/13 nodes are available: 1 node(s) had taints that the pod didn't tolerate, 12 Insufficient cpu.
I0116 14:08:40.160928       1 util.go:1534] [meng] calling OnlineAlloX
I0116 14:08:40.160973       1 util.go:1550] [meng] numAvailMachines == 7,  allpods length: 21
I0116 14:08:40.173737       1 scheduler.go:459] [meng] sched.schedule(pod) has error: user3/user3-pytorch-lenet-4, 0/13 nodes are available: 1 node(s) had taints that the pod didn't tolerate, 12 Insufficient cpu.
I0116 14:08:40.275766       1 util.go:1534] [meng] calling OnlineAlloX
I0116 14:08:40.275797       1 util.go:1550] [meng] numAvailMachines == 7,  allpods length: 21
I0116 14:08:40.288081       1 scheduler.go:459] [meng] sched.schedule(pod) has error: user3/user3-pytorch-lenet-4, 0/13 nodes are available: 1 node(s) had taints that the pod didn't tolerate, 12 Insufficient cpu.
I0116 14:08:40.390384       1 util.go:1534] [meng] calling OnlineAlloX
I0116 14:08:40.390418       1 util.go:1550] [meng] numAvailMachines == 7,  allpods length: 21
I0116 14:08:40.402916       1 scheduler.go:459] [meng] sched.schedule(pod) has error: user3/user3-pytorch-lenet-4, 0/13 nodes are available: 1 node(s) had taints that the pod didn't tolerate, 12 Insufficient cpu.
I0116 14:08:40.505323       1 util.go:1534] [meng] calling OnlineAlloX
I0116 14:08:40.505359       1 util.go:1550] [meng] numAvailMachines == 7,  allpods length: 21
I0116 14:08:40.518058       1 scheduler.go:459] [meng] sched.schedule(pod) has error: user3/user3-pytorch-lenet-4, 0/13 nodes are available: 1 node(s) had taints that the pod didn't tolerate, 12 Insufficient cpu.
I0116 14:08:40.620134       1 util.go:1534] [meng] calling OnlineAlloX
I0116 14:08:40.620174       1 util.go:1550] [meng] numAvailMachines == 7,  allpods length: 21
I0116 14:08:40.632653       1 scheduler.go:459] [meng] sched.schedule(pod) has error: user3/user3-pytorch-lenet-4, 0/13 nodes are available: 1 node(s) had taints that the pod didn't tolerate, 12 Insufficient cpu.
I0116 14:08:40.734877       1 util.go:1534] [meng] calling OnlineAlloX
I0116 14:08:40.734904       1 util.go:1550] [meng] numAvailMachines == 7,  allpods length: 21
I0116 14:08:40.747254       1 scheduler.go:459] [meng] sched.schedule(pod) has error: user3/user3-pytorch-lenet-4, 0/13 nodes are available: 1 node(s) had taints that the pod didn't tolerate, 12 Insufficient cpu.
I0116 14:08:40.849454       1 util.go:1534] [meng] calling OnlineAlloX
I0116 14:08:40.849484       1 util.go:1550] [meng] numAvailMachines == 7,  allpods length: 21
I0116 14:08:40.861650       1 scheduler.go:459] [meng] sched.schedule(pod) has error: user3/user3-pytorch-lenet-4, 0/13 nodes are available: 1 node(s) had taints that the pod didn't tolerate, 12 Insufficient cpu.
I0116 14:08:40.963643       1 util.go:1534] [meng] calling OnlineAlloX
I0116 14:08:40.963673       1 util.go:1550] [meng] numAvailMachines == 7,  allpods length: 21
I0116 14:08:40.976830       1 scheduler.go:459] [meng] sched.schedule(pod) has error: user3/user3-pytorch-lenet-4, 0/13 nodes are available: 1 node(s) had taints that the pod didn't tolerate, 12 Insufficient cpu.
I0116 14:08:41.079124       1 util.go:1534] [meng] calling OnlineAlloX
I0116 14:08:41.079159       1 util.go:1550] [meng] numAvailMachines == 7,  allpods length: 21
I0116 14:08:41.091372       1 scheduler.go:459] [meng] sched.schedule(pod) has error: user3/user3-pytorch-lenet-4, 0/13 nodes are available: 1 node(s) had taints that the pod didn't tolerate, 12 Insufficient cpu.
I0116 14:08:41.193910       1 util.go:1534] [meng] calling OnlineAlloX
I0116 14:08:41.193950       1 util.go:1550] [meng] numAvailMachines == 7,  allpods length: 21
I0116 14:08:41.206040       1 scheduler.go:459] [meng] sched.schedule(pod) has error: user3/user3-pytorch-lenet-4, 0/13 nodes are available: 1 node(s) had taints that the pod didn't tolerate, 12 Insufficient cpu.
I0116 14:08:41.308254       1 util.go:1534] [meng] calling OnlineAlloX
I0116 14:08:41.308283       1 util.go:1550] [meng] numAvailMachines == 7,  allpods length: 21
I0116 14:08:41.321411       1 scheduler.go:459] [meng] sched.schedule(pod) has error: user3/user3-pytorch-lenet-4, 0/13 nodes are available: 1 node(s) had taints that the pod didn't tolerate, 12 Insufficient cpu.
I0116 14:08:41.423757       1 util.go:1534] [meng] calling OnlineAlloX
I0116 14:08:41.423805       1 util.go:1550] [meng] numAvailMachines == 7,  allpods length: 21
I0116 14:08:41.437947       1 scheduler.go:459] [meng] sched.schedule(pod) has error: user3/user3-pytorch-lenet-4, 0/13 nodes are available: 1 node(s) had taints that the pod didn't tolerate, 12 Insufficient cpu.
I0116 14:08:41.540204       1 util.go:1534] [meng] calling OnlineAlloX
I0116 14:08:41.540236       1 util.go:1550] [meng] numAvailMachines == 7,  allpods length: 21
I0116 14:08:41.553485       1 scheduler.go:459] [meng] sched.schedule(pod) has error: user3/user3-pytorch-lenet-4, 0/13 nodes are available: 1 node(s) had taints that the pod didn't tolerate, 12 Insufficient cpu.
I0116 14:08:41.655829       1 util.go:1534] [meng] calling OnlineAlloX
I0116 14:08:41.655858       1 util.go:1550] [meng] numAvailMachines == 7,  allpods length: 21
I0116 14:08:41.668569       1 scheduler.go:459] [meng] sched.schedule(pod) has error: user3/user3-pytorch-lenet-4, 0/13 nodes are available: 1 node(s) had taints that the pod didn't tolerate, 12 Insufficient cpu.
I0116 14:08:41.771219       1 util.go:1534] [meng] calling OnlineAlloX
I0116 14:08:41.771251       1 util.go:1550] [meng] numAvailMachines == 7,  allpods length: 21
I0116 14:08:41.784163       1 scheduler.go:459] [meng] sched.schedule(pod) has error: user3/user3-pytorch-lenet-4, 0/13 nodes are available: 1 node(s) had taints that the pod didn't tolerate, 12 Insufficient cpu.
I0116 14:08:41.886451       1 util.go:1534] [meng] calling OnlineAlloX
I0116 14:08:41.886491       1 util.go:1550] [meng] numAvailMachines == 7,  allpods length: 21
I0116 14:08:41.898932       1 scheduler.go:459] [meng] sched.schedule(pod) has error: user3/user3-pytorch-lenet-4, 0/13 nodes are available: 1 node(s) had taints that the pod didn't tolerate, 12 Insufficient cpu.
I0116 14:08:42.001396       1 util.go:1534] [meng] calling OnlineAlloX
I0116 14:08:42.001426       1 util.go:1550] [meng] numAvailMachines == 7,  allpods length: 21
I0116 14:08:42.014180       1 scheduler.go:459] [meng] sched.schedule(pod) has error: user3/user3-pytorch-lenet-4, 0/13 nodes are available: 1 node(s) had taints that the pod didn't tolerate, 12 Insufficient cpu.
I0116 14:08:42.116366       1 util.go:1534] [meng] calling OnlineAlloX
I0116 14:08:42.116395       1 util.go:1550] [meng] numAvailMachines == 7,  allpods length: 21
I0116 14:08:42.129057       1 scheduler.go:459] [meng] sched.schedule(pod) has error: user3/user3-pytorch-lenet-4, 0/13 nodes are available: 1 node(s) had taints that the pod didn't tolerate, 12 Insufficient cpu.
I0116 14:08:42.231424       1 util.go:1534] [meng] calling OnlineAlloX
I0116 14:08:42.231464       1 util.go:1550] [meng] numAvailMachines == 7,  allpods length: 21
I0116 14:08:42.243559       1 scheduler.go:459] [meng] sched.schedule(pod) has error: user3/user3-pytorch-lenet-4, 0/13 nodes are available: 1 node(s) had taints that the pod didn't tolerate, 12 Insufficient cpu.
I0116 14:08:42.345741       1 util.go:1534] [meng] calling OnlineAlloX
I0116 14:08:42.345770       1 util.go:1550] [meng] numAvailMachines == 7,  allpods length: 21
I0116 14:08:42.359044       1 scheduler.go:459] [meng] sched.schedule(pod) has error: user3/user3-pytorch-lenet-4, 0/13 nodes are available: 1 node(s) had taints that the pod didn't tolerate, 12 Insufficient cpu.
I0116 14:08:42.461194       1 util.go:1534] [meng] calling OnlineAlloX
I0116 14:08:42.461223       1 util.go:1550] [meng] numAvailMachines == 7,  allpods length: 21
I0116 14:08:42.473722       1 scheduler.go:459] [meng] sched.schedule(pod) has error: user3/user3-pytorch-lenet-4, 0/13 nodes are available: 1 node(s) had taints that the pod didn't tolerate, 12 Insufficient cpu.
I0116 14:08:42.575716       1 util.go:1534] [meng] calling OnlineAlloX
I0116 14:08:42.575744       1 util.go:1550] [meng] numAvailMachines == 7,  allpods length: 21
I0116 14:08:42.588073       1 scheduler.go:459] [meng] sched.schedule(pod) has error: user3/user3-pytorch-lenet-4, 0/13 nodes are available: 1 node(s) had taints that the pod didn't tolerate, 12 Insufficient cpu.
I0116 14:08:42.690047       1 util.go:1534] [meng] calling OnlineAlloX
I0116 14:08:42.690075       1 util.go:1550] [meng] numAvailMachines == 7,  allpods length: 21
I0116 14:08:42.703011       1 scheduler.go:459] [meng] sched.schedule(pod) has error: user3/user3-pytorch-lenet-4, 0/13 nodes are available: 1 node(s) had taints that the pod didn't tolerate, 12 Insufficient cpu.
I0116 14:08:42.805183       1 util.go:1534] [meng] calling OnlineAlloX
I0116 14:08:42.805212       1 util.go:1550] [meng] numAvailMachines == 7,  allpods length: 21
I0116 14:08:42.817377       1 scheduler.go:459] [meng] sched.schedule(pod) has error: user3/user3-pytorch-lenet-4, 0/13 nodes are available: 1 node(s) had taints that the pod didn't tolerate, 12 Insufficient cpu.
I0116 14:08:42.919578       1 util.go:1534] [meng] calling OnlineAlloX
I0116 14:08:42.919610       1 util.go:1550] [meng] numAvailMachines == 7,  allpods length: 21
I0116 14:08:42.931716       1 scheduler.go:459] [meng] sched.schedule(pod) has error: user3/user3-pytorch-lenet-4, 0/13 nodes are available: 1 node(s) had taints that the pod didn't tolerate, 12 Insufficient cpu.
I0116 14:08:43.034038       1 util.go:1534] [meng] calling OnlineAlloX
I0116 14:08:43.034067       1 util.go:1550] [meng] numAvailMachines == 7,  allpods length: 21
I0116 14:08:43.046816       1 scheduler.go:459] [meng] sched.schedule(pod) has error: user3/user3-pytorch-lenet-4, 0/13 nodes are available: 1 node(s) had taints that the pod didn't tolerate, 12 Insufficient cpu.
I0116 14:08:43.149280       1 util.go:1534] [meng] calling OnlineAlloX
I0116 14:08:43.149309       1 util.go:1550] [meng] numAvailMachines == 7,  allpods length: 21
I0116 14:08:43.161930       1 scheduler.go:459] [meng] sched.schedule(pod) has error: user3/user3-pytorch-lenet-4, 0/13 nodes are available: 1 node(s) had taints that the pod didn't tolerate, 12 Insufficient cpu.
I0116 14:08:43.263910       1 util.go:1534] [meng] calling OnlineAlloX
I0116 14:08:43.263939       1 util.go:1550] [meng] numAvailMachines == 7,  allpods length: 21
I0116 14:08:43.276367       1 scheduler.go:459] [meng] sched.schedule(pod) has error: user3/user3-pytorch-lenet-4, 0/13 nodes are available: 1 node(s) had taints that the pod didn't tolerate, 12 Insufficient cpu.
I0116 14:08:43.378353       1 util.go:1534] [meng] calling OnlineAlloX
I0116 14:08:43.378381       1 util.go:1550] [meng] numAvailMachines == 7,  allpods length: 21
I0116 14:08:43.391840       1 scheduler.go:459] [meng] sched.schedule(pod) has error: user3/user3-pytorch-lenet-4, 0/13 nodes are available: 1 node(s) had taints that the pod didn't tolerate, 12 Insufficient cpu.
I0116 14:08:43.494121       1 util.go:1534] [meng] calling OnlineAlloX
I0116 14:08:43.494149       1 util.go:1550] [meng] numAvailMachines == 7,  allpods length: 21
I0116 14:08:43.506821       1 scheduler.go:459] [meng] sched.schedule(pod) has error: user3/user3-pytorch-lenet-4, 0/13 nodes are available: 1 node(s) had taints that the pod didn't tolerate, 12 Insufficient cpu.
I0116 14:08:43.608818       1 util.go:1534] [meng] calling OnlineAlloX
I0116 14:08:43.608847       1 util.go:1550] [meng] numAvailMachines == 7,  allpods length: 21
I0116 14:08:43.620976       1 scheduler.go:459] [meng] sched.schedule(pod) has error: user3/user3-pytorch-lenet-4, 0/13 nodes are available: 1 node(s) had taints that the pod didn't tolerate, 12 Insufficient cpu.
I0116 14:08:43.722975       1 util.go:1534] [meng] calling OnlineAlloX
I0116 14:08:43.723003       1 util.go:1550] [meng] numAvailMachines == 7,  allpods length: 21
I0116 14:08:43.735164       1 scheduler.go:459] [meng] sched.schedule(pod) has error: user3/user3-pytorch-lenet-4, 0/13 nodes are available: 1 node(s) had taints that the pod didn't tolerate, 12 Insufficient cpu.
I0116 14:08:43.837314       1 util.go:1534] [meng] calling OnlineAlloX
I0116 14:08:43.837353       1 util.go:1550] [meng] numAvailMachines == 7,  allpods length: 21
I0116 14:08:43.850667       1 scheduler.go:459] [meng] sched.schedule(pod) has error: user3/user3-pytorch-lenet-4, 0/13 nodes are available: 1 node(s) had taints that the pod didn't tolerate, 12 Insufficient cpu.
I0116 14:08:43.952805       1 util.go:1534] [meng] calling OnlineAlloX
I0116 14:08:43.952839       1 util.go:1550] [meng] numAvailMachines == 7,  allpods length: 21
I0116 14:08:43.965494       1 scheduler.go:459] [meng] sched.schedule(pod) has error: user3/user3-pytorch-lenet-4, 0/13 nodes are available: 1 node(s) had taints that the pod didn't tolerate, 12 Insufficient cpu.
I0116 14:08:44.067707       1 util.go:1534] [meng] calling OnlineAlloX
I0116 14:08:44.067736       1 util.go:1550] [meng] numAvailMachines == 7,  allpods length: 21
I0116 14:08:44.080074       1 scheduler.go:459] [meng] sched.schedule(pod) has error: user3/user3-pytorch-lenet-4, 0/13 nodes are available: 1 node(s) had taints that the pod didn't tolerate, 12 Insufficient cpu.
I0116 14:08:44.182163       1 util.go:1534] [meng] calling OnlineAlloX
I0116 14:08:44.182194       1 util.go:1550] [meng] numAvailMachines == 7,  allpods length: 21
I0116 14:08:44.194757       1 scheduler.go:459] [meng] sched.schedule(pod) has error: user3/user3-pytorch-lenet-4, 0/13 nodes are available: 1 node(s) had taints that the pod didn't tolerate, 12 Insufficient cpu.
I0116 14:08:44.296749       1 util.go:1534] [meng] calling OnlineAlloX
I0116 14:08:44.296777       1 util.go:1550] [meng] numAvailMachines == 7,  allpods length: 21
I0116 14:08:44.309373       1 scheduler.go:459] [meng] sched.schedule(pod) has error: user3/user3-pytorch-lenet-4, 0/13 nodes are available: 1 node(s) had taints that the pod didn't tolerate, 12 Insufficient cpu.
I0116 14:08:44.411393       1 util.go:1534] [meng] calling OnlineAlloX
I0116 14:08:44.411433       1 util.go:1550] [meng] numAvailMachines == 7,  allpods length: 21
I0116 14:08:44.423854       1 scheduler.go:459] [meng] sched.schedule(pod) has error: user3/user3-pytorch-lenet-4, 0/13 nodes are available: 1 node(s) had taints that the pod didn't tolerate, 12 Insufficient cpu.
I0116 14:08:44.526056       1 util.go:1534] [meng] calling OnlineAlloX
I0116 14:08:44.526084       1 util.go:1550] [meng] numAvailMachines == 7,  allpods length: 21
I0116 14:08:44.538329       1 scheduler.go:459] [meng] sched.schedule(pod) has error: user3/user3-pytorch-lenet-4, 0/13 nodes are available: 1 node(s) had taints that the pod didn't tolerate, 12 Insufficient cpu.
I0116 14:08:44.641062       1 util.go:1534] [meng] calling OnlineAlloX
I0116 14:08:44.641090       1 util.go:1550] [meng] numAvailMachines == 7,  allpods length: 21
I0116 14:08:44.654079       1 scheduler.go:459] [meng] sched.schedule(pod) has error: user3/user3-pytorch-lenet-4, 0/13 nodes are available: 1 node(s) had taints that the pod didn't tolerate, 12 Insufficient cpu.
I0116 14:08:44.756231       1 util.go:1534] [meng] calling OnlineAlloX
I0116 14:08:44.756269       1 util.go:1550] [meng] numAvailMachines == 7,  allpods length: 21
I0116 14:08:44.768835       1 scheduler.go:459] [meng] sched.schedule(pod) has error: user3/user3-pytorch-lenet-4, 0/13 nodes are available: 1 node(s) had taints that the pod didn't tolerate, 12 Insufficient cpu.
I0116 14:08:44.870909       1 util.go:1534] [meng] calling OnlineAlloX
I0116 14:08:44.870936       1 util.go:1550] [meng] numAvailMachines == 7,  allpods length: 21
I0116 14:08:44.884008       1 scheduler.go:459] [meng] sched.schedule(pod) has error: user3/user3-pytorch-lenet-4, 0/13 nodes are available: 1 node(s) had taints that the pod didn't tolerate, 12 Insufficient cpu.
I0116 14:08:44.985852       1 util.go:1534] [meng] calling OnlineAlloX
I0116 14:08:44.985881       1 util.go:1550] [meng] numAvailMachines == 7,  allpods length: 21
I0116 14:08:44.998666       1 scheduler.go:459] [meng] sched.schedule(pod) has error: user3/user3-pytorch-lenet-4, 0/13 nodes are available: 1 node(s) had taints that the pod didn't tolerate, 12 Insufficient cpu.
I0116 14:08:45.100552       1 util.go:1534] [meng] calling OnlineAlloX
I0116 14:08:45.100580       1 util.go:1550] [meng] numAvailMachines == 7,  allpods length: 21
I0116 14:08:45.112807       1 scheduler.go:459] [meng] sched.schedule(pod) has error: user3/user3-pytorch-lenet-4, 0/13 nodes are available: 1 node(s) had taints that the pod didn't tolerate, 12 Insufficient cpu.
I0116 14:08:45.214667       1 util.go:1534] [meng] calling OnlineAlloX
I0116 14:08:45.214695       1 util.go:1550] [meng] numAvailMachines == 7,  allpods length: 21
I0116 14:08:45.227810       1 scheduler.go:459] [meng] sched.schedule(pod) has error: user3/user3-pytorch-lenet-4, 0/13 nodes are available: 1 node(s) had taints that the pod didn't tolerate, 12 Insufficient cpu.
I0116 14:08:45.329862       1 util.go:1534] [meng] calling OnlineAlloX
I0116 14:08:45.329903       1 util.go:1550] [meng] numAvailMachines == 7,  allpods length: 21
I0116 14:08:45.342490       1 scheduler.go:459] [meng] sched.schedule(pod) has error: user3/user3-pytorch-lenet-4, 0/13 nodes are available: 1 node(s) had taints that the pod didn't tolerate, 12 Insufficient cpu.
I0116 14:08:45.444553       1 util.go:1534] [meng] calling OnlineAlloX
I0116 14:08:45.444581       1 util.go:1550] [meng] numAvailMachines == 7,  allpods length: 21
I0116 14:08:45.456966       1 scheduler.go:459] [meng] sched.schedule(pod) has error: user3/user3-pytorch-lenet-4, 0/13 nodes are available: 1 node(s) had taints that the pod didn't tolerate, 12 Insufficient cpu.
I0116 14:08:45.559044       1 util.go:1534] [meng] calling OnlineAlloX
I0116 14:08:45.559073       1 util.go:1550] [meng] numAvailMachines == 7,  allpods length: 21
I0116 14:08:45.571131       1 scheduler.go:459] [meng] sched.schedule(pod) has error: user3/user3-pytorch-lenet-4, 0/13 nodes are available: 1 node(s) had taints that the pod didn't tolerate, 12 Insufficient cpu.
I0116 14:08:45.673447       1 util.go:1534] [meng] calling OnlineAlloX
I0116 14:08:45.673476       1 util.go:1550] [meng] numAvailMachines == 7,  allpods length: 21
I0116 14:08:45.686159       1 scheduler.go:459] [meng] sched.schedule(pod) has error: user3/user3-pytorch-lenet-4, 0/13 nodes are available: 1 node(s) had taints that the pod didn't tolerate, 12 Insufficient cpu.
I0116 14:08:45.788536       1 util.go:1534] [meng] calling OnlineAlloX
I0116 14:08:45.788565       1 util.go:1550] [meng] numAvailMachines == 7,  allpods length: 21
I0116 14:08:45.800869       1 scheduler.go:459] [meng] sched.schedule(pod) has error: user3/user3-pytorch-lenet-4, 0/13 nodes are available: 1 node(s) had taints that the pod didn't tolerate, 12 Insufficient cpu.
I0116 14:08:45.903046       1 util.go:1534] [meng] calling OnlineAlloX
I0116 14:08:45.903075       1 util.go:1550] [meng] numAvailMachines == 7,  allpods length: 21
I0116 14:08:45.915765       1 scheduler.go:459] [meng] sched.schedule(pod) has error: user3/user3-pytorch-lenet-4, 0/13 nodes are available: 1 node(s) had taints that the pod didn't tolerate, 12 Insufficient cpu.
I0116 14:08:46.017743       1 util.go:1534] [meng] calling OnlineAlloX
I0116 14:08:46.017773       1 util.go:1550] [meng] numAvailMachines == 7,  allpods length: 21
I0116 14:08:46.029961       1 scheduler.go:459] [meng] sched.schedule(pod) has error: user3/user3-pytorch-lenet-4, 0/13 nodes are available: 1 node(s) had taints that the pod didn't tolerate, 12 Insufficient cpu.
I0116 14:08:46.131968       1 util.go:1534] [meng] calling OnlineAlloX
I0116 14:08:46.131997       1 util.go:1550] [meng] numAvailMachines == 7,  allpods length: 21
I0116 14:08:46.144874       1 scheduler.go:459] [meng] sched.schedule(pod) has error: user3/user3-pytorch-lenet-4, 0/13 nodes are available: 1 node(s) had taints that the pod didn't tolerate, 12 Insufficient cpu.
I0116 14:08:46.246956       1 util.go:1534] [meng] calling OnlineAlloX
I0116 14:08:46.246984       1 util.go:1550] [meng] numAvailMachines == 7,  allpods length: 21
I0116 14:08:46.259526       1 scheduler.go:459] [meng] sched.schedule(pod) has error: user3/user3-pytorch-lenet-4, 0/13 nodes are available: 1 node(s) had taints that the pod didn't tolerate, 12 Insufficient cpu.
I0116 14:08:46.361594       1 util.go:1534] [meng] calling OnlineAlloX
I0116 14:08:46.361624       1 util.go:1550] [meng] numAvailMachines == 7,  allpods length: 21
I0116 14:08:46.374024       1 scheduler.go:459] [meng] sched.schedule(pod) has error: user3/user3-pytorch-lenet-4, 0/13 nodes are available: 1 node(s) had taints that the pod didn't tolerate, 12 Insufficient cpu.
I0116 14:08:46.476145       1 util.go:1534] [meng] calling OnlineAlloX
I0116 14:08:46.476184       1 util.go:1550] [meng] numAvailMachines == 7,  allpods length: 21
I0116 14:08:46.488751       1 scheduler.go:459] [meng] sched.schedule(pod) has error: user3/user3-pytorch-lenet-4, 0/13 nodes are available: 1 node(s) had taints that the pod didn't tolerate, 12 Insufficient cpu.
I0116 14:08:46.590824       1 util.go:1534] [meng] calling OnlineAlloX
I0116 14:08:46.590852       1 util.go:1550] [meng] numAvailMachines == 7,  allpods length: 21
I0116 14:08:46.603620       1 scheduler.go:459] [meng] sched.schedule(pod) has error: user3/user3-pytorch-lenet-4, 0/13 nodes are available: 1 node(s) had taints that the pod didn't tolerate, 12 Insufficient cpu.
I0116 14:08:46.705873       1 util.go:1534] [meng] calling OnlineAlloX
I0116 14:08:46.705917       1 util.go:1550] [meng] numAvailMachines == 7,  allpods length: 21
I0116 14:08:46.718297       1 scheduler.go:459] [meng] sched.schedule(pod) has error: user3/user3-pytorch-lenet-4, 0/13 nodes are available: 1 node(s) had taints that the pod didn't tolerate, 12 Insufficient cpu.
I0116 14:08:46.820204       1 util.go:1534] [meng] calling OnlineAlloX
I0116 14:08:46.820235       1 util.go:1550] [meng] numAvailMachines == 7,  allpods length: 21
I0116 14:08:46.833803       1 scheduler.go:459] [meng] sched.schedule(pod) has error: user3/user3-pytorch-lenet-4, 0/13 nodes are available: 1 node(s) had taints that the pod didn't tolerate, 12 Insufficient cpu.
I0116 14:08:46.935877       1 util.go:1534] [meng] calling OnlineAlloX
I0116 14:08:46.935907       1 util.go:1550] [meng] numAvailMachines == 7,  allpods length: 21
I0116 14:08:46.948672       1 scheduler.go:459] [meng] sched.schedule(pod) has error: user3/user3-pytorch-lenet-4, 0/13 nodes are available: 1 node(s) had taints that the pod didn't tolerate, 12 Insufficient cpu.
I0116 14:08:47.050746       1 util.go:1534] [meng] calling OnlineAlloX
I0116 14:08:47.050786       1 util.go:1550] [meng] numAvailMachines == 7,  allpods length: 21
I0116 14:08:47.062928       1 scheduler.go:459] [meng] sched.schedule(pod) has error: user3/user3-pytorch-lenet-4, 0/13 nodes are available: 1 node(s) had taints that the pod didn't tolerate, 12 Insufficient cpu.
I0116 14:08:47.164904       1 util.go:1534] [meng] calling OnlineAlloX
I0116 14:08:47.164935       1 util.go:1550] [meng] numAvailMachines == 7,  allpods length: 21
I0116 14:08:47.177182       1 scheduler.go:459] [meng] sched.schedule(pod) has error: user3/user3-pytorch-lenet-4, 0/13 nodes are available: 1 node(s) had taints that the pod didn't tolerate, 12 Insufficient cpu.
I0116 14:08:47.279292       1 util.go:1534] [meng] calling OnlineAlloX
I0116 14:08:47.279332       1 util.go:1550] [meng] numAvailMachines == 7,  allpods length: 21
I0116 14:08:47.292162       1 scheduler.go:459] [meng] sched.schedule(pod) has error: user3/user3-pytorch-lenet-4, 0/13 nodes are available: 1 node(s) had taints that the pod didn't tolerate, 12 Insufficient cpu.
I0116 14:08:47.394425       1 util.go:1534] [meng] calling OnlineAlloX
I0116 14:08:47.394464       1 util.go:1550] [meng] numAvailMachines == 7,  allpods length: 21
I0116 14:08:47.406549       1 scheduler.go:459] [meng] sched.schedule(pod) has error: user3/user3-pytorch-lenet-4, 0/13 nodes are available: 1 node(s) had taints that the pod didn't tolerate, 12 Insufficient cpu.
I0116 14:08:47.508815       1 util.go:1534] [meng] calling OnlineAlloX
I0116 14:08:47.508844       1 util.go:1550] [meng] numAvailMachines == 7,  allpods length: 21
I0116 14:08:47.520991       1 scheduler.go:459] [meng] sched.schedule(pod) has error: user3/user3-pytorch-lenet-4, 0/13 nodes are available: 1 node(s) had taints that the pod didn't tolerate, 12 Insufficient cpu.
I0116 14:08:47.623034       1 util.go:1534] [meng] calling OnlineAlloX
I0116 14:08:47.623064       1 util.go:1550] [meng] numAvailMachines == 7,  allpods length: 21
I0116 14:08:47.635106       1 scheduler.go:459] [meng] sched.schedule(pod) has error: user3/user3-pytorch-lenet-4, 0/13 nodes are available: 1 node(s) had taints that the pod didn't tolerate, 12 Insufficient cpu.
I0116 14:08:47.737462       1 util.go:1534] [meng] calling OnlineAlloX
I0116 14:08:47.737490       1 util.go:1550] [meng] numAvailMachines == 7,  allpods length: 21
I0116 14:08:47.750112       1 scheduler.go:459] [meng] sched.schedule(pod) has error: user3/user3-pytorch-lenet-4, 0/13 nodes are available: 1 node(s) had taints that the pod didn't tolerate, 12 Insufficient cpu.
I0116 14:08:47.852446       1 util.go:1534] [meng] calling OnlineAlloX
I0116 14:08:47.852474       1 util.go:1550] [meng] numAvailMachines == 7,  allpods length: 21
I0116 14:08:47.864613       1 scheduler.go:459] [meng] sched.schedule(pod) has error: user3/user3-pytorch-lenet-4, 0/13 nodes are available: 1 node(s) had taints that the pod didn't tolerate, 12 Insufficient cpu.
I0116 14:08:47.966771       1 util.go:1534] [meng] calling OnlineAlloX
I0116 14:08:47.966799       1 util.go:1550] [meng] numAvailMachines == 7,  allpods length: 21
I0116 14:08:47.979152       1 scheduler.go:459] [meng] sched.schedule(pod) has error: user3/user3-pytorch-lenet-4, 0/13 nodes are available: 1 node(s) had taints that the pod didn't tolerate, 12 Insufficient cpu.
I0116 14:08:48.024354       1 factory.go:1129] [meng] deletePodFromCache
I0116 14:08:48.024365       1 factory.go:1136] [meng] JCT: 50.047545522s, total jct: 5m19.036259625s, count: 12, average JCT: 26.586354968s
I0116 14:08:48.034316       1 factory.go:798] [meng] computeComplTimeForAllPods completed
I0116 14:08:48.034335       1 factory.go:806] [tanle] Event pod completed user2/user2-pytorch-lenet-3%!(EXTRA v1.PodPhase=Succeeded)
I0116 14:08:48.034355       1 factory.go:1149] [meng] check delete pod user2/user2-pytorch-lenet-3, Running
I0116 14:08:48.034361       1 util.go:143] [meng] UpdateFairScore user2/user2-pytorch-lenet-3, false
I0116 14:08:48.034369       1 util.go:192] [meng] delete PodMachineMap in UpdateFairScore user2/user2-pytorch-lenet-3, false
I0116 14:08:48.034374       1 util.go:196] [tanle] FairScoreMap:  map[user1:0.38888888888888895 user2:0.1944444444444445 user3:0.38888888888888895 user4:0.38888888888888895]
I0116 14:08:48.081043       1 util.go:1534] [meng] calling OnlineAlloX
I0116 14:08:48.081072       1 util.go:1550] [meng] numAvailMachines == 8,  allpods length: 21
I0116 14:08:48.093721       1 util.go:196] [tanle] FairScoreMap:  map[user1:0.38888888888888895 user2:0.1944444444444445 user3:0.5833333333333334 user4:0.38888888888888895]
I0116 14:08:48.095658       1 scheduler.go:406] [tanle] binding user3/user3-pytorch-lenet-4 on GPU false-->meng-allox-cpu-4
I0116 14:08:48.193875       1 util.go:1534] [meng] calling OnlineAlloX
I0116 14:08:48.193904       1 util.go:1550] [meng] numAvailMachines == 7,  allpods length: 20
I0116 14:08:48.199387       1 factory.go:1129] [meng] deletePodFromCache
I0116 14:08:48.199414       1 factory.go:1136] [meng] JCT: 50.222594036s, total jct: 6m9.258853661s, count: 13, average JCT: 28.404527204s
I0116 14:08:48.205343       1 util.go:196] [tanle] FairScoreMap:  map[user1:0.38888888888888895 user2:0.44444444444444453 user3:0.5833333333333334 user4:0.38888888888888895]
I0116 14:08:48.207336       1 scheduler.go:406] [tanle] binding user2/user2-pytorch-googlenet on GPU true-->meng-allox-egpu-2
I0116 14:08:48.209340       1 factory.go:798] [meng] computeComplTimeForAllPods completed
I0116 14:08:48.209358       1 factory.go:806] [tanle] Event pod completed user3/user3-pytorch-lenet-5%!(EXTRA v1.PodPhase=Succeeded)
I0116 14:08:48.209377       1 factory.go:1149] [meng] check delete pod user3/user3-pytorch-lenet-5, Running
I0116 14:08:48.209383       1 util.go:143] [meng] UpdateFairScore user3/user3-pytorch-lenet-5, false
I0116 14:08:48.209389       1 util.go:192] [meng] delete PodMachineMap in UpdateFairScore user3/user3-pytorch-lenet-5, false
I0116 14:08:48.209394       1 util.go:196] [tanle] FairScoreMap:  map[user1:0.38888888888888895 user2:0.44444444444444453 user3:0.38888888888888895 user4:0.38888888888888895]
I0116 14:08:48.305503       1 util.go:1534] [meng] calling OnlineAlloX
I0116 14:08:48.305549       1 util.go:1550] [meng] numAvailMachines == 7,  allpods length: 19
I0116 14:08:48.315205       1 util.go:196] [tanle] FairScoreMap:  map[user1:0.38888888888888895 user2:0.44444444444444453 user3:0.638888888888889 user4:0.38888888888888895]
I0116 14:08:48.317383       1 scheduler.go:406] [tanle] binding user3/user3-pytorch-googlenet on GPU true-->meng-allox-egpu-4
I0116 14:08:48.415357       1 util.go:1534] [meng] calling OnlineAlloX
I0116 14:08:48.415405       1 util.go:1550] [meng] numAvailMachines == 6,  allpods length: 18
I0116 14:08:48.424074       1 util.go:196] [tanle] FairScoreMap:  map[user1:0.38888888888888895 user2:0.44444444444444453 user3:0.638888888888889 user4:0.638888888888889]
I0116 14:08:48.429156       1 scheduler.go:406] [tanle] binding user4/user4-pytorch-googlenet on GPU true-->meng-allox-egpu-1
I0116 14:08:48.524231       1 util.go:1534] [meng] calling OnlineAlloX
I0116 14:08:48.524260       1 util.go:1550] [meng] numAvailMachines == 5,  allpods length: 17
I0116 14:08:48.532789       1 util.go:196] [tanle] FairScoreMap:  map[user2:0.44444444444444453 user3:0.638888888888889 user4:0.638888888888889 user1:0.638888888888889]
I0116 14:08:48.535486       1 scheduler.go:406] [tanle] binding user1/user1-pytorch-googlenet on GPU true-->meng-allox-egpu-3
I0116 14:08:48.632945       1 util.go:1534] [meng] calling OnlineAlloX
I0116 14:08:48.632986       1 util.go:1550] [meng] numAvailMachines == 4,  allpods length: 16
I0116 14:08:48.639080       1 util.go:1534] [meng] calling OnlineAlloX
I0116 14:08:48.639133       1 util.go:1550] [meng] numAvailMachines == 4,  allpods length: 16
I0116 14:08:48.746012       1 util.go:1534] [meng] calling OnlineAlloX
I0116 14:08:48.746065       1 util.go:1550] [meng] numAvailMachines == 4,  allpods length: 16
I0116 14:08:48.752046       1 util.go:1534] [meng] calling OnlineAlloX
I0116 14:08:48.752112       1 util.go:1550] [meng] numAvailMachines == 4,  allpods length: 16
I0116 14:08:48.859164       1 util.go:1534] [meng] calling OnlineAlloX
I0116 14:08:48.859224       1 util.go:1550] [meng] numAvailMachines == 4,  allpods length: 16
I0116 14:08:48.865143       1 util.go:1534] [meng] calling OnlineAlloX
I0116 14:08:48.865200       1 util.go:1550] [meng] numAvailMachines == 4,  allpods length: 16
I0116 14:08:48.972280       1 util.go:1534] [meng] calling OnlineAlloX
I0116 14:08:48.972336       1 util.go:1550] [meng] numAvailMachines == 4,  allpods length: 16
I0116 14:08:48.978328       1 util.go:1534] [meng] calling OnlineAlloX
I0116 14:08:48.978394       1 util.go:1550] [meng] numAvailMachines == 4,  allpods length: 16
I0116 14:08:49.085380       1 util.go:1534] [meng] calling OnlineAlloX
I0116 14:08:49.085432       1 util.go:1550] [meng] numAvailMachines == 4,  allpods length: 16
I0116 14:08:49.091223       1 util.go:1534] [meng] calling OnlineAlloX
I0116 14:08:49.091276       1 util.go:1550] [meng] numAvailMachines == 4,  allpods length: 16
I0116 14:08:49.198095       1 util.go:1534] [meng] calling OnlineAlloX
I0116 14:08:49.198144       1 util.go:1550] [meng] numAvailMachines == 4,  allpods length: 16
I0116 14:08:49.204313       1 util.go:1534] [meng] calling OnlineAlloX
I0116 14:08:49.204365       1 util.go:1550] [meng] numAvailMachines == 4,  allpods length: 16
I0116 14:08:49.311255       1 util.go:1534] [meng] calling OnlineAlloX
I0116 14:08:49.311303       1 util.go:1550] [meng] numAvailMachines == 4,  allpods length: 16
I0116 14:08:49.317509       1 util.go:1534] [meng] calling OnlineAlloX
I0116 14:08:49.317561       1 util.go:1550] [meng] numAvailMachines == 4,  allpods length: 16
I0116 14:08:49.424590       1 util.go:1534] [meng] calling OnlineAlloX
I0116 14:08:49.424641       1 util.go:1550] [meng] numAvailMachines == 4,  allpods length: 16
I0116 14:08:49.430593       1 util.go:1534] [meng] calling OnlineAlloX
I0116 14:08:49.430645       1 util.go:1550] [meng] numAvailMachines == 4,  allpods length: 16
I0116 14:08:49.537610       1 util.go:1534] [meng] calling OnlineAlloX
I0116 14:08:49.537659       1 util.go:1550] [meng] numAvailMachines == 4,  allpods length: 16
I0116 14:08:49.543516       1 util.go:1534] [meng] calling OnlineAlloX
I0116 14:08:49.543568       1 util.go:1550] [meng] numAvailMachines == 4,  allpods length: 16
I0116 14:08:49.650485       1 util.go:1534] [meng] calling OnlineAlloX
I0116 14:08:49.650534       1 util.go:1550] [meng] numAvailMachines == 4,  allpods length: 16
I0116 14:08:49.656375       1 util.go:1534] [meng] calling OnlineAlloX
I0116 14:08:49.656427       1 util.go:1550] [meng] numAvailMachines == 4,  allpods length: 16
I0116 14:08:49.763305       1 util.go:1534] [meng] calling OnlineAlloX
I0116 14:08:49.763353       1 util.go:1550] [meng] numAvailMachines == 4,  allpods length: 16
I0116 14:08:49.769765       1 util.go:1534] [meng] calling OnlineAlloX
I0116 14:08:49.769959       1 util.go:1550] [meng] numAvailMachines == 4,  allpods length: 16
I0116 14:08:49.876380       1 util.go:1534] [meng] calling OnlineAlloX
I0116 14:08:49.876427       1 util.go:1550] [meng] numAvailMachines == 4,  allpods length: 16
I0116 14:08:49.882982       1 util.go:1534] [meng] calling OnlineAlloX
I0116 14:08:49.883035       1 util.go:1550] [meng] numAvailMachines == 4,  allpods length: 16
I0116 14:08:49.988965       1 util.go:1534] [meng] calling OnlineAlloX
I0116 14:08:49.989019       1 util.go:1550] [meng] numAvailMachines == 4,  allpods length: 16
I0116 14:08:49.995701       1 util.go:1534] [meng] calling OnlineAlloX
I0116 14:08:49.995753       1 util.go:1550] [meng] numAvailMachines == 4,  allpods length: 16
I0116 14:08:50.101625       1 util.go:1534] [meng] calling OnlineAlloX
I0116 14:08:50.101688       1 util.go:1550] [meng] numAvailMachines == 4,  allpods length: 16
I0116 14:08:50.107798       1 util.go:1534] [meng] calling OnlineAlloX
I0116 14:08:50.107851       1 util.go:1550] [meng] numAvailMachines == 4,  allpods length: 16
I0116 14:08:50.214795       1 util.go:1534] [meng] calling OnlineAlloX
I0116 14:08:50.214837       1 util.go:1550] [meng] numAvailMachines == 4,  allpods length: 16
I0116 14:08:50.221213       1 util.go:1534] [meng] calling OnlineAlloX
I0116 14:08:50.221269       1 util.go:1550] [meng] numAvailMachines == 4,  allpods length: 16
I0116 14:08:50.327586       1 util.go:1534] [meng] calling OnlineAlloX
I0116 14:08:50.327627       1 util.go:1550] [meng] numAvailMachines == 4,  allpods length: 16
I0116 14:08:50.333538       1 util.go:1534] [meng] calling OnlineAlloX
I0116 14:08:50.333598       1 util.go:1550] [meng] numAvailMachines == 4,  allpods length: 16
I0116 14:08:50.440535       1 util.go:1534] [meng] calling OnlineAlloX
I0116 14:08:50.440576       1 util.go:1550] [meng] numAvailMachines == 4,  allpods length: 16
I0116 14:08:50.447204       1 util.go:1534] [meng] calling OnlineAlloX
I0116 14:08:50.447263       1 util.go:1550] [meng] numAvailMachines == 4,  allpods length: 16
I0116 14:08:50.553427       1 util.go:1534] [meng] calling OnlineAlloX
I0116 14:08:50.553476       1 util.go:1550] [meng] numAvailMachines == 4,  allpods length: 16
I0116 14:08:50.559926       1 util.go:1534] [meng] calling OnlineAlloX
I0116 14:08:50.559983       1 util.go:1550] [meng] numAvailMachines == 4,  allpods length: 16
I0116 14:08:50.666065       1 util.go:1534] [meng] calling OnlineAlloX
I0116 14:08:50.666113       1 util.go:1550] [meng] numAvailMachines == 4,  allpods length: 16
I0116 14:08:50.672743       1 util.go:1534] [meng] calling OnlineAlloX
I0116 14:08:50.672799       1 util.go:1550] [meng] numAvailMachines == 4,  allpods length: 16
I0116 14:08:50.778716       1 util.go:1534] [meng] calling OnlineAlloX
I0116 14:08:50.778765       1 util.go:1550] [meng] numAvailMachines == 4,  allpods length: 16
I0116 14:08:50.785366       1 util.go:1534] [meng] calling OnlineAlloX
I0116 14:08:50.785419       1 util.go:1550] [meng] numAvailMachines == 4,  allpods length: 16
I0116 14:08:50.891394       1 util.go:1534] [meng] calling OnlineAlloX
I0116 14:08:50.891443       1 util.go:1550] [meng] numAvailMachines == 4,  allpods length: 16
I0116 14:08:50.898408       1 util.go:1534] [meng] calling OnlineAlloX
I0116 14:08:50.898460       1 util.go:1550] [meng] numAvailMachines == 4,  allpods length: 16
I0116 14:08:51.004336       1 util.go:1534] [meng] calling OnlineAlloX
I0116 14:08:51.004386       1 util.go:1550] [meng] numAvailMachines == 4,  allpods length: 16
I0116 14:08:51.011271       1 util.go:1534] [meng] calling OnlineAlloX
I0116 14:08:51.011323       1 util.go:1550] [meng] numAvailMachines == 4,  allpods length: 16
I0116 14:08:51.117292       1 util.go:1534] [meng] calling OnlineAlloX
I0116 14:08:51.117339       1 util.go:1550] [meng] numAvailMachines == 4,  allpods length: 16
I0116 14:08:51.123963       1 util.go:1534] [meng] calling OnlineAlloX
I0116 14:08:51.124022       1 util.go:1550] [meng] numAvailMachines == 4,  allpods length: 16
I0116 14:08:51.221708       1 factory.go:1129] [meng] deletePodFromCache
I0116 14:08:51.221725       1 factory.go:1136] [meng] JCT: 53.244905782s, total jct: 7m2.503759443s, count: 14, average JCT: 30.17883996s
I0116 14:08:51.229846       1 util.go:1534] [meng] calling OnlineAlloX
I0116 14:08:51.229903       1 util.go:1550] [meng] numAvailMachines == 4,  allpods length: 16
I0116 14:08:51.234848       1 factory.go:798] [meng] computeComplTimeForAllPods completed
I0116 14:08:51.234877       1 factory.go:806] [tanle] Event pod completed user3/user3-pytorch-lenet-2%!(EXTRA v1.PodPhase=Succeeded)
I0116 14:08:51.234898       1 factory.go:1149] [meng] check delete pod user3/user3-pytorch-lenet-2, Running
I0116 14:08:51.234904       1 util.go:143] [meng] UpdateFairScore user3/user3-pytorch-lenet-2, false
I0116 14:08:51.234911       1 util.go:192] [meng] delete PodMachineMap in UpdateFairScore user3/user3-pytorch-lenet-2, false
I0116 14:08:51.234914       1 util.go:196] [tanle] FairScoreMap:  map[user2:0.44444444444444453 user3:0.44444444444444453 user4:0.638888888888889 user1:0.638888888888889]
I0116 14:08:51.236288       1 util.go:1534] [meng] calling OnlineAlloX
I0116 14:08:51.236338       1 util.go:1550] [meng] numAvailMachines == 5,  allpods length: 16
I0116 14:08:51.343212       1 util.go:1534] [meng] calling OnlineAlloX
I0116 14:08:51.343282       1 util.go:1550] [meng] numAvailMachines == 5,  allpods length: 16
I0116 14:08:51.349722       1 util.go:1534] [meng] calling OnlineAlloX
I0116 14:08:51.349777       1 util.go:1550] [meng] numAvailMachines == 5,  allpods length: 16
I0116 14:08:51.456851       1 util.go:1534] [meng] calling OnlineAlloX
I0116 14:08:51.456927       1 util.go:1550] [meng] numAvailMachines == 5,  allpods length: 16
I0116 14:08:51.463518       1 util.go:1534] [meng] calling OnlineAlloX
I0116 14:08:51.463587       1 util.go:1550] [meng] numAvailMachines == 5,  allpods length: 16
I0116 14:08:51.571004       1 util.go:1534] [meng] calling OnlineAlloX
I0116 14:08:51.571072       1 util.go:1550] [meng] numAvailMachines == 5,  allpods length: 16
I0116 14:08:51.578025       1 util.go:1534] [meng] calling OnlineAlloX
I0116 14:08:51.578123       1 util.go:1550] [meng] numAvailMachines == 5,  allpods length: 16
I0116 14:08:51.685339       1 util.go:1534] [meng] calling OnlineAlloX
I0116 14:08:51.685392       1 util.go:1550] [meng] numAvailMachines == 5,  allpods length: 16
I0116 14:08:51.691958       1 util.go:1534] [meng] calling OnlineAlloX
I0116 14:08:51.692151       1 util.go:1550] [meng] numAvailMachines == 5,  allpods length: 16
I0116 14:08:51.799079       1 util.go:1534] [meng] calling OnlineAlloX
I0116 14:08:51.799131       1 util.go:1550] [meng] numAvailMachines == 5,  allpods length: 16
I0116 14:08:51.806123       1 util.go:1534] [meng] calling OnlineAlloX
I0116 14:08:51.806181       1 util.go:1550] [meng] numAvailMachines == 5,  allpods length: 16
I0116 14:08:51.912838       1 util.go:1534] [meng] calling OnlineAlloX
I0116 14:08:51.912887       1 util.go:1550] [meng] numAvailMachines == 5,  allpods length: 16
I0116 14:08:51.919732       1 util.go:1534] [meng] calling OnlineAlloX
I0116 14:08:51.919788       1 util.go:1550] [meng] numAvailMachines == 5,  allpods length: 16
I0116 14:08:52.026623       1 util.go:1534] [meng] calling OnlineAlloX
I0116 14:08:52.026673       1 util.go:1550] [meng] numAvailMachines == 5,  allpods length: 16
I0116 14:08:52.033521       1 util.go:1534] [meng] calling OnlineAlloX
I0116 14:08:52.033577       1 util.go:1550] [meng] numAvailMachines == 5,  allpods length: 16
I0116 14:08:52.140531       1 util.go:1534] [meng] calling OnlineAlloX
I0116 14:08:52.140579       1 util.go:1550] [meng] numAvailMachines == 5,  allpods length: 16
I0116 14:08:52.147371       1 util.go:1534] [meng] calling OnlineAlloX
I0116 14:08:52.147431       1 util.go:1550] [meng] numAvailMachines == 5,  allpods length: 16
I0116 14:08:52.253902       1 util.go:1534] [meng] calling OnlineAlloX
I0116 14:08:52.253952       1 util.go:1550] [meng] numAvailMachines == 5,  allpods length: 16
I0116 14:08:52.260630       1 util.go:1534] [meng] calling OnlineAlloX
I0116 14:08:52.260686       1 util.go:1550] [meng] numAvailMachines == 5,  allpods length: 16
I0116 14:08:52.366915       1 util.go:1534] [meng] calling OnlineAlloX
I0116 14:08:52.366962       1 util.go:1550] [meng] numAvailMachines == 5,  allpods length: 16
I0116 14:08:52.373476       1 util.go:1534] [meng] calling OnlineAlloX
I0116 14:08:52.373532       1 util.go:1550] [meng] numAvailMachines == 5,  allpods length: 16
I0116 14:08:52.479847       1 util.go:1534] [meng] calling OnlineAlloX
I0116 14:08:52.479895       1 util.go:1550] [meng] numAvailMachines == 5,  allpods length: 16
I0116 14:08:52.486402       1 util.go:1534] [meng] calling OnlineAlloX
I0116 14:08:52.486458       1 util.go:1550] [meng] numAvailMachines == 5,  allpods length: 16
I0116 14:08:52.592963       1 util.go:1534] [meng] calling OnlineAlloX
I0116 14:08:52.593009       1 util.go:1550] [meng] numAvailMachines == 5,  allpods length: 16
I0116 14:08:52.599824       1 util.go:1534] [meng] calling OnlineAlloX
I0116 14:08:52.599878       1 util.go:1550] [meng] numAvailMachines == 5,  allpods length: 16
I0116 14:08:52.706456       1 util.go:1534] [meng] calling OnlineAlloX
I0116 14:08:52.706503       1 util.go:1550] [meng] numAvailMachines == 5,  allpods length: 16
I0116 14:08:52.712734       1 util.go:1534] [meng] calling OnlineAlloX
I0116 14:08:52.712884       1 util.go:1550] [meng] numAvailMachines == 5,  allpods length: 16
I0116 14:08:52.819546       1 util.go:1534] [meng] calling OnlineAlloX
I0116 14:08:52.819595       1 util.go:1550] [meng] numAvailMachines == 5,  allpods length: 16
I0116 14:08:52.826045       1 util.go:1534] [meng] calling OnlineAlloX
I0116 14:08:52.826255       1 util.go:1550] [meng] numAvailMachines == 5,  allpods length: 16
I0116 14:08:52.932681       1 util.go:1534] [meng] calling OnlineAlloX
I0116 14:08:52.932729       1 util.go:1550] [meng] numAvailMachines == 5,  allpods length: 16
I0116 14:08:52.939274       1 util.go:1534] [meng] calling OnlineAlloX
I0116 14:08:52.939330       1 util.go:1550] [meng] numAvailMachines == 5,  allpods length: 16
I0116 14:08:53.045701       1 util.go:1534] [meng] calling OnlineAlloX
I0116 14:08:53.045751       1 util.go:1550] [meng] numAvailMachines == 5,  allpods length: 16
I0116 14:08:53.052147       1 util.go:1534] [meng] calling OnlineAlloX
I0116 14:08:53.052283       1 util.go:1550] [meng] numAvailMachines == 5,  allpods length: 16
I0116 14:08:53.158848       1 util.go:1534] [meng] calling OnlineAlloX
I0116 14:08:53.158899       1 util.go:1550] [meng] numAvailMachines == 5,  allpods length: 16
I0116 14:08:53.165400       1 util.go:1534] [meng] calling OnlineAlloX
I0116 14:08:53.165457       1 util.go:1550] [meng] numAvailMachines == 5,  allpods length: 16
I0116 14:08:53.271988       1 util.go:1534] [meng] calling OnlineAlloX
I0116 14:08:53.272030       1 util.go:1550] [meng] numAvailMachines == 5,  allpods length: 16
I0116 14:08:53.278716       1 util.go:1534] [meng] calling OnlineAlloX
I0116 14:08:53.278775       1 util.go:1550] [meng] numAvailMachines == 5,  allpods length: 16
I0116 14:08:53.385156       1 util.go:1534] [meng] calling OnlineAlloX
I0116 14:08:53.385204       1 util.go:1550] [meng] numAvailMachines == 5,  allpods length: 16
I0116 14:08:53.391820       1 util.go:1534] [meng] calling OnlineAlloX
I0116 14:08:53.391878       1 util.go:1550] [meng] numAvailMachines == 5,  allpods length: 16
I0116 14:08:53.498301       1 util.go:1534] [meng] calling OnlineAlloX
I0116 14:08:53.498350       1 util.go:1550] [meng] numAvailMachines == 5,  allpods length: 16
I0116 14:08:53.504859       1 util.go:1534] [meng] calling OnlineAlloX
I0116 14:08:53.504914       1 util.go:1550] [meng] numAvailMachines == 5,  allpods length: 16
I0116 14:08:53.611316       1 util.go:1534] [meng] calling OnlineAlloX
I0116 14:08:53.611366       1 util.go:1550] [meng] numAvailMachines == 5,  allpods length: 16
I0116 14:08:53.617911       1 util.go:1534] [meng] calling OnlineAlloX
I0116 14:08:53.617968       1 util.go:1550] [meng] numAvailMachines == 5,  allpods length: 16
I0116 14:08:53.724349       1 util.go:1534] [meng] calling OnlineAlloX
I0116 14:08:53.724397       1 util.go:1550] [meng] numAvailMachines == 5,  allpods length: 16
I0116 14:08:53.730804       1 util.go:1534] [meng] calling OnlineAlloX
I0116 14:08:53.730860       1 util.go:1550] [meng] numAvailMachines == 5,  allpods length: 16
I0116 14:08:53.837400       1 util.go:1534] [meng] calling OnlineAlloX
I0116 14:08:53.837447       1 util.go:1550] [meng] numAvailMachines == 5,  allpods length: 16
I0116 14:08:53.843966       1 util.go:1534] [meng] calling OnlineAlloX
I0116 14:08:53.844023       1 util.go:1550] [meng] numAvailMachines == 5,  allpods length: 16
I0116 14:08:53.950536       1 util.go:1534] [meng] calling OnlineAlloX
I0116 14:08:53.950582       1 util.go:1550] [meng] numAvailMachines == 5,  allpods length: 16
I0116 14:08:53.957165       1 util.go:1534] [meng] calling OnlineAlloX
I0116 14:08:53.957224       1 util.go:1550] [meng] numAvailMachines == 5,  allpods length: 16
I0116 14:08:54.063435       1 util.go:1534] [meng] calling OnlineAlloX
I0116 14:08:54.063484       1 util.go:1550] [meng] numAvailMachines == 5,  allpods length: 16
I0116 14:08:54.070305       1 util.go:1534] [meng] calling OnlineAlloX
I0116 14:08:54.070363       1 util.go:1550] [meng] numAvailMachines == 5,  allpods length: 16
I0116 14:08:54.176163       1 util.go:1534] [meng] calling OnlineAlloX
I0116 14:08:54.176222       1 util.go:1550] [meng] numAvailMachines == 5,  allpods length: 16
I0116 14:08:54.183426       1 util.go:1534] [meng] calling OnlineAlloX
I0116 14:08:54.183480       1 util.go:1550] [meng] numAvailMachines == 5,  allpods length: 16
I0116 14:08:54.290367       1 util.go:1534] [meng] calling OnlineAlloX
I0116 14:08:54.290417       1 util.go:1550] [meng] numAvailMachines == 5,  allpods length: 16
I0116 14:08:54.296950       1 util.go:1534] [meng] calling OnlineAlloX
I0116 14:08:54.297001       1 util.go:1550] [meng] numAvailMachines == 5,  allpods length: 16
I0116 14:08:54.404256       1 util.go:1534] [meng] calling OnlineAlloX
I0116 14:08:54.404306       1 util.go:1550] [meng] numAvailMachines == 5,  allpods length: 16
I0116 14:08:54.410398       1 util.go:1534] [meng] calling OnlineAlloX
I0116 14:08:54.410450       1 util.go:1550] [meng] numAvailMachines == 5,  allpods length: 16
I0116 14:08:54.517215       1 util.go:1534] [meng] calling OnlineAlloX
I0116 14:08:54.517263       1 util.go:1550] [meng] numAvailMachines == 5,  allpods length: 16
I0116 14:08:54.523225       1 util.go:1534] [meng] calling OnlineAlloX
I0116 14:08:54.523277       1 util.go:1550] [meng] numAvailMachines == 5,  allpods length: 16
I0116 14:08:54.630177       1 util.go:1534] [meng] calling OnlineAlloX
I0116 14:08:54.630224       1 util.go:1550] [meng] numAvailMachines == 5,  allpods length: 16
I0116 14:08:54.636080       1 util.go:1534] [meng] calling OnlineAlloX
I0116 14:08:54.636134       1 util.go:1550] [meng] numAvailMachines == 5,  allpods length: 16
I0116 14:08:54.742928       1 util.go:1534] [meng] calling OnlineAlloX
I0116 14:08:54.742976       1 util.go:1550] [meng] numAvailMachines == 5,  allpods length: 16
I0116 14:08:54.749006       1 util.go:1534] [meng] calling OnlineAlloX
I0116 14:08:54.749057       1 util.go:1550] [meng] numAvailMachines == 5,  allpods length: 16
I0116 14:08:54.855900       1 util.go:1534] [meng] calling OnlineAlloX
I0116 14:08:54.855949       1 util.go:1550] [meng] numAvailMachines == 5,  allpods length: 16
I0116 14:08:54.861770       1 util.go:1534] [meng] calling OnlineAlloX
I0116 14:08:54.861821       1 util.go:1550] [meng] numAvailMachines == 5,  allpods length: 16
I0116 14:08:54.968647       1 util.go:1534] [meng] calling OnlineAlloX
I0116 14:08:54.968690       1 util.go:1550] [meng] numAvailMachines == 5,  allpods length: 16
I0116 14:08:54.974456       1 util.go:1534] [meng] calling OnlineAlloX
I0116 14:08:54.974508       1 util.go:1550] [meng] numAvailMachines == 5,  allpods length: 16
I0116 14:08:55.081454       1 util.go:1534] [meng] calling OnlineAlloX
I0116 14:08:55.081502       1 util.go:1550] [meng] numAvailMachines == 5,  allpods length: 16
I0116 14:08:55.087121       1 util.go:1534] [meng] calling OnlineAlloX
I0116 14:08:55.087172       1 util.go:1550] [meng] numAvailMachines == 5,  allpods length: 16
I0116 14:08:55.194056       1 util.go:1534] [meng] calling OnlineAlloX
I0116 14:08:55.194103       1 util.go:1550] [meng] numAvailMachines == 5,  allpods length: 16
I0116 14:08:55.199909       1 util.go:1534] [meng] calling OnlineAlloX
I0116 14:08:55.199960       1 util.go:1550] [meng] numAvailMachines == 5,  allpods length: 16
I0116 14:08:55.306871       1 util.go:1534] [meng] calling OnlineAlloX
I0116 14:08:55.306920       1 util.go:1550] [meng] numAvailMachines == 5,  allpods length: 16
I0116 14:08:55.312671       1 util.go:1534] [meng] calling OnlineAlloX
I0116 14:08:55.312722       1 util.go:1550] [meng] numAvailMachines == 5,  allpods length: 16
I0116 14:08:55.419460       1 util.go:1534] [meng] calling OnlineAlloX
I0116 14:08:55.419508       1 util.go:1550] [meng] numAvailMachines == 5,  allpods length: 16
I0116 14:08:55.425259       1 util.go:1534] [meng] calling OnlineAlloX
I0116 14:08:55.425312       1 util.go:1550] [meng] numAvailMachines == 5,  allpods length: 16
I0116 14:08:55.532208       1 util.go:1534] [meng] calling OnlineAlloX
I0116 14:08:55.532256       1 util.go:1550] [meng] numAvailMachines == 5,  allpods length: 16
I0116 14:08:55.537980       1 util.go:1534] [meng] calling OnlineAlloX
I0116 14:08:55.538030       1 util.go:1550] [meng] numAvailMachines == 5,  allpods length: 16
I0116 14:08:55.644803       1 util.go:1534] [meng] calling OnlineAlloX
I0116 14:08:55.644856       1 util.go:1550] [meng] numAvailMachines == 5,  allpods length: 16
I0116 14:08:55.650822       1 util.go:1534] [meng] calling OnlineAlloX
I0116 14:08:55.650878       1 util.go:1550] [meng] numAvailMachines == 5,  allpods length: 16
I0116 14:08:55.758065       1 util.go:1534] [meng] calling OnlineAlloX
I0116 14:08:55.758114       1 util.go:1550] [meng] numAvailMachines == 5,  allpods length: 16
I0116 14:08:55.763976       1 util.go:1534] [meng] calling OnlineAlloX
I0116 14:08:55.764030       1 util.go:1550] [meng] numAvailMachines == 5,  allpods length: 16
I0116 14:08:55.871052       1 util.go:1534] [meng] calling OnlineAlloX
I0116 14:08:55.871103       1 util.go:1550] [meng] numAvailMachines == 5,  allpods length: 16
I0116 14:08:55.876964       1 util.go:1534] [meng] calling OnlineAlloX
I0116 14:08:55.877017       1 util.go:1550] [meng] numAvailMachines == 5,  allpods length: 16
I0116 14:08:55.983940       1 util.go:1534] [meng] calling OnlineAlloX
I0116 14:08:55.983989       1 util.go:1550] [meng] numAvailMachines == 5,  allpods length: 16
I0116 14:08:55.989745       1 util.go:1534] [meng] calling OnlineAlloX
I0116 14:08:55.989797       1 util.go:1550] [meng] numAvailMachines == 5,  allpods length: 16
I0116 14:08:56.096684       1 util.go:1534] [meng] calling OnlineAlloX
I0116 14:08:56.096733       1 util.go:1550] [meng] numAvailMachines == 5,  allpods length: 16
I0116 14:08:56.102474       1 util.go:1534] [meng] calling OnlineAlloX
I0116 14:08:56.102527       1 util.go:1550] [meng] numAvailMachines == 5,  allpods length: 16
I0116 14:08:56.209562       1 util.go:1534] [meng] calling OnlineAlloX
I0116 14:08:56.209618       1 util.go:1550] [meng] numAvailMachines == 5,  allpods length: 16
I0116 14:08:56.215767       1 util.go:1534] [meng] calling OnlineAlloX
I0116 14:08:56.215818       1 util.go:1550] [meng] numAvailMachines == 5,  allpods length: 16
I0116 14:08:56.322746       1 util.go:1534] [meng] calling OnlineAlloX
I0116 14:08:56.322794       1 util.go:1550] [meng] numAvailMachines == 5,  allpods length: 16
I0116 14:08:56.328603       1 util.go:1534] [meng] calling OnlineAlloX
I0116 14:08:56.328655       1 util.go:1550] [meng] numAvailMachines == 5,  allpods length: 16
I0116 14:08:56.435683       1 util.go:1534] [meng] calling OnlineAlloX
I0116 14:08:56.435731       1 util.go:1550] [meng] numAvailMachines == 5,  allpods length: 16
I0116 14:08:56.441503       1 util.go:1534] [meng] calling OnlineAlloX
I0116 14:08:56.441554       1 util.go:1550] [meng] numAvailMachines == 5,  allpods length: 16
I0116 14:08:56.548369       1 util.go:1534] [meng] calling OnlineAlloX
I0116 14:08:56.548417       1 util.go:1550] [meng] numAvailMachines == 5,  allpods length: 16
I0116 14:08:56.554106       1 util.go:1534] [meng] calling OnlineAlloX
I0116 14:08:56.554158       1 util.go:1550] [meng] numAvailMachines == 5,  allpods length: 16
I0116 14:08:56.661265       1 util.go:1534] [meng] calling OnlineAlloX
I0116 14:08:56.661314       1 util.go:1550] [meng] numAvailMachines == 5,  allpods length: 16
I0116 14:08:56.667233       1 util.go:1534] [meng] calling OnlineAlloX
I0116 14:08:56.667285       1 util.go:1550] [meng] numAvailMachines == 5,  allpods length: 16
I0116 14:08:56.774175       1 util.go:1534] [meng] calling OnlineAlloX
I0116 14:08:56.774225       1 util.go:1550] [meng] numAvailMachines == 5,  allpods length: 16
I0116 14:08:56.780070       1 util.go:1534] [meng] calling OnlineAlloX
I0116 14:08:56.780122       1 util.go:1550] [meng] numAvailMachines == 5,  allpods length: 16
I0116 14:08:56.886878       1 util.go:1534] [meng] calling OnlineAlloX
I0116 14:08:56.886973       1 util.go:1550] [meng] numAvailMachines == 5,  allpods length: 16
I0116 14:08:56.893632       1 util.go:1534] [meng] calling OnlineAlloX
I0116 14:08:56.893853       1 util.go:1550] [meng] numAvailMachines == 5,  allpods length: 16
I0116 14:08:56.993903       1 factory.go:1129] [meng] deletePodFromCache
I0116 14:08:56.993919       1 factory.go:1136] [meng] JCT: 59.017100156s, total jct: 8m1.520859599s, count: 15, average JCT: 32.101390639s
I0116 14:08:57.001066       1 util.go:1534] [meng] calling OnlineAlloX
I0116 14:08:57.001109       1 util.go:1550] [meng] numAvailMachines == 5,  allpods length: 16
I0116 14:08:57.004810       1 factory.go:798] [meng] computeComplTimeForAllPods completed
I0116 14:08:57.004839       1 factory.go:806] [tanle] Event pod completed user4/user4-pytorch-lenet-5%!(EXTRA v1.PodPhase=Succeeded)
I0116 14:08:57.004862       1 factory.go:1149] [meng] check delete pod user4/user4-pytorch-lenet-5, Running
I0116 14:08:57.004869       1 util.go:143] [meng] UpdateFairScore user4/user4-pytorch-lenet-5, false
I0116 14:08:57.004876       1 util.go:192] [meng] delete PodMachineMap in UpdateFairScore user4/user4-pytorch-lenet-5, false
I0116 14:08:57.004880       1 util.go:196] [tanle] FairScoreMap:  map[user2:0.44444444444444453 user3:0.44444444444444453 user4:0.44444444444444453 user1:0.638888888888889]
I0116 14:08:57.008309       1 util.go:1534] [meng] calling OnlineAlloX
I0116 14:08:57.008364       1 util.go:1550] [meng] numAvailMachines == 6,  allpods length: 16
I0116 14:08:57.114644       1 util.go:1534] [meng] calling OnlineAlloX
I0116 14:08:57.114708       1 util.go:1550] [meng] numAvailMachines == 6,  allpods length: 16
I0116 14:08:57.121799       1 util.go:1534] [meng] calling OnlineAlloX
I0116 14:08:57.121851       1 util.go:1550] [meng] numAvailMachines == 6,  allpods length: 16
I0116 14:08:57.228064       1 util.go:1534] [meng] calling OnlineAlloX
I0116 14:08:57.228115       1 util.go:1550] [meng] numAvailMachines == 6,  allpods length: 16
I0116 14:08:57.235260       1 util.go:1534] [meng] calling OnlineAlloX
I0116 14:08:57.235320       1 util.go:1550] [meng] numAvailMachines == 6,  allpods length: 16
I0116 14:08:57.341414       1 util.go:1534] [meng] calling OnlineAlloX
I0116 14:08:57.341461       1 util.go:1550] [meng] numAvailMachines == 6,  allpods length: 16
I0116 14:08:57.348534       1 util.go:1534] [meng] calling OnlineAlloX
I0116 14:08:57.348585       1 util.go:1550] [meng] numAvailMachines == 6,  allpods length: 16
I0116 14:08:57.454681       1 util.go:1534] [meng] calling OnlineAlloX
I0116 14:08:57.454720       1 util.go:1550] [meng] numAvailMachines == 6,  allpods length: 16
I0116 14:08:57.461354       1 util.go:1534] [meng] calling OnlineAlloX
I0116 14:08:57.461406       1 util.go:1550] [meng] numAvailMachines == 6,  allpods length: 16
I0116 14:08:57.567388       1 util.go:1534] [meng] calling OnlineAlloX
I0116 14:08:57.567436       1 util.go:1550] [meng] numAvailMachines == 6,  allpods length: 16
I0116 14:08:57.574369       1 util.go:1534] [meng] calling OnlineAlloX
I0116 14:08:57.574422       1 util.go:1550] [meng] numAvailMachines == 6,  allpods length: 16
I0116 14:08:57.680645       1 util.go:1534] [meng] calling OnlineAlloX
I0116 14:08:57.680693       1 util.go:1550] [meng] numAvailMachines == 6,  allpods length: 16
I0116 14:08:57.686875       1 util.go:1534] [meng] calling OnlineAlloX
I0116 14:08:57.686927       1 util.go:1550] [meng] numAvailMachines == 6,  allpods length: 16
I0116 14:08:57.793653       1 util.go:1534] [meng] calling OnlineAlloX
I0116 14:08:57.793701       1 util.go:1550] [meng] numAvailMachines == 6,  allpods length: 16
I0116 14:08:57.799958       1 util.go:1534] [meng] calling OnlineAlloX
I0116 14:08:57.800009       1 util.go:1550] [meng] numAvailMachines == 6,  allpods length: 16
I0116 14:08:57.906933       1 util.go:1534] [meng] calling OnlineAlloX
I0116 14:08:57.906985       1 util.go:1550] [meng] numAvailMachines == 6,  allpods length: 16
I0116 14:08:57.913064       1 util.go:1534] [meng] calling OnlineAlloX
I0116 14:08:57.913115       1 util.go:1550] [meng] numAvailMachines == 6,  allpods length: 16
I0116 14:08:58.019534       1 util.go:1534] [meng] calling OnlineAlloX
I0116 14:08:58.019580       1 util.go:1550] [meng] numAvailMachines == 6,  allpods length: 16
I0116 14:08:58.025758       1 util.go:1534] [meng] calling OnlineAlloX
I0116 14:08:58.025814       1 util.go:1550] [meng] numAvailMachines == 6,  allpods length: 16
I0116 14:08:58.104751       1 factory.go:1129] [meng] deletePodFromCache
I0116 14:08:58.104771       1 factory.go:1136] [meng] JCT: 1m0.127950797s, total jct: 9m1.648810396s, count: 16, average JCT: 33.853050649s
I0116 14:08:58.114763       1 factory.go:798] [meng] computeComplTimeForAllPods completed
I0116 14:08:58.114789       1 factory.go:806] [tanle] Event pod completed user3/user3-pytorch-googlenet%!(EXTRA v1.PodPhase=Succeeded)
I0116 14:08:58.114812       1 factory.go:1149] [meng] check delete pod user3/user3-pytorch-googlenet, Running
I0116 14:08:58.114819       1 util.go:143] [meng] UpdateFairScore user3/user3-pytorch-googlenet, false
I0116 14:08:58.114825       1 util.go:192] [meng] delete PodMachineMap in UpdateFairScore user3/user3-pytorch-googlenet, false
I0116 14:08:58.114829       1 util.go:196] [tanle] FairScoreMap:  map[user1:0.638888888888889 user2:0.44444444444444453 user3:0.19444444444444453 user4:0.44444444444444453]
I0116 14:08:58.132700       1 util.go:1534] [meng] calling OnlineAlloX
I0116 14:08:58.132734       1 util.go:1550] [meng] numAvailMachines == 7,  allpods length: 16
I0116 14:08:58.138792       1 util.go:196] [tanle] FairScoreMap:  map[user2:0.44444444444444453 user3:0.44444444444444453 user4:0.44444444444444453 user1:0.638888888888889]
I0116 14:08:58.141038       1 scheduler.go:406] [tanle] binding user3/user3-pytorch-resnet34 on GPU true-->meng-allox-egpu-4
I0116 14:08:58.196725       1 factory.go:1129] [meng] deletePodFromCache
I0116 14:08:58.196736       1 factory.go:1136] [meng] JCT: 1m0.219916373s, total jct: 10m1.868726769s, count: 17, average JCT: 35.404042751s
I0116 14:08:58.205982       1 factory.go:798] [meng] computeComplTimeForAllPods completed
I0116 14:08:58.206005       1 factory.go:806] [tanle] Event pod completed user4/user4-pytorch-googlenet%!(EXTRA v1.PodPhase=Succeeded)
I0116 14:08:58.206024       1 factory.go:1149] [meng] check delete pod user4/user4-pytorch-googlenet, Running
I0116 14:08:58.206030       1 util.go:143] [meng] UpdateFairScore user4/user4-pytorch-googlenet, false
I0116 14:08:58.206036       1 util.go:192] [meng] delete PodMachineMap in UpdateFairScore user4/user4-pytorch-googlenet, false
I0116 14:08:58.206040       1 util.go:196] [tanle] FairScoreMap:  map[user1:0.638888888888889 user2:0.44444444444444453 user3:0.44444444444444453 user4:0.19444444444444453]
I0116 14:08:58.238951       1 util.go:1534] [meng] calling OnlineAlloX
I0116 14:08:58.238992       1 util.go:1550] [meng] numAvailMachines == 7,  allpods length: 15
I0116 14:08:58.244415       1 util.go:196] [tanle] FairScoreMap:  map[user2:0.44444444444444453 user3:0.44444444444444453 user4:0.44444444444444453 user1:0.638888888888889]
I0116 14:08:58.246794       1 scheduler.go:406] [tanle] binding user4/user4-pytorch-resnet34 on GPU true-->meng-allox-egpu-1
I0116 14:08:58.344568       1 util.go:1534] [meng] calling OnlineAlloX
I0116 14:08:58.344612       1 util.go:1550] [meng] numAvailMachines == 6,  allpods length: 14
I0116 14:08:58.348868       1 util.go:1534] [meng] calling OnlineAlloX
I0116 14:08:58.348918       1 util.go:1550] [meng] numAvailMachines == 6,  allpods length: 14
I0116 14:08:58.403899       1 factory.go:1129] [meng] deletePodFromCache
I0116 14:08:58.403915       1 factory.go:1136] [meng] JCT: 1m0.427095862s, total jct: 11m2.295822631s, count: 18, average JCT: 36.794212368s
I0116 14:08:58.413114       1 factory.go:798] [meng] computeComplTimeForAllPods completed
I0116 14:08:58.413134       1 factory.go:806] [tanle] Event pod completed user1/user1-pytorch-googlenet%!(EXTRA v1.PodPhase=Succeeded)
I0116 14:08:58.413159       1 factory.go:1149] [meng] check delete pod user1/user1-pytorch-googlenet, Running
I0116 14:08:58.413164       1 util.go:143] [meng] UpdateFairScore user1/user1-pytorch-googlenet, false
I0116 14:08:58.413170       1 util.go:192] [meng] delete PodMachineMap in UpdateFairScore user1/user1-pytorch-googlenet, false
I0116 14:08:58.413174       1 util.go:196] [tanle] FairScoreMap:  map[user1:0.38888888888888895 user2:0.44444444444444453 user3:0.44444444444444453 user4:0.44444444444444453]
I0116 14:08:58.452913       1 util.go:1534] [meng] calling OnlineAlloX
I0116 14:08:58.452953       1 util.go:1550] [meng] numAvailMachines == 7,  allpods length: 14
I0116 14:08:58.456977       1 util.go:196] [tanle] FairScoreMap:  map[user3:0.44444444444444453 user4:0.44444444444444453 user1:0.38888888888888895 user2:0.6944444444444445]
I0116 14:08:58.462206       1 scheduler.go:406] [tanle] binding user2/user2-pytorch-resnet34 on GPU true-->meng-allox-egpu-3
I0116 14:08:58.516638       1 factory.go:1129] [meng] deletePodFromCache
I0116 14:08:58.516647       1 factory.go:1136] [meng] JCT: 1m0.539828113s, total jct: 12m2.835650744s, count: 19, average JCT: 38.043981618s
I0116 14:08:58.526135       1 factory.go:798] [meng] computeComplTimeForAllPods completed
I0116 14:08:58.526152       1 factory.go:806] [tanle] Event pod completed user1/user1-pytorch-lenet-3%!(EXTRA v1.PodPhase=Succeeded)
I0116 14:08:58.526171       1 factory.go:1149] [meng] check delete pod user1/user1-pytorch-lenet-3, Running
I0116 14:08:58.526177       1 util.go:143] [meng] UpdateFairScore user1/user1-pytorch-lenet-3, false
I0116 14:08:58.526183       1 util.go:192] [meng] delete PodMachineMap in UpdateFairScore user1/user1-pytorch-lenet-3, false
I0116 14:08:58.526187       1 util.go:196] [tanle] FairScoreMap:  map[user1:0.1944444444444445 user2:0.6944444444444445 user3:0.44444444444444453 user4:0.44444444444444453]
I0116 14:08:58.557126       1 util.go:1534] [meng] calling OnlineAlloX
I0116 14:08:58.557154       1 util.go:1550] [meng] numAvailMachines == 7,  allpods length: 13
I0116 14:08:58.560713       1 util.go:1534] [meng] calling OnlineAlloX
I0116 14:08:58.560768       1 util.go:1550] [meng] numAvailMachines == 7,  allpods length: 13
I0116 14:08:58.664370       1 util.go:1534] [meng] calling OnlineAlloX
I0116 14:08:58.664417       1 util.go:1550] [meng] numAvailMachines == 7,  allpods length: 13
I0116 14:08:58.667942       1 util.go:1534] [meng] calling OnlineAlloX
I0116 14:08:58.667993       1 util.go:1550] [meng] numAvailMachines == 7,  allpods length: 13
I0116 14:08:58.771396       1 util.go:1534] [meng] calling OnlineAlloX
I0116 14:08:58.771436       1 util.go:1550] [meng] numAvailMachines == 7,  allpods length: 13
I0116 14:08:58.774827       1 util.go:1534] [meng] calling OnlineAlloX
I0116 14:08:58.774893       1 util.go:1550] [meng] numAvailMachines == 7,  allpods length: 13
I0116 14:08:58.857986       1 factory.go:1129] [meng] deletePodFromCache
I0116 14:08:58.858003       1 factory.go:1136] [meng] JCT: 1m0.881183475s, total jct: 13m3.716834219s, count: 20, average JCT: 39.18584171s
I0116 14:08:58.867666       1 factory.go:798] [meng] computeComplTimeForAllPods completed
I0116 14:08:58.867687       1 factory.go:806] [tanle] Event pod completed user2/user2-pytorch-googlenet%!(EXTRA v1.PodPhase=Succeeded)
I0116 14:08:58.867707       1 factory.go:1149] [meng] check delete pod user2/user2-pytorch-googlenet, Running
I0116 14:08:58.867713       1 util.go:143] [meng] UpdateFairScore user2/user2-pytorch-googlenet, false
I0116 14:08:58.867719       1 util.go:192] [meng] delete PodMachineMap in UpdateFairScore user2/user2-pytorch-googlenet, false
I0116 14:08:58.867724       1 util.go:196] [tanle] FairScoreMap:  map[user4:0.44444444444444453 user1:0.1944444444444445 user2:0.44444444444444453 user3:0.44444444444444453]
I0116 14:08:58.878212       1 util.go:1534] [meng] calling OnlineAlloX
I0116 14:08:58.878256       1 util.go:1550] [meng] numAvailMachines == 8,  allpods length: 13
I0116 14:08:58.882083       1 util.go:196] [tanle] FairScoreMap:  map[user4:0.44444444444444453 user1:0.44444444444444453 user2:0.44444444444444453 user3:0.44444444444444453]
I0116 14:08:58.883957       1 scheduler.go:406] [tanle] binding user1/user1-pytorch-resnet34 on GPU true-->meng-allox-egpu-2
I0116 14:08:58.982236       1 util.go:1534] [meng] calling OnlineAlloX
I0116 14:08:58.982267       1 util.go:1550] [meng] numAvailMachines == 7,  allpods length: 12
I0116 14:08:58.985230       1 util.go:1534] [meng] calling OnlineAlloX
I0116 14:08:58.985297       1 util.go:1550] [meng] numAvailMachines == 7,  allpods length: 12
I0116 14:08:59.087664       1 util.go:1534] [meng] calling OnlineAlloX
I0116 14:08:59.087713       1 util.go:1550] [meng] numAvailMachines == 7,  allpods length: 12
I0116 14:08:59.090542       1 util.go:1534] [meng] calling OnlineAlloX
I0116 14:08:59.090592       1 util.go:1550] [meng] numAvailMachines == 7,  allpods length: 12
I0116 14:08:59.193556       1 util.go:1534] [meng] calling OnlineAlloX
I0116 14:08:59.193605       1 util.go:1550] [meng] numAvailMachines == 7,  allpods length: 12
I0116 14:08:59.195649       1 util.go:1534] [meng] calling OnlineAlloX
I0116 14:08:59.195683       1 util.go:1550] [meng] numAvailMachines == 7,  allpods length: 12
I0116 14:08:59.298675       1 util.go:1534] [meng] calling OnlineAlloX
I0116 14:08:59.298723       1 util.go:1550] [meng] numAvailMachines == 7,  allpods length: 12
I0116 14:08:59.301554       1 util.go:1534] [meng] calling OnlineAlloX
I0116 14:08:59.301617       1 util.go:1550] [meng] numAvailMachines == 7,  allpods length: 12
I0116 14:08:59.403734       1 util.go:1534] [meng] calling OnlineAlloX
I0116 14:08:59.403779       1 util.go:1550] [meng] numAvailMachines == 7,  allpods length: 12
I0116 14:08:59.406737       1 util.go:1534] [meng] calling OnlineAlloX
I0116 14:08:59.406788       1 util.go:1550] [meng] numAvailMachines == 7,  allpods length: 12
I0116 14:08:59.509733       1 util.go:1534] [meng] calling OnlineAlloX
I0116 14:08:59.509780       1 util.go:1550] [meng] numAvailMachines == 7,  allpods length: 12
I0116 14:08:59.511832       1 util.go:1534] [meng] calling OnlineAlloX
I0116 14:08:59.511869       1 util.go:1550] [meng] numAvailMachines == 7,  allpods length: 12
I0116 14:08:59.614710       1 util.go:1534] [meng] calling OnlineAlloX
I0116 14:08:59.614757       1 util.go:1550] [meng] numAvailMachines == 7,  allpods length: 12
I0116 14:08:59.617639       1 util.go:1534] [meng] calling OnlineAlloX
I0116 14:08:59.617689       1 util.go:1550] [meng] numAvailMachines == 7,  allpods length: 12
I0116 14:08:59.719827       1 util.go:1534] [meng] calling OnlineAlloX
I0116 14:08:59.719868       1 util.go:1550] [meng] numAvailMachines == 7,  allpods length: 12
I0116 14:08:59.722669       1 util.go:1534] [meng] calling OnlineAlloX
I0116 14:08:59.722719       1 util.go:1550] [meng] numAvailMachines == 7,  allpods length: 12
I0116 14:08:59.825524       1 util.go:1534] [meng] calling OnlineAlloX
I0116 14:08:59.825571       1 util.go:1550] [meng] numAvailMachines == 7,  allpods length: 12
I0116 14:08:59.827600       1 util.go:1534] [meng] calling OnlineAlloX
I0116 14:08:59.827636       1 util.go:1550] [meng] numAvailMachines == 7,  allpods length: 12
I0116 14:08:59.930388       1 util.go:1534] [meng] calling OnlineAlloX
I0116 14:08:59.930434       1 util.go:1550] [meng] numAvailMachines == 7,  allpods length: 12
I0116 14:08:59.933342       1 util.go:1534] [meng] calling OnlineAlloX
I0116 14:08:59.933391       1 util.go:1550] [meng] numAvailMachines == 7,  allpods length: 12
I0116 14:09:00.035515       1 util.go:1534] [meng] calling OnlineAlloX
I0116 14:09:00.035559       1 util.go:1550] [meng] numAvailMachines == 7,  allpods length: 12
I0116 14:09:00.038473       1 util.go:1534] [meng] calling OnlineAlloX
I0116 14:09:00.038522       1 util.go:1550] [meng] numAvailMachines == 7,  allpods length: 12
I0116 14:09:00.141473       1 util.go:1534] [meng] calling OnlineAlloX
I0116 14:09:00.141519       1 util.go:1550] [meng] numAvailMachines == 7,  allpods length: 12
I0116 14:09:00.143544       1 util.go:1534] [meng] calling OnlineAlloX
I0116 14:09:00.143582       1 util.go:1550] [meng] numAvailMachines == 7,  allpods length: 12
I0116 14:09:00.246529       1 util.go:1534] [meng] calling OnlineAlloX
I0116 14:09:00.246573       1 util.go:1550] [meng] numAvailMachines == 7,  allpods length: 12
I0116 14:09:00.249459       1 util.go:1534] [meng] calling OnlineAlloX
I0116 14:09:00.249509       1 util.go:1550] [meng] numAvailMachines == 7,  allpods length: 12
I0116 14:09:00.351936       1 util.go:1534] [meng] calling OnlineAlloX
I0116 14:09:00.351983       1 util.go:1550] [meng] numAvailMachines == 7,  allpods length: 12
I0116 14:09:00.354023       1 util.go:1534] [meng] calling OnlineAlloX
I0116 14:09:00.354059       1 util.go:1550] [meng] numAvailMachines == 7,  allpods length: 12
I0116 14:09:00.457208       1 util.go:1534] [meng] calling OnlineAlloX
I0116 14:09:00.457248       1 util.go:1550] [meng] numAvailMachines == 7,  allpods length: 12
I0116 14:09:00.460126       1 util.go:1534] [meng] calling OnlineAlloX
I0116 14:09:00.460177       1 util.go:1550] [meng] numAvailMachines == 7,  allpods length: 12
I0116 14:09:00.563071       1 util.go:1534] [meng] calling OnlineAlloX
I0116 14:09:00.563117       1 util.go:1550] [meng] numAvailMachines == 7,  allpods length: 12
I0116 14:09:00.565140       1 util.go:1534] [meng] calling OnlineAlloX
I0116 14:09:00.565174       1 util.go:1550] [meng] numAvailMachines == 7,  allpods length: 12
I0116 14:09:00.667994       1 util.go:1534] [meng] calling OnlineAlloX
I0116 14:09:00.668036       1 util.go:1550] [meng] numAvailMachines == 7,  allpods length: 12
I0116 14:09:00.670919       1 util.go:1534] [meng] calling OnlineAlloX
I0116 14:09:00.670972       1 util.go:1550] [meng] numAvailMachines == 7,  allpods length: 12
I0116 14:09:00.773820       1 util.go:1534] [meng] calling OnlineAlloX
I0116 14:09:00.773866       1 util.go:1550] [meng] numAvailMachines == 7,  allpods length: 12
I0116 14:09:00.775910       1 util.go:1534] [meng] calling OnlineAlloX
I0116 14:09:00.775945       1 util.go:1550] [meng] numAvailMachines == 7,  allpods length: 12
I0116 14:09:00.879238       1 util.go:1534] [meng] calling OnlineAlloX
I0116 14:09:00.879286       1 util.go:1550] [meng] numAvailMachines == 7,  allpods length: 12
I0116 14:09:00.882114       1 util.go:1534] [meng] calling OnlineAlloX
I0116 14:09:00.882167       1 util.go:1550] [meng] numAvailMachines == 7,  allpods length: 12
I0116 14:09:00.984282       1 util.go:1534] [meng] calling OnlineAlloX
I0116 14:09:00.984325       1 util.go:1550] [meng] numAvailMachines == 7,  allpods length: 12
I0116 14:09:00.987251       1 util.go:1534] [meng] calling OnlineAlloX
I0116 14:09:00.987302       1 util.go:1550] [meng] numAvailMachines == 7,  allpods length: 12
I0116 14:09:01.090264       1 util.go:1534] [meng] calling OnlineAlloX
I0116 14:09:01.090308       1 util.go:1550] [meng] numAvailMachines == 7,  allpods length: 12
I0116 14:09:01.092354       1 util.go:1534] [meng] calling OnlineAlloX
I0116 14:09:01.092390       1 util.go:1550] [meng] numAvailMachines == 7,  allpods length: 12
I0116 14:09:01.195202       1 util.go:1534] [meng] calling OnlineAlloX
I0116 14:09:01.195241       1 util.go:1550] [meng] numAvailMachines == 7,  allpods length: 12
I0116 14:09:01.198065       1 util.go:1534] [meng] calling OnlineAlloX
I0116 14:09:01.198116       1 util.go:1550] [meng] numAvailMachines == 7,  allpods length: 12
I0116 14:09:01.300961       1 util.go:1534] [meng] calling OnlineAlloX
I0116 14:09:01.301007       1 util.go:1550] [meng] numAvailMachines == 7,  allpods length: 12
I0116 14:09:01.303039       1 util.go:1534] [meng] calling OnlineAlloX
I0116 14:09:01.303076       1 util.go:1550] [meng] numAvailMachines == 7,  allpods length: 12
I0116 14:09:01.406127       1 util.go:1534] [meng] calling OnlineAlloX
I0116 14:09:01.406175       1 util.go:1550] [meng] numAvailMachines == 7,  allpods length: 12
I0116 14:09:01.408913       1 util.go:1534] [meng] calling OnlineAlloX
I0116 14:09:01.408964       1 util.go:1550] [meng] numAvailMachines == 7,  allpods length: 12
I0116 14:09:01.511071       1 util.go:1534] [meng] calling OnlineAlloX
I0116 14:09:01.511129       1 util.go:1550] [meng] numAvailMachines == 7,  allpods length: 12
I0116 14:09:01.514309       1 util.go:1534] [meng] calling OnlineAlloX
I0116 14:09:01.514375       1 util.go:1550] [meng] numAvailMachines == 7,  allpods length: 12
I0116 14:09:01.617503       1 util.go:1534] [meng] calling OnlineAlloX
I0116 14:09:01.617556       1 util.go:1550] [meng] numAvailMachines == 7,  allpods length: 12
I0116 14:09:01.619948       1 util.go:1534] [meng] calling OnlineAlloX
I0116 14:09:01.619987       1 util.go:1550] [meng] numAvailMachines == 7,  allpods length: 12
I0116 14:09:01.723369       1 util.go:1534] [meng] calling OnlineAlloX
I0116 14:09:01.723417       1 util.go:1550] [meng] numAvailMachines == 7,  allpods length: 12
I0116 14:09:01.726423       1 util.go:1534] [meng] calling OnlineAlloX
I0116 14:09:01.726477       1 util.go:1550] [meng] numAvailMachines == 7,  allpods length: 12
I0116 14:09:01.828864       1 util.go:1534] [meng] calling OnlineAlloX
I0116 14:09:01.828905       1 util.go:1550] [meng] numAvailMachines == 7,  allpods length: 12
I0116 14:09:01.831825       1 util.go:1534] [meng] calling OnlineAlloX
I0116 14:09:01.831875       1 util.go:1550] [meng] numAvailMachines == 7,  allpods length: 12
I0116 14:09:01.934989       1 util.go:1534] [meng] calling OnlineAlloX
I0116 14:09:01.935033       1 util.go:1550] [meng] numAvailMachines == 7,  allpods length: 12
I0116 14:09:01.937238       1 util.go:1534] [meng] calling OnlineAlloX
I0116 14:09:01.937274       1 util.go:1550] [meng] numAvailMachines == 7,  allpods length: 12
I0116 14:09:02.040302       1 util.go:1534] [meng] calling OnlineAlloX
I0116 14:09:02.040348       1 util.go:1550] [meng] numAvailMachines == 7,  allpods length: 12
I0116 14:09:02.043281       1 util.go:1534] [meng] calling OnlineAlloX
I0116 14:09:02.043330       1 util.go:1550] [meng] numAvailMachines == 7,  allpods length: 12
I0116 14:09:02.145564       1 util.go:1534] [meng] calling OnlineAlloX
I0116 14:09:02.145611       1 util.go:1550] [meng] numAvailMachines == 7,  allpods length: 12
I0116 14:09:02.148401       1 util.go:1534] [meng] calling OnlineAlloX
I0116 14:09:02.148451       1 util.go:1550] [meng] numAvailMachines == 7,  allpods length: 12
I0116 14:09:02.251308       1 util.go:1534] [meng] calling OnlineAlloX
I0116 14:09:02.251356       1 util.go:1550] [meng] numAvailMachines == 7,  allpods length: 12
I0116 14:09:02.253487       1 util.go:1534] [meng] calling OnlineAlloX
I0116 14:09:02.253522       1 util.go:1550] [meng] numAvailMachines == 7,  allpods length: 12
I0116 14:09:02.356575       1 util.go:1534] [meng] calling OnlineAlloX
I0116 14:09:02.356622       1 util.go:1550] [meng] numAvailMachines == 7,  allpods length: 12
I0116 14:09:02.359695       1 util.go:1534] [meng] calling OnlineAlloX
I0116 14:09:02.359745       1 util.go:1550] [meng] numAvailMachines == 7,  allpods length: 12
I0116 14:09:02.461941       1 util.go:1534] [meng] calling OnlineAlloX
I0116 14:09:02.462337       1 util.go:1550] [meng] numAvailMachines == 7,  allpods length: 12
I0116 14:09:02.464887       1 util.go:1534] [meng] calling OnlineAlloX
I0116 14:09:02.464936       1 util.go:1550] [meng] numAvailMachines == 7,  allpods length: 12
I0116 14:09:02.568075       1 util.go:1534] [meng] calling OnlineAlloX
I0116 14:09:02.568119       1 util.go:1550] [meng] numAvailMachines == 7,  allpods length: 12
I0116 14:09:02.571030       1 util.go:1534] [meng] calling OnlineAlloX
I0116 14:09:02.571087       1 util.go:1550] [meng] numAvailMachines == 7,  allpods length: 12
I0116 14:09:02.673284       1 util.go:1534] [meng] calling OnlineAlloX
I0116 14:09:02.673324       1 util.go:1550] [meng] numAvailMachines == 7,  allpods length: 12
I0116 14:09:02.676213       1 util.go:1534] [meng] calling OnlineAlloX
I0116 14:09:02.676264       1 util.go:1550] [meng] numAvailMachines == 7,  allpods length: 12
I0116 14:09:02.779258       1 util.go:1534] [meng] calling OnlineAlloX
I0116 14:09:02.779304       1 util.go:1550] [meng] numAvailMachines == 7,  allpods length: 12
I0116 14:09:02.781375       1 util.go:1534] [meng] calling OnlineAlloX
I0116 14:09:02.781409       1 util.go:1550] [meng] numAvailMachines == 7,  allpods length: 12
I0116 14:09:02.884315       1 util.go:1534] [meng] calling OnlineAlloX
I0116 14:09:02.884361       1 util.go:1550] [meng] numAvailMachines == 7,  allpods length: 12
I0116 14:09:02.887178       1 util.go:1534] [meng] calling OnlineAlloX
I0116 14:09:02.887230       1 util.go:1550] [meng] numAvailMachines == 7,  allpods length: 12
I0116 14:09:02.989374       1 util.go:1534] [meng] calling OnlineAlloX
I0116 14:09:02.989417       1 util.go:1550] [meng] numAvailMachines == 7,  allpods length: 12
I0116 14:09:02.992252       1 util.go:1534] [meng] calling OnlineAlloX
I0116 14:09:02.992303       1 util.go:1550] [meng] numAvailMachines == 7,  allpods length: 12
I0116 14:09:03.095261       1 util.go:1534] [meng] calling OnlineAlloX
I0116 14:09:03.095313       1 util.go:1550] [meng] numAvailMachines == 7,  allpods length: 12
I0116 14:09:03.097373       1 util.go:1534] [meng] calling OnlineAlloX
I0116 14:09:03.097407       1 util.go:1550] [meng] numAvailMachines == 7,  allpods length: 12
I0116 14:09:03.200261       1 util.go:1534] [meng] calling OnlineAlloX
I0116 14:09:03.200317       1 util.go:1550] [meng] numAvailMachines == 7,  allpods length: 12
I0116 14:09:03.203158       1 util.go:1534] [meng] calling OnlineAlloX
I0116 14:09:03.203211       1 util.go:1550] [meng] numAvailMachines == 7,  allpods length: 12
I0116 14:09:03.305365       1 util.go:1534] [meng] calling OnlineAlloX
I0116 14:09:03.305414       1 util.go:1550] [meng] numAvailMachines == 7,  allpods length: 12
I0116 14:09:03.308348       1 util.go:1534] [meng] calling OnlineAlloX
I0116 14:09:03.308397       1 util.go:1550] [meng] numAvailMachines == 7,  allpods length: 12
I0116 14:09:03.411265       1 util.go:1534] [meng] calling OnlineAlloX
I0116 14:09:03.411311       1 util.go:1550] [meng] numAvailMachines == 7,  allpods length: 12
I0116 14:09:03.413371       1 util.go:1534] [meng] calling OnlineAlloX
I0116 14:09:03.413405       1 util.go:1550] [meng] numAvailMachines == 7,  allpods length: 12
I0116 14:09:03.516303       1 util.go:1534] [meng] calling OnlineAlloX
I0116 14:09:03.516352       1 util.go:1550] [meng] numAvailMachines == 7,  allpods length: 12
I0116 14:09:03.519272       1 util.go:1534] [meng] calling OnlineAlloX
I0116 14:09:03.519323       1 util.go:1550] [meng] numAvailMachines == 7,  allpods length: 12
I0116 14:09:03.621456       1 util.go:1534] [meng] calling OnlineAlloX
I0116 14:09:03.621495       1 util.go:1550] [meng] numAvailMachines == 7,  allpods length: 12
I0116 14:09:03.624344       1 util.go:1534] [meng] calling OnlineAlloX
I0116 14:09:03.624393       1 util.go:1550] [meng] numAvailMachines == 7,  allpods length: 12
I0116 14:09:03.727360       1 util.go:1534] [meng] calling OnlineAlloX
I0116 14:09:03.727406       1 util.go:1550] [meng] numAvailMachines == 7,  allpods length: 12
I0116 14:09:03.729441       1 util.go:1534] [meng] calling OnlineAlloX
I0116 14:09:03.729476       1 util.go:1550] [meng] numAvailMachines == 7,  allpods length: 12
I0116 14:09:03.832394       1 util.go:1534] [meng] calling OnlineAlloX
I0116 14:09:03.832440       1 util.go:1550] [meng] numAvailMachines == 7,  allpods length: 12
I0116 14:09:03.835258       1 util.go:1534] [meng] calling OnlineAlloX
I0116 14:09:03.835309       1 util.go:1550] [meng] numAvailMachines == 7,  allpods length: 12
I0116 14:09:03.937441       1 util.go:1534] [meng] calling OnlineAlloX
I0116 14:09:03.937484       1 util.go:1550] [meng] numAvailMachines == 7,  allpods length: 12
I0116 14:09:03.940198       1 util.go:1534] [meng] calling OnlineAlloX
I0116 14:09:03.940248       1 util.go:1550] [meng] numAvailMachines == 7,  allpods length: 12
I0116 14:09:04.043301       1 util.go:1534] [meng] calling OnlineAlloX
I0116 14:09:04.043346       1 util.go:1550] [meng] numAvailMachines == 7,  allpods length: 12
I0116 14:09:04.045961       1 util.go:1534] [meng] calling OnlineAlloX
I0116 14:09:04.046221       1 util.go:1550] [meng] numAvailMachines == 7,  allpods length: 12
I0116 14:09:04.148587       1 util.go:1534] [meng] calling OnlineAlloX
I0116 14:09:04.148631       1 util.go:1550] [meng] numAvailMachines == 7,  allpods length: 12
I0116 14:09:04.151641       1 util.go:1534] [meng] calling OnlineAlloX
I0116 14:09:04.151691       1 util.go:1550] [meng] numAvailMachines == 7,  allpods length: 12
I0116 14:09:04.254599       1 util.go:1534] [meng] calling OnlineAlloX
I0116 14:09:04.254652       1 util.go:1550] [meng] numAvailMachines == 7,  allpods length: 12
I0116 14:09:04.256690       1 util.go:1534] [meng] calling OnlineAlloX
I0116 14:09:04.256734       1 util.go:1550] [meng] numAvailMachines == 7,  allpods length: 12
I0116 14:09:04.359688       1 util.go:1534] [meng] calling OnlineAlloX
I0116 14:09:04.359735       1 util.go:1550] [meng] numAvailMachines == 7,  allpods length: 12
I0116 14:09:04.362539       1 util.go:1534] [meng] calling OnlineAlloX
I0116 14:09:04.362592       1 util.go:1550] [meng] numAvailMachines == 7,  allpods length: 12
I0116 14:09:04.464702       1 util.go:1534] [meng] calling OnlineAlloX
I0116 14:09:04.464740       1 util.go:1550] [meng] numAvailMachines == 7,  allpods length: 12
I0116 14:09:04.467609       1 util.go:1534] [meng] calling OnlineAlloX
I0116 14:09:04.467658       1 util.go:1550] [meng] numAvailMachines == 7,  allpods length: 12
I0116 14:09:04.570495       1 util.go:1534] [meng] calling OnlineAlloX
I0116 14:09:04.570542       1 util.go:1550] [meng] numAvailMachines == 7,  allpods length: 12
I0116 14:09:04.572685       1 util.go:1534] [meng] calling OnlineAlloX
I0116 14:09:04.572723       1 util.go:1550] [meng] numAvailMachines == 7,  allpods length: 12
I0116 14:09:04.675806       1 util.go:1534] [meng] calling OnlineAlloX
I0116 14:09:04.675851       1 util.go:1550] [meng] numAvailMachines == 7,  allpods length: 12
I0116 14:09:04.679238       1 util.go:1534] [meng] calling OnlineAlloX
I0116 14:09:04.679293       1 util.go:1550] [meng] numAvailMachines == 7,  allpods length: 12
I0116 14:09:04.781409       1 util.go:1534] [meng] calling OnlineAlloX
I0116 14:09:04.781456       1 util.go:1550] [meng] numAvailMachines == 7,  allpods length: 12
I0116 14:09:04.784220       1 util.go:1534] [meng] calling OnlineAlloX
I0116 14:09:04.784270       1 util.go:1550] [meng] numAvailMachines == 7,  allpods length: 12
I0116 14:09:04.887062       1 util.go:1534] [meng] calling OnlineAlloX
I0116 14:09:04.887102       1 util.go:1550] [meng] numAvailMachines == 7,  allpods length: 12
I0116 14:09:04.889125       1 util.go:1534] [meng] calling OnlineAlloX
I0116 14:09:04.889159       1 util.go:1550] [meng] numAvailMachines == 7,  allpods length: 12
I0116 14:09:04.992033       1 util.go:1534] [meng] calling OnlineAlloX
I0116 14:09:04.992080       1 util.go:1550] [meng] numAvailMachines == 7,  allpods length: 12
I0116 14:09:04.994835       1 util.go:1534] [meng] calling OnlineAlloX
I0116 14:09:04.994886       1 util.go:1550] [meng] numAvailMachines == 7,  allpods length: 12
I0116 14:09:05.097022       1 util.go:1534] [meng] calling OnlineAlloX
I0116 14:09:05.097066       1 util.go:1550] [meng] numAvailMachines == 7,  allpods length: 12
I0116 14:09:05.099911       1 util.go:1534] [meng] calling OnlineAlloX
I0116 14:09:05.099966       1 util.go:1550] [meng] numAvailMachines == 7,  allpods length: 12
I0116 14:09:05.202839       1 util.go:1534] [meng] calling OnlineAlloX
I0116 14:09:05.202896       1 util.go:1550] [meng] numAvailMachines == 7,  allpods length: 12
I0116 14:09:05.204942       1 util.go:1534] [meng] calling OnlineAlloX
I0116 14:09:05.204989       1 util.go:1550] [meng] numAvailMachines == 7,  allpods length: 12
I0116 14:09:05.307851       1 util.go:1534] [meng] calling OnlineAlloX
I0116 14:09:05.307897       1 util.go:1550] [meng] numAvailMachines == 7,  allpods length: 12
I0116 14:09:05.310752       1 util.go:1534] [meng] calling OnlineAlloX
I0116 14:09:05.310802       1 util.go:1550] [meng] numAvailMachines == 7,  allpods length: 12
I0116 14:09:05.413219       1 util.go:1534] [meng] calling OnlineAlloX
I0116 14:09:05.413266       1 util.go:1550] [meng] numAvailMachines == 7,  allpods length: 12
I0116 14:09:05.415292       1 util.go:1534] [meng] calling OnlineAlloX
I0116 14:09:05.415328       1 util.go:1550] [meng] numAvailMachines == 7,  allpods length: 12
I0116 14:09:05.518633       1 util.go:1534] [meng] calling OnlineAlloX
I0116 14:09:05.518679       1 util.go:1550] [meng] numAvailMachines == 7,  allpods length: 12
I0116 14:09:05.521558       1 util.go:1534] [meng] calling OnlineAlloX
I0116 14:09:05.521616       1 util.go:1550] [meng] numAvailMachines == 7,  allpods length: 12
I0116 14:09:05.623710       1 util.go:1534] [meng] calling OnlineAlloX
I0116 14:09:05.623749       1 util.go:1550] [meng] numAvailMachines == 7,  allpods length: 12
I0116 14:09:05.626819       1 util.go:1534] [meng] calling OnlineAlloX
I0116 14:09:05.626867       1 util.go:1550] [meng] numAvailMachines == 7,  allpods length: 12
I0116 14:09:05.717518       1 factory.go:1129] [meng] deletePodFromCache
I0116 14:09:05.717537       1 factory.go:1136] [meng] JCT: 1m7.740718024s, total jct: 14m11.457552243s, count: 21, average JCT: 40.545597725s
I0116 14:09:05.728544       1 factory.go:798] [meng] computeComplTimeForAllPods completed
I0116 14:09:05.728563       1 factory.go:806] [tanle] Event pod completed user1/user1-pytorch-lenet-4%!(EXTRA v1.PodPhase=Succeeded)
I0116 14:09:05.728589       1 factory.go:1149] [meng] check delete pod user1/user1-pytorch-lenet-4, Running
I0116 14:09:05.728595       1 util.go:143] [meng] UpdateFairScore user1/user1-pytorch-lenet-4, false
I0116 14:09:05.728602       1 util.go:192] [meng] delete PodMachineMap in UpdateFairScore user1/user1-pytorch-lenet-4, false
I0116 14:09:05.728606       1 util.go:196] [tanle] FairScoreMap:  map[user1:0.2500000000000001 user2:0.44444444444444453 user3:0.44444444444444453 user4:0.44444444444444453]
I0116 14:09:05.729617       1 util.go:1534] [meng] calling OnlineAlloX
I0116 14:09:05.729653       1 util.go:1550] [meng] numAvailMachines == 8,  allpods length: 12
I0116 14:09:05.731694       1 util.go:1534] [meng] calling OnlineAlloX
I0116 14:09:05.731729       1 util.go:1550] [meng] numAvailMachines == 8,  allpods length: 12
I0116 14:09:05.834642       1 util.go:1534] [meng] calling OnlineAlloX
I0116 14:09:05.834689       1 util.go:1550] [meng] numAvailMachines == 8,  allpods length: 12
I0116 14:09:05.837684       1 util.go:1534] [meng] calling OnlineAlloX
I0116 14:09:05.837734       1 util.go:1550] [meng] numAvailMachines == 8,  allpods length: 12
I0116 14:09:05.940630       1 util.go:1534] [meng] calling OnlineAlloX
I0116 14:09:05.940678       1 util.go:1550] [meng] numAvailMachines == 8,  allpods length: 12
I0116 14:09:05.942701       1 util.go:1534] [meng] calling OnlineAlloX
I0116 14:09:05.942737       1 util.go:1550] [meng] numAvailMachines == 8,  allpods length: 12
I0116 14:09:06.045743       1 util.go:1534] [meng] calling OnlineAlloX
I0116 14:09:06.045791       1 util.go:1550] [meng] numAvailMachines == 8,  allpods length: 12
I0116 14:09:06.048642       1 util.go:1534] [meng] calling OnlineAlloX
I0116 14:09:06.048694       1 util.go:1550] [meng] numAvailMachines == 8,  allpods length: 12
I0116 14:09:06.150826       1 util.go:1534] [meng] calling OnlineAlloX
I0116 14:09:06.150871       1 util.go:1550] [meng] numAvailMachines == 8,  allpods length: 12
I0116 14:09:06.153789       1 util.go:1534] [meng] calling OnlineAlloX
I0116 14:09:06.153842       1 util.go:1550] [meng] numAvailMachines == 8,  allpods length: 12
I0116 14:09:06.256703       1 util.go:1534] [meng] calling OnlineAlloX
I0116 14:09:06.256752       1 util.go:1550] [meng] numAvailMachines == 8,  allpods length: 12
I0116 14:09:06.258785       1 util.go:1534] [meng] calling OnlineAlloX
I0116 14:09:06.258822       1 util.go:1550] [meng] numAvailMachines == 8,  allpods length: 12
I0116 14:09:06.361788       1 util.go:1534] [meng] calling OnlineAlloX
I0116 14:09:06.361840       1 util.go:1550] [meng] numAvailMachines == 8,  allpods length: 12
I0116 14:09:06.364680       1 util.go:1534] [meng] calling OnlineAlloX
I0116 14:09:06.364733       1 util.go:1550] [meng] numAvailMachines == 8,  allpods length: 12
I0116 14:09:06.382177       1 factory.go:1129] [meng] deletePodFromCache
I0116 14:09:06.382193       1 factory.go:1136] [meng] JCT: 1m8.405373416s, total jct: 15m19.862925659s, count: 22, average JCT: 41.811951166s
I0116 14:09:06.393781       1 factory.go:798] [meng] computeComplTimeForAllPods completed
I0116 14:09:06.393835       1 factory.go:806] [tanle] Event pod completed user4/user4-pytorch-lenet-4%!(EXTRA v1.PodPhase=Succeeded)
I0116 14:09:06.393866       1 factory.go:1149] [meng] check delete pod user4/user4-pytorch-lenet-4, Running
I0116 14:09:06.393981       1 util.go:143] [meng] UpdateFairScore user4/user4-pytorch-lenet-4, false
I0116 14:09:06.394138       1 util.go:192] [meng] delete PodMachineMap in UpdateFairScore user4/user4-pytorch-lenet-4, false
I0116 14:09:06.394153       1 util.go:196] [tanle] FairScoreMap:  map[user3:0.44444444444444453 user4:0.2500000000000001 user1:0.2500000000000001 user2:0.44444444444444453]
I0116 14:09:06.466966       1 util.go:1534] [meng] calling OnlineAlloX
I0116 14:09:06.467017       1 util.go:1550] [meng] numAvailMachines == 9,  allpods length: 12
I0116 14:09:06.469166       1 util.go:1534] [meng] calling OnlineAlloX
I0116 14:09:06.469201       1 util.go:1550] [meng] numAvailMachines == 9,  allpods length: 12
I0116 14:09:06.532176       1 factory.go:1129] [meng] deletePodFromCache
I0116 14:09:06.532190       1 factory.go:1136] [meng] JCT: 1m8.555371485s, total jct: 16m28.418297144s, count: 23, average JCT: 42.974708571s
I0116 14:09:06.542601       1 factory.go:798] [meng] computeComplTimeForAllPods completed
I0116 14:09:06.542621       1 factory.go:806] [tanle] Event pod completed user2/user2-pytorch-lenet-4%!(EXTRA v1.PodPhase=Succeeded)
I0116 14:09:06.542641       1 factory.go:1149] [meng] check delete pod user2/user2-pytorch-lenet-4, Running
I0116 14:09:06.542647       1 util.go:143] [meng] UpdateFairScore user2/user2-pytorch-lenet-4, false
I0116 14:09:06.542653       1 util.go:192] [meng] delete PodMachineMap in UpdateFairScore user2/user2-pytorch-lenet-4, false
I0116 14:09:06.542657       1 util.go:196] [tanle] FairScoreMap:  map[user4:0.2500000000000001 user1:0.2500000000000001 user2:0.2500000000000001 user3:0.44444444444444453]
I0116 14:09:06.572519       1 util.go:1534] [meng] calling OnlineAlloX
I0116 14:09:06.572557       1 util.go:1550] [meng] numAvailMachines == 10,  allpods length: 12
I0116 14:09:06.575510       1 util.go:1534] [meng] calling OnlineAlloX
I0116 14:09:06.575558       1 util.go:1550] [meng] numAvailMachines == 10,  allpods length: 12
I0116 14:09:06.678077       1 util.go:1534] [meng] calling OnlineAlloX
I0116 14:09:06.678122       1 util.go:1550] [meng] numAvailMachines == 10,  allpods length: 12
I0116 14:09:06.680160       1 util.go:1534] [meng] calling OnlineAlloX
I0116 14:09:06.680196       1 util.go:1550] [meng] numAvailMachines == 10,  allpods length: 12
I0116 14:09:06.783242       1 util.go:1534] [meng] calling OnlineAlloX
I0116 14:09:06.783292       1 util.go:1550] [meng] numAvailMachines == 10,  allpods length: 12
I0116 14:09:06.786087       1 util.go:1534] [meng] calling OnlineAlloX
I0116 14:09:06.786227       1 util.go:1550] [meng] numAvailMachines == 10,  allpods length: 12
I0116 14:09:06.888799       1 util.go:1534] [meng] calling OnlineAlloX
I0116 14:09:06.888865       1 util.go:1550] [meng] numAvailMachines == 10,  allpods length: 12
I0116 14:09:06.892280       1 util.go:1534] [meng] calling OnlineAlloX
I0116 14:09:06.892337       1 util.go:1550] [meng] numAvailMachines == 10,  allpods length: 12
I0116 14:09:06.995390       1 util.go:1534] [meng] calling OnlineAlloX
I0116 14:09:06.995436       1 util.go:1550] [meng] numAvailMachines == 10,  allpods length: 12
I0116 14:09:06.997802       1 util.go:1534] [meng] calling OnlineAlloX
I0116 14:09:06.997839       1 util.go:1550] [meng] numAvailMachines == 10,  allpods length: 12
I0116 14:09:07.100905       1 util.go:1534] [meng] calling OnlineAlloX
I0116 14:09:07.100952       1 util.go:1550] [meng] numAvailMachines == 10,  allpods length: 12
I0116 14:09:07.103934       1 util.go:1534] [meng] calling OnlineAlloX
I0116 14:09:07.103987       1 util.go:1550] [meng] numAvailMachines == 10,  allpods length: 12
I0116 14:09:07.206364       1 util.go:1534] [meng] calling OnlineAlloX
I0116 14:09:07.206399       1 util.go:1550] [meng] numAvailMachines == 10,  allpods length: 12
I0116 14:09:07.209422       1 util.go:1534] [meng] calling OnlineAlloX
I0116 14:09:07.209469       1 util.go:1550] [meng] numAvailMachines == 10,  allpods length: 12
I0116 14:09:07.312528       1 util.go:1534] [meng] calling OnlineAlloX
I0116 14:09:07.312573       1 util.go:1550] [meng] numAvailMachines == 10,  allpods length: 12
I0116 14:09:07.314798       1 util.go:1534] [meng] calling OnlineAlloX
I0116 14:09:07.314832       1 util.go:1550] [meng] numAvailMachines == 10,  allpods length: 12
I0116 14:09:07.417896       1 util.go:1534] [meng] calling OnlineAlloX
I0116 14:09:07.417939       1 util.go:1550] [meng] numAvailMachines == 10,  allpods length: 12
I0116 14:09:07.420968       1 util.go:1534] [meng] calling OnlineAlloX
I0116 14:09:07.421015       1 util.go:1550] [meng] numAvailMachines == 10,  allpods length: 12
I0116 14:09:07.523262       1 util.go:1534] [meng] calling OnlineAlloX
I0116 14:09:07.523307       1 util.go:1550] [meng] numAvailMachines == 10,  allpods length: 12
I0116 14:09:07.526393       1 util.go:1534] [meng] calling OnlineAlloX
I0116 14:09:07.526447       1 util.go:1550] [meng] numAvailMachines == 10,  allpods length: 12
I0116 14:09:07.629452       1 util.go:1534] [meng] calling OnlineAlloX
I0116 14:09:07.629501       1 util.go:1550] [meng] numAvailMachines == 10,  allpods length: 12
I0116 14:09:07.631752       1 util.go:1534] [meng] calling OnlineAlloX
I0116 14:09:07.631904       1 util.go:1550] [meng] numAvailMachines == 10,  allpods length: 12
I0116 14:09:07.734683       1 util.go:1534] [meng] calling OnlineAlloX
I0116 14:09:07.734729       1 util.go:1550] [meng] numAvailMachines == 10,  allpods length: 12
I0116 14:09:07.737783       1 util.go:1534] [meng] calling OnlineAlloX
I0116 14:09:07.737834       1 util.go:1550] [meng] numAvailMachines == 10,  allpods length: 12
I0116 14:09:07.840807       1 util.go:1534] [meng] calling OnlineAlloX
I0116 14:09:07.840854       1 util.go:1550] [meng] numAvailMachines == 10,  allpods length: 12
I0116 14:09:07.842994       1 util.go:1534] [meng] calling OnlineAlloX
I0116 14:09:07.843028       1 util.go:1550] [meng] numAvailMachines == 10,  allpods length: 12
I0116 14:09:07.946136       1 util.go:1534] [meng] calling OnlineAlloX
I0116 14:09:07.946184       1 util.go:1550] [meng] numAvailMachines == 10,  allpods length: 12
I0116 14:09:07.949024       1 util.go:1534] [meng] calling OnlineAlloX
I0116 14:09:07.949078       1 util.go:1550] [meng] numAvailMachines == 10,  allpods length: 12
I0116 14:09:08.051280       1 util.go:1534] [meng] calling OnlineAlloX
I0116 14:09:08.051322       1 util.go:1550] [meng] numAvailMachines == 10,  allpods length: 12
I0116 14:09:08.054199       1 util.go:1534] [meng] calling OnlineAlloX
I0116 14:09:08.054251       1 util.go:1550] [meng] numAvailMachines == 10,  allpods length: 12
I0116 14:09:08.157123       1 util.go:1534] [meng] calling OnlineAlloX
I0116 14:09:08.157169       1 util.go:1550] [meng] numAvailMachines == 10,  allpods length: 12
I0116 14:09:08.159238       1 util.go:1534] [meng] calling OnlineAlloX
I0116 14:09:08.159271       1 util.go:1550] [meng] numAvailMachines == 10,  allpods length: 12
I0116 14:09:08.262217       1 util.go:1534] [meng] calling OnlineAlloX
I0116 14:09:08.262266       1 util.go:1550] [meng] numAvailMachines == 10,  allpods length: 12
I0116 14:09:08.265182       1 util.go:1534] [meng] calling OnlineAlloX
I0116 14:09:08.265238       1 util.go:1550] [meng] numAvailMachines == 10,  allpods length: 12
I0116 14:09:08.367390       1 util.go:1534] [meng] calling OnlineAlloX
I0116 14:09:08.367434       1 util.go:1550] [meng] numAvailMachines == 10,  allpods length: 12
I0116 14:09:08.370381       1 util.go:1534] [meng] calling OnlineAlloX
I0116 14:09:08.370433       1 util.go:1550] [meng] numAvailMachines == 10,  allpods length: 12
I0116 14:09:08.473391       1 util.go:1534] [meng] calling OnlineAlloX
I0116 14:09:08.473437       1 util.go:1550] [meng] numAvailMachines == 10,  allpods length: 12
I0116 14:09:08.475510       1 util.go:1534] [meng] calling OnlineAlloX
I0116 14:09:08.475544       1 util.go:1550] [meng] numAvailMachines == 10,  allpods length: 12
I0116 14:09:08.578509       1 util.go:1534] [meng] calling OnlineAlloX
I0116 14:09:08.578556       1 util.go:1550] [meng] numAvailMachines == 10,  allpods length: 12
I0116 14:09:08.581421       1 util.go:1534] [meng] calling OnlineAlloX
I0116 14:09:08.581471       1 util.go:1550] [meng] numAvailMachines == 10,  allpods length: 12
I0116 14:09:08.683618       1 util.go:1534] [meng] calling OnlineAlloX
I0116 14:09:08.683654       1 util.go:1550] [meng] numAvailMachines == 10,  allpods length: 12
I0116 14:09:08.686492       1 util.go:1534] [meng] calling OnlineAlloX
I0116 14:09:08.686547       1 util.go:1550] [meng] numAvailMachines == 10,  allpods length: 12
I0116 14:09:08.789561       1 util.go:1534] [meng] calling OnlineAlloX
I0116 14:09:08.789611       1 util.go:1550] [meng] numAvailMachines == 10,  allpods length: 12
I0116 14:09:08.792287       1 util.go:1534] [meng] calling OnlineAlloX
I0116 14:09:08.792336       1 util.go:1550] [meng] numAvailMachines == 10,  allpods length: 12
I0116 14:09:08.894476       1 util.go:1534] [meng] calling OnlineAlloX
I0116 14:09:08.894528       1 util.go:1550] [meng] numAvailMachines == 10,  allpods length: 12
I0116 14:09:08.897292       1 util.go:1534] [meng] calling OnlineAlloX
I0116 14:09:08.897342       1 util.go:1550] [meng] numAvailMachines == 10,  allpods length: 12
I0116 14:09:09.000398       1 util.go:1534] [meng] calling OnlineAlloX
I0116 14:09:09.000445       1 util.go:1550] [meng] numAvailMachines == 10,  allpods length: 12
I0116 14:09:09.002554       1 util.go:1534] [meng] calling OnlineAlloX
I0116 14:09:09.002589       1 util.go:1550] [meng] numAvailMachines == 10,  allpods length: 12
I0116 14:09:09.105632       1 util.go:1534] [meng] calling OnlineAlloX
I0116 14:09:09.105677       1 util.go:1550] [meng] numAvailMachines == 10,  allpods length: 12
I0116 14:09:09.108593       1 util.go:1534] [meng] calling OnlineAlloX
I0116 14:09:09.108640       1 util.go:1550] [meng] numAvailMachines == 10,  allpods length: 12
I0116 14:09:09.210780       1 util.go:1534] [meng] calling OnlineAlloX
I0116 14:09:09.210822       1 util.go:1550] [meng] numAvailMachines == 10,  allpods length: 12
I0116 14:09:09.213689       1 util.go:1534] [meng] calling OnlineAlloX
I0116 14:09:09.213741       1 util.go:1550] [meng] numAvailMachines == 10,  allpods length: 12
I0116 14:09:09.316702       1 util.go:1534] [meng] calling OnlineAlloX
I0116 14:09:09.316748       1 util.go:1550] [meng] numAvailMachines == 10,  allpods length: 12
I0116 14:09:09.318800       1 util.go:1534] [meng] calling OnlineAlloX
I0116 14:09:09.318835       1 util.go:1550] [meng] numAvailMachines == 10,  allpods length: 12
I0116 14:09:09.404073       1 factory.go:1129] [meng] deletePodFromCache
I0116 14:09:09.404083       1 factory.go:1136] [meng] JCT: 1m11.427264041s, total jct: 17m39.845561185s, count: 24, average JCT: 44.160231716s
I0116 14:09:09.417932       1 factory.go:798] [meng] computeComplTimeForAllPods completed
I0116 14:09:09.417959       1 factory.go:806] [tanle] Event pod completed user3/user3-pytorch-resnet34%!(EXTRA v1.PodPhase=Succeeded)
I0116 14:09:09.417980       1 factory.go:1149] [meng] check delete pod user3/user3-pytorch-resnet34, Running
I0116 14:09:09.417986       1 util.go:143] [meng] UpdateFairScore user3/user3-pytorch-resnet34, false
I0116 14:09:09.417993       1 util.go:192] [meng] delete PodMachineMap in UpdateFairScore user3/user3-pytorch-resnet34, false
I0116 14:09:09.417998       1 util.go:196] [tanle] FairScoreMap:  map[user1:0.2500000000000001 user2:0.2500000000000001 user3:0.19444444444444453 user4:0.2500000000000001]
I0116 14:09:09.421769       1 util.go:1534] [meng] calling OnlineAlloX
I0116 14:09:09.421805       1 util.go:1550] [meng] numAvailMachines == 11,  allpods length: 12
I0116 14:09:09.424973       1 util.go:196] [tanle] FairScoreMap:  map[user4:0.2500000000000001 user1:0.2500000000000001 user2:0.5000000000000001 user3:0.19444444444444453]
I0116 14:09:09.427112       1 scheduler.go:406] [tanle] binding user2/user2-pytorch-alexnet on GPU true-->meng-allox-egpu-4
I0116 14:09:09.444338       1 factory.go:1129] [meng] deletePodFromCache
I0116 14:09:09.444347       1 factory.go:1136] [meng] JCT: 1m11.467528568s, total jct: 18m51.313089753s, count: 25, average JCT: 45.25252359s
I0116 14:09:09.454511       1 factory.go:798] [meng] computeComplTimeForAllPods completed
I0116 14:09:09.454533       1 factory.go:806] [tanle] Event pod completed user4/user4-pytorch-resnet34%!(EXTRA v1.PodPhase=Succeeded)
I0116 14:09:09.454551       1 factory.go:1149] [meng] check delete pod user4/user4-pytorch-resnet34, Running
I0116 14:09:09.454558       1 util.go:143] [meng] UpdateFairScore user4/user4-pytorch-resnet34, false
I0116 14:09:09.454564       1 util.go:192] [meng] delete PodMachineMap in UpdateFairScore user4/user4-pytorch-resnet34, false
I0116 14:09:09.454569       1 util.go:196] [tanle] FairScoreMap:  map[user1:0.2500000000000001 user2:0.5000000000000001 user3:0.19444444444444453 user4:1.1102230246251565e-16]
I0116 14:09:09.525127       1 util.go:1534] [meng] calling OnlineAlloX
I0116 14:09:09.525153       1 util.go:1550] [meng] numAvailMachines == 11,  allpods length: 11
I0116 14:09:09.528308       1 util.go:196] [tanle] FairScoreMap:  map[user1:0.5000000000000001 user2:0.5000000000000001 user3:0.19444444444444453 user4:1.1102230246251565e-16]
I0116 14:09:09.530589       1 scheduler.go:406] [tanle] binding user1/user1-pytorch-alexnet on GPU true-->meng-allox-egpu-1
I0116 14:09:09.628457       1 util.go:1534] [meng] calling OnlineAlloX
I0116 14:09:09.628484       1 util.go:1550] [meng] numAvailMachines == 10,  allpods length: 10
I0116 14:09:09.630983       1 util.go:1534] [meng] calling OnlineAlloX
I0116 14:09:09.631031       1 util.go:1550] [meng] numAvailMachines == 10,  allpods length: 10
I0116 14:09:09.682424       1 factory.go:1129] [meng] deletePodFromCache
I0116 14:09:09.682437       1 factory.go:1136] [meng] JCT: 1m11.705618213s, total jct: 20m3.018707966s, count: 26, average JCT: 46.269950306s
I0116 14:09:09.692466       1 factory.go:798] [meng] computeComplTimeForAllPods completed
I0116 14:09:09.692484       1 factory.go:806] [tanle] Event pod completed user2/user2-pytorch-resnet34%!(EXTRA v1.PodPhase=Succeeded)
I0116 14:09:09.692501       1 factory.go:1149] [meng] check delete pod user2/user2-pytorch-resnet34, Running
I0116 14:09:09.692507       1 util.go:143] [meng] UpdateFairScore user2/user2-pytorch-resnet34, false
I0116 14:09:09.692513       1 util.go:192] [meng] delete PodMachineMap in UpdateFairScore user2/user2-pytorch-resnet34, false
I0116 14:09:09.692518       1 util.go:196] [tanle] FairScoreMap:  map[user1:0.5000000000000001 user2:0.2500000000000001 user3:0.19444444444444453 user4:1.1102230246251565e-16]
I0116 14:09:09.732508       1 util.go:1534] [meng] calling OnlineAlloX
I0116 14:09:09.732540       1 util.go:1550] [meng] numAvailMachines == 11,  allpods length: 10
I0116 14:09:09.735025       1 util.go:196] [tanle] FairScoreMap:  map[user1:0.5000000000000001 user2:0.2500000000000001 user3:0.44444444444444453 user4:1.1102230246251565e-16]
I0116 14:09:09.737128       1 scheduler.go:406] [tanle] binding user3/user3-pytorch-alexnet on GPU true-->meng-allox-egpu-3
I0116 14:09:09.835203       1 util.go:1534] [meng] calling OnlineAlloX
I0116 14:09:09.835240       1 util.go:1550] [meng] numAvailMachines == 10,  allpods length: 9
I0116 14:09:09.836247       1 util.go:1534] [meng] calling OnlineAlloX
I0116 14:09:09.836281       1 util.go:1550] [meng] numAvailMachines == 10,  allpods length: 9
I0116 14:09:09.938500       1 util.go:1534] [meng] calling OnlineAlloX
I0116 14:09:09.938551       1 util.go:1550] [meng] numAvailMachines == 10,  allpods length: 9
I0116 14:09:09.939562       1 util.go:1534] [meng] calling OnlineAlloX
I0116 14:09:09.939597       1 util.go:1550] [meng] numAvailMachines == 10,  allpods length: 9
I0116 14:09:10.040692       1 util.go:1534] [meng] calling OnlineAlloX
I0116 14:09:10.040729       1 util.go:1550] [meng] numAvailMachines == 10,  allpods length: 9
I0116 14:09:10.042448       1 util.go:1534] [meng] calling OnlineAlloX
I0116 14:09:10.042502       1 util.go:1550] [meng] numAvailMachines == 10,  allpods length: 9
I0116 14:09:10.043010       1 factory.go:1129] [meng] deletePodFromCache
I0116 14:09:10.043022       1 factory.go:1136] [meng] JCT: 1m12.066203393s, total jct: 21m15.084911359s, count: 27, average JCT: 47.225367087s
I0116 14:09:10.056113       1 factory.go:798] [meng] computeComplTimeForAllPods completed
I0116 14:09:10.056136       1 factory.go:806] [tanle] Event pod completed user1/user1-pytorch-resnet34%!(EXTRA v1.PodPhase=Succeeded)
I0116 14:09:10.056160       1 factory.go:1149] [meng] check delete pod user1/user1-pytorch-resnet34, Running
I0116 14:09:10.056165       1 util.go:143] [meng] UpdateFairScore user1/user1-pytorch-resnet34, false
I0116 14:09:10.056171       1 util.go:192] [meng] delete PodMachineMap in UpdateFairScore user1/user1-pytorch-resnet34, false
I0116 14:09:10.056175       1 util.go:196] [tanle] FairScoreMap:  map[user4:1.1102230246251565e-16 user1:0.2500000000000001 user2:0.2500000000000001 user3:0.44444444444444453]
I0116 14:09:10.143596       1 util.go:1534] [meng] calling OnlineAlloX
I0116 14:09:10.143633       1 util.go:1550] [meng] numAvailMachines == 11,  allpods length: 9
I0116 14:09:10.145167       1 util.go:196] [tanle] FairScoreMap:  map[user1:0.2500000000000001 user2:0.2500000000000001 user3:0.44444444444444453 user4:0.2500000000000001]
I0116 14:09:10.147219       1 scheduler.go:406] [tanle] binding user4/user4-pytorch-alexnet on GPU true-->meng-allox-egpu-2
I0116 14:09:10.245613       1 util.go:1534] [meng] calling OnlineAlloX
I0116 14:09:10.245653       1 util.go:1550] [meng] numAvailMachines == 10,  allpods length: 8
I0116 14:09:10.246433       1 util.go:1534] [meng] calling OnlineAlloX
I0116 14:09:10.246466       1 util.go:1550] [meng] numAvailMachines == 10,  allpods length: 8
I0116 14:09:10.347290       1 util.go:1534] [meng] calling OnlineAlloX
I0116 14:09:10.347326       1 util.go:1550] [meng] numAvailMachines == 10,  allpods length: 8
I0116 14:09:10.348785       1 util.go:1534] [meng] calling OnlineAlloX
I0116 14:09:10.348837       1 util.go:1550] [meng] numAvailMachines == 10,  allpods length: 8
I0116 14:09:10.450070       1 util.go:1534] [meng] calling OnlineAlloX
I0116 14:09:10.450106       1 util.go:1550] [meng] numAvailMachines == 10,  allpods length: 8
I0116 14:09:10.450881       1 util.go:1534] [meng] calling OnlineAlloX
I0116 14:09:10.450912       1 util.go:1550] [meng] numAvailMachines == 10,  allpods length: 8
I0116 14:09:10.551745       1 util.go:1534] [meng] calling OnlineAlloX
I0116 14:09:10.551782       1 util.go:1550] [meng] numAvailMachines == 10,  allpods length: 8
I0116 14:09:10.552928       1 util.go:1534] [meng] calling OnlineAlloX
I0116 14:09:10.553058       1 util.go:1550] [meng] numAvailMachines == 10,  allpods length: 8
I0116 14:09:10.654675       1 util.go:1534] [meng] calling OnlineAlloX
I0116 14:09:10.654719       1 util.go:1550] [meng] numAvailMachines == 10,  allpods length: 8
I0116 14:09:10.655502       1 util.go:1534] [meng] calling OnlineAlloX
I0116 14:09:10.655534       1 util.go:1550] [meng] numAvailMachines == 10,  allpods length: 8
I0116 14:09:10.756356       1 util.go:1534] [meng] calling OnlineAlloX
I0116 14:09:10.756388       1 util.go:1550] [meng] numAvailMachines == 10,  allpods length: 8
I0116 14:09:10.757157       1 util.go:1534] [meng] calling OnlineAlloX
I0116 14:09:10.757187       1 util.go:1550] [meng] numAvailMachines == 10,  allpods length: 8
I0116 14:09:10.858832       1 util.go:1534] [meng] calling OnlineAlloX
I0116 14:09:10.858879       1 util.go:1550] [meng] numAvailMachines == 10,  allpods length: 8
I0116 14:09:10.859666       1 util.go:1534] [meng] calling OnlineAlloX
I0116 14:09:10.859703       1 util.go:1550] [meng] numAvailMachines == 10,  allpods length: 8
I0116 14:09:10.960543       1 util.go:1534] [meng] calling OnlineAlloX
I0116 14:09:10.960588       1 util.go:1550] [meng] numAvailMachines == 10,  allpods length: 8
I0116 14:09:10.961411       1 util.go:1534] [meng] calling OnlineAlloX
I0116 14:09:10.961451       1 util.go:1550] [meng] numAvailMachines == 10,  allpods length: 8
I0116 14:09:11.063090       1 util.go:1534] [meng] calling OnlineAlloX
I0116 14:09:11.063129       1 util.go:1550] [meng] numAvailMachines == 10,  allpods length: 8
I0116 14:09:11.063907       1 util.go:1534] [meng] calling OnlineAlloX
I0116 14:09:11.063940       1 util.go:1550] [meng] numAvailMachines == 10,  allpods length: 8
I0116 14:09:11.164773       1 util.go:1534] [meng] calling OnlineAlloX
I0116 14:09:11.164812       1 util.go:1550] [meng] numAvailMachines == 10,  allpods length: 8
I0116 14:09:11.165575       1 util.go:1534] [meng] calling OnlineAlloX
I0116 14:09:11.165617       1 util.go:1550] [meng] numAvailMachines == 10,  allpods length: 8
I0116 14:09:11.266457       1 util.go:1534] [meng] calling OnlineAlloX
I0116 14:09:11.266629       1 util.go:1550] [meng] numAvailMachines == 10,  allpods length: 8
I0116 14:09:11.268429       1 util.go:1534] [meng] calling OnlineAlloX
I0116 14:09:11.268473       1 util.go:1550] [meng] numAvailMachines == 10,  allpods length: 8
I0116 14:09:11.369307       1 util.go:1534] [meng] calling OnlineAlloX
I0116 14:09:11.369344       1 util.go:1550] [meng] numAvailMachines == 10,  allpods length: 8
I0116 14:09:11.370096       1 util.go:1534] [meng] calling OnlineAlloX
I0116 14:09:11.370129       1 util.go:1550] [meng] numAvailMachines == 10,  allpods length: 8
I0116 14:09:11.470962       1 util.go:1534] [meng] calling OnlineAlloX
I0116 14:09:11.471001       1 util.go:1550] [meng] numAvailMachines == 10,  allpods length: 8
I0116 14:09:11.472467       1 util.go:1534] [meng] calling OnlineAlloX
I0116 14:09:11.472519       1 util.go:1550] [meng] numAvailMachines == 10,  allpods length: 8
I0116 14:09:11.573397       1 util.go:1534] [meng] calling OnlineAlloX
I0116 14:09:11.573458       1 util.go:1550] [meng] numAvailMachines == 10,  allpods length: 8
I0116 14:09:11.574341       1 util.go:1534] [meng] calling OnlineAlloX
I0116 14:09:11.574381       1 util.go:1550] [meng] numAvailMachines == 10,  allpods length: 8
I0116 14:09:11.675309       1 util.go:1534] [meng] calling OnlineAlloX
I0116 14:09:11.675366       1 util.go:1550] [meng] numAvailMachines == 10,  allpods length: 8
I0116 14:09:11.676212       1 util.go:1534] [meng] calling OnlineAlloX
I0116 14:09:11.676246       1 util.go:1550] [meng] numAvailMachines == 10,  allpods length: 8
I0116 14:09:11.777138       1 util.go:1534] [meng] calling OnlineAlloX
I0116 14:09:11.777185       1 util.go:1550] [meng] numAvailMachines == 10,  allpods length: 8
I0116 14:09:11.778055       1 util.go:1534] [meng] calling OnlineAlloX
I0116 14:09:11.778093       1 util.go:1550] [meng] numAvailMachines == 10,  allpods length: 8
I0116 14:09:11.880176       1 util.go:1534] [meng] calling OnlineAlloX
I0116 14:09:11.880218       1 util.go:1550] [meng] numAvailMachines == 10,  allpods length: 8
I0116 14:09:11.881064       1 util.go:1534] [meng] calling OnlineAlloX
I0116 14:09:11.881096       1 util.go:1550] [meng] numAvailMachines == 10,  allpods length: 8
I0116 14:09:11.982008       1 util.go:1534] [meng] calling OnlineAlloX
I0116 14:09:11.982045       1 util.go:1550] [meng] numAvailMachines == 10,  allpods length: 8
I0116 14:09:11.983666       1 util.go:1534] [meng] calling OnlineAlloX
I0116 14:09:11.983721       1 util.go:1550] [meng] numAvailMachines == 10,  allpods length: 8
I0116 14:09:12.084634       1 util.go:1534] [meng] calling OnlineAlloX
I0116 14:09:12.084673       1 util.go:1550] [meng] numAvailMachines == 10,  allpods length: 8
I0116 14:09:12.085513       1 util.go:1534] [meng] calling OnlineAlloX
I0116 14:09:12.085550       1 util.go:1550] [meng] numAvailMachines == 10,  allpods length: 8
I0116 14:09:12.186459       1 util.go:1534] [meng] calling OnlineAlloX
I0116 14:09:12.186500       1 util.go:1550] [meng] numAvailMachines == 10,  allpods length: 8
I0116 14:09:12.187323       1 util.go:1534] [meng] calling OnlineAlloX
I0116 14:09:12.187358       1 util.go:1550] [meng] numAvailMachines == 10,  allpods length: 8
I0116 14:09:12.289040       1 util.go:1534] [meng] calling OnlineAlloX
I0116 14:09:12.289085       1 util.go:1550] [meng] numAvailMachines == 10,  allpods length: 8
I0116 14:09:12.289917       1 util.go:1534] [meng] calling OnlineAlloX
I0116 14:09:12.289952       1 util.go:1550] [meng] numAvailMachines == 10,  allpods length: 8
I0116 14:09:12.390849       1 util.go:1534] [meng] calling OnlineAlloX
I0116 14:09:12.390890       1 util.go:1550] [meng] numAvailMachines == 10,  allpods length: 8
I0116 14:09:12.391920       1 util.go:1534] [meng] calling OnlineAlloX
I0116 14:09:12.392098       1 util.go:1550] [meng] numAvailMachines == 10,  allpods length: 8
I0116 14:09:12.493445       1 util.go:1534] [meng] calling OnlineAlloX
I0116 14:09:12.493490       1 util.go:1550] [meng] numAvailMachines == 10,  allpods length: 8
I0116 14:09:12.494300       1 util.go:1534] [meng] calling OnlineAlloX
I0116 14:09:12.494334       1 util.go:1550] [meng] numAvailMachines == 10,  allpods length: 8
I0116 14:09:12.595209       1 util.go:1534] [meng] calling OnlineAlloX
I0116 14:09:12.595244       1 util.go:1550] [meng] numAvailMachines == 10,  allpods length: 8
I0116 14:09:12.596056       1 util.go:1534] [meng] calling OnlineAlloX
I0116 14:09:12.596087       1 util.go:1550] [meng] numAvailMachines == 10,  allpods length: 8
I0116 14:09:12.697738       1 util.go:1534] [meng] calling OnlineAlloX
I0116 14:09:12.697785       1 util.go:1550] [meng] numAvailMachines == 10,  allpods length: 8
I0116 14:09:12.698581       1 util.go:1534] [meng] calling OnlineAlloX
I0116 14:09:12.698613       1 util.go:1550] [meng] numAvailMachines == 10,  allpods length: 8
I0116 14:09:12.799491       1 util.go:1534] [meng] calling OnlineAlloX
I0116 14:09:12.799530       1 util.go:1550] [meng] numAvailMachines == 10,  allpods length: 8
I0116 14:09:12.800339       1 util.go:1534] [meng] calling OnlineAlloX
I0116 14:09:12.800370       1 util.go:1550] [meng] numAvailMachines == 10,  allpods length: 8
I0116 14:09:12.901679       1 util.go:1534] [meng] calling OnlineAlloX
I0116 14:09:12.901726       1 util.go:1550] [meng] numAvailMachines == 10,  allpods length: 8
I0116 14:09:12.902544       1 util.go:1534] [meng] calling OnlineAlloX
I0116 14:09:12.902580       1 util.go:1550] [meng] numAvailMachines == 10,  allpods length: 8
I0116 14:09:13.003477       1 util.go:1534] [meng] calling OnlineAlloX
I0116 14:09:13.003518       1 util.go:1550] [meng] numAvailMachines == 10,  allpods length: 8
I0116 14:09:13.004308       1 util.go:1534] [meng] calling OnlineAlloX
I0116 14:09:13.004340       1 util.go:1550] [meng] numAvailMachines == 10,  allpods length: 8
I0116 14:09:13.105234       1 util.go:1534] [meng] calling OnlineAlloX
I0116 14:09:13.105271       1 util.go:1550] [meng] numAvailMachines == 10,  allpods length: 8
I0116 14:09:13.106832       1 util.go:1534] [meng] calling OnlineAlloX
I0116 14:09:13.106884       1 util.go:1550] [meng] numAvailMachines == 10,  allpods length: 8
I0116 14:09:13.207823       1 util.go:1534] [meng] calling OnlineAlloX
I0116 14:09:13.207860       1 util.go:1550] [meng] numAvailMachines == 10,  allpods length: 8
I0116 14:09:13.208692       1 util.go:1534] [meng] calling OnlineAlloX
I0116 14:09:13.208728       1 util.go:1550] [meng] numAvailMachines == 10,  allpods length: 8
I0116 14:09:13.309616       1 util.go:1534] [meng] calling OnlineAlloX
I0116 14:09:13.309653       1 util.go:1550] [meng] numAvailMachines == 10,  allpods length: 8
I0116 14:09:13.311251       1 util.go:1534] [meng] calling OnlineAlloX
I0116 14:09:13.311303       1 util.go:1550] [meng] numAvailMachines == 10,  allpods length: 8
I0116 14:09:13.412210       1 util.go:1534] [meng] calling OnlineAlloX
I0116 14:09:13.412252       1 util.go:1550] [meng] numAvailMachines == 10,  allpods length: 8
I0116 14:09:13.413038       1 util.go:1534] [meng] calling OnlineAlloX
I0116 14:09:13.413072       1 util.go:1550] [meng] numAvailMachines == 10,  allpods length: 8
I0116 14:09:13.513941       1 util.go:1534] [meng] calling OnlineAlloX
I0116 14:09:13.513979       1 util.go:1550] [meng] numAvailMachines == 10,  allpods length: 8
I0116 14:09:13.515083       1 util.go:1534] [meng] calling OnlineAlloX
I0116 14:09:13.515161       1 util.go:1550] [meng] numAvailMachines == 10,  allpods length: 8
I0116 14:09:13.616573       1 util.go:1534] [meng] calling OnlineAlloX
I0116 14:09:13.616617       1 util.go:1550] [meng] numAvailMachines == 10,  allpods length: 8
I0116 14:09:13.617397       1 util.go:1534] [meng] calling OnlineAlloX
I0116 14:09:13.617430       1 util.go:1550] [meng] numAvailMachines == 10,  allpods length: 8
I0116 14:09:13.718280       1 util.go:1534] [meng] calling OnlineAlloX
I0116 14:09:13.718313       1 util.go:1550] [meng] numAvailMachines == 10,  allpods length: 8
I0116 14:09:13.719087       1 util.go:1534] [meng] calling OnlineAlloX
I0116 14:09:13.719119       1 util.go:1550] [meng] numAvailMachines == 10,  allpods length: 8
I0116 14:09:13.820757       1 util.go:1534] [meng] calling OnlineAlloX
I0116 14:09:13.820801       1 util.go:1550] [meng] numAvailMachines == 10,  allpods length: 8
I0116 14:09:13.821572       1 util.go:1534] [meng] calling OnlineAlloX
I0116 14:09:13.821614       1 util.go:1550] [meng] numAvailMachines == 10,  allpods length: 8
I0116 14:09:13.922456       1 util.go:1534] [meng] calling OnlineAlloX
I0116 14:09:13.922503       1 util.go:1550] [meng] numAvailMachines == 10,  allpods length: 8
I0116 14:09:13.923283       1 util.go:1534] [meng] calling OnlineAlloX
I0116 14:09:13.923323       1 util.go:1550] [meng] numAvailMachines == 10,  allpods length: 8
I0116 14:09:14.024618       1 util.go:1534] [meng] calling OnlineAlloX
I0116 14:09:14.024665       1 util.go:1550] [meng] numAvailMachines == 10,  allpods length: 8
I0116 14:09:14.025433       1 util.go:1534] [meng] calling OnlineAlloX
I0116 14:09:14.025466       1 util.go:1550] [meng] numAvailMachines == 10,  allpods length: 8
I0116 14:09:14.126316       1 util.go:1534] [meng] calling OnlineAlloX
I0116 14:09:14.126356       1 util.go:1550] [meng] numAvailMachines == 10,  allpods length: 8
I0116 14:09:14.127126       1 util.go:1534] [meng] calling OnlineAlloX
I0116 14:09:14.127158       1 util.go:1550] [meng] numAvailMachines == 10,  allpods length: 8
I0116 14:09:14.227991       1 util.go:1534] [meng] calling OnlineAlloX
I0116 14:09:14.228022       1 util.go:1550] [meng] numAvailMachines == 10,  allpods length: 8
I0116 14:09:14.229483       1 util.go:1534] [meng] calling OnlineAlloX
I0116 14:09:14.229543       1 util.go:1550] [meng] numAvailMachines == 10,  allpods length: 8
I0116 14:09:14.330664       1 util.go:1534] [meng] calling OnlineAlloX
I0116 14:09:14.330703       1 util.go:1550] [meng] numAvailMachines == 10,  allpods length: 8
I0116 14:09:14.331481       1 util.go:1534] [meng] calling OnlineAlloX
I0116 14:09:14.331517       1 util.go:1550] [meng] numAvailMachines == 10,  allpods length: 8
I0116 14:09:14.432367       1 util.go:1534] [meng] calling OnlineAlloX
I0116 14:09:14.432410       1 util.go:1550] [meng] numAvailMachines == 10,  allpods length: 8
I0116 14:09:14.433801       1 util.go:1534] [meng] calling OnlineAlloX
I0116 14:09:14.434061       1 util.go:1550] [meng] numAvailMachines == 10,  allpods length: 8
I0116 14:09:14.534980       1 util.go:1534] [meng] calling OnlineAlloX
I0116 14:09:14.535024       1 util.go:1550] [meng] numAvailMachines == 10,  allpods length: 8
I0116 14:09:14.535794       1 util.go:1534] [meng] calling OnlineAlloX
I0116 14:09:14.535830       1 util.go:1550] [meng] numAvailMachines == 10,  allpods length: 8
I0116 14:09:14.636659       1 util.go:1534] [meng] calling OnlineAlloX
I0116 14:09:14.636701       1 util.go:1550] [meng] numAvailMachines == 10,  allpods length: 8
I0116 14:09:14.637478       1 util.go:1534] [meng] calling OnlineAlloX
I0116 14:09:14.637510       1 util.go:1550] [meng] numAvailMachines == 10,  allpods length: 8
I0116 14:09:14.738924       1 util.go:1534] [meng] calling OnlineAlloX
I0116 14:09:14.738972       1 util.go:1550] [meng] numAvailMachines == 10,  allpods length: 8
I0116 14:09:14.739747       1 util.go:1534] [meng] calling OnlineAlloX
I0116 14:09:14.739779       1 util.go:1550] [meng] numAvailMachines == 10,  allpods length: 8
I0116 14:09:14.840618       1 util.go:1534] [meng] calling OnlineAlloX
I0116 14:09:14.840659       1 util.go:1550] [meng] numAvailMachines == 10,  allpods length: 8
I0116 14:09:14.841415       1 util.go:1534] [meng] calling OnlineAlloX
I0116 14:09:14.841447       1 util.go:1550] [meng] numAvailMachines == 10,  allpods length: 8
I0116 14:09:14.942705       1 util.go:1534] [meng] calling OnlineAlloX
I0116 14:09:14.942744       1 util.go:1550] [meng] numAvailMachines == 10,  allpods length: 8
I0116 14:09:14.943510       1 util.go:1534] [meng] calling OnlineAlloX
I0116 14:09:14.943541       1 util.go:1550] [meng] numAvailMachines == 10,  allpods length: 8
I0116 14:09:15.044379       1 util.go:1534] [meng] calling OnlineAlloX
I0116 14:09:15.044414       1 util.go:1550] [meng] numAvailMachines == 10,  allpods length: 8
I0116 14:09:15.045181       1 util.go:1534] [meng] calling OnlineAlloX
I0116 14:09:15.045211       1 util.go:1550] [meng] numAvailMachines == 10,  allpods length: 8
I0116 14:09:15.146421       1 util.go:1534] [meng] calling OnlineAlloX
I0116 14:09:15.146467       1 util.go:1550] [meng] numAvailMachines == 10,  allpods length: 8
I0116 14:09:15.147228       1 util.go:1534] [meng] calling OnlineAlloX
I0116 14:09:15.147259       1 util.go:1550] [meng] numAvailMachines == 10,  allpods length: 8
I0116 14:09:15.248096       1 util.go:1534] [meng] calling OnlineAlloX
I0116 14:09:15.248137       1 util.go:1550] [meng] numAvailMachines == 10,  allpods length: 8
I0116 14:09:15.248914       1 util.go:1534] [meng] calling OnlineAlloX
I0116 14:09:15.248946       1 util.go:1550] [meng] numAvailMachines == 10,  allpods length: 8
I0116 14:09:15.350079       1 util.go:1534] [meng] calling OnlineAlloX
I0116 14:09:15.350126       1 util.go:1550] [meng] numAvailMachines == 10,  allpods length: 8
I0116 14:09:15.350885       1 util.go:1534] [meng] calling OnlineAlloX
I0116 14:09:15.350917       1 util.go:1550] [meng] numAvailMachines == 10,  allpods length: 8
I0116 14:09:15.451754       1 util.go:1534] [meng] calling OnlineAlloX
I0116 14:09:15.451794       1 util.go:1550] [meng] numAvailMachines == 10,  allpods length: 8
I0116 14:09:15.452580       1 util.go:1534] [meng] calling OnlineAlloX
I0116 14:09:15.452613       1 util.go:1550] [meng] numAvailMachines == 10,  allpods length: 8
I0116 14:09:15.553750       1 util.go:1534] [meng] calling OnlineAlloX
I0116 14:09:15.553796       1 util.go:1550] [meng] numAvailMachines == 10,  allpods length: 8
I0116 14:09:15.554543       1 util.go:1534] [meng] calling OnlineAlloX
I0116 14:09:15.554574       1 util.go:1550] [meng] numAvailMachines == 10,  allpods length: 8
I0116 14:09:15.655398       1 util.go:1534] [meng] calling OnlineAlloX
I0116 14:09:15.655433       1 util.go:1550] [meng] numAvailMachines == 10,  allpods length: 8
I0116 14:09:15.656178       1 util.go:1534] [meng] calling OnlineAlloX
I0116 14:09:15.656207       1 util.go:1550] [meng] numAvailMachines == 10,  allpods length: 8
I0116 14:09:15.757366       1 util.go:1534] [meng] calling OnlineAlloX
I0116 14:09:15.757413       1 util.go:1550] [meng] numAvailMachines == 10,  allpods length: 8
I0116 14:09:15.758176       1 util.go:1534] [meng] calling OnlineAlloX
I0116 14:09:15.758209       1 util.go:1550] [meng] numAvailMachines == 10,  allpods length: 8
I0116 14:09:15.859041       1 util.go:1534] [meng] calling OnlineAlloX
I0116 14:09:15.859085       1 util.go:1550] [meng] numAvailMachines == 10,  allpods length: 8
I0116 14:09:15.859836       1 util.go:1534] [meng] calling OnlineAlloX
I0116 14:09:15.859872       1 util.go:1550] [meng] numAvailMachines == 10,  allpods length: 8
I0116 14:09:15.961001       1 util.go:1534] [meng] calling OnlineAlloX
I0116 14:09:15.961047       1 util.go:1550] [meng] numAvailMachines == 10,  allpods length: 8
I0116 14:09:15.961805       1 util.go:1534] [meng] calling OnlineAlloX
I0116 14:09:15.961838       1 util.go:1550] [meng] numAvailMachines == 10,  allpods length: 8
I0116 14:09:16.062655       1 util.go:1534] [meng] calling OnlineAlloX
I0116 14:09:16.062688       1 util.go:1550] [meng] numAvailMachines == 10,  allpods length: 8
I0116 14:09:16.063429       1 util.go:1534] [meng] calling OnlineAlloX
I0116 14:09:16.063460       1 util.go:1550] [meng] numAvailMachines == 10,  allpods length: 8
I0116 14:09:16.164688       1 util.go:1534] [meng] calling OnlineAlloX
I0116 14:09:16.164730       1 util.go:1550] [meng] numAvailMachines == 10,  allpods length: 8
I0116 14:09:16.165494       1 util.go:1534] [meng] calling OnlineAlloX
I0116 14:09:16.165525       1 util.go:1550] [meng] numAvailMachines == 10,  allpods length: 8
I0116 14:09:16.266366       1 util.go:1534] [meng] calling OnlineAlloX
I0116 14:09:16.266410       1 util.go:1550] [meng] numAvailMachines == 10,  allpods length: 8
I0116 14:09:16.267176       1 util.go:1534] [meng] calling OnlineAlloX
I0116 14:09:16.267208       1 util.go:1550] [meng] numAvailMachines == 10,  allpods length: 8
I0116 14:09:16.368439       1 util.go:1534] [meng] calling OnlineAlloX
I0116 14:09:16.368484       1 util.go:1550] [meng] numAvailMachines == 10,  allpods length: 8
I0116 14:09:16.369236       1 util.go:1534] [meng] calling OnlineAlloX
I0116 14:09:16.369268       1 util.go:1550] [meng] numAvailMachines == 10,  allpods length: 8
I0116 14:09:16.470107       1 util.go:1534] [meng] calling OnlineAlloX
I0116 14:09:16.470145       1 util.go:1550] [meng] numAvailMachines == 10,  allpods length: 8
I0116 14:09:16.470902       1 util.go:1534] [meng] calling OnlineAlloX
I0116 14:09:16.470934       1 util.go:1550] [meng] numAvailMachines == 10,  allpods length: 8
I0116 14:09:16.572065       1 util.go:1534] [meng] calling OnlineAlloX
I0116 14:09:16.572110       1 util.go:1550] [meng] numAvailMachines == 10,  allpods length: 8
I0116 14:09:16.572863       1 util.go:1534] [meng] calling OnlineAlloX
I0116 14:09:16.572895       1 util.go:1550] [meng] numAvailMachines == 10,  allpods length: 8
I0116 14:09:16.673741       1 util.go:1534] [meng] calling OnlineAlloX
I0116 14:09:16.673782       1 util.go:1550] [meng] numAvailMachines == 10,  allpods length: 8
I0116 14:09:16.674538       1 util.go:1534] [meng] calling OnlineAlloX
I0116 14:09:16.674569       1 util.go:1550] [meng] numAvailMachines == 10,  allpods length: 8
I0116 14:09:16.775773       1 util.go:1534] [meng] calling OnlineAlloX
I0116 14:09:16.775827       1 util.go:1550] [meng] numAvailMachines == 10,  allpods length: 8
I0116 14:09:16.776659       1 util.go:1534] [meng] calling OnlineAlloX
I0116 14:09:16.776693       1 util.go:1550] [meng] numAvailMachines == 10,  allpods length: 8
I0116 14:09:16.877585       1 util.go:1534] [meng] calling OnlineAlloX
I0116 14:09:16.877654       1 util.go:1550] [meng] numAvailMachines == 10,  allpods length: 8
I0116 14:09:16.878542       1 util.go:1534] [meng] calling OnlineAlloX
I0116 14:09:16.878584       1 util.go:1550] [meng] numAvailMachines == 10,  allpods length: 8
I0116 14:09:16.979905       1 util.go:1534] [meng] calling OnlineAlloX
I0116 14:09:16.979950       1 util.go:1550] [meng] numAvailMachines == 10,  allpods length: 8
I0116 14:09:16.980807       1 util.go:1534] [meng] calling OnlineAlloX
I0116 14:09:16.980840       1 util.go:1550] [meng] numAvailMachines == 10,  allpods length: 8
I0116 14:09:17.081782       1 util.go:1534] [meng] calling OnlineAlloX
I0116 14:09:17.081820       1 util.go:1550] [meng] numAvailMachines == 10,  allpods length: 8
I0116 14:09:17.082688       1 util.go:1534] [meng] calling OnlineAlloX
I0116 14:09:17.082721       1 util.go:1550] [meng] numAvailMachines == 10,  allpods length: 8
I0116 14:09:17.184049       1 util.go:1534] [meng] calling OnlineAlloX
I0116 14:09:17.184096       1 util.go:1550] [meng] numAvailMachines == 10,  allpods length: 8
I0116 14:09:17.184956       1 util.go:1534] [meng] calling OnlineAlloX
I0116 14:09:17.184989       1 util.go:1550] [meng] numAvailMachines == 10,  allpods length: 8
I0116 14:09:17.285927       1 util.go:1534] [meng] calling OnlineAlloX
I0116 14:09:17.285968       1 util.go:1550] [meng] numAvailMachines == 10,  allpods length: 8
I0116 14:09:17.286831       1 util.go:1534] [meng] calling OnlineAlloX
I0116 14:09:17.286864       1 util.go:1550] [meng] numAvailMachines == 10,  allpods length: 8
I0116 14:09:17.387786       1 util.go:1534] [meng] calling OnlineAlloX
I0116 14:09:17.388008       1 util.go:1550] [meng] numAvailMachines == 10,  allpods length: 8
I0116 14:09:17.389747       1 util.go:1534] [meng] calling OnlineAlloX
I0116 14:09:17.389794       1 util.go:1550] [meng] numAvailMachines == 10,  allpods length: 8
I0116 14:09:17.490708       1 util.go:1534] [meng] calling OnlineAlloX
I0116 14:09:17.490743       1 util.go:1550] [meng] numAvailMachines == 10,  allpods length: 8
I0116 14:09:17.491588       1 util.go:1534] [meng] calling OnlineAlloX
I0116 14:09:17.491620       1 util.go:1550] [meng] numAvailMachines == 10,  allpods length: 8
I0116 14:09:17.592537       1 util.go:1534] [meng] calling OnlineAlloX
I0116 14:09:17.592572       1 util.go:1550] [meng] numAvailMachines == 10,  allpods length: 8
I0116 14:09:17.594196       1 util.go:1534] [meng] calling OnlineAlloX
I0116 14:09:17.594252       1 util.go:1550] [meng] numAvailMachines == 10,  allpods length: 8
I0116 14:09:17.695185       1 util.go:1534] [meng] calling OnlineAlloX
I0116 14:09:17.695231       1 util.go:1550] [meng] numAvailMachines == 10,  allpods length: 8
I0116 14:09:17.696084       1 util.go:1534] [meng] calling OnlineAlloX
I0116 14:09:17.696130       1 util.go:1550] [meng] numAvailMachines == 10,  allpods length: 8
I0116 14:09:17.797049       1 util.go:1534] [meng] calling OnlineAlloX
I0116 14:09:17.797089       1 util.go:1550] [meng] numAvailMachines == 10,  allpods length: 8
I0116 14:09:17.798435       1 util.go:1534] [meng] calling OnlineAlloX
I0116 14:09:17.798533       1 util.go:1550] [meng] numAvailMachines == 10,  allpods length: 8
I0116 14:09:17.899926       1 util.go:1534] [meng] calling OnlineAlloX
I0116 14:09:17.899970       1 util.go:1550] [meng] numAvailMachines == 10,  allpods length: 8
I0116 14:09:17.900813       1 util.go:1534] [meng] calling OnlineAlloX
I0116 14:09:17.900847       1 util.go:1550] [meng] numAvailMachines == 10,  allpods length: 8
I0116 14:09:18.001764       1 util.go:1534] [meng] calling OnlineAlloX
I0116 14:09:18.001811       1 util.go:1550] [meng] numAvailMachines == 10,  allpods length: 8
I0116 14:09:18.002660       1 util.go:1534] [meng] calling OnlineAlloX
I0116 14:09:18.002697       1 util.go:1550] [meng] numAvailMachines == 10,  allpods length: 8
I0116 14:09:18.104385       1 util.go:1534] [meng] calling OnlineAlloX
I0116 14:09:18.104436       1 util.go:1550] [meng] numAvailMachines == 10,  allpods length: 8
I0116 14:09:18.105265       1 util.go:1534] [meng] calling OnlineAlloX
I0116 14:09:18.105298       1 util.go:1550] [meng] numAvailMachines == 10,  allpods length: 8
I0116 14:09:18.206183       1 util.go:1534] [meng] calling OnlineAlloX
I0116 14:09:18.206225       1 util.go:1550] [meng] numAvailMachines == 10,  allpods length: 8
I0116 14:09:18.207050       1 util.go:1534] [meng] calling OnlineAlloX
I0116 14:09:18.207081       1 util.go:1550] [meng] numAvailMachines == 10,  allpods length: 8
I0116 14:09:18.308579       1 util.go:1534] [meng] calling OnlineAlloX
I0116 14:09:18.308626       1 util.go:1550] [meng] numAvailMachines == 10,  allpods length: 8
I0116 14:09:18.309408       1 util.go:1534] [meng] calling OnlineAlloX
I0116 14:09:18.309439       1 util.go:1550] [meng] numAvailMachines == 10,  allpods length: 8
I0116 14:09:18.410290       1 util.go:1534] [meng] calling OnlineAlloX
I0116 14:09:18.410322       1 util.go:1550] [meng] numAvailMachines == 10,  allpods length: 8
I0116 14:09:18.411135       1 util.go:1534] [meng] calling OnlineAlloX
I0116 14:09:18.411166       1 util.go:1550] [meng] numAvailMachines == 10,  allpods length: 8
I0116 14:09:18.512032       1 util.go:1534] [meng] calling OnlineAlloX
I0116 14:09:18.512065       1 util.go:1550] [meng] numAvailMachines == 10,  allpods length: 8
I0116 14:09:18.513719       1 util.go:1534] [meng] calling OnlineAlloX
I0116 14:09:18.513773       1 util.go:1550] [meng] numAvailMachines == 10,  allpods length: 8
I0116 14:09:18.614948       1 util.go:1534] [meng] calling OnlineAlloX
I0116 14:09:18.614987       1 util.go:1550] [meng] numAvailMachines == 10,  allpods length: 8
I0116 14:09:18.615793       1 util.go:1534] [meng] calling OnlineAlloX
I0116 14:09:18.615826       1 util.go:1550] [meng] numAvailMachines == 10,  allpods length: 8
I0116 14:09:18.716709       1 util.go:1534] [meng] calling OnlineAlloX
I0116 14:09:18.716748       1 util.go:1550] [meng] numAvailMachines == 10,  allpods length: 8
I0116 14:09:18.717987       1 util.go:1534] [meng] calling OnlineAlloX
I0116 14:09:18.718142       1 util.go:1550] [meng] numAvailMachines == 10,  allpods length: 8
I0116 14:09:18.819417       1 util.go:1534] [meng] calling OnlineAlloX
I0116 14:09:18.819459       1 util.go:1550] [meng] numAvailMachines == 10,  allpods length: 8
I0116 14:09:18.820239       1 util.go:1534] [meng] calling OnlineAlloX
I0116 14:09:18.820272       1 util.go:1550] [meng] numAvailMachines == 10,  allpods length: 8
I0116 14:09:18.921124       1 util.go:1534] [meng] calling OnlineAlloX
I0116 14:09:18.921156       1 util.go:1550] [meng] numAvailMachines == 10,  allpods length: 8
I0116 14:09:18.921951       1 util.go:1534] [meng] calling OnlineAlloX
I0116 14:09:18.921981       1 util.go:1550] [meng] numAvailMachines == 10,  allpods length: 8
I0116 14:09:19.023477       1 util.go:1534] [meng] calling OnlineAlloX
I0116 14:09:19.023522       1 util.go:1550] [meng] numAvailMachines == 10,  allpods length: 8
I0116 14:09:19.024312       1 util.go:1534] [meng] calling OnlineAlloX
I0116 14:09:19.024345       1 util.go:1550] [meng] numAvailMachines == 10,  allpods length: 8
I0116 14:09:19.125213       1 util.go:1534] [meng] calling OnlineAlloX
I0116 14:09:19.125256       1 util.go:1550] [meng] numAvailMachines == 10,  allpods length: 8
I0116 14:09:19.126094       1 util.go:1534] [meng] calling OnlineAlloX
I0116 14:09:19.126128       1 util.go:1550] [meng] numAvailMachines == 10,  allpods length: 8
I0116 14:09:19.227430       1 util.go:1534] [meng] calling OnlineAlloX
I0116 14:09:19.227476       1 util.go:1550] [meng] numAvailMachines == 10,  allpods length: 8
I0116 14:09:19.228292       1 util.go:1534] [meng] calling OnlineAlloX
I0116 14:09:19.228324       1 util.go:1550] [meng] numAvailMachines == 10,  allpods length: 8
I0116 14:09:19.329193       1 util.go:1534] [meng] calling OnlineAlloX
I0116 14:09:19.329240       1 util.go:1550] [meng] numAvailMachines == 10,  allpods length: 8
I0116 14:09:19.330069       1 util.go:1534] [meng] calling OnlineAlloX
I0116 14:09:19.330103       1 util.go:1550] [meng] numAvailMachines == 10,  allpods length: 8
I0116 14:09:19.431300       1 util.go:1534] [meng] calling OnlineAlloX
I0116 14:09:19.431340       1 util.go:1550] [meng] numAvailMachines == 10,  allpods length: 8
I0116 14:09:19.432157       1 util.go:1534] [meng] calling OnlineAlloX
I0116 14:09:19.432190       1 util.go:1550] [meng] numAvailMachines == 10,  allpods length: 8
I0116 14:09:19.533064       1 util.go:1534] [meng] calling OnlineAlloX
I0116 14:09:19.533099       1 util.go:1550] [meng] numAvailMachines == 10,  allpods length: 8
I0116 14:09:19.533925       1 util.go:1534] [meng] calling OnlineAlloX
I0116 14:09:19.533956       1 util.go:1550] [meng] numAvailMachines == 10,  allpods length: 8
I0116 14:09:19.635205       1 util.go:1534] [meng] calling OnlineAlloX
I0116 14:09:19.635250       1 util.go:1550] [meng] numAvailMachines == 10,  allpods length: 8
I0116 14:09:19.636053       1 util.go:1534] [meng] calling OnlineAlloX
I0116 14:09:19.636086       1 util.go:1550] [meng] numAvailMachines == 10,  allpods length: 8
I0116 14:09:19.736979       1 util.go:1534] [meng] calling OnlineAlloX
I0116 14:09:19.737024       1 util.go:1550] [meng] numAvailMachines == 10,  allpods length: 8
I0116 14:09:19.737850       1 util.go:1534] [meng] calling OnlineAlloX
I0116 14:09:19.737889       1 util.go:1550] [meng] numAvailMachines == 10,  allpods length: 8
I0116 14:09:19.838977       1 util.go:1534] [meng] calling OnlineAlloX
I0116 14:09:19.839023       1 util.go:1550] [meng] numAvailMachines == 10,  allpods length: 8
I0116 14:09:19.839828       1 util.go:1534] [meng] calling OnlineAlloX
I0116 14:09:19.839860       1 util.go:1550] [meng] numAvailMachines == 10,  allpods length: 8
I0116 14:09:19.940739       1 util.go:1534] [meng] calling OnlineAlloX
I0116 14:09:19.940775       1 util.go:1550] [meng] numAvailMachines == 10,  allpods length: 8
I0116 14:09:19.941575       1 util.go:1534] [meng] calling OnlineAlloX
I0116 14:09:19.941615       1 util.go:1550] [meng] numAvailMachines == 10,  allpods length: 8
I0116 14:09:20.042868       1 util.go:1534] [meng] calling OnlineAlloX
I0116 14:09:20.042914       1 util.go:1550] [meng] numAvailMachines == 10,  allpods length: 8
I0116 14:09:20.043713       1 util.go:1534] [meng] calling OnlineAlloX
I0116 14:09:20.043747       1 util.go:1550] [meng] numAvailMachines == 10,  allpods length: 8
I0116 14:09:20.144616       1 util.go:1534] [meng] calling OnlineAlloX
I0116 14:09:20.144660       1 util.go:1550] [meng] numAvailMachines == 10,  allpods length: 8
I0116 14:09:20.145463       1 util.go:1534] [meng] calling OnlineAlloX
I0116 14:09:20.145498       1 util.go:1550] [meng] numAvailMachines == 10,  allpods length: 8
I0116 14:09:20.246378       1 util.go:1534] [meng] calling OnlineAlloX
I0116 14:09:20.246431       1 util.go:1550] [meng] numAvailMachines == 10,  allpods length: 8
I0116 14:09:20.247228       1 util.go:1534] [meng] calling OnlineAlloX
I0116 14:09:20.247261       1 util.go:1550] [meng] numAvailMachines == 10,  allpods length: 8
I0116 14:09:20.348113       1 util.go:1534] [meng] calling OnlineAlloX
I0116 14:09:20.348148       1 util.go:1550] [meng] numAvailMachines == 10,  allpods length: 8
I0116 14:09:20.348939       1 util.go:1534] [meng] calling OnlineAlloX
I0116 14:09:20.348970       1 util.go:1550] [meng] numAvailMachines == 10,  allpods length: 8
I0116 14:09:20.450220       1 util.go:1534] [meng] calling OnlineAlloX
I0116 14:09:20.450257       1 util.go:1550] [meng] numAvailMachines == 10,  allpods length: 8
I0116 14:09:20.451030       1 util.go:1534] [meng] calling OnlineAlloX
I0116 14:09:20.451064       1 util.go:1550] [meng] numAvailMachines == 10,  allpods length: 8
I0116 14:09:20.551912       1 util.go:1534] [meng] calling OnlineAlloX
I0116 14:09:20.551944       1 util.go:1550] [meng] numAvailMachines == 10,  allpods length: 8
I0116 14:09:20.552726       1 util.go:1534] [meng] calling OnlineAlloX
I0116 14:09:20.552757       1 util.go:1550] [meng] numAvailMachines == 10,  allpods length: 8
I0116 14:09:20.653610       1 util.go:1534] [meng] calling OnlineAlloX
I0116 14:09:20.653640       1 util.go:1550] [meng] numAvailMachines == 10,  allpods length: 8
I0116 14:09:20.655227       1 util.go:1534] [meng] calling OnlineAlloX
I0116 14:09:20.655280       1 util.go:1550] [meng] numAvailMachines == 10,  allpods length: 8
I0116 14:09:20.756421       1 util.go:1534] [meng] calling OnlineAlloX
I0116 14:09:20.756454       1 util.go:1550] [meng] numAvailMachines == 10,  allpods length: 8
I0116 14:09:20.757232       1 util.go:1534] [meng] calling OnlineAlloX
I0116 14:09:20.757264       1 util.go:1550] [meng] numAvailMachines == 10,  allpods length: 8
I0116 14:09:20.858119       1 util.go:1534] [meng] calling OnlineAlloX
I0116 14:09:20.858156       1 util.go:1550] [meng] numAvailMachines == 10,  allpods length: 8
I0116 14:09:20.859427       1 util.go:1534] [meng] calling OnlineAlloX
I0116 14:09:20.859798       1 util.go:1550] [meng] numAvailMachines == 10,  allpods length: 8
I0116 14:09:20.960720       1 util.go:1534] [meng] calling OnlineAlloX
I0116 14:09:20.960768       1 util.go:1550] [meng] numAvailMachines == 10,  allpods length: 8
I0116 14:09:20.961546       1 util.go:1534] [meng] calling OnlineAlloX
I0116 14:09:20.961584       1 util.go:1550] [meng] numAvailMachines == 10,  allpods length: 8
I0116 14:09:21.062449       1 util.go:1534] [meng] calling OnlineAlloX
I0116 14:09:21.062492       1 util.go:1550] [meng] numAvailMachines == 10,  allpods length: 8
I0116 14:09:21.063268       1 util.go:1534] [meng] calling OnlineAlloX
I0116 14:09:21.063308       1 util.go:1550] [meng] numAvailMachines == 10,  allpods length: 8
I0116 14:09:21.165136       1 util.go:1534] [meng] calling OnlineAlloX
I0116 14:09:21.165174       1 util.go:1550] [meng] numAvailMachines == 10,  allpods length: 8
I0116 14:09:21.165957       1 util.go:1534] [meng] calling OnlineAlloX
I0116 14:09:21.165991       1 util.go:1550] [meng] numAvailMachines == 10,  allpods length: 8
I0116 14:09:21.266814       1 util.go:1534] [meng] calling OnlineAlloX
I0116 14:09:21.266855       1 util.go:1550] [meng] numAvailMachines == 10,  allpods length: 8
I0116 14:09:21.267617       1 util.go:1534] [meng] calling OnlineAlloX
I0116 14:09:21.267648       1 util.go:1550] [meng] numAvailMachines == 10,  allpods length: 8
I0116 14:09:21.369069       1 util.go:1534] [meng] calling OnlineAlloX
I0116 14:09:21.369116       1 util.go:1550] [meng] numAvailMachines == 10,  allpods length: 8
I0116 14:09:21.369899       1 util.go:1534] [meng] calling OnlineAlloX
I0116 14:09:21.369934       1 util.go:1550] [meng] numAvailMachines == 10,  allpods length: 8
I0116 14:09:21.470781       1 util.go:1534] [meng] calling OnlineAlloX
I0116 14:09:21.470827       1 util.go:1550] [meng] numAvailMachines == 10,  allpods length: 8
I0116 14:09:21.471650       1 util.go:1534] [meng] calling OnlineAlloX
I0116 14:09:21.471684       1 util.go:1550] [meng] numAvailMachines == 10,  allpods length: 8
I0116 14:09:21.572573       1 util.go:1534] [meng] calling OnlineAlloX
I0116 14:09:21.572610       1 util.go:1550] [meng] numAvailMachines == 10,  allpods length: 8
I0116 14:09:21.574306       1 util.go:1534] [meng] calling OnlineAlloX
I0116 14:09:21.574362       1 util.go:1550] [meng] numAvailMachines == 10,  allpods length: 8
I0116 14:09:21.638710       1 factory.go:1129] [meng] deletePodFromCache
I0116 14:09:21.638730       1 factory.go:1136] [meng] JCT: 1m23.661910182s, total jct: 22m38.746821541s, count: 28, average JCT: 48.526672197s
I0116 14:09:21.652257       1 factory.go:798] [meng] computeComplTimeForAllPods completed
I0116 14:09:21.652280       1 factory.go:806] [tanle] Event pod completed user1/user1-pytorch-alexnet%!(EXTRA v1.PodPhase=Succeeded)
I0116 14:09:21.652309       1 factory.go:1149] [meng] check delete pod user1/user1-pytorch-alexnet, Running
I0116 14:09:21.652315       1 util.go:143] [meng] UpdateFairScore user1/user1-pytorch-alexnet, false
I0116 14:09:21.652324       1 util.go:192] [meng] delete PodMachineMap in UpdateFairScore user1/user1-pytorch-alexnet, false
I0116 14:09:21.652328       1 util.go:196] [tanle] FairScoreMap:  map[user3:0.44444444444444453 user4:0.2500000000000001 user1:1.1102230246251565e-16 user2:0.2500000000000001]
I0116 14:09:21.660988       1 factory.go:1129] [meng] deletePodFromCache
I0116 14:09:21.660997       1 factory.go:1136] [meng] JCT: 1m23.684178391s, total jct: 24m2.430999932s, count: 29, average JCT: 49.738999997s
I0116 14:09:21.670827       1 factory.go:798] [meng] computeComplTimeForAllPods completed
I0116 14:09:21.670851       1 factory.go:806] [tanle] Event pod completed user2/user2-pytorch-alexnet%!(EXTRA v1.PodPhase=Succeeded)
I0116 14:09:21.670874       1 factory.go:1149] [meng] check delete pod user2/user2-pytorch-alexnet, Running
I0116 14:09:21.670881       1 util.go:143] [meng] UpdateFairScore user2/user2-pytorch-alexnet, false
I0116 14:09:21.670888       1 util.go:192] [meng] delete PodMachineMap in UpdateFairScore user2/user2-pytorch-alexnet, false
I0116 14:09:21.670893       1 util.go:196] [tanle] FairScoreMap:  map[user1:1.1102230246251565e-16 user2:1.1102230246251565e-16 user3:0.44444444444444453 user4:0.2500000000000001]
I0116 14:09:21.675586       1 util.go:1534] [meng] calling OnlineAlloX
I0116 14:09:21.675631       1 util.go:1550] [meng] numAvailMachines == 12,  allpods length: 8
I0116 14:09:21.677723       1 util.go:196] [tanle] FairScoreMap:  map[user4:0.2500000000000001 user1:1.1102230246251565e-16 user2:0.2500000000000001 user3:0.44444444444444453]
I0116 14:09:21.679867       1 scheduler.go:406] [tanle] binding user2/user2-pytorch-shufflenet on GPU true-->meng-allox-egpu-1
I0116 14:09:21.777891       1 util.go:1534] [meng] calling OnlineAlloX
I0116 14:09:21.777925       1 util.go:1550] [meng] numAvailMachines == 11,  allpods length: 7
I0116 14:09:21.778706       1 util.go:196] [tanle] FairScoreMap:  map[user1:1.1102230246251565e-16 user2:0.5000000000000001 user3:0.44444444444444453 user4:0.2500000000000001]
I0116 14:09:21.781275       1 scheduler.go:406] [tanle] binding user2/user2-pytorch-mobilenet on GPU true-->meng-allox-egpu-4
I0116 14:09:21.878476       1 factory.go:1129] [meng] deletePodFromCache
I0116 14:09:21.878490       1 factory.go:1136] [meng] JCT: 1m23.901671084s, total jct: 25m26.332671016s, count: 30, average JCT: 50.8777557s
I0116 14:09:21.878852       1 util.go:1534] [meng] calling OnlineAlloX
I0116 14:09:21.878878       1 util.go:1550] [meng] numAvailMachines == 10,  allpods length: 6
I0116 14:09:21.879313       1 util.go:1534] [meng] calling OnlineAlloX
I0116 14:09:21.879345       1 util.go:1550] [meng] numAvailMachines == 10,  allpods length: 6
I0116 14:09:21.887878       1 factory.go:798] [meng] computeComplTimeForAllPods completed
I0116 14:09:21.887902       1 factory.go:806] [tanle] Event pod completed user3/user3-pytorch-alexnet%!(EXTRA v1.PodPhase=Succeeded)
I0116 14:09:21.887924       1 factory.go:1149] [meng] check delete pod user3/user3-pytorch-alexnet, Running
I0116 14:09:21.887932       1 util.go:143] [meng] UpdateFairScore user3/user3-pytorch-alexnet, false
I0116 14:09:21.887942       1 util.go:192] [meng] delete PodMachineMap in UpdateFairScore user3/user3-pytorch-alexnet, false
I0116 14:09:21.887949       1 util.go:196] [tanle] FairScoreMap:  map[user1:1.1102230246251565e-16 user2:0.5000000000000001 user3:0.19444444444444453 user4:0.2500000000000001]
I0116 14:09:21.980191       1 util.go:1534] [meng] calling OnlineAlloX
I0116 14:09:21.980235       1 util.go:1550] [meng] numAvailMachines == 11,  allpods length: 6
I0116 14:09:21.980838       1 util.go:196] [tanle] FairScoreMap:  map[user4:0.2500000000000001 user1:0.2500000000000001 user2:0.5000000000000001 user3:0.19444444444444453]
I0116 14:09:21.983019       1 scheduler.go:406] [tanle] binding user1/user1-pytorch-mobilenet on GPU true-->meng-allox-egpu-3
I0116 14:09:22.080987       1 util.go:1534] [meng] calling OnlineAlloX
I0116 14:09:22.081017       1 util.go:1550] [meng] numAvailMachines == 10,  allpods length: 5
I0116 14:09:22.081309       1 util.go:1534] [meng] calling OnlineAlloX
I0116 14:09:22.081336       1 util.go:1550] [meng] numAvailMachines == 10,  allpods length: 5
I0116 14:09:22.181681       1 util.go:1534] [meng] calling OnlineAlloX
I0116 14:09:22.181712       1 util.go:1550] [meng] numAvailMachines == 10,  allpods length: 5
I0116 14:09:22.181980       1 util.go:1534] [meng] calling OnlineAlloX
I0116 14:09:22.182005       1 util.go:1550] [meng] numAvailMachines == 10,  allpods length: 5
I0116 14:09:22.282335       1 util.go:1534] [meng] calling OnlineAlloX
I0116 14:09:22.282375       1 util.go:1550] [meng] numAvailMachines == 10,  allpods length: 5
I0116 14:09:22.283088       1 util.go:1534] [meng] calling OnlineAlloX
I0116 14:09:22.283217       1 util.go:1550] [meng] numAvailMachines == 10,  allpods length: 5
I0116 14:09:22.287693       1 factory.go:1129] [meng] deletePodFromCache
I0116 14:09:22.287702       1 factory.go:1136] [meng] JCT: 1m24.310882721s, total jct: 26m50.643553737s, count: 31, average JCT: 51.956243668s
I0116 14:09:22.298047       1 factory.go:798] [meng] computeComplTimeForAllPods completed
I0116 14:09:22.298072       1 factory.go:806] [tanle] Event pod completed user4/user4-pytorch-alexnet%!(EXTRA v1.PodPhase=Succeeded)
I0116 14:09:22.298097       1 factory.go:1149] [meng] check delete pod user4/user4-pytorch-alexnet, Running
I0116 14:09:22.298105       1 util.go:143] [meng] UpdateFairScore user4/user4-pytorch-alexnet, false
I0116 14:09:22.298116       1 util.go:192] [meng] delete PodMachineMap in UpdateFairScore user4/user4-pytorch-alexnet, false
I0116 14:09:22.298123       1 util.go:196] [tanle] FairScoreMap:  map[user2:0.5000000000000001 user3:0.19444444444444453 user4:1.1102230246251565e-16 user1:0.2500000000000001]
I0116 14:09:22.383958       1 util.go:1534] [meng] calling OnlineAlloX
I0116 14:09:22.384001       1 util.go:1550] [meng] numAvailMachines == 11,  allpods length: 5
I0116 14:09:22.384442       1 util.go:196] [tanle] FairScoreMap:  map[user1:0.2500000000000001 user2:0.5000000000000001 user3:0.19444444444444453 user4:0.2500000000000001]
I0116 14:09:22.386733       1 scheduler.go:406] [tanle] binding user4/user4-pytorch-mobilenet on GPU true-->meng-allox-egpu-2
I0116 14:09:22.484592       1 util.go:1534] [meng] calling OnlineAlloX
I0116 14:09:22.484623       1 util.go:1550] [meng] numAvailMachines == 10,  allpods length: 4
I0116 14:09:22.484791       1 util.go:1534] [meng] calling OnlineAlloX
I0116 14:09:22.484817       1 util.go:1550] [meng] numAvailMachines == 10,  allpods length: 4
I0116 14:09:22.585044       1 util.go:1534] [meng] calling OnlineAlloX
I0116 14:09:22.585071       1 util.go:1550] [meng] numAvailMachines == 10,  allpods length: 4
I0116 14:09:22.585232       1 util.go:1534] [meng] calling OnlineAlloX
I0116 14:09:22.585255       1 util.go:1550] [meng] numAvailMachines == 10,  allpods length: 4
I0116 14:09:22.685483       1 util.go:1534] [meng] calling OnlineAlloX
I0116 14:09:22.685511       1 util.go:1550] [meng] numAvailMachines == 10,  allpods length: 4
I0116 14:09:22.685679       1 util.go:1534] [meng] calling OnlineAlloX
I0116 14:09:22.685704       1 util.go:1550] [meng] numAvailMachines == 10,  allpods length: 4
I0116 14:09:22.785928       1 util.go:1534] [meng] calling OnlineAlloX
I0116 14:09:22.785969       1 util.go:1550] [meng] numAvailMachines == 10,  allpods length: 4
I0116 14:09:22.786141       1 util.go:1534] [meng] calling OnlineAlloX
I0116 14:09:22.786165       1 util.go:1550] [meng] numAvailMachines == 10,  allpods length: 4
I0116 14:09:22.886697       1 util.go:1534] [meng] calling OnlineAlloX
I0116 14:09:22.886746       1 util.go:1550] [meng] numAvailMachines == 10,  allpods length: 4
I0116 14:09:22.886905       1 util.go:1534] [meng] calling OnlineAlloX
I0116 14:09:22.886935       1 util.go:1550] [meng] numAvailMachines == 10,  allpods length: 4
I0116 14:09:22.987161       1 util.go:1534] [meng] calling OnlineAlloX
I0116 14:09:22.987198       1 util.go:1550] [meng] numAvailMachines == 10,  allpods length: 4
I0116 14:09:22.987359       1 util.go:1534] [meng] calling OnlineAlloX
I0116 14:09:22.987387       1 util.go:1550] [meng] numAvailMachines == 10,  allpods length: 4
I0116 14:09:23.087612       1 util.go:1534] [meng] calling OnlineAlloX
I0116 14:09:23.087643       1 util.go:1550] [meng] numAvailMachines == 10,  allpods length: 4
I0116 14:09:23.087800       1 util.go:1534] [meng] calling OnlineAlloX
I0116 14:09:23.087828       1 util.go:1550] [meng] numAvailMachines == 10,  allpods length: 4
I0116 14:09:23.188054       1 util.go:1534] [meng] calling OnlineAlloX
I0116 14:09:23.188095       1 util.go:1550] [meng] numAvailMachines == 10,  allpods length: 4
I0116 14:09:23.188256       1 util.go:1534] [meng] calling OnlineAlloX
I0116 14:09:23.188280       1 util.go:1550] [meng] numAvailMachines == 10,  allpods length: 4
I0116 14:09:23.288500       1 util.go:1534] [meng] calling OnlineAlloX
I0116 14:09:23.288537       1 util.go:1550] [meng] numAvailMachines == 10,  allpods length: 4
I0116 14:09:23.288700       1 util.go:1534] [meng] calling OnlineAlloX
I0116 14:09:23.288724       1 util.go:1550] [meng] numAvailMachines == 10,  allpods length: 4
I0116 14:09:23.388940       1 util.go:1534] [meng] calling OnlineAlloX
I0116 14:09:23.388974       1 util.go:1550] [meng] numAvailMachines == 10,  allpods length: 4
I0116 14:09:23.389127       1 util.go:1534] [meng] calling OnlineAlloX
I0116 14:09:23.389149       1 util.go:1550] [meng] numAvailMachines == 10,  allpods length: 4
I0116 14:09:23.489374       1 util.go:1534] [meng] calling OnlineAlloX
I0116 14:09:23.489408       1 util.go:1550] [meng] numAvailMachines == 10,  allpods length: 4
I0116 14:09:23.489566       1 util.go:1534] [meng] calling OnlineAlloX
I0116 14:09:23.489602       1 util.go:1550] [meng] numAvailMachines == 10,  allpods length: 4
I0116 14:09:23.589836       1 util.go:1534] [meng] calling OnlineAlloX
I0116 14:09:23.589863       1 util.go:1550] [meng] numAvailMachines == 10,  allpods length: 4
I0116 14:09:23.590016       1 util.go:1534] [meng] calling OnlineAlloX
I0116 14:09:23.590037       1 util.go:1550] [meng] numAvailMachines == 10,  allpods length: 4
I0116 14:09:23.690256       1 util.go:1534] [meng] calling OnlineAlloX
I0116 14:09:23.690297       1 util.go:1550] [meng] numAvailMachines == 10,  allpods length: 4
I0116 14:09:23.690455       1 util.go:1534] [meng] calling OnlineAlloX
I0116 14:09:23.690480       1 util.go:1550] [meng] numAvailMachines == 10,  allpods length: 4
I0116 14:09:23.790711       1 util.go:1534] [meng] calling OnlineAlloX
I0116 14:09:23.790749       1 util.go:1550] [meng] numAvailMachines == 10,  allpods length: 4
I0116 14:09:23.791267       1 util.go:1534] [meng] calling OnlineAlloX
I0116 14:09:23.791352       1 util.go:1550] [meng] numAvailMachines == 10,  allpods length: 4
I0116 14:09:23.891626       1 util.go:1534] [meng] calling OnlineAlloX
I0116 14:09:23.891663       1 util.go:1550] [meng] numAvailMachines == 10,  allpods length: 4
I0116 14:09:23.891815       1 util.go:1534] [meng] calling OnlineAlloX
I0116 14:09:23.891840       1 util.go:1550] [meng] numAvailMachines == 10,  allpods length: 4
I0116 14:09:23.992064       1 util.go:1534] [meng] calling OnlineAlloX
I0116 14:09:23.992105       1 util.go:1550] [meng] numAvailMachines == 10,  allpods length: 4
I0116 14:09:23.992262       1 util.go:1534] [meng] calling OnlineAlloX
I0116 14:09:23.992286       1 util.go:1550] [meng] numAvailMachines == 10,  allpods length: 4
I0116 14:09:24.092507       1 util.go:1534] [meng] calling OnlineAlloX
I0116 14:09:24.092544       1 util.go:1550] [meng] numAvailMachines == 10,  allpods length: 4
I0116 14:09:24.092705       1 util.go:1534] [meng] calling OnlineAlloX
I0116 14:09:24.092730       1 util.go:1550] [meng] numAvailMachines == 10,  allpods length: 4
I0116 14:09:24.192942       1 util.go:1534] [meng] calling OnlineAlloX
I0116 14:09:24.192970       1 util.go:1550] [meng] numAvailMachines == 10,  allpods length: 4
I0116 14:09:24.193123       1 util.go:1534] [meng] calling OnlineAlloX
I0116 14:09:24.193145       1 util.go:1550] [meng] numAvailMachines == 10,  allpods length: 4
I0116 14:09:24.293370       1 util.go:1534] [meng] calling OnlineAlloX
I0116 14:09:24.293414       1 util.go:1550] [meng] numAvailMachines == 10,  allpods length: 4
I0116 14:09:24.293577       1 util.go:1534] [meng] calling OnlineAlloX
I0116 14:09:24.293607       1 util.go:1550] [meng] numAvailMachines == 10,  allpods length: 4
I0116 14:09:24.393824       1 util.go:1534] [meng] calling OnlineAlloX
I0116 14:09:24.393852       1 util.go:1550] [meng] numAvailMachines == 10,  allpods length: 4
I0116 14:09:24.394002       1 util.go:1534] [meng] calling OnlineAlloX
I0116 14:09:24.394024       1 util.go:1550] [meng] numAvailMachines == 10,  allpods length: 4
I0116 14:09:24.494249       1 util.go:1534] [meng] calling OnlineAlloX
I0116 14:09:24.494297       1 util.go:1550] [meng] numAvailMachines == 10,  allpods length: 4
I0116 14:09:24.494454       1 util.go:1534] [meng] calling OnlineAlloX
I0116 14:09:24.494479       1 util.go:1550] [meng] numAvailMachines == 10,  allpods length: 4
I0116 14:09:24.594695       1 util.go:1534] [meng] calling OnlineAlloX
I0116 14:09:24.594730       1 util.go:1550] [meng] numAvailMachines == 10,  allpods length: 4
I0116 14:09:24.594889       1 util.go:1534] [meng] calling OnlineAlloX
I0116 14:09:24.594913       1 util.go:1550] [meng] numAvailMachines == 10,  allpods length: 4
I0116 14:09:24.695127       1 util.go:1534] [meng] calling OnlineAlloX
I0116 14:09:24.695162       1 util.go:1550] [meng] numAvailMachines == 10,  allpods length: 4
I0116 14:09:24.695315       1 util.go:1534] [meng] calling OnlineAlloX
I0116 14:09:24.695337       1 util.go:1550] [meng] numAvailMachines == 10,  allpods length: 4
I0116 14:09:24.795550       1 util.go:1534] [meng] calling OnlineAlloX
I0116 14:09:24.795591       1 util.go:1550] [meng] numAvailMachines == 10,  allpods length: 4
I0116 14:09:24.795746       1 util.go:1534] [meng] calling OnlineAlloX
I0116 14:09:24.795770       1 util.go:1550] [meng] numAvailMachines == 10,  allpods length: 4
I0116 14:09:24.895992       1 util.go:1534] [meng] calling OnlineAlloX
I0116 14:09:24.896033       1 util.go:1550] [meng] numAvailMachines == 10,  allpods length: 4
I0116 14:09:24.896195       1 util.go:1534] [meng] calling OnlineAlloX
I0116 14:09:24.896219       1 util.go:1550] [meng] numAvailMachines == 10,  allpods length: 4
I0116 14:09:24.996441       1 util.go:1534] [meng] calling OnlineAlloX
I0116 14:09:24.996480       1 util.go:1550] [meng] numAvailMachines == 10,  allpods length: 4
I0116 14:09:24.996636       1 util.go:1534] [meng] calling OnlineAlloX
I0116 14:09:24.996660       1 util.go:1550] [meng] numAvailMachines == 10,  allpods length: 4
I0116 14:09:25.096870       1 util.go:1534] [meng] calling OnlineAlloX
I0116 14:09:25.096897       1 util.go:1550] [meng] numAvailMachines == 10,  allpods length: 4
I0116 14:09:25.097049       1 util.go:1534] [meng] calling OnlineAlloX
I0116 14:09:25.097070       1 util.go:1550] [meng] numAvailMachines == 10,  allpods length: 4
I0116 14:09:25.197278       1 util.go:1534] [meng] calling OnlineAlloX
I0116 14:09:25.197306       1 util.go:1550] [meng] numAvailMachines == 10,  allpods length: 4
I0116 14:09:25.197457       1 util.go:1534] [meng] calling OnlineAlloX
I0116 14:09:25.197479       1 util.go:1550] [meng] numAvailMachines == 10,  allpods length: 4
I0116 14:09:25.297706       1 util.go:1534] [meng] calling OnlineAlloX
I0116 14:09:25.297743       1 util.go:1550] [meng] numAvailMachines == 10,  allpods length: 4
I0116 14:09:25.297901       1 util.go:1534] [meng] calling OnlineAlloX
I0116 14:09:25.297927       1 util.go:1550] [meng] numAvailMachines == 10,  allpods length: 4
I0116 14:09:25.398143       1 util.go:1534] [meng] calling OnlineAlloX
I0116 14:09:25.398168       1 util.go:1550] [meng] numAvailMachines == 10,  allpods length: 4
I0116 14:09:25.398319       1 util.go:1534] [meng] calling OnlineAlloX
I0116 14:09:25.398339       1 util.go:1550] [meng] numAvailMachines == 10,  allpods length: 4
I0116 14:09:25.498556       1 util.go:1534] [meng] calling OnlineAlloX
I0116 14:09:25.498585       1 util.go:1550] [meng] numAvailMachines == 10,  allpods length: 4
I0116 14:09:25.498729       1 util.go:1534] [meng] calling OnlineAlloX
I0116 14:09:25.498753       1 util.go:1550] [meng] numAvailMachines == 10,  allpods length: 4
I0116 14:09:25.598974       1 util.go:1534] [meng] calling OnlineAlloX
I0116 14:09:25.599002       1 util.go:1550] [meng] numAvailMachines == 10,  allpods length: 4
I0116 14:09:25.599154       1 util.go:1534] [meng] calling OnlineAlloX
I0116 14:09:25.599176       1 util.go:1550] [meng] numAvailMachines == 10,  allpods length: 4
I0116 14:09:25.699719       1 util.go:1534] [meng] calling OnlineAlloX
I0116 14:09:25.699765       1 util.go:1550] [meng] numAvailMachines == 10,  allpods length: 4
I0116 14:09:25.699922       1 util.go:1534] [meng] calling OnlineAlloX
I0116 14:09:25.699946       1 util.go:1550] [meng] numAvailMachines == 10,  allpods length: 4
I0116 14:09:25.800167       1 util.go:1534] [meng] calling OnlineAlloX
I0116 14:09:25.800210       1 util.go:1550] [meng] numAvailMachines == 10,  allpods length: 4
I0116 14:09:25.800363       1 util.go:1534] [meng] calling OnlineAlloX
I0116 14:09:25.800387       1 util.go:1550] [meng] numAvailMachines == 10,  allpods length: 4
I0116 14:09:25.900596       1 util.go:1534] [meng] calling OnlineAlloX
I0116 14:09:25.900619       1 util.go:1550] [meng] numAvailMachines == 10,  allpods length: 4
I0116 14:09:25.900765       1 util.go:1534] [meng] calling OnlineAlloX
I0116 14:09:25.900786       1 util.go:1550] [meng] numAvailMachines == 10,  allpods length: 4
I0116 14:09:26.000991       1 util.go:1534] [meng] calling OnlineAlloX
I0116 14:09:26.001014       1 util.go:1550] [meng] numAvailMachines == 10,  allpods length: 4
I0116 14:09:26.001158       1 util.go:1534] [meng] calling OnlineAlloX
I0116 14:09:26.001178       1 util.go:1550] [meng] numAvailMachines == 10,  allpods length: 4
I0116 14:09:26.101391       1 util.go:1534] [meng] calling OnlineAlloX
I0116 14:09:26.101414       1 util.go:1550] [meng] numAvailMachines == 10,  allpods length: 4
I0116 14:09:26.101563       1 util.go:1534] [meng] calling OnlineAlloX
I0116 14:09:26.101583       1 util.go:1550] [meng] numAvailMachines == 10,  allpods length: 4
I0116 14:09:26.201795       1 util.go:1534] [meng] calling OnlineAlloX
I0116 14:09:26.201821       1 util.go:1550] [meng] numAvailMachines == 10,  allpods length: 4
I0116 14:09:26.201974       1 util.go:1534] [meng] calling OnlineAlloX
I0116 14:09:26.201994       1 util.go:1550] [meng] numAvailMachines == 10,  allpods length: 4
I0116 14:09:26.302199       1 util.go:1534] [meng] calling OnlineAlloX
I0116 14:09:26.302223       1 util.go:1550] [meng] numAvailMachines == 10,  allpods length: 4
I0116 14:09:26.302368       1 util.go:1534] [meng] calling OnlineAlloX
I0116 14:09:26.302388       1 util.go:1550] [meng] numAvailMachines == 10,  allpods length: 4
I0116 14:09:26.402602       1 util.go:1534] [meng] calling OnlineAlloX
I0116 14:09:26.402626       1 util.go:1550] [meng] numAvailMachines == 10,  allpods length: 4
I0116 14:09:26.402770       1 util.go:1534] [meng] calling OnlineAlloX
I0116 14:09:26.402791       1 util.go:1550] [meng] numAvailMachines == 10,  allpods length: 4
I0116 14:09:26.501117       1 factory.go:1129] [meng] deletePodFromCache
I0116 14:09:26.501127       1 factory.go:1136] [meng] JCT: 1m28.524308302s, total jct: 28m19.167862039s, count: 32, average JCT: 53.098995688s
I0116 14:09:26.502999       1 util.go:1534] [meng] calling OnlineAlloX
I0116 14:09:26.503024       1 util.go:1550] [meng] numAvailMachines == 10,  allpods length: 4
I0116 14:09:26.503172       1 util.go:1534] [meng] calling OnlineAlloX
I0116 14:09:26.503192       1 util.go:1550] [meng] numAvailMachines == 10,  allpods length: 4
I0116 14:09:26.511141       1 factory.go:798] [meng] computeComplTimeForAllPods completed
I0116 14:09:26.511164       1 factory.go:806] [tanle] Event pod completed user3/user3-pytorch-lenet-4%!(EXTRA v1.PodPhase=Succeeded)
I0116 14:09:26.511184       1 factory.go:1149] [meng] check delete pod user3/user3-pytorch-lenet-4, Running
I0116 14:09:26.511190       1 util.go:143] [meng] UpdateFairScore user3/user3-pytorch-lenet-4, false
I0116 14:09:26.511197       1 util.go:192] [meng] delete PodMachineMap in UpdateFairScore user3/user3-pytorch-lenet-4, false
I0116 14:09:26.511200       1 util.go:196] [tanle] FairScoreMap:  map[user1:0.2500000000000001 user2:0.5000000000000001 user3:8.326672684688674e-17 user4:0.2500000000000001]
I0116 14:09:26.603404       1 util.go:1534] [meng] calling OnlineAlloX
I0116 14:09:26.603434       1 util.go:1550] [meng] numAvailMachines == 11,  allpods length: 4
I0116 14:09:26.603585       1 util.go:1534] [meng] calling OnlineAlloX
I0116 14:09:26.603606       1 util.go:1550] [meng] numAvailMachines == 11,  allpods length: 4
I0116 14:09:26.704234       1 util.go:1534] [meng] calling OnlineAlloX
I0116 14:09:26.704279       1 util.go:1550] [meng] numAvailMachines == 11,  allpods length: 4
I0116 14:09:26.704436       1 util.go:1534] [meng] calling OnlineAlloX
I0116 14:09:26.704460       1 util.go:1550] [meng] numAvailMachines == 11,  allpods length: 4
I0116 14:09:26.804684       1 util.go:1534] [meng] calling OnlineAlloX
I0116 14:09:26.804731       1 util.go:1550] [meng] numAvailMachines == 11,  allpods length: 4
I0116 14:09:26.804894       1 util.go:1534] [meng] calling OnlineAlloX
I0116 14:09:26.804919       1 util.go:1550] [meng] numAvailMachines == 11,  allpods length: 4
I0116 14:09:26.905147       1 util.go:1534] [meng] calling OnlineAlloX
I0116 14:09:26.905187       1 util.go:1550] [meng] numAvailMachines == 11,  allpods length: 4
I0116 14:09:26.905354       1 util.go:1534] [meng] calling OnlineAlloX
I0116 14:09:26.905379       1 util.go:1550] [meng] numAvailMachines == 11,  allpods length: 4
I0116 14:09:27.005624       1 util.go:1534] [meng] calling OnlineAlloX
I0116 14:09:27.005671       1 util.go:1550] [meng] numAvailMachines == 11,  allpods length: 4
I0116 14:09:27.005847       1 util.go:1534] [meng] calling OnlineAlloX
I0116 14:09:27.005871       1 util.go:1550] [meng] numAvailMachines == 11,  allpods length: 4
I0116 14:09:27.106098       1 util.go:1534] [meng] calling OnlineAlloX
I0116 14:09:27.106135       1 util.go:1550] [meng] numAvailMachines == 11,  allpods length: 4
I0116 14:09:27.106301       1 util.go:1534] [meng] calling OnlineAlloX
I0116 14:09:27.106326       1 util.go:1550] [meng] numAvailMachines == 11,  allpods length: 4
I0116 14:09:27.206557       1 util.go:1534] [meng] calling OnlineAlloX
I0116 14:09:27.206597       1 util.go:1550] [meng] numAvailMachines == 11,  allpods length: 4
I0116 14:09:27.206766       1 util.go:1534] [meng] calling OnlineAlloX
I0116 14:09:27.206791       1 util.go:1550] [meng] numAvailMachines == 11,  allpods length: 4
I0116 14:09:27.307021       1 util.go:1534] [meng] calling OnlineAlloX
I0116 14:09:27.307059       1 util.go:1550] [meng] numAvailMachines == 11,  allpods length: 4
I0116 14:09:27.307229       1 util.go:1534] [meng] calling OnlineAlloX
I0116 14:09:27.307253       1 util.go:1550] [meng] numAvailMachines == 11,  allpods length: 4
I0116 14:09:27.407471       1 util.go:1534] [meng] calling OnlineAlloX
I0116 14:09:27.407498       1 util.go:1550] [meng] numAvailMachines == 11,  allpods length: 4
I0116 14:09:27.407666       1 util.go:1534] [meng] calling OnlineAlloX
I0116 14:09:27.407688       1 util.go:1550] [meng] numAvailMachines == 11,  allpods length: 4
I0116 14:09:27.507926       1 util.go:1534] [meng] calling OnlineAlloX
I0116 14:09:27.507968       1 util.go:1550] [meng] numAvailMachines == 11,  allpods length: 4
I0116 14:09:27.508133       1 util.go:1534] [meng] calling OnlineAlloX
I0116 14:09:27.508157       1 util.go:1550] [meng] numAvailMachines == 11,  allpods length: 4
I0116 14:09:27.608396       1 util.go:1534] [meng] calling OnlineAlloX
I0116 14:09:27.608425       1 util.go:1550] [meng] numAvailMachines == 11,  allpods length: 4
I0116 14:09:27.608587       1 util.go:1534] [meng] calling OnlineAlloX
I0116 14:09:27.608610       1 util.go:1550] [meng] numAvailMachines == 11,  allpods length: 4
I0116 14:09:27.708844       1 util.go:1534] [meng] calling OnlineAlloX
I0116 14:09:27.708884       1 util.go:1550] [meng] numAvailMachines == 11,  allpods length: 4
I0116 14:09:27.709056       1 util.go:1534] [meng] calling OnlineAlloX
I0116 14:09:27.709082       1 util.go:1550] [meng] numAvailMachines == 11,  allpods length: 4
I0116 14:09:27.809307       1 util.go:1534] [meng] calling OnlineAlloX
I0116 14:09:27.809336       1 util.go:1550] [meng] numAvailMachines == 11,  allpods length: 4
I0116 14:09:27.809501       1 util.go:1534] [meng] calling OnlineAlloX
I0116 14:09:27.809524       1 util.go:1550] [meng] numAvailMachines == 11,  allpods length: 4
I0116 14:09:27.909758       1 util.go:1534] [meng] calling OnlineAlloX
I0116 14:09:27.909793       1 util.go:1550] [meng] numAvailMachines == 11,  allpods length: 4
I0116 14:09:27.909961       1 util.go:1534] [meng] calling OnlineAlloX
I0116 14:09:27.909983       1 util.go:1550] [meng] numAvailMachines == 11,  allpods length: 4
I0116 14:09:28.010630       1 util.go:1534] [meng] calling OnlineAlloX
I0116 14:09:28.010675       1 util.go:1550] [meng] numAvailMachines == 11,  allpods length: 4
I0116 14:09:28.010834       1 util.go:1534] [meng] calling OnlineAlloX
I0116 14:09:28.010858       1 util.go:1550] [meng] numAvailMachines == 11,  allpods length: 4
I0116 14:09:28.111088       1 util.go:1534] [meng] calling OnlineAlloX
I0116 14:09:28.111129       1 util.go:1550] [meng] numAvailMachines == 11,  allpods length: 4
I0116 14:09:28.111291       1 util.go:1534] [meng] calling OnlineAlloX
I0116 14:09:28.111316       1 util.go:1550] [meng] numAvailMachines == 11,  allpods length: 4
I0116 14:09:28.211531       1 util.go:1534] [meng] calling OnlineAlloX
I0116 14:09:28.211557       1 util.go:1550] [meng] numAvailMachines == 11,  allpods length: 4
I0116 14:09:28.211718       1 util.go:1534] [meng] calling OnlineAlloX
I0116 14:09:28.211739       1 util.go:1550] [meng] numAvailMachines == 11,  allpods length: 4
I0116 14:09:28.311952       1 util.go:1534] [meng] calling OnlineAlloX
I0116 14:09:28.311977       1 util.go:1550] [meng] numAvailMachines == 11,  allpods length: 4
I0116 14:09:28.312139       1 util.go:1534] [meng] calling OnlineAlloX
I0116 14:09:28.312159       1 util.go:1550] [meng] numAvailMachines == 11,  allpods length: 4
I0116 14:09:28.412377       1 util.go:1534] [meng] calling OnlineAlloX
I0116 14:09:28.412403       1 util.go:1550] [meng] numAvailMachines == 11,  allpods length: 4
I0116 14:09:28.412561       1 util.go:1534] [meng] calling OnlineAlloX
I0116 14:09:28.412582       1 util.go:1550] [meng] numAvailMachines == 11,  allpods length: 4
I0116 14:09:28.512812       1 util.go:1534] [meng] calling OnlineAlloX
I0116 14:09:28.512854       1 util.go:1550] [meng] numAvailMachines == 11,  allpods length: 4
I0116 14:09:28.513024       1 util.go:1534] [meng] calling OnlineAlloX
I0116 14:09:28.513048       1 util.go:1550] [meng] numAvailMachines == 11,  allpods length: 4
I0116 14:09:28.613292       1 util.go:1534] [meng] calling OnlineAlloX
I0116 14:09:28.613329       1 util.go:1550] [meng] numAvailMachines == 11,  allpods length: 4
I0116 14:09:28.613497       1 util.go:1534] [meng] calling OnlineAlloX
I0116 14:09:28.613520       1 util.go:1550] [meng] numAvailMachines == 11,  allpods length: 4
I0116 14:09:28.713756       1 util.go:1534] [meng] calling OnlineAlloX
I0116 14:09:28.713783       1 util.go:1550] [meng] numAvailMachines == 11,  allpods length: 4
I0116 14:09:28.713937       1 util.go:1534] [meng] calling OnlineAlloX
I0116 14:09:28.713958       1 util.go:1550] [meng] numAvailMachines == 11,  allpods length: 4
I0116 14:09:28.814182       1 util.go:1534] [meng] calling OnlineAlloX
I0116 14:09:28.814205       1 util.go:1550] [meng] numAvailMachines == 11,  allpods length: 4
I0116 14:09:28.814356       1 util.go:1534] [meng] calling OnlineAlloX
I0116 14:09:28.814377       1 util.go:1550] [meng] numAvailMachines == 11,  allpods length: 4
I0116 14:09:28.914598       1 util.go:1534] [meng] calling OnlineAlloX
I0116 14:09:28.914626       1 util.go:1550] [meng] numAvailMachines == 11,  allpods length: 4
I0116 14:09:28.914789       1 util.go:1534] [meng] calling OnlineAlloX
I0116 14:09:28.914810       1 util.go:1550] [meng] numAvailMachines == 11,  allpods length: 4
I0116 14:09:29.015039       1 util.go:1534] [meng] calling OnlineAlloX
I0116 14:09:29.015066       1 util.go:1550] [meng] numAvailMachines == 11,  allpods length: 4
I0116 14:09:29.015226       1 util.go:1534] [meng] calling OnlineAlloX
I0116 14:09:29.015247       1 util.go:1550] [meng] numAvailMachines == 11,  allpods length: 4
I0116 14:09:29.115468       1 util.go:1534] [meng] calling OnlineAlloX
I0116 14:09:29.115493       1 util.go:1550] [meng] numAvailMachines == 11,  allpods length: 4
I0116 14:09:29.115651       1 util.go:1534] [meng] calling OnlineAlloX
I0116 14:09:29.115671       1 util.go:1550] [meng] numAvailMachines == 11,  allpods length: 4
I0116 14:09:29.215898       1 util.go:1534] [meng] calling OnlineAlloX
I0116 14:09:29.215921       1 util.go:1550] [meng] numAvailMachines == 11,  allpods length: 4
I0116 14:09:29.216074       1 util.go:1534] [meng] calling OnlineAlloX
I0116 14:09:29.216095       1 util.go:1550] [meng] numAvailMachines == 11,  allpods length: 4
I0116 14:09:29.316626       1 util.go:1534] [meng] calling OnlineAlloX
I0116 14:09:29.316670       1 util.go:1550] [meng] numAvailMachines == 11,  allpods length: 4
I0116 14:09:29.316832       1 util.go:1534] [meng] calling OnlineAlloX
I0116 14:09:29.316856       1 util.go:1550] [meng] numAvailMachines == 11,  allpods length: 4
I0116 14:09:29.417078       1 util.go:1534] [meng] calling OnlineAlloX
I0116 14:09:29.417114       1 util.go:1550] [meng] numAvailMachines == 11,  allpods length: 4
I0116 14:09:29.417272       1 util.go:1534] [meng] calling OnlineAlloX
I0116 14:09:29.417295       1 util.go:1550] [meng] numAvailMachines == 11,  allpods length: 4
I0116 14:09:29.517525       1 util.go:1534] [meng] calling OnlineAlloX
I0116 14:09:29.517568       1 util.go:1550] [meng] numAvailMachines == 11,  allpods length: 4
I0116 14:09:29.517733       1 util.go:1534] [meng] calling OnlineAlloX
I0116 14:09:29.517758       1 util.go:1550] [meng] numAvailMachines == 11,  allpods length: 4
I0116 14:09:29.617978       1 util.go:1534] [meng] calling OnlineAlloX
I0116 14:09:29.618002       1 util.go:1550] [meng] numAvailMachines == 11,  allpods length: 4
I0116 14:09:29.618149       1 util.go:1534] [meng] calling OnlineAlloX
I0116 14:09:29.618170       1 util.go:1550] [meng] numAvailMachines == 11,  allpods length: 4
I0116 14:09:29.718390       1 util.go:1534] [meng] calling OnlineAlloX
I0116 14:09:29.718424       1 util.go:1550] [meng] numAvailMachines == 11,  allpods length: 4
I0116 14:09:29.718587       1 util.go:1534] [meng] calling OnlineAlloX
I0116 14:09:29.718609       1 util.go:1550] [meng] numAvailMachines == 11,  allpods length: 4
I0116 14:09:29.818833       1 util.go:1534] [meng] calling OnlineAlloX
I0116 14:09:29.818869       1 util.go:1550] [meng] numAvailMachines == 11,  allpods length: 4
I0116 14:09:29.819030       1 util.go:1534] [meng] calling OnlineAlloX
I0116 14:09:29.819056       1 util.go:1550] [meng] numAvailMachines == 11,  allpods length: 4
I0116 14:09:29.919285       1 util.go:1534] [meng] calling OnlineAlloX
I0116 14:09:29.919310       1 util.go:1550] [meng] numAvailMachines == 11,  allpods length: 4
I0116 14:09:29.919466       1 util.go:1534] [meng] calling OnlineAlloX
I0116 14:09:29.919488       1 util.go:1550] [meng] numAvailMachines == 11,  allpods length: 4
I0116 14:09:30.019706       1 util.go:1534] [meng] calling OnlineAlloX
I0116 14:09:30.019732       1 util.go:1550] [meng] numAvailMachines == 11,  allpods length: 4
I0116 14:09:30.019882       1 util.go:1534] [meng] calling OnlineAlloX
I0116 14:09:30.019903       1 util.go:1550] [meng] numAvailMachines == 11,  allpods length: 4
I0116 14:09:30.120122       1 util.go:1534] [meng] calling OnlineAlloX
I0116 14:09:30.120144       1 util.go:1550] [meng] numAvailMachines == 11,  allpods length: 4
I0116 14:09:30.120297       1 util.go:1534] [meng] calling OnlineAlloX
I0116 14:09:30.120318       1 util.go:1550] [meng] numAvailMachines == 11,  allpods length: 4
I0116 14:09:30.220545       1 util.go:1534] [meng] calling OnlineAlloX
I0116 14:09:30.220577       1 util.go:1550] [meng] numAvailMachines == 11,  allpods length: 4
I0116 14:09:30.220733       1 util.go:1534] [meng] calling OnlineAlloX
I0116 14:09:30.220754       1 util.go:1550] [meng] numAvailMachines == 11,  allpods length: 4
I0116 14:09:30.320980       1 util.go:1534] [meng] calling OnlineAlloX
I0116 14:09:30.321019       1 util.go:1550] [meng] numAvailMachines == 11,  allpods length: 4
I0116 14:09:30.321184       1 util.go:1534] [meng] calling OnlineAlloX
I0116 14:09:30.321209       1 util.go:1550] [meng] numAvailMachines == 11,  allpods length: 4
I0116 14:09:30.421431       1 util.go:1534] [meng] calling OnlineAlloX
I0116 14:09:30.421456       1 util.go:1550] [meng] numAvailMachines == 11,  allpods length: 4
I0116 14:09:30.421617       1 util.go:1534] [meng] calling OnlineAlloX
I0116 14:09:30.421639       1 util.go:1550] [meng] numAvailMachines == 11,  allpods length: 4
I0116 14:09:30.521859       1 util.go:1534] [meng] calling OnlineAlloX
I0116 14:09:30.521895       1 util.go:1550] [meng] numAvailMachines == 11,  allpods length: 4
I0116 14:09:30.522058       1 util.go:1534] [meng] calling OnlineAlloX
I0116 14:09:30.522083       1 util.go:1550] [meng] numAvailMachines == 11,  allpods length: 4
I0116 14:09:30.622675       1 util.go:1534] [meng] calling OnlineAlloX
I0116 14:09:30.622722       1 util.go:1550] [meng] numAvailMachines == 11,  allpods length: 4
I0116 14:09:30.622878       1 util.go:1534] [meng] calling OnlineAlloX
I0116 14:09:30.622902       1 util.go:1550] [meng] numAvailMachines == 11,  allpods length: 4
I0116 14:09:30.723128       1 util.go:1534] [meng] calling OnlineAlloX
I0116 14:09:30.723159       1 util.go:1550] [meng] numAvailMachines == 11,  allpods length: 4
I0116 14:09:30.723317       1 util.go:1534] [meng] calling OnlineAlloX
I0116 14:09:30.723341       1 util.go:1550] [meng] numAvailMachines == 11,  allpods length: 4
I0116 14:09:30.823558       1 util.go:1534] [meng] calling OnlineAlloX
I0116 14:09:30.823597       1 util.go:1550] [meng] numAvailMachines == 11,  allpods length: 4
I0116 14:09:30.823754       1 util.go:1534] [meng] calling OnlineAlloX
I0116 14:09:30.823778       1 util.go:1550] [meng] numAvailMachines == 11,  allpods length: 4
I0116 14:09:30.924007       1 util.go:1534] [meng] calling OnlineAlloX
I0116 14:09:30.924047       1 util.go:1550] [meng] numAvailMachines == 11,  allpods length: 4
I0116 14:09:30.924212       1 util.go:1534] [meng] calling OnlineAlloX
I0116 14:09:30.924235       1 util.go:1550] [meng] numAvailMachines == 11,  allpods length: 4
I0116 14:09:31.024461       1 util.go:1534] [meng] calling OnlineAlloX
I0116 14:09:31.024485       1 util.go:1550] [meng] numAvailMachines == 11,  allpods length: 4
I0116 14:09:31.024639       1 util.go:1534] [meng] calling OnlineAlloX
I0116 14:09:31.024660       1 util.go:1550] [meng] numAvailMachines == 11,  allpods length: 4
I0116 14:09:31.124884       1 util.go:1534] [meng] calling OnlineAlloX
I0116 14:09:31.124924       1 util.go:1550] [meng] numAvailMachines == 11,  allpods length: 4
I0116 14:09:31.125091       1 util.go:1534] [meng] calling OnlineAlloX
I0116 14:09:31.125115       1 util.go:1550] [meng] numAvailMachines == 11,  allpods length: 4
I0116 14:09:31.225338       1 util.go:1534] [meng] calling OnlineAlloX
I0116 14:09:31.225374       1 util.go:1550] [meng] numAvailMachines == 11,  allpods length: 4
I0116 14:09:31.225530       1 util.go:1534] [meng] calling OnlineAlloX
I0116 14:09:31.225553       1 util.go:1550] [meng] numAvailMachines == 11,  allpods length: 4
I0116 14:09:31.325775       1 util.go:1534] [meng] calling OnlineAlloX
I0116 14:09:31.325811       1 util.go:1550] [meng] numAvailMachines == 11,  allpods length: 4
I0116 14:09:31.325972       1 util.go:1534] [meng] calling OnlineAlloX
I0116 14:09:31.325994       1 util.go:1550] [meng] numAvailMachines == 11,  allpods length: 4
I0116 14:09:31.426224       1 util.go:1534] [meng] calling OnlineAlloX
I0116 14:09:31.426262       1 util.go:1550] [meng] numAvailMachines == 11,  allpods length: 4
I0116 14:09:31.426427       1 util.go:1534] [meng] calling OnlineAlloX
I0116 14:09:31.426452       1 util.go:1550] [meng] numAvailMachines == 11,  allpods length: 4
I0116 14:09:31.526673       1 util.go:1534] [meng] calling OnlineAlloX
I0116 14:09:31.526708       1 util.go:1550] [meng] numAvailMachines == 11,  allpods length: 4
I0116 14:09:31.526868       1 util.go:1534] [meng] calling OnlineAlloX
I0116 14:09:31.526890       1 util.go:1550] [meng] numAvailMachines == 11,  allpods length: 4
I0116 14:09:31.627111       1 util.go:1534] [meng] calling OnlineAlloX
I0116 14:09:31.627144       1 util.go:1550] [meng] numAvailMachines == 11,  allpods length: 4
I0116 14:09:31.627301       1 util.go:1534] [meng] calling OnlineAlloX
I0116 14:09:31.627324       1 util.go:1550] [meng] numAvailMachines == 11,  allpods length: 4
I0116 14:09:31.727545       1 util.go:1534] [meng] calling OnlineAlloX
I0116 14:09:31.727576       1 util.go:1550] [meng] numAvailMachines == 11,  allpods length: 4
I0116 14:09:31.727737       1 util.go:1534] [meng] calling OnlineAlloX
I0116 14:09:31.727760       1 util.go:1550] [meng] numAvailMachines == 11,  allpods length: 4
I0116 14:09:31.827984       1 util.go:1534] [meng] calling OnlineAlloX
I0116 14:09:31.828023       1 util.go:1550] [meng] numAvailMachines == 11,  allpods length: 4
I0116 14:09:31.828187       1 util.go:1534] [meng] calling OnlineAlloX
I0116 14:09:31.828211       1 util.go:1550] [meng] numAvailMachines == 11,  allpods length: 4
I0116 14:09:31.928433       1 util.go:1534] [meng] calling OnlineAlloX
I0116 14:09:31.928461       1 util.go:1550] [meng] numAvailMachines == 11,  allpods length: 4
I0116 14:09:31.929036       1 util.go:1534] [meng] calling OnlineAlloX
I0116 14:09:31.929145       1 util.go:1550] [meng] numAvailMachines == 11,  allpods length: 4
I0116 14:09:32.029662       1 util.go:1534] [meng] calling OnlineAlloX
I0116 14:09:32.029705       1 util.go:1550] [meng] numAvailMachines == 11,  allpods length: 4
I0116 14:09:32.029868       1 util.go:1534] [meng] calling OnlineAlloX
I0116 14:09:32.029891       1 util.go:1550] [meng] numAvailMachines == 11,  allpods length: 4
I0116 14:09:32.130118       1 util.go:1534] [meng] calling OnlineAlloX
I0116 14:09:32.130151       1 util.go:1550] [meng] numAvailMachines == 11,  allpods length: 4
I0116 14:09:32.130311       1 util.go:1534] [meng] calling OnlineAlloX
I0116 14:09:32.130334       1 util.go:1550] [meng] numAvailMachines == 11,  allpods length: 4
I0116 14:09:32.230561       1 util.go:1534] [meng] calling OnlineAlloX
I0116 14:09:32.230605       1 util.go:1550] [meng] numAvailMachines == 11,  allpods length: 4
I0116 14:09:32.230768       1 util.go:1534] [meng] calling OnlineAlloX
I0116 14:09:32.230792       1 util.go:1550] [meng] numAvailMachines == 11,  allpods length: 4
I0116 14:09:32.331010       1 util.go:1534] [meng] calling OnlineAlloX
I0116 14:09:32.331033       1 util.go:1550] [meng] numAvailMachines == 11,  allpods length: 4
I0116 14:09:32.331190       1 util.go:1534] [meng] calling OnlineAlloX
I0116 14:09:32.331212       1 util.go:1550] [meng] numAvailMachines == 11,  allpods length: 4
I0116 14:09:32.431428       1 util.go:1534] [meng] calling OnlineAlloX
I0116 14:09:32.431450       1 util.go:1550] [meng] numAvailMachines == 11,  allpods length: 4
I0116 14:09:32.431601       1 util.go:1534] [meng] calling OnlineAlloX
I0116 14:09:32.431623       1 util.go:1550] [meng] numAvailMachines == 11,  allpods length: 4
I0116 14:09:32.531837       1 util.go:1534] [meng] calling OnlineAlloX
I0116 14:09:32.531859       1 util.go:1550] [meng] numAvailMachines == 11,  allpods length: 4
I0116 14:09:32.532019       1 util.go:1534] [meng] calling OnlineAlloX
I0116 14:09:32.532041       1 util.go:1550] [meng] numAvailMachines == 11,  allpods length: 4
I0116 14:09:32.632264       1 util.go:1534] [meng] calling OnlineAlloX
I0116 14:09:32.632288       1 util.go:1550] [meng] numAvailMachines == 11,  allpods length: 4
I0116 14:09:32.632440       1 util.go:1534] [meng] calling OnlineAlloX
I0116 14:09:32.632460       1 util.go:1550] [meng] numAvailMachines == 11,  allpods length: 4
I0116 14:09:32.732685       1 util.go:1534] [meng] calling OnlineAlloX
I0116 14:09:32.732722       1 util.go:1550] [meng] numAvailMachines == 11,  allpods length: 4
I0116 14:09:32.732880       1 util.go:1534] [meng] calling OnlineAlloX
I0116 14:09:32.732904       1 util.go:1550] [meng] numAvailMachines == 11,  allpods length: 4
I0116 14:09:32.833125       1 util.go:1534] [meng] calling OnlineAlloX
I0116 14:09:32.833148       1 util.go:1550] [meng] numAvailMachines == 11,  allpods length: 4
I0116 14:09:32.833301       1 util.go:1534] [meng] calling OnlineAlloX
I0116 14:09:32.833323       1 util.go:1550] [meng] numAvailMachines == 11,  allpods length: 4
I0116 14:09:32.933536       1 util.go:1534] [meng] calling OnlineAlloX
I0116 14:09:32.933560       1 util.go:1550] [meng] numAvailMachines == 11,  allpods length: 4
I0116 14:09:32.933721       1 util.go:1534] [meng] calling OnlineAlloX
I0116 14:09:32.933743       1 util.go:1550] [meng] numAvailMachines == 11,  allpods length: 4
I0116 14:09:33.033960       1 util.go:1534] [meng] calling OnlineAlloX
I0116 14:09:33.033983       1 util.go:1550] [meng] numAvailMachines == 11,  allpods length: 4
I0116 14:09:33.034135       1 util.go:1534] [meng] calling OnlineAlloX
I0116 14:09:33.034157       1 util.go:1550] [meng] numAvailMachines == 11,  allpods length: 4
I0116 14:09:33.134375       1 util.go:1534] [meng] calling OnlineAlloX
I0116 14:09:33.134399       1 util.go:1550] [meng] numAvailMachines == 11,  allpods length: 4
I0116 14:09:33.134552       1 util.go:1534] [meng] calling OnlineAlloX
I0116 14:09:33.134573       1 util.go:1550] [meng] numAvailMachines == 11,  allpods length: 4
I0116 14:09:33.234793       1 util.go:1534] [meng] calling OnlineAlloX
I0116 14:09:33.234815       1 util.go:1550] [meng] numAvailMachines == 11,  allpods length: 4
I0116 14:09:33.234968       1 util.go:1534] [meng] calling OnlineAlloX
I0116 14:09:33.234988       1 util.go:1550] [meng] numAvailMachines == 11,  allpods length: 4
I0116 14:09:33.335204       1 util.go:1534] [meng] calling OnlineAlloX
I0116 14:09:33.335232       1 util.go:1550] [meng] numAvailMachines == 11,  allpods length: 4
I0116 14:09:33.335743       1 util.go:1534] [meng] calling OnlineAlloX
I0116 14:09:33.335841       1 util.go:1550] [meng] numAvailMachines == 11,  allpods length: 4
I0116 14:09:33.436162       1 util.go:1534] [meng] calling OnlineAlloX
I0116 14:09:33.436203       1 util.go:1550] [meng] numAvailMachines == 11,  allpods length: 4
I0116 14:09:33.436364       1 util.go:1534] [meng] calling OnlineAlloX
I0116 14:09:33.436387       1 util.go:1550] [meng] numAvailMachines == 11,  allpods length: 4
I0116 14:09:33.536611       1 util.go:1534] [meng] calling OnlineAlloX
I0116 14:09:33.536654       1 util.go:1550] [meng] numAvailMachines == 11,  allpods length: 4
I0116 14:09:33.536820       1 util.go:1534] [meng] calling OnlineAlloX
I0116 14:09:33.536843       1 util.go:1550] [meng] numAvailMachines == 11,  allpods length: 4
I0116 14:09:33.637065       1 util.go:1534] [meng] calling OnlineAlloX
I0116 14:09:33.637097       1 util.go:1550] [meng] numAvailMachines == 11,  allpods length: 4
I0116 14:09:33.637253       1 util.go:1534] [meng] calling OnlineAlloX
I0116 14:09:33.637276       1 util.go:1550] [meng] numAvailMachines == 11,  allpods length: 4
I0116 14:09:33.737497       1 util.go:1534] [meng] calling OnlineAlloX
I0116 14:09:33.737530       1 util.go:1550] [meng] numAvailMachines == 11,  allpods length: 4
I0116 14:09:33.737701       1 util.go:1534] [meng] calling OnlineAlloX
I0116 14:09:33.737724       1 util.go:1550] [meng] numAvailMachines == 11,  allpods length: 4
I0116 14:09:33.837954       1 util.go:1534] [meng] calling OnlineAlloX
I0116 14:09:33.837985       1 util.go:1550] [meng] numAvailMachines == 11,  allpods length: 4
I0116 14:09:33.838141       1 util.go:1534] [meng] calling OnlineAlloX
I0116 14:09:33.838162       1 util.go:1550] [meng] numAvailMachines == 11,  allpods length: 4
I0116 14:09:33.938379       1 util.go:1534] [meng] calling OnlineAlloX
I0116 14:09:33.938415       1 util.go:1550] [meng] numAvailMachines == 11,  allpods length: 4
I0116 14:09:33.938575       1 util.go:1534] [meng] calling OnlineAlloX
I0116 14:09:33.938601       1 util.go:1550] [meng] numAvailMachines == 11,  allpods length: 4
I0116 14:09:34.038826       1 util.go:1534] [meng] calling OnlineAlloX
I0116 14:09:34.038866       1 util.go:1550] [meng] numAvailMachines == 11,  allpods length: 4
I0116 14:09:34.039031       1 util.go:1534] [meng] calling OnlineAlloX
I0116 14:09:34.039058       1 util.go:1550] [meng] numAvailMachines == 11,  allpods length: 4
I0116 14:09:34.139282       1 util.go:1534] [meng] calling OnlineAlloX
I0116 14:09:34.139309       1 util.go:1550] [meng] numAvailMachines == 11,  allpods length: 4
I0116 14:09:34.139462       1 util.go:1534] [meng] calling OnlineAlloX
I0116 14:09:34.139482       1 util.go:1550] [meng] numAvailMachines == 11,  allpods length: 4
I0116 14:09:34.239696       1 util.go:1534] [meng] calling OnlineAlloX
I0116 14:09:34.239720       1 util.go:1550] [meng] numAvailMachines == 11,  allpods length: 4
I0116 14:09:34.239867       1 util.go:1534] [meng] calling OnlineAlloX
I0116 14:09:34.239886       1 util.go:1550] [meng] numAvailMachines == 11,  allpods length: 4
I0116 14:09:34.340101       1 util.go:1534] [meng] calling OnlineAlloX
I0116 14:09:34.340130       1 util.go:1550] [meng] numAvailMachines == 11,  allpods length: 4
I0116 14:09:34.340290       1 util.go:1534] [meng] calling OnlineAlloX
I0116 14:09:34.340314       1 util.go:1550] [meng] numAvailMachines == 11,  allpods length: 4
I0116 14:09:34.440541       1 util.go:1534] [meng] calling OnlineAlloX
I0116 14:09:34.440568       1 util.go:1550] [meng] numAvailMachines == 11,  allpods length: 4
I0116 14:09:34.440724       1 util.go:1534] [meng] calling OnlineAlloX
I0116 14:09:34.440746       1 util.go:1550] [meng] numAvailMachines == 11,  allpods length: 4
I0116 14:09:34.540967       1 util.go:1534] [meng] calling OnlineAlloX
I0116 14:09:34.540996       1 util.go:1550] [meng] numAvailMachines == 11,  allpods length: 4
I0116 14:09:34.541150       1 util.go:1534] [meng] calling OnlineAlloX
I0116 14:09:34.541172       1 util.go:1550] [meng] numAvailMachines == 11,  allpods length: 4
I0116 14:09:34.641394       1 util.go:1534] [meng] calling OnlineAlloX
I0116 14:09:34.641417       1 util.go:1550] [meng] numAvailMachines == 11,  allpods length: 4
I0116 14:09:34.641572       1 util.go:1534] [meng] calling OnlineAlloX
I0116 14:09:34.641602       1 util.go:1550] [meng] numAvailMachines == 11,  allpods length: 4
I0116 14:09:34.741832       1 util.go:1534] [meng] calling OnlineAlloX
I0116 14:09:34.741871       1 util.go:1550] [meng] numAvailMachines == 11,  allpods length: 4
I0116 14:09:34.742029       1 util.go:1534] [meng] calling OnlineAlloX
I0116 14:09:34.742052       1 util.go:1550] [meng] numAvailMachines == 11,  allpods length: 4
I0116 14:09:34.842679       1 util.go:1534] [meng] calling OnlineAlloX
I0116 14:09:34.842730       1 util.go:1550] [meng] numAvailMachines == 11,  allpods length: 4
I0116 14:09:34.842894       1 util.go:1534] [meng] calling OnlineAlloX
I0116 14:09:34.842926       1 util.go:1550] [meng] numAvailMachines == 11,  allpods length: 4
I0116 14:09:34.943165       1 util.go:1534] [meng] calling OnlineAlloX
I0116 14:09:34.943217       1 util.go:1550] [meng] numAvailMachines == 11,  allpods length: 4
I0116 14:09:34.943387       1 util.go:1534] [meng] calling OnlineAlloX
I0116 14:09:34.943413       1 util.go:1550] [meng] numAvailMachines == 11,  allpods length: 4
I0116 14:09:35.043640       1 util.go:1534] [meng] calling OnlineAlloX
I0116 14:09:35.043680       1 util.go:1550] [meng] numAvailMachines == 11,  allpods length: 4
I0116 14:09:35.043834       1 util.go:1534] [meng] calling OnlineAlloX
I0116 14:09:35.043858       1 util.go:1550] [meng] numAvailMachines == 11,  allpods length: 4
I0116 14:09:35.144071       1 util.go:1534] [meng] calling OnlineAlloX
I0116 14:09:35.144097       1 util.go:1550] [meng] numAvailMachines == 11,  allpods length: 4
I0116 14:09:35.144250       1 util.go:1534] [meng] calling OnlineAlloX
I0116 14:09:35.144272       1 util.go:1550] [meng] numAvailMachines == 11,  allpods length: 4
I0116 14:09:35.244494       1 util.go:1534] [meng] calling OnlineAlloX
I0116 14:09:35.244533       1 util.go:1550] [meng] numAvailMachines == 11,  allpods length: 4
I0116 14:09:35.244689       1 util.go:1534] [meng] calling OnlineAlloX
I0116 14:09:35.244713       1 util.go:1550] [meng] numAvailMachines == 11,  allpods length: 4
I0116 14:09:35.344926       1 util.go:1534] [meng] calling OnlineAlloX
I0116 14:09:35.344949       1 util.go:1550] [meng] numAvailMachines == 11,  allpods length: 4
I0116 14:09:35.345102       1 util.go:1534] [meng] calling OnlineAlloX
I0116 14:09:35.345125       1 util.go:1550] [meng] numAvailMachines == 11,  allpods length: 4
I0116 14:09:35.445341       1 util.go:1534] [meng] calling OnlineAlloX
I0116 14:09:35.445364       1 util.go:1550] [meng] numAvailMachines == 11,  allpods length: 4
I0116 14:09:35.445515       1 util.go:1534] [meng] calling OnlineAlloX
I0116 14:09:35.445536       1 util.go:1550] [meng] numAvailMachines == 11,  allpods length: 4
I0116 14:09:35.545757       1 util.go:1534] [meng] calling OnlineAlloX
I0116 14:09:35.545793       1 util.go:1550] [meng] numAvailMachines == 11,  allpods length: 4
I0116 14:09:35.545948       1 util.go:1534] [meng] calling OnlineAlloX
I0116 14:09:35.545972       1 util.go:1550] [meng] numAvailMachines == 11,  allpods length: 4
I0116 14:09:35.646184       1 util.go:1534] [meng] calling OnlineAlloX
I0116 14:09:35.646210       1 util.go:1550] [meng] numAvailMachines == 11,  allpods length: 4
I0116 14:09:35.646354       1 util.go:1534] [meng] calling OnlineAlloX
I0116 14:09:35.646374       1 util.go:1550] [meng] numAvailMachines == 11,  allpods length: 4
I0116 14:09:35.746585       1 util.go:1534] [meng] calling OnlineAlloX
I0116 14:09:35.746622       1 util.go:1550] [meng] numAvailMachines == 11,  allpods length: 4
I0116 14:09:35.746777       1 util.go:1534] [meng] calling OnlineAlloX
I0116 14:09:35.746803       1 util.go:1550] [meng] numAvailMachines == 11,  allpods length: 4
I0116 14:09:35.847022       1 util.go:1534] [meng] calling OnlineAlloX
I0116 14:09:35.847048       1 util.go:1550] [meng] numAvailMachines == 11,  allpods length: 4
I0116 14:09:35.847204       1 util.go:1534] [meng] calling OnlineAlloX
I0116 14:09:35.847225       1 util.go:1550] [meng] numAvailMachines == 11,  allpods length: 4
I0116 14:09:35.947445       1 util.go:1534] [meng] calling OnlineAlloX
I0116 14:09:35.947483       1 util.go:1550] [meng] numAvailMachines == 11,  allpods length: 4
I0116 14:09:35.947639       1 util.go:1534] [meng] calling OnlineAlloX
I0116 14:09:35.947663       1 util.go:1550] [meng] numAvailMachines == 11,  allpods length: 4
I0116 14:09:36.047886       1 util.go:1534] [meng] calling OnlineAlloX
I0116 14:09:36.047921       1 util.go:1550] [meng] numAvailMachines == 11,  allpods length: 4
I0116 14:09:36.048079       1 util.go:1534] [meng] calling OnlineAlloX
I0116 14:09:36.048101       1 util.go:1550] [meng] numAvailMachines == 11,  allpods length: 4
I0116 14:09:36.148319       1 util.go:1534] [meng] calling OnlineAlloX
I0116 14:09:36.148345       1 util.go:1550] [meng] numAvailMachines == 11,  allpods length: 4
I0116 14:09:36.148848       1 util.go:1534] [meng] calling OnlineAlloX
I0116 14:09:36.148940       1 util.go:1550] [meng] numAvailMachines == 11,  allpods length: 4
I0116 14:09:36.249341       1 util.go:1534] [meng] calling OnlineAlloX
I0116 14:09:36.249380       1 util.go:1550] [meng] numAvailMachines == 11,  allpods length: 4
I0116 14:09:36.249536       1 util.go:1534] [meng] calling OnlineAlloX
I0116 14:09:36.249560       1 util.go:1550] [meng] numAvailMachines == 11,  allpods length: 4
I0116 14:09:36.349791       1 util.go:1534] [meng] calling OnlineAlloX
I0116 14:09:36.349831       1 util.go:1550] [meng] numAvailMachines == 11,  allpods length: 4
I0116 14:09:36.349986       1 util.go:1534] [meng] calling OnlineAlloX
I0116 14:09:36.350009       1 util.go:1550] [meng] numAvailMachines == 11,  allpods length: 4
I0116 14:09:36.450238       1 util.go:1534] [meng] calling OnlineAlloX
I0116 14:09:36.450276       1 util.go:1550] [meng] numAvailMachines == 11,  allpods length: 4
I0116 14:09:36.450431       1 util.go:1534] [meng] calling OnlineAlloX
I0116 14:09:36.450455       1 util.go:1550] [meng] numAvailMachines == 11,  allpods length: 4
I0116 14:09:36.550675       1 util.go:1534] [meng] calling OnlineAlloX
I0116 14:09:36.550707       1 util.go:1550] [meng] numAvailMachines == 11,  allpods length: 4
I0116 14:09:36.550859       1 util.go:1534] [meng] calling OnlineAlloX
I0116 14:09:36.550880       1 util.go:1550] [meng] numAvailMachines == 11,  allpods length: 4
I0116 14:09:36.651101       1 util.go:1534] [meng] calling OnlineAlloX
I0116 14:09:36.651126       1 util.go:1550] [meng] numAvailMachines == 11,  allpods length: 4
I0116 14:09:36.651279       1 util.go:1534] [meng] calling OnlineAlloX
I0116 14:09:36.651300       1 util.go:1550] [meng] numAvailMachines == 11,  allpods length: 4
I0116 14:09:36.751523       1 util.go:1534] [meng] calling OnlineAlloX
I0116 14:09:36.751563       1 util.go:1550] [meng] numAvailMachines == 11,  allpods length: 4
I0116 14:09:36.751725       1 util.go:1534] [meng] calling OnlineAlloX
I0116 14:09:36.751748       1 util.go:1550] [meng] numAvailMachines == 11,  allpods length: 4
I0116 14:09:36.851903       1 factory.go:1129] [meng] deletePodFromCache
I0116 14:09:36.851916       1 factory.go:1136] [meng] JCT: 1m38.875095322s, total jct: 29m58.042957361s, count: 33, average JCT: 54.486150223s
I0116 14:09:36.851962       1 util.go:1534] [meng] calling OnlineAlloX
I0116 14:09:36.852016       1 util.go:1550] [meng] numAvailMachines == 11,  allpods length: 4
I0116 14:09:36.852189       1 util.go:1534] [meng] calling OnlineAlloX
I0116 14:09:36.852213       1 util.go:1550] [meng] numAvailMachines == 11,  allpods length: 4
I0116 14:09:36.865289       1 factory.go:798] [meng] computeComplTimeForAllPods completed
I0116 14:09:36.865310       1 factory.go:806] [tanle] Event pod completed user2/user2-pytorch-shufflenet%!(EXTRA v1.PodPhase=Succeeded)
I0116 14:09:36.865338       1 factory.go:1149] [meng] check delete pod user2/user2-pytorch-shufflenet, Running
I0116 14:09:36.865344       1 util.go:143] [meng] UpdateFairScore user2/user2-pytorch-shufflenet, false
I0116 14:09:36.865351       1 util.go:192] [meng] delete PodMachineMap in UpdateFairScore user2/user2-pytorch-shufflenet, false
I0116 14:09:36.865356       1 util.go:196] [tanle] FairScoreMap:  map[user4:0.2500000000000001 user1:0.2500000000000001 user2:0.2500000000000001 user3:8.326672684688674e-17]
I0116 14:09:36.952431       1 util.go:1534] [meng] calling OnlineAlloX
I0116 14:09:36.952465       1 util.go:1550] [meng] numAvailMachines == 12,  allpods length: 4
I0116 14:09:36.952855       1 util.go:196] [tanle] FairScoreMap:  map[user1:0.2500000000000001 user2:0.2500000000000001 user3:0.2500000000000001 user4:0.2500000000000001]
I0116 14:09:36.955050       1 scheduler.go:406] [tanle] binding user3/user3-pytorch-shufflenet on GPU true-->meng-allox-egpu-1
I0116 14:09:36.985663       1 factory.go:1129] [meng] deletePodFromCache
I0116 14:09:36.985679       1 factory.go:1136] [meng] JCT: 1m39.008859573s, total jct: 31m37.051816934s, count: 34, average JCT: 55.795641674s
I0116 14:09:36.998781       1 factory.go:798] [meng] computeComplTimeForAllPods completed
I0116 14:09:36.998800       1 factory.go:806] [tanle] Event pod completed user2/user2-pytorch-mobilenet%!(EXTRA v1.PodPhase=Succeeded)
I0116 14:09:36.998822       1 factory.go:1149] [meng] check delete pod user2/user2-pytorch-mobilenet, Running
I0116 14:09:36.998828       1 util.go:143] [meng] UpdateFairScore user2/user2-pytorch-mobilenet, false
I0116 14:09:36.998835       1 util.go:192] [meng] delete PodMachineMap in UpdateFairScore user2/user2-pytorch-mobilenet, false
I0116 14:09:36.998839       1 util.go:196] [tanle] FairScoreMap:  map[user2:1.1102230246251565e-16 user3:0.2500000000000001 user4:0.2500000000000001 user1:0.2500000000000001]
I0116 14:09:37.053018       1 util.go:1534] [meng] calling OnlineAlloX
I0116 14:09:37.053073       1 util.go:1550] [meng] numAvailMachines == 12,  allpods length: 3
I0116 14:09:37.053336       1 util.go:196] [tanle] FairScoreMap:  map[user1:0.2500000000000001 user2:1.1102230246251565e-16 user3:0.5000000000000001 user4:0.2500000000000001]
I0116 14:09:37.055725       1 scheduler.go:406] [tanle] binding user3/user3-pytorch-mobilenet on GPU true-->meng-allox-egpu-4
I0116 14:09:37.153492       1 util.go:1534] [meng] calling OnlineAlloX
I0116 14:09:37.153524       1 util.go:1550] [meng] numAvailMachines == 11,  allpods length: 2
I0116 14:09:37.153583       1 util.go:1534] [meng] calling OnlineAlloX
I0116 14:09:37.153625       1 util.go:1550] [meng] numAvailMachines == 11,  allpods length: 2
I0116 14:09:37.176593       1 factory.go:1129] [meng] deletePodFromCache
I0116 14:09:37.176602       1 factory.go:1136] [meng] JCT: 1m39.1997832s, total jct: 33m16.251600134s, count: 35, average JCT: 57.035760003s
I0116 14:09:37.186272       1 factory.go:798] [meng] computeComplTimeForAllPods completed
I0116 14:09:37.186293       1 factory.go:806] [tanle] Event pod completed user1/user1-pytorch-mobilenet%!(EXTRA v1.PodPhase=Succeeded)
I0116 14:09:37.186317       1 factory.go:1149] [meng] check delete pod user1/user1-pytorch-mobilenet, Running
I0116 14:09:37.186323       1 util.go:143] [meng] UpdateFairScore user1/user1-pytorch-mobilenet, false
I0116 14:09:37.186329       1 util.go:192] [meng] delete PodMachineMap in UpdateFairScore user1/user1-pytorch-mobilenet, false
I0116 14:09:37.186333       1 util.go:196] [tanle] FairScoreMap:  map[user3:0.5000000000000001 user4:0.2500000000000001 user1:1.1102230246251565e-16 user2:1.1102230246251565e-16]
I0116 14:09:37.253737       1 util.go:1534] [meng] calling OnlineAlloX
I0116 14:09:37.253763       1 util.go:1550] [meng] numAvailMachines == 12,  allpods length: 2
I0116 14:09:37.253958       1 util.go:196] [tanle] FairScoreMap:  map[user4:0.2500000000000001 user1:0.2500000000000001 user2:1.1102230246251565e-16 user3:0.5000000000000001]
I0116 14:09:37.256245       1 scheduler.go:406] [tanle] binding user1/user1-pytorch-shufflenet on GPU true-->meng-allox-egpu-3
I0116 14:09:37.354109       1 util.go:1534] [meng] calling OnlineAlloX
I0116 14:09:37.354148       1 util.go:1550] [meng] numAvailMachines == 11,  allpods length: 1
I0116 14:09:37.354169       1 util.go:1534] [meng] calling OnlineAlloX
I0116 14:09:37.354191       1 util.go:1550] [meng] numAvailMachines == 11,  allpods length: 1
I0116 14:09:37.454282       1 util.go:1534] [meng] calling OnlineAlloX
I0116 14:09:37.454325       1 util.go:1550] [meng] numAvailMachines == 11,  allpods length: 1
I0116 14:09:37.454349       1 util.go:1534] [meng] calling OnlineAlloX
I0116 14:09:37.454371       1 util.go:1550] [meng] numAvailMachines == 11,  allpods length: 1
I0116 14:09:37.554459       1 util.go:1534] [meng] calling OnlineAlloX
I0116 14:09:37.554493       1 util.go:1550] [meng] numAvailMachines == 11,  allpods length: 1
I0116 14:09:37.554515       1 util.go:1534] [meng] calling OnlineAlloX
I0116 14:09:37.554536       1 util.go:1550] [meng] numAvailMachines == 11,  allpods length: 1
I0116 14:09:37.575583       1 factory.go:1129] [meng] deletePodFromCache
I0116 14:09:37.575592       1 factory.go:1136] [meng] JCT: 1m39.598772957s, total jct: 34m55.850373091s, count: 36, average JCT: 58.218065919s
I0116 14:09:37.585451       1 factory.go:798] [meng] computeComplTimeForAllPods completed
I0116 14:09:37.585475       1 factory.go:806] [tanle] Event pod completed user4/user4-pytorch-mobilenet%!(EXTRA v1.PodPhase=Succeeded)
I0116 14:09:37.585494       1 factory.go:1149] [meng] check delete pod user4/user4-pytorch-mobilenet, Running
I0116 14:09:37.585499       1 util.go:143] [meng] UpdateFairScore user4/user4-pytorch-mobilenet, false
I0116 14:09:37.585505       1 util.go:192] [meng] delete PodMachineMap in UpdateFairScore user4/user4-pytorch-mobilenet, false
I0116 14:09:37.585509       1 util.go:196] [tanle] FairScoreMap:  map[user1:0.2500000000000001 user2:1.1102230246251565e-16 user3:0.5000000000000001 user4:1.1102230246251565e-16]
I0116 14:09:37.654625       1 util.go:1534] [meng] calling OnlineAlloX
I0116 14:09:37.654664       1 util.go:1550] [meng] numAvailMachines == 12,  allpods length: 1
I0116 14:09:37.654851       1 util.go:196] [tanle] FairScoreMap:  map[user1:0.2500000000000001 user2:1.1102230246251565e-16 user3:0.5000000000000001 user4:0.2500000000000001]
I0116 14:09:37.657040       1 scheduler.go:406] [tanle] binding user4/user4-pytorch-shufflenet on GPU true-->meng-allox-egpu-2
I0116 14:09:52.147016       1 factory.go:1129] [meng] deletePodFromCache
I0116 14:09:52.147029       1 factory.go:1136] [meng] JCT: 1m54.170210193s, total jct: 36m50.020583284s, count: 37, average JCT: 59.730286034s
I0116 14:09:52.160347       1 factory.go:798] [meng] computeComplTimeForAllPods completed
I0116 14:09:52.160373       1 factory.go:806] [tanle] Event pod completed user3/user3-pytorch-shufflenet%!(EXTRA v1.PodPhase=Succeeded)
I0116 14:09:52.160396       1 factory.go:1149] [meng] check delete pod user3/user3-pytorch-shufflenet, Running
I0116 14:09:52.160402       1 util.go:143] [meng] UpdateFairScore user3/user3-pytorch-shufflenet, false
I0116 14:09:52.160413       1 util.go:192] [meng] delete PodMachineMap in UpdateFairScore user3/user3-pytorch-shufflenet, false
I0116 14:09:52.160417       1 util.go:196] [tanle] FairScoreMap:  map[user1:0.2500000000000001 user2:1.1102230246251565e-16 user3:0.2500000000000001 user4:0.2500000000000001]
I0116 14:09:52.237642       1 factory.go:1129] [meng] deletePodFromCache
I0116 14:09:52.237652       1 factory.go:1136] [meng] JCT: 1m54.260833037s, total jct: 38m44.281416321s, count: 38, average JCT: 1m1.165300429s
I0116 14:09:52.248593       1 factory.go:798] [meng] computeComplTimeForAllPods completed
I0116 14:09:52.248625       1 factory.go:806] [tanle] Event pod completed user3/user3-pytorch-mobilenet%!(EXTRA v1.PodPhase=Succeeded)
I0116 14:09:52.248649       1 factory.go:1149] [meng] check delete pod user3/user3-pytorch-mobilenet, Running
I0116 14:09:52.248655       1 util.go:143] [meng] UpdateFairScore user3/user3-pytorch-mobilenet, false
I0116 14:09:52.248663       1 util.go:192] [meng] delete PodMachineMap in UpdateFairScore user3/user3-pytorch-mobilenet, false
I0116 14:09:52.248666       1 util.go:196] [tanle] FairScoreMap:  map[user2:1.1102230246251565e-16 user3:1.1102230246251565e-16 user4:0.2500000000000001 user1:0.2500000000000001]
I0116 14:09:52.508473       1 factory.go:1129] [meng] deletePodFromCache
I0116 14:09:52.508482       1 factory.go:1136] [meng] JCT: 1m54.531663164s, total jct: 40m38.813079485s, count: 39, average JCT: 1m2.533668704s
I0116 14:09:52.518266       1 factory.go:798] [meng] computeComplTimeForAllPods completed
I0116 14:09:52.518289       1 factory.go:806] [tanle] Event pod completed user1/user1-pytorch-shufflenet%!(EXTRA v1.PodPhase=Succeeded)
I0116 14:09:52.518312       1 factory.go:1149] [meng] check delete pod user1/user1-pytorch-shufflenet, Running
I0116 14:09:52.518318       1 util.go:143] [meng] UpdateFairScore user1/user1-pytorch-shufflenet, false
I0116 14:09:52.518325       1 util.go:192] [meng] delete PodMachineMap in UpdateFairScore user1/user1-pytorch-shufflenet, false
I0116 14:09:52.518328       1 util.go:196] [tanle] FairScoreMap:  map[user4:0.2500000000000001 user1:1.1102230246251565e-16 user2:1.1102230246251565e-16 user3:1.1102230246251565e-16]
I0116 14:09:52.915016       1 factory.go:1129] [meng] deletePodFromCache
I0116 14:09:52.915027       1 factory.go:1136] [meng] JCT: 1m54.93820743s, total jct: 42m33.751286915s, count: 40, average JCT: 1m3.843782172s
I0116 14:09:52.924687       1 factory.go:798] [meng] computeComplTimeForAllPods completed
I0116 14:09:52.924710       1 factory.go:806] [tanle] Event pod completed user4/user4-pytorch-shufflenet%!(EXTRA v1.PodPhase=Succeeded)
I0116 14:09:52.924726       1 factory.go:1149] [meng] check delete pod user4/user4-pytorch-shufflenet, Running
I0116 14:09:52.924732       1 util.go:143] [meng] UpdateFairScore user4/user4-pytorch-shufflenet, false
I0116 14:09:52.924738       1 util.go:192] [meng] delete PodMachineMap in UpdateFairScore user4/user4-pytorch-shufflenet, false
I0116 14:09:52.924741       1 util.go:196] [tanle] FairScoreMap:  map[user1:1.1102230246251565e-16 user2:1.1102230246251565e-16 user3:1.1102230246251565e-16 user4:1.1102230246251565e-16]
